Workbook

Sheet Tăng áp HK A1,2
A2: TT | B2: NỘI DUNG CÔNG VIỆC | D2: Nhãn hiệu/Xuất xứ | E2: Đơn vị tính | F2: Khối lượng | G2: Đầu vào | K2: Đơn giá | M2: Thuế Vat (theo quy định) | O2: Thành tiền | Q2: Ghi Chú
B3: BOQ | C3: NHÀ THẦU | G3: Đơn giá | H3: Lợi nhuận | I3: Hao hụt | J3: Vật liệu phụ | K3: Vật tư | L3: Nhân công | O3: Vật tư | P3: Nhân công
B4: Hạng mục: HỆ THỐNG ĐIỀU ÁP VÀ HÚT KHÓI - KHỐI A1+A2
B5: A. HỆ THỐNG TĂNG ÁP THANG BỘ VÀ SẢNH THANG MÁY HẦM
B6: Thiết bị
B7: Quạt tạo áp, động cơ cấp "H" chịu nhiệt độ tối đa 300°C trong 2h
B8: Quạt tạo áp: PAF-B2.01 - Hướng trục, nối ống gió. - Lưu lượng: 2600L/s@350Pa | E8: cái | F8: 1 | M8: =K8*8% -> 0 | N8: =L8*8% -> 0 | O8: =(K8+M8)*F8 -> 0 | P8: =(L8+N8)*F8 -> 0
B9: Quạt tạo áp: PAF-B1.01 - Hướng trục, nối ống gió. - Lưu lượng: 3400L/s@300Pa | E9: cái | F9: 1 | M9: =K9*8% -> 0 | N9: =L9*8% -> 0 | O9: =(K9+M9)*F9 -> 0 | P9: =(L9+N9)*F9 -> 0
B10: Quạt tạo áp: PAF-B1.02 - Hướng trục, nối ống gió. - Lưu lượng: 4300L/s@300Pa | E10: Cái | F10: 1 | M10: =K10*8% -> 0 | N10: =L10*8% -> 0 | O10: =(K10+M10)*F10 -> 0 | P10: =(L10+N10)*F10 -> 0
B11: Quạt tạo áp: PAF-B1.03 - Hướng trục, nối ống gió. - Lưu lượng: 3400L/s@300Pa | E11: Cái | F11: 1 | M11: =K11*8% -> 0 | N11: =L11*8% -> 0 | O11: =(K11+M11)*F11 -> 0 | P11: =(L11+N11)*F11 -> 0
B12: Quạt tạo áp: PAF-B1.04 - Hướng trục, nối ống gió. - Lưu lượng: 3400L/s@300Pa | E12: Cái | F12: 1 | M12: =K12*8% -> 0 | N12: =L12*8% -> 0 | O12: =(K12+M12)*F12 -> 0 | P12: =(L12+N12)*F12 -> 0
B13: Quạt tạo áp: PAF-A1-1F.01 - Hướng trục, nối ống gió. - Lưu lượng: 3200L/s@300Pa | E13: Cái | F13: 1 | M13: =K13*8% -> 0 | N13: =L13*8% -> 0 | O13: =(K13+M13)*F13 -> 0 | P13: =(L13+N13)*F13 -> 0
B14: Quạt tạo áp: PAF-A1-1F.02 - Hướng trục, nối ống gió. - Lưu lượng: 4150L/s@300Pa | E14: Cái | F14: 1 | M14: =K14*8% -> 0 | N14: =L14*8% -> 0 | O14: =(K14+M14)*F14 -> 0 | P14: =(L14+N14)*F14 -> 0
B15: Quạt tạo áp: PAF-A1-1F.03 - Hướng trục, nối ống gió. - Lưu lượng: 1050L/s@300Pa | E15: Cái | F15: 1 | M15: =K15*8% -> 0 | N15: =L15*8% -> 0 | O15: =(K15+M15)*F15 -> 0 | P15: =(L15+N15)*F15 -> 0
B16: Quạt tạo áp: PAF-A2-1F.01 - Hướng trục, nối ống gió. - Lưu lượng: 4300L/s@300Pa | E16: Cái | F16: 1 | M16: =K16*8% -> 0 | N16: =L16*8% -> 0 | O16: =(K16+M16)*F16 -> 0 | P16: =(L16+N16)*F16 -> 0
B17: Quạt tạo áp: PAF-A2-1F.02 - Hướng trục, nối ống gió. - Lưu lượng: 5100L/s@300Pa | E17: Cái | F17: 1
B18: Quạt tạo áp: PAF-A2-1F.03 - Hướng trục, nối ống gió. - Lưu lượng: 3400L/s@300Pa | E18: Cái | F18: 1 | M18: =K18*8% -> 0 | N18: =L18*8% -> 0 | O18: =(K18+M18)*F18 -> 0 | P18: =(L18+N18)*F18 -> 0
B19: Quạt tạo áp: PAF-A2-1F.04 - Hướng trục, nối ống gió. - Lưu lượng: 1050L/s@300Pa | E19: Cái | F19: 1 | M19: =K19*8% -> 0 | N19: =L19*8% -> 0 | O19: =(K19+M19)*F19 -> 0 | P19: =(L19+N19)*F19 -> 0
B20: Lò xo chống rung cho quạt | E20: Cái | F20: 48 | M20: =K20*8% -> 0 | N20: =L20*8% -> 0 | O20: =(K20+M20)*F20 -> 0 | P20: =(L20+N20)*F20 -> 0
B21: Vật tư phụ lắp đặt thiết bị (simili chống cháy, U...) | E21: Lô | F21: 1 | M21: =K21*8% -> 0 | N21: =L21*8% -> 0 | O21: =(K21+M21)*F21 -> 0 | P21: =(L21+N21)*F21 -> 0
B22: II. Vật tư đường ống | M22: =K22*8% -> 0 | N22: =L22*8% -> 0 | O22: =(K22+M22)*F22 -> 0 | P22: =(L22+N22)*F22 -> 0
B23: Bộ cảm biến khói, loại gắn trên ống gió | E23: cái | F23: 7 | M23: =K23*8% -> 0 | N23: =L23*8% -> 0 | O23: =(K23+M23)*F23 -> 0 | P23: =(L23+N23)*F23 -> 0
B24: Van một chiều NRD 500x500 | E24: cái | F24: 2 | M24: =K24*8% -> 0 | N24: =L24*8% -> 0 | O24: =(K24+M24)*F24 -> 0 | P24: =(L24+N24)*F24 -> 0
B25: Van một chiều NRD 600x500 | E25: cái | F25: 1
B26: Van một chiều NRD 900x300 | E26: cái | F26: 1 | M26: =K26*10% -> 0 | N26: =L26*8% -> 0 | O26: =(K26+M26)*F26 -> 0 | P26: =(L26+N26)*F26 -> 0
B27: Van xả áp PRD 1100x400 | E27: cái | F27: 8 | M27: =K27*10% -> 0 | N27: =L27*8% -> 0 | O27: =(K27+M27)*F27 -> 0 | P27: =(L27+N27)*F27 -> 0
B28: Van chặn lửa MFD, EI60 | M28: =K28*10% -> 0 | N28: =L28*8% -> 0 | O28: =(K28+M28)*F28 -> 0 | P28: =(L28+N28)*F28 -> 0
B29: Van chặn lửa MFD, EI60 MFD 400x250 | E29: cửa | F29: 3 | M29: =K29*10% -> 0 | N29: =L29*8% -> 0 | O29: =(K29+M29)*F29 -> 0 | P29: =(L29+N29)*F29 -> 0
B30: Van chặn lửa MFD, EI60 MFD 500x500 | E30: cái | F30: 5 | M30: =K30*10% -> 0 | N30: =L30*8% -> 0 | O30: =(K30+M30)*F30 -> 0 | P30: =(L30+N30)*F30 -> 0
B31: Van chặn lửa MFD, EI60 MFD 600x500 | E31: cái | F31: 2 | M31: =K31*10% -> 0 | N31: =L31*8% -> 0 | O31: =(K31+M31)*F31 -> 0 | P31: =(L31+N31)*F31 -> 0
B32: Van chặn lửa MFD, EI60 MFD 900x300 | E32: cái | F32: 3 | M32: =K32*10% -> 0 | N32: =L32*8% -> 0 | O32: =(K32+M32)*F32 -> 0 | P32: =(L32+N32)*F32 -> 0
B33: Louver lấy gió tươi | M33: =K33*10% -> 0 | N33: =L33*8% -> 0 | O33: =(K33+M33)*F33 -> 0 | P33: =(L33+N33)*F33 -> 0
B34: Louver lấy gió tươi FAL + LCCT 1900x500 | E34: cái | F34: 4 | M34: =K34*10% -> 0 | N34: =L34*8% -> 0 | O34: =(K34+M34)*F34 -> 0 | P34: =(L34+N34)*F34 -> 0
B35: Miệng gió | M35: =K35*10% -> 0 | N35: =L35*8% -> 0 | O35: =(K35+M35)*F35 -> 0 | P35: =(L35+N35)*F35 -> 0
B36: Miệng gió xả áp PAG 1150x550 | E36: Cái | F36: 27 | M36: =K36*10% -> 0 | N36: =L36*8% -> 0 | O36: =(K36+M36)*F36 -> 0 | P36: =(L36+N36)*F36 -> 0
B37: Miệng gió tạo áp PAG 600x300 + OBD Kèm box gió | E37: cái | F37: 6 | M37: =K37*10% -> 0 | N37: =L37*8% -> 0 | O37: =(K37+M37)*F37 -> 0 | P37: =(L37+N37)*F37 -> 0
B38: Miệng gió tạo áp PAG 800x350 + OBD Kèm box gió | E38: cái | F38: 2 | M38: =K38*10% -> 0 | N38: =L38*8% -> 0 | O38: =(K38+M38)*F38 -> 0 | P38: =(L38+N38)*F38 -> 0
B39: Miệng gió tạo áp SAG 250x250 + OBD Kèm box gió | E39: cái | F39: 6 | M39: =K39*10% -> 0 | N39: =L39*8% -> 0 | O39: =(K39+M39)*F39 -> 0 | P39: =(L39+N39)*F39 -> 0
B40: Miệng gió tạo áp SAG 1000x500 + OBD Kèm box gió | E40: cái | F40: 18 | M40: =K40*8% -> 0 | N40: =L40*8% -> 0 | O40: =(K40+M40)*F40 -> 0 | P40: =(L40+N40)*F40 -> 0
B41: Miệng gió tạo áp SAG 1150x550 + OBD Kèm box gió | E41: cái | F41: 11
...

Sheet Tang áp HK A3
A2: TT | B2: NỘI DUNG CÔNG VIỆC | D2: Nhãn hiệu/Xuất xứ | E2: Đơn vị tính | F2: Khối lượng | G2: Đầu vào | K2: Đơn giá | M2: Thuế Vat (theo quy định) | O2: Thành tiền | Q2: Ghi Chú
B3: BOQ | C3: NHÀ THẦU | G3: Đơn giá | H3: Lợi nhuận | I3: Hao hụt | J3: Vật liệu phụ | K3: Vật tư | L3: Nhân công | O3: Vật tư | P3: Nhân công
B4: Hạng mục: HỆ THỐNG ĐIỀU ÁP VÀ HÚT KHÓI - KHỐI A3
B5: A. TẦNG HẦM (TẦNG B1, B2, B3)
B6: I. HỆ THỐNG TẠO ÁP
B7: a. Thiết bị
B8: Quạt tạo áp_Loại hướng trục SPAF-B3-BF-04 16.920m3/h@300Pa | E8: cái | F8: 1 | M8: =K8*8% -> 0 | N8: =L8*8% -> 0 | O8: =(K8+M8)*F8 -> 0 | P8: =(L8+N8)*F8 -> 0
B9: Quạt tạo áp_Loại hướng trục SPAF-B3-BF-02 6.000m3/h@200Pa | E9: cái | F9: 1 | M9: =K9*8% -> 0 | N9: =L9*8% -> 0 | O9: =(K9+M9)*F9 -> 0 | P9: =(L9+N9)*F9 -> 0
B10: Quạt tạo áp_Loại hướng trục SPAF-B1-BF-01 14.040m3/h@300Pa | E10: cái | F10: 1 | M10: =K10*8% -> 0 | N10: =L10*8% -> 0 | O10: =(K10+M10)*F10 -> 0 | P10: =(L10+N10)*F10 -> 0
B11: Quạt tạo áp_Loại hướng trục SPAF-B2-BF-04 18.000m3/h@300Pa | E11: cái | F11: 1 | M11: =K11*8% -> 0 | N11: =L11*8% -> 0 | O11: =(K11+M11)*F11 -> 0 | P11: =(L11+N11)*F11 -> 0
B12: Quạt tạo áp_Loại hướng trục SPAF-B2-BF-02 6.000m3/h@200Pa | E12: cái | F12: 1 | M12: =K12*8% -> 0 | N12: =L12*8% -> 0 | O12: =(K12+M12)*F12 -> 0 | P12: =(L12+N12)*F12 -> 0
B13: Quạt tạo áp_Loại hướng trục SPAF-B1-BF-01 14.040m3/h@300Pa | E13: cái | F13: 1 | M13: =K13*8% -> 0 | N13: =L13*8% -> 0 | O13: =(K13+M13)*F13 -> 0 | P13: =(L13+N13)*F13 -> 0
B14: Quạt tạo áp_Loại hướng trục SPAF-B1-BF-02 17.640m3/h@300Pa | E14: cái | F14: 1 | M14: =K14*8% -> 0 | N14: =L14*8% -> 0 | O14: =(K14+M14)*F14 -> 0 | P14: =(L14+N14)*F14 -> 0
B15: Quạt tạo áp_Loại hướng trục SPAF-B1-BF-03 16.200m3/h@300Pa | E15: cái | F15: 1 | M15: =K15*8% -> 0 | N15: =L15*8% -> 0 | O15: =(K15+M15)*F15 -> 0 | P15: =(L15+N15)*F15 -> 0
B16: Quạt tạo áp_Loại hướng trục SPAF-B1-BF-04 16.920m3/h@300Pa | E16: cái | F16: 1 | M16: =K16*8% -> 0 | N16: =L16*8% -> 0 | O16: =(K16+M16)*F16 -> 0 | P16: =(L16+N16)*F16 -> 0
B17: Nối mềm chống cháy | E17: bộ | F17: 9
B18: Ty treo giá đỡ | E18: trọn gói | F18: 1 | M18: =K18*8% -> 0 | N18: =L18*8% -> 0 | O18: =(K18+M18)*F18 -> 0 | P18: =(L18+N18)*F18 -> 0
M19: =K19*8% -> 0 | N19: =L19*8% -> 0 | O19: =(K19+M19)*F19 -> 0 | P19: =(L19+N19)*F19 -> 0
B20: b. Ống gió | M20: =K20*8% -> 0 | N20: =L20*8% -> 0 | O20: =(K20+M20)*F20 -> 0 | P20: =(L20+N20)*F20 -> 0
B21: Ống gió chống cháy EI120 | M21: =K21*8% -> 0 | N21: =L21*8% -> 0 | O21: =(K21+M21)*F21 -> 0 | P21: =(L21+N21)*F21 -> 0
B22: Ống gió thẳng | M22: =K22*8% -> 0 | N22: =L22*8% -> 0 | O22: =(K22+M22)*F22 -> 0 | P22: =(L22+N22)*F22 -> 0
B23: Ống gió chống cháy EI120 800x450 | E23: m | F23: 150 | M23: =K23*8% -> 0 | N23: =L23*8% -> 0 | O23: =(K23+M23)*F23 -> 0 | P23: =(L23+N23)*F23 -> 0
B24: Ống gió chống cháy EI120 800x400 | E24: m | F24: 282 | M24: =K24*8% -> 0 | N24: =L24*8% -> 0 | O24: =(K24+M24)*F24 -> 0 | P24: =(L24+N24)*F24 -> 0
B25: Ống gió chống cháy EI120 600x300 | E25: m | F25: 63
B26: Ống gió chống cháy EI120 1000x500 | E26: m | F26: 11 | M26: =K26*10% -> 0 | N26: =L26*8% -> 0 | O26: =(K26+M26)*F26 -> 0 | P26: =(L26+N26)*F26 -> 0
B27: Ống gió chống cháy EI120 800x350 | E27: m | F27: 41 | M27: =K27*10% -> 0 | N27: =L27*8% -> 0 | O27: =(K27+M27)*F27 -> 0 | P27: =(L27+N27)*F27 -> 0
B28: Ống gió chống cháy EI120 550x550 | E28: m | F28: 98 | M28: =K28*10% -> 0 | N28: =L28*8% -> 0 | O28: =(K28+M28)*F28 -> 0 | P28: =(L28+N28)*F28 -> 0
B29: Ống gió chống cháy EI120 800x400 | E29: m | F29: 13 | M29: =K29*10% -> 0 | N29: =L29*8% -> 0 | O29: =(K29+M29)*F29 -> 0 | P29: =(L29+N29)*F29 -> 0
B30: Chân rẽ | M30: =K30*10% -> 0 | N30: =L30*8% -> 0 | O30: =(K30+M30)*F30 -> 0 | P30: =(L30+N30)*F30 -> 0
B31: Chân rẽ 800x450-200H | E31: cái | F31: 1 | M31: =K31*10% -> 0 | N31: =L31*8% -> 0 | O31: =(K31+M31)*F31 -> 0 | P31: =(L31+N31)*F31 -> 0
B32: Co ngang ống gió | M32: =K32*10% -> 0 | N32: =L32*8% -> 0 | O32: =(K32+M32)*F32 -> 0 | P32: =(L32+N32)*F32 -> 0
B33: Co ngang ống gió 800x400-600R-45° | E33: cái | F33: 4 | M33: =K33*10% -> 0 | N33: =L33*8% -> 0 | O33: =(K33+M33)*F33 -> 0 | P33: =(L33+N33)*F33 -> 0
B34: Co ngang ống gió 800x450-600R-45° | E34: cái | F34: 1 | M34: =K34*10% -> 0 | N34: =L34*8% -> 0 | O34: =(K34+M34)*F34 -> 0 | P34: =(L34+N34)*F34 -> 0
B35: Co ngang ống gió 600x300-600R-45° | E35: cái | F35: 2 | M35: =K35*10% -> 0 | N35: =L35*8% -> 0 | O35: =(K35+M35)*F35 -> 0 | P35: =(L35+N35)*F35 -> 0
B36: Co ngang ống gió 800x400-400R-90° | E36: cái | F36: 10 | M36: =K36*10% -> 0 | N36: =L36*8% -> 0 | O36: =(K36+M36)*F36 -> 0 | P36: =(L36+N36)*F36 -> 0
B37: Co ngang ống gió 600x300-400R-90° | E37: cái | F37: 4 | M37: =K37*10% -> 0 | N37: =L37*8% -> 0 | O37: =(K37+M37)*F37 -> 0 | P37: =(L37+N37)*F37 -> 0
B38: Co ngang ống gió 800x450-400R-90° | E38: cái | F38: 4 | M38: =K38*10% -> 0 | N38: =L38*8% -> 0 | O38: =(K38+M38)*F38 -> 0 | P38: =(L38+N38)*F38 -> 0
B39: Co ngang ống gió 800x350-400R-90° | E39: cái | F39: 4 | M39: =K39*10% -> 0 | N39: =L39*8% -> 0 | O39: =(K39+M39)*F39 -> 0 | P39: =(L39+N39)*F39 -> 0
B40: Ty treo giá đỡ | E40: trọn gói | F40: 1 | M40: =K40*8% -> 0 | N40: =L40*8% -> 0 | O40: =(K40+M40)*F40 -> 0 | P40: =(L40+N40)*F40 -> 0
B42: Miệng gió Air grill | M42: =K42*8% -> 0 | N42: =L42*8% -> 0 | O42: =(K42+M42)*F42 -> 0 | P42: =(L42+N42)*F42 -> 0
...

Sheet DHKK A3
A2: TT | B2: NỘI DUNG CÔNG VIỆC | D2: Nhãn hiệu/Xuất xứ | E2: Đơn vị tính | F2: Khối lượng | G2: Đầu vào | K2: Đơn giá | M2: Thuế Vat (theo quy định) | O2: Thành tiền | Q2: Ghi Chú
B3: BOQ | C3: NHÀ THẦU | G3: Đơn giá | H3: Lợi nhuận | I3: Hao hụt | J3: Vật liệu phụ | K3: Vật tư | L3: Nhân công | O3: Vật tư | P3: Nhân công
B4: Hạng mục: HỆ THỐNG ĐIỀU HÒA KHÔNG KHÍ VÀ THÔNG GIÓ - KHỐI A1 + A2
B5: A. PHẦN CÔNG CỘNG
B6: I. Đường ống
B7: 1. Ống nước ngưng
B8: Ống nước ngưng uPVC D.27 | C8: Ống nước ngưng uPVC D.27 Class 1 | D8: Tiền Phong/Việt Nam | E8: m | F8: 452 | G8: 14404 | H8: =G8*5% -> 720.2 | I8: =(G8+H8)*10% -> 1512.42 | J8: =(G8+H8+I8)*17% -> 2828.2254 | K8: =G8+H8+I8+J8 -> 19464.845 | L8: =K8*25% -> 4866.2114 | M8: =K8*8% -> 1557.1876 | N8: =L8*8% -> 389.29691 | O8: =(K8+M8)*F8 -> 9501958.9 | P8: =(L8+N8)*F8 -> 2375489.7
B9: Ống nước ngưng uPVC D.34 | C9: Ống nước ngưng uPVC D.34 Class 1 | D9: Tiền Phong/Việt Nam | E9: m | F9: 225 | G9: 17604 | H9: =G9*5% -> 880.2 | I9: =(G9+H9)*10% -> 1848.42 | J9: =(G9+H9+I9)*17% -> 3456.5454 | K9: =G9+H9+I9+J9 -> 23789.165 | L9: =K9*25% -> 5947.2914 | M9: =K9*8% -> 1903.1332 | N9: =L9*8% -> 475.78331 | O9: =(K9+M9)*F9 -> 5780767.2 | P9: =(L9+N9)*F9 -> 1445191.8
B10: Ống nước ngưng uPVC D.42 | C10: Ống nước ngưng uPVC D.42 Class 1 | D10: Tiền Phong/Việt Nam | E10: m | F10: 178 | G10: 24192 | H10: =G10*5% -> 1209.6 | I10: =(G10+H10)*10% -> 2540.16 | J10: =(G10+H10+I10)*17% -> 4750.0992 | K10: =G10+H10+I10+J10 -> 32691.859 | L10: =K10*25% -> 8172.9648 | M10: =K10*8% -> 2615.3487 | N10: =L10*8% -> 653.83718 | O10: =(K10+M10)*F10 -> 6284683 | P10: =(L10+N10)*F10 -> 1571170.8
B11: Ống nước ngưng uPVC D.60 | C11: Ống nước ngưng uPVC D.60 Class 1 | D11: Tiền Phong/Việt Nam | E11: m | F11: 4885 | G11: 40716 | H11: =G11*5% -> 2035.8 | I11: =(G11+H11)*10% -> 4275.18 | J11: =(G11+H11+I11)*17% -> 7994.5866 | K11: =G11+H11+I11+J11 -> 55021.567 | L11: =K11*25% -> 13755.392 | M11: =K11*8% -> 4401.7253 | N11: =L11*8% -> 1100.4313 | O11: =(K11+M11)*F11 -> 2.9028278e+08 | P11: =(L11+N11)*F11 -> 72570695
B12: Ống nước ngưng uPVC D.75 | C12: Ống nước ngưng uPVC D.75 Class 1 | D12: Tiền Phong/Việt Nam | E12: m | F12: 104 | G12: 51840 | H12: =G12*5% -> 2592 | I12: =(G12+H12)*10% -> 5443.2 | J12: =(G12+H12+I12)*17% -> 10178.784 | K12: =G12+H12+I12+J12 -> 70053.984 | L12: =K12*25% -> 17513.496 | M12: =K12*8% -> 5604.3187 | N12: =L12*8% -> 1401.0797 | O12: =(K12+M12)*F12 -> 7868463.5 | P12: =(L12+N12)*F12 -> 1967115.9
B13: Ống nước ngưng uPVC D.90 | C13: Ống nước ngưng uPVC D.90 Class 1 | D13: Tiền Phong/Việt Nam | E13: m | F13: 56 | G13: 63936 | H13: =G13*5% -> 3196.8 | I13: =(G13+H13)*10% -> 6713.28 | J13: =(G13+H13+I13)*17% -> 12553.834 | K13: =G13+H13+I13+J13 -> 86399.914 | L13: =K13*25% -> 21599.978 | M13: =K13*8% -> 6911.9931 | N13: =L13*8% -> 1727.9983 | O13: =(K13+M13)*F13 -> 5225466.8 | P13: =(L13+N13)*F13 -> 1306366.7
B14: Ống nước ngưng uPVC D.114 | C14: Ống nước ngưng uPVC D.110 Class 1 | D14: Tiền Phong/Việt Nam | E14: m | F14: 236 | G14: 95148 | H14: =G14*5% -> 4757.4 | I14: =(G14+H14)*10% -> 9990.54 | J14: =(G14+H14+I14)*17% -> 18682.31 | K14: =G14+H14+I14+J14 -> 128578.25 | L14: =K14*25% -> 32144.562 | M14: =K14*8% -> 10286.26 | N14: =L14*8% -> 2571.565 | O14: =(K14+M14)*F14 -> 32772024 | P14: =(L14+N14)*F14 -> 8193006.1
B15: Phụ kiện ống nước ngưng | D15: Việt Nam | E15: Lô | F15: 1 | G15: =SUM(O8:O14)*17% -> 60811745 | H15: =G15*5% -> 3040587.2 | I15: =(G15+H15)*10% -> 6385233.2 | J15: =(G15+H15+I15)*17% -> 11940386 | K15: =G15+H15+I15+J15 -> 82177951 | L15: =K15*25% -> 20544488 | M15: =K15*8% -> 6574236.1 | N15: =L15*8% -> 1643559 | O15: =(K15+M15)*F15 -> 88752187 | P15: =(L15+N15)*F15 -> 22188047
B16: Vật tư phụ | D16: Việt Nam | E16: Lô | F16: 1 | G16: =SUM(O8:O14)*15% -> 53657422 | H16: =G16*5% -> 2682871.1 | I16: =(G16+H16)*10% -> 5634029.3 | J16: =(G16+H16+I16)*17% -> 10535635 | K16: =G16+H16+I16+J16 -> 72509957 | L16: =K16*25% -> 18127489 | M16: =K16*8% -> 5800796.5 | N16: =L16*8% -> 1450199.1 | O16: =(K16+M16)*F16 -> 78310753 | P16: =(L16+N16)*F16 -> 19577688
B17: Ống Cách nhiệt ống nước ngưng, tỉ trọng 25kg/m3
B18: Cách nhiệt ống D.27 dày 10mm | C18: Cách nhiệt ống D26.7 dày 10mm | D18: THERMOBREAK-Sekisui /Thái Lan | E18: m | F18: 452 | G18: =69613/2 -> 34806.5 | H18: =G18*5% -> 1740.325 | I18: =(G18+H18)*10% -> 3654.6825 | J18: =(G18+H18+I18)*17% -> 6834.2563 | K18: =G18+H18+I18+J18 -> 47035.764 | L18: =K18*25% -> 11758.941 | M18: =K18*8% -> 3762.8611 | N18: =L18*8% -> 940.71528 | O18: =(K18+M18)*F18 -> 22960978 | P18: =(L18+N18)*F18 -> 5740244.6
B19: Cách nhiệt ống D34 dày 10mm | C19: Cách nhiệt ống D33.4 dày 10mm | D19: THERMOBREAK-Sekisui /Thái Lan | E19: m | F19: 225 | G19: =78147/2 -> 39073.5 | H19: =G19*5% -> 1953.675 | I19: =(G19+H19)*10% -> 4102.7175 | J19: =(G19+H19+I19)*17% -> 7672.0817 | K19: =G19+H19+I19+J19 -> 52801.974 | L19: =K19*25% -> 13200.494 | M19: =K19*8% -> 4224.1579 | N19: =L19*8% -> 1056.0395 | O19: =(K19+M19)*F19 -> 12830880 | P19: =(L19+N19)*F19 -> 3207719.9
B20: Cách nhiệt ống D42 dày 10mm | C20: Cách nhiệt ống D42.2 dày 10mm | D20: THERMOBREAK-Sekisui /Thái Lan | E20: m | F20: 178 | G20: =97075/2 -> 48537.5 | H20: =G20*5% -> 2426.875 | I20: =(G20+H20)*10% -> 5096.4375 | J20: =(G20+H20+I20)*17% -> 9530.3381 | K20: =G20+H20+I20+J20 -> 65591.151 | L20: =K20*25% -> 16397.788 | M20: =K20*8% -> 5247.2921 | N20: =L20*8% -> 1311.823 | O20: =(K20+M20)*F20 -> 12609243 | P20: =(L20+N20)*F20 -> 3152310.7
B21: Cách nhiệt ống D60 dày 10mm | C21: Cách nhiệt ống D60.3 dày 10mm | D21: THERMOBREAK-Sekisui /Thái Lan | E21: m | F21: 4885 | G21: =126999/2 -> 63499.5 | H21: =G21*5% -> 3174.975 | I21: =(G21+H21)*10% -> 6667.4475 | J21: =(G21+H21+I21)*17% -> 12468.127 | K21: =G21+H21+I21+J21 -> 85810.049 | L21: =K21*25% -> 21452.512 | M21: =K21*8% -> 6864.8039 | N21: =L21*8% -> 1716.201 | O21: =(K21+M21)*F21 -> 4.5271666e+08 | P21: =(L21+N21)*F21 -> 1.1317916e+08
B22: Cách nhiệt ống D75 dày 10mm | C22: Cách nhiệt ống D76.2 dày 10mm | D22: THERMOBREAK-Sekisui /Thái Lan | E22: m | F22: 104 | G22: =158729/2 -> 79364.5 | H22: =G22*5% -> 3968.225 | I22: =(G22+H22)*10% -> 8333.2725 | J22: =(G22+H22+I22)*17% -> 15583.22 | K22: =G22+H22+I22+J22 -> 107249.22 | L22: =K22*25% -> 26812.304 | M22: =K22*8% -> 8579.9374 | N22: =L22*8% -> 2144.9843 | O22: =(K22+M22)*F22 -> 12046232 | P22: =(L22+N22)*F22 -> 3011558
B23: Cách nhiệt ống D90 dày 10mm | C23: Cách nhiệt ống D88.9 dày 10mm | D23: THERMOBREAK-Sekisui /Thái Lan | E23: m | F23: 56 | G23: =167892/2 -> 83946 | H23: =G23*5% -> 4197.3 | I23: =(G23+H23)*10% -> 8814.33 | J23: =(G23+H23+I23)*17% -> 16482.797 | K23: =G23+H23+I23+J23 -> 113440.43 | L23: =K23*25% -> 28360.107 | M23: =K23*8% -> 9075.2342 | N23: =L23*8% -> 2268.8085 | O23: =(K23+M23)*F23 -> 6860877 | P23: =(L23+N23)*F23 -> 1715219.3
B24: Cách nhiệt ống D114 dày 10mm | C24: Cách nhiệt ống D114.3 dày 10mm | D24: THERMOBREAK-Sekisui /Thái Lan | E24: m | F24: 236 | G24: =225881/2 -> 112940.5 | H24: =G24*5% -> 5647.025 | I24: =(G24+H24)*10% -> 11858.753 | J24: =(G24+H24+I24)*17% -> 22175.867 | K24: =G24+H24+I24+J24 -> 152622.14 | L24: =K24*25% -> 38155.536 | M24: =K24*8% -> 12209.772 | N24: =L24*8% -> 3052.4429 | O24: =(K24+M24)*F24 -> 38900332 | P24: =(L24+N24)*F24 -> 9725083.1
B25: 2. Ống đồng
B26: Ống đồng Ø6.4 | C26: Ống đồng Ø6.35 dày 0.71 mm | D26: Toàn phát/Việt Nam | E26: m | F26: 75 | G26: 44300 | H26: =G26*25% -> 11075 | I26: =(G26+H26)*10% -> 5537.5 | J26: =(G26+H26+I26)*17% -> 10355.125 | K26: =G26+H26+I26+J26 -> 71267.625 | L26: =K26*25% -> 17816.906 | M26: =K26*10% -> 7126.7625 | N26: =L26*8% -> 1425.3525 | O26: =(K26+M26)*F26 -> 5879579.1 | P26: =(L26+N26)*F26 -> 1443169.4
B27: Ống đồng Ø9.5 | C27: Ống đồng Ø9.5 dày 0.71 mm | D27: Toàn phát/Việt Nam | E27: m | F27: 1117 | G27: 69300 | H27: =G27*25% -> 17325 | I27: =(G27+H27)*10% -> 8662.5 | J27: =(G27+H27+I27)*17% -> 16198.875 | K27: =G27+H27+I27+J27 -> 111486.38 | L27: =K27*25% -> 27871.594 | M27: =K27*10% -> 11148.638 | N27: =L27*8% -> 2229.7275 | O27: =(K27+M27)*F27 -> 1.3698331e+08 | P27: =(L27+N27)*F27 -> 33623176
B28: Ống đồng Ø12.7 | C28: Ống đồng Ø12.7 dày 0.71 mm | D28: Toàn phát/Việt Nam | E28: m | F28: 75 | G28: 94400 | H28: =G28*25% -> 23600 | I28: =(G28+H28)*10% -> 11800 | J28: =(G28+H28+I28)*17% -> 22066 | K28: =G28+H28+I28+J28 -> 151866 | L28: =K28*25% -> 37966.5 | M28: =K28*10% -> 15186.6 | N28: =L28*8% -> 3037.32 | O28: =(K28+M28)*F28 -> 12528945 | P28: =(L28+N28)*F28 -> 3075286.5
B29: Ống đồng Ø15.9 | C29: Ống đồng Ø15.9 dày 0.71 mm | D29: Toàn phát/Việt Nam | E29: m | F29: 1083 | G29: 119100 | H29: =G29*25% -> 29775 | I29: =(G29+H29)*10% -> 14887.5 | J29: =(G29+H29+I29)*17% -> 27839.625 | K29: =G29+H29+I29+J29 -> 191602.12 | L29: =K29*25% -> 47900.531 | M29: =K29*10% -> 19160.213 | N29: =L29*8% -> 3832.0425 | O29: =(K29+M29)*F29 -> 2.2825561e+08 | P29: =(L29+N29)*F29 -> 56026377
B30: Ống đồng Ø19.1 | C30: Ống đồng Ø19.1 dày 0.71 mm | D30: Toàn phát/Việt Nam | E30: m | F30: 115 | G30: 2162000 | H30: =G30*25% -> 540500 | I30: =(G30+H30)*10% -> 270250 | J30: =(G30+H30+I30)*17% -> 505367.5 | K30: =G30+H30+I30+J30 -> 3478117.5 | L30: =K30*25% -> 869529.38 | M30: =K30*10% -> 347811.75 | N30: =L30*8% -> 69562.35 | O30: =(K30+M30)*F30 -> 4.3998186e+08 | P30: =(L30+N30)*F30 -> 1.0799555e+08
B31: Ống đồng Ø22.2 | C31: Ống đồng Ø22.2 dày 0.81 mm | D31: Toàn phát/Việt Nam | E31: m | F31: 81 | G31: 688000 | H31: =G31*25% -> 172000 | I31: =(G31+H31)*10% -> 86000 | J31: =(G31+H31+I31)*17% -> 160820 | K31: =G31+H31+I31+J31 -> 1106820 | L31: =K31*25% -> 276705 | M31: =K31*10% -> 110682 | N31: =L31*8% -> 22136.4 | O31: =(K31+M31)*F31 -> 98617662 | P31: =(L31+N31)*F31 -> 24206153
B32: Ống đồng Ø28.6 | C32: Ống đồng Ø28.6 dày 1.00 mm | D32: Toàn phát/Việt Nam | E32: m | F32: 47 | G32: 894000 | H32: =G32*25% -> 223500 | I32: =(G32+H32)*10% -> 111750 | J32: =(G32+H32+I32)*17% -> 208972.5 | K32: =G32+H32+I32+J32 -> 1438222.5 | L32: =K32*25% -> 359555.62 | M32: =K32*10% -> 143822.25 | N32: =L32*8% -> 28764.45 | O32: =(K32+M32)*F32 -> 74356103 | P32: =(L32+N32)*F32 -> 18251044
B33: Ống đồng Ø34.9 | C33: Ống đồng Ø34.9 dày 1.00 mm | D33: Toàn phát/Việt Nam | E33: m | F33: 42 | G33: 1312000 | H33: =G33*25% -> 328000 | I33: =(G33+H33)*10% -> 164000 | J33: =(G33+H33+I33)*17% -> 306680 | K33: =G33+H33+I33+J33 -> 2110680 | L33: =K33*25% -> 527670 | M33: =K33*10% -> 211068 | N33: =L33*8% -> 42213.6 | O33: =(K33+M33)*F33 -> 97513416 | P33: =(L33+N33)*F33 -> 23935111
B34: Ống đồng Ø41.3 | C34: Ống đồng Ø41.3 dày 1.20 mm | D34: Toàn phát/Việt Nam | E34: m | F34: 100 | G34: 1559000 | H34: =G34*25% -> 389750 | I34: =(G34+H34)*10% -> 194875 | J34: =(G34+H34+I34)*17% -> 364416.25 | K34: =G34+H34+I34+J34 -> 2508041.2 | L34: =K34*25% -> 627010.31 | M34: =K34*10% -> 250804.12 | N34: =L34*8% -> 50160.825 | O34: =(K34+M34)*F34 -> 2.7588454e+08 | P34: =(L34+N34)*F34 -> 67717114
B35: Bộ chia gas dàn lạnh | C35: KHRP26A22T8, KHRP26A33T8 | D35: Daikin/Việt Nam | E35: Cái | F35: 34 | G35: 1255000 | K35: =G35+H35+I35+J35 -> 1255000 | L35: 200000 | M35: =K35*10% -> 125500 | N35: =L35*8% -> 16000 | O35: =(K35+M35)*F35 -> 46937000 | P35: =(L35+N35)*F35 -> 7344000
C36: KHRP26A72T8 | D36: Daikin/Việt Nam | E36: Cái | G36: 1637000 | K36: =G36+H36+I36+J36 -> 1637000 | L36: 200000 | M36: =K36*10% -> 163700 | N36: =L36*8% -> 16000 | O36: =(K36+M36)*F36 -> 0 | P36: =(L36+N36)*F36 -> 0
C37: KHRP26A73T8, KHRP26A73TP8 | D37: Daikin/Việt Nam | E37: Cái | G37: 2700000 | K37: =G37+H37+I37+J37 -> 2700000 | L37: 200000 | M37: =K37*10% -> 270000 | N37: =L37*8% -> 16000 | O37: =(K37+M37)*F37 -> 0 | P37: =(L37+N37)*F37 -> 0
B38: Bộ chia gas dàn nóng | C38: BHFP22R168-8 | D38: Daikin/Việt Nam | E38: Cái | F38: 8 | G38: 1746000 | K38: =G38+H38+I38+J38 -> 1746000 | L38: 500000 | M38: =K38*10% -> 174600 | N38: =L38*8% -> 40000 | O38: =(K38+M38)*F38 -> 15364800 | P38: =(L38+N38)*F38 -> 4320000
C39: BHFP22R135-8 | D39: Daikin/Việt Nam | E39: Cái | G39: 3383000 | K39: =G39+H39+I39+J39 -> 3383000 | L39: 500000 | M39: =K39*10% -> 338300 | N39: =L39*8% -> 40000 | O39: =(K39+M39)*F39 -> 0 | P39: =(L39+N39)*F39 -> 0
B40: Vật tư phụ | D40: Việt Nam | E40: Lô | F40: 1 | G40: =SUM(O26:O34)*20% -> 2.7400021e+08 | H40: =G40*5% -> 13700010 | I40: =(G40+H40)*10% -> 28770022 | J40: =(G40+H40+I40)*17% -> 53799940 | K40: =G40+H40+I40+J40 -> 3.7027018e+08 | L40: =K40*25% -> 92567544 | M40: =K40*8% -> 29621614 | N40: =L40*8% -> 7405403.6 | O40: =(K40+M40)*F40 -> 3.9989179e+08 | P40: =(L40+N40)*F40 -> 99972948
B41: Ống Cách nhiệt ống gas lạnh, tỉ trọng 25kg/m3
...

Sheet  DHKK tgio A3
A2: TT | B2: NỘI DUNG CÔNG VIỆC | D2: Nhãn hiệu/Xuất xứ | E2: Đơn vị tính | F2: Khối lượng | G2: Đầu vào | K2: Đơn giá | M2: Thuế Vat (theo quy định) | O2: Thành tiền | Q2: Ghi Chú
B3: BOQ | C3: NHÀ THẦU | G3: Đơn giá | H3: Lợi nhuận | I3: Hao hụt | J3: Băng keo | K3: Vật tư | L3: Nhân công | O3: Vật tư | P3: Nhân công
B4: Hạng mục: HỆ THỐNG ĐIỀU HÒA KHÔNG KHÍ VÀ THÔNG GIÓ - KHỐI A3
B5: A. PHẦN CÔNG CỘNG
B6: I. Đường ống
B7: 1. Ống nước ngưng
B8: Ống nước ngưng uPVC D.27 | C8: ='DHKK A3'!C8 -> Ống nước ngưng uPVC D.27 Class 1 | D8: Tiền Phong/Việt Nam | E8: m | F8: 50 | K8: ='DHKK A3'!K8 -> 19464.845 | L8: =K8*25% -> 4866.2114 | M8: =K8*8% -> 1557.1876 | N8: =L8*8% -> 389.29691 | O8: =(K8+M8)*F8 -> 1051101.7 | P8: =(L8+N8)*F8 -> 262775.41
B9: Ống nước ngưng uPVC D.34 | C9: ='DHKK A3'!C9 -> Ống nước ngưng uPVC D.34 Class 1 | D9: Tiền Phong/Việt Nam | E9: m | F9: 276 | K9: ='DHKK A3'!K9 -> 23789.165 | L9: =K9*25% -> 5947.2914 | M9: =K9*8% -> 1903.1332 | N9: =L9*8% -> 475.78331 | O9: =(K9+M9)*F9 -> 7091074.4 | P9: =(L9+N9)*F9 -> 1772768.6
B10: Ống nước ngưng uPVC D.42 | C10: ='DHKK A3'!C10 -> Ống nước ngưng uPVC D.42 Class 1 | D10: Tiền Phong/Việt Nam | E10: m | F10: 99 | K10: ='DHKK A3'!K10 -> 32691.859 | L10: =K10*25% -> 8172.9648 | M10: =K10*8% -> 2615.3487 | N10: =L10*8% -> 653.83718 | O10: =(K10+M10)*F10 -> 3495413.6 | P10: =(L10+N10)*F10 -> 873853.4
B11: Ống nước ngưng uPVC D.49 | C11: Ống nước ngưng uPVC D.48 Class 1 | D11: Tiền Phong/Việt Nam | E11: m | F11: 110 | G11: 28728 | H11: =G11*5% -> 1436.4 | I11: =(G11+H11)*10% -> 3016.44 | J11: =(G11+H11+I11)*17% -> 5640.7428 | K11: =G11+H11+I11+J11 -> 38821.583 | L11: =K11*25% -> 9705.3957 | M11: =K11*8% -> 3105.7266 | N11: =L11*8% -> 776.43166 | O11: =(K11+M11)*F11 -> 4612004 | P11: =(L11+N11)*F11 -> 1153001
B12: Ống nước ngưng uPVC D.60 | C12: ='DHKK A3'!C11 -> Ống nước ngưng uPVC D.60 Class 1 | D12: Tiền Phong/Việt Nam | E12: m | F12: 2640 | K12: ='DHKK A3'!K11 -> 55021.567 | L12: =K12*25% -> 13755.392 | M12: ='DHKK A3'!M11 -> 4401.7253 | N12: ='DHKK A3'!N11 -> 1100.4313 | O12: =(K12+M12)*F12 -> 1.5687749e+08 | P12: =(L12+N12)*F12 -> 39219373
B13: Ống nước ngưng uPVC D.75 | C13: ='DHKK A3'!C12 -> Ống nước ngưng uPVC D.75 Class 1 | D13: Tiền Phong/Việt Nam | E13: m | F13: 40 | K13: ='DHKK A3'!K12 -> 70053.984 | L13: =K13*25% -> 17513.496 | M13: ='DHKK A3'!M12 -> 5604.3187 | N13: ='DHKK A3'!N12 -> 1401.0797 | O13: =(K13+M13)*F13 -> 3026332.1 | P13: =(L13+N13)*F13 -> 756583.03
B14: Ống nước ngưng uPVC D.90 | C14: ='DHKK A3'!C13 -> Ống nước ngưng uPVC D.90 Class 1 | D14: Tiền Phong/Việt Nam | E14: m | F14: 40 | K14: ='DHKK A3'!K13 -> 86399.914 | L14: =K14*25% -> 21599.978 | M14: ='DHKK A3'!M13 -> 6911.9931 | N14: ='DHKK A3'!N13 -> 1727.9983 | O14: =(K14+M14)*F14 -> 3732476.3 | P14: =(L14+N14)*F14 -> 933119.07
B15: Ống nước ngưng uPVC D.114 | C15: ='DHKK A3'!C14 -> Ống nước ngưng uPVC D.110 Class 1 | D15: Tiền Phong/Việt Nam | E15: m | F15: 123 | K15: ='DHKK A3'!K14 -> 128578.25 | L15: =K15*25% -> 32144.562 | M15: ='DHKK A3'!M14 -> 10286.26 | N15: ='DHKK A3'!N14 -> 2571.565 | O15: =(K15+M15)*F15 -> 17080335 | P15: =(L15+N15)*F15 -> 4270083.7
B16: Phụ kiện ống nước ngưng | D16: Việt Nam | E16: Lô | F16: 1 | K16: =SUM(O8:O15)*17% -> 33484259 | L16: =K16*25% -> 8371064.7 | M16: ='DHKK A3'!M15 -> 6574236.1 | N16: ='DHKK A3'!N15 -> 1643559 | O16: =(K16+M16)*F16 -> 40058495 | P16: =(L16+N16)*F16 -> 10014624
B17: Vật tư phụ | D17: Việt Nam | E17: Lô | F17: 1 | K17: =SUM(O8:O15)*15% -> 29544934 | L17: =K17*25% -> 7386233.5 | M17: ='DHKK A3'!M16 -> 5800796.5 | N17: ='DHKK A3'!N16 -> 1450199.1 | O17: =(K17+M17)*F17 -> 35345731 | P17: =(L17+N17)*F17 -> 8836432.7
B18: Ống Cách nhiệt ống nước ngưng, tỉ trọng 25kg/m3
B19: Cách nhiệt ống D.27 dày 10mm | C19: Cách nhiệt ống D26.7 dày 10mm | D19: THERMOBREAK-Sekisui /Thái Lan | E19: m | F19: 50 | K19: ='DHKK A3'!K18 -> 47035.764 | L19: =K19*25% -> 11758.941 | M19: =K19*8% -> 3762.8611 | N19: =L19*8% -> 940.71528 | O19: =(K19+M19)*F19 -> 2539931.2 | P19: =(L19+N19)*F19 -> 634982.81
B20: Cách nhiệt ống D.34 dày 10mm | C20: Cách nhiệt ống D33.4 dày 10mm | D20: THERMOBREAK-Sekisui /Thái Lan | E20: m | F20: 276 | K20: ='DHKK A3'!K19 -> 52801.974 | L20: =K20*25% -> 13200.494 | M20: =K20*8% -> 4224.1579 | N20: =L20*8% -> 1056.0395 | O20: =(K20+M20)*F20 -> 15739212 | P20: =(L20+N20)*F20 -> 3934803.1
B21: Cách nhiệt ống D.42 dày 10mm | C21: Cách nhiệt ống D42.2 dày 10mm | D21: THERMOBREAK-Sekisui /Thái Lan | E21: m | F21: 99 | K21: ='DHKK A3'!K20 -> 65591.151 | L21: =K21*25% -> 16397.788 | M21: =K21*8% -> 5247.2921 | N21: =L21*8% -> 1311.823 | O21: =(K21+M21)*F21 -> 7013005.8 | P21: =(L21+N21)*F21 -> 1753251.5
B22: Cách nhiệt ống D.429 dày 10mm | C22: Cách nhiệt ống D48 dày 10mm | D22: THERMOBREAK-Sekisui /Thái Lan | E22: m | F22: 110 | G22: 58150 | H22: =G22*5% -> 2907.5 | I22: =(G22+H22)*10% -> 6105.75 | J22: =(G22+H22+I22)*17% -> 11417.753 | K22: =G22+H22+I22+J22 -> 78581.003 | L22: =K22*25% -> 19645.251 | M22: =K22*8% -> 6286.4802 | N22: =L22*8% -> 1571.62 | O22: =(K22+M22)*F22 -> 9335423.1 | P22: =(L22+N22)*F22 -> 2333855.8
B23: Cách nhiệt ống D.60 dày 10mm | C23: ='DHKK A3'!C21 -> Cách nhiệt ống D60.3 dày 10mm | D23: THERMOBREAK-Sekisui /Thái Lan | E23: m | F23: 2640 | K23: ='DHKK A3'!K21 -> 85810.049 | L23: =K23*25% -> 21452.512 | M23: =K23*8% -> 6864.8039 | N23: =L23*8% -> 1716.201 | O23: =(K23+M23)*F23 -> 2.4466161e+08 | P23: =(L23+N23)*F23 -> 61165403
B24: Cách nhiệt ống D.75 dày 10mm | C24: ='DHKK A3'!C22 -> Cách nhiệt ống D76.2 dày 10mm | D24: THERMOBREAK-Sekisui /Thái Lan | E24: m | F24: 40 | K24: ='DHKK A3'!K22 -> 107249.22 | L24: =K24*25% -> 26812.304 | M24: =K24*8% -> 8579.9374 | N24: =L24*8% -> 2144.9843 | O24: =(K24+M24)*F24 -> 4633166.2 | P24: =(L24+N24)*F24 -> 1158291.5
B25: Cách nhiệt ống D.90 dày 10mm | C25: ='DHKK A3'!C23 -> Cách nhiệt ống D88.9 dày 10mm | D25: THERMOBREAK-Sekisui /Thái Lan | E25: m | F25: 40 | K25: ='DHKK A3'!K23 -> 113440.43 | L25: =K25*25% -> 28360.107 | M25: =K25*8% -> 9075.2342 | N25: =L25*8% -> 2268.8085 | O25: =(K25+M25)*F25 -> 4900626.5 | P25: =(L25+N25)*F25 -> 1225156.6
B26: Cách nhiệt ống D.114 dày 10mm | C26: ='DHKK A3'!C24 -> Cách nhiệt ống D114.3 dày 10mm | D26: THERMOBREAK-Sekisui /Thái Lan | E26: m | F26: 123 | K26: ='DHKK A3'!K24 -> 152622.14 | L26: =K26*25% -> 38155.536 | M26: =K26*8% -> 12209.772 | N26: =L26*8% -> 3052.4429 | O26: =(K26+M26)*F26 -> 20274326 | P26: =(L26+N26)*F26 -> 5068581.4
B27: 2. Ống đồng
B28: Ống đồng Ø6.4 | C28: Ống đồng Ø6.4 dày 0.71 mm | D28: Toàn phát/Việt Nam | E28: m | F28: 25 | K28: ='DHKK A3'!K26 -> 71267.625 | L28: =K28*25% -> 17816.906 | M28: =K28*10% -> 7126.7625 | N28: =L28*8% -> 1425.3525 | O28: =(K28+M28)*F28 -> 1959859.7 | P28: =(L28+N28)*F28 -> 481056.47
B29: Ống đồng Ø9.5 | C29: Ống đồng Ø9.5 dày 0.71 mm | D29: Toàn phát/Việt Nam | E29: m | F29: 527 | K29: ='DHKK A3'!K27 -> 111486.38 | L29: =K29*25% -> 27871.594 | M29: =K29*10% -> 11148.638 | N29: =L29*8% -> 2229.7275 | O29: =(K29+M29)*F29 -> 64628652 | P29: =(L29+N29)*F29 -> 15863396
B30: Ống đồng Ø12.7 | C30: Ống đồng Ø12.7 dày 0.71 mm | D30: Toàn phát/Việt Nam | E30: m | F30: 33 | K30: ='DHKK A3'!K28 -> 151866 | L30: =K30*25% -> 37966.5 | M30: =K30*10% -> 15186.6 | N30: =L30*8% -> 3037.32 | O30: =(K30+M30)*F30 -> 5512735.8 | P30: =(L30+N30)*F30 -> 1353126.1
B31: Ống đồng Ø15.9 | C31: Ống đồng Ø15.9 dày 0.71 mm | D31: Toàn phát/Việt Nam | E31: m | F31: 527 | K31: ='DHKK A3'!K29 -> 191602.12 | L31: =K31*25% -> 47900.531 | M31: =K31*10% -> 19160.213 | N31: =L31*8% -> 3832.0425 | O31: =(K31+M31)*F31 -> 1.1107175e+08 | P31: =(L31+N31)*F31 -> 27263066
B32: Ống đồng Ø19.1 | C32: Ống đồng Ø19.1 dày 0.71 mm | D32: Toàn phát/Việt Nam | E32: m | F32: 28 | K32: ='DHKK A3'!K30 -> 3478117.5 | L32: =K32*25% -> 869529.38 | M32: =K32*10% -> 347811.75 | N32: =L32*8% -> 69562.35 | O32: =(K32+M32)*F32 -> 107126019 | P32: =(L32+N32)*F32 -> 26294568
B33: Ống đồng Ø22.2 | C33: Ống đồng Ø22.2 dày 0.81 mm | D33: Toàn phát/Việt Nam | E33: m | F33: 8 | K33: ='DHKK A3'!K31 -> 1106820 | L33: =K33*25% -> 276705 | M33: =K33*10% -> 110682 | N33: =L33*8% -> 22136.4 | O33: =(K33+M33)*F33 -> 9740016 | P33: =(L33+N33)*F33 -> 2390731.2
B34: Ống đồng Ø28.6 | C34: Ống đồng Ø28.6 dày 1.00 mm | D34: Toàn phát/Việt Nam | E34: m | F34: 18 | K34: ='DHKK A3'!K32 -> 1438222.5 | L34: =K34*25% -> 359555.62 | M34: =K34*10% -> 143822.25 | N34: =L34*8% -> 28764.45 | O34: =(K34+M34)*F34 -> 28476806 | P34: =(L34+N34)*F34 -> 6989761.4
B35: Ống đồng Ø34.9 | C35: Ống đồng Ø34.9 dày 1.00 mm | D35: Toàn phát/Việt Nam | E35: m | F35: 28 | K35: ='DHKK A3'!K33 -> 2110680 | L35: =K35*25% -> 527670 | M35: =K35*10% -> 211068 | N35: =L35*8% -> 42213.6 | O35: =(K35+M35)*F35 -> 65008944 | P35: =(L35+N35)*F35 -> 15956741
B36: Bộ chia gas dàn lạnh | C36: KHRP26A22T8, KHRP26A33T8 | D36: Daikin/Việt Nam | E36: Cái | F36: 8 | G36: ='DHKK A3'!G35 -> 1255000 | K36: =G36+H36+I36+J36 -> 1255000 | L36: ='DHKK A3'!L35 -> 200000 | M36: =K36*10% -> 125500 | N36: =L36*8% -> 16000 | O36: =(K36+M36)*F36 -> 11044000 | P36: =(L36+N36)*F36 -> 1728000
C37: KHRP26A72T8 | D37: Daikin/Việt Nam | E37: Cái | G37: ='DHKK A3'!G36 -> 1637000 | K37: =G37+H37+I37+J37 -> 1637000 | L37: ='DHKK A3'!L36 -> 200000 | M37: =K37*10% -> 163700 | N37: =L37*8% -> 16000 | O37: =(K37+M37)*F37 -> 0 | P37: =(L37+N37)*F37 -> 0
C38: KHRP26A73T8, KHRP26A73TP8 | D38: Daikin/Việt Nam | E38: Cái | G38: ='DHKK A3'!G37 -> 2700000 | K38: =G38+H38+I38+J38 -> 2700000 | L38: ='DHKK A3'!L37 -> 200000 | M38: =K38*10% -> 270000 | N38: =L38*8% -> 16000 | O38: =(K38+M38)*F38 -> 0 | P38: =(L38+N38)*F38 -> 0
B39: Bộ chia gas dàn nóng | C39: BHFP22R168-8 | D39: Daikin/Việt Nam | E39: Cái | F39: 1 | G39: ='DHKK A3'!G38 -> 1746000 | K39: =G39+H39+I39+J39 -> 1746000 | L39: ='DHKK A3'!L38 -> 500000 | M39: =K39*10% -> 174600 | N39: =L39*8% -> 40000 | O39: =(K39+M39)*F39 -> 1920600 | P39: =(L39+N39)*F39 -> 540000
C40: BHFP22R135-8 | D40: Daikin/Việt Nam | E40: Cái | G40: ='DHKK A3'!G39 -> 3383000 | K40: =G40+H40+I40+J40 -> 3383000 | L40: ='DHKK A3'!L39 -> 500000 | M40: =K40*10% -> 338300 | N40: =L40*8% -> 40000 | O40: =(K40+M40)*F40 -> 0 | P40: =(L40+N40)*F40 -> 0
B41: Vật tư phụ | D41: Việt Nam | E41: Lô | F41: 1 | K41: =SUM(O28:O35)*20% -> 78704957 | L41: =K41*25% -> 19676239 | M41: =K41*10% -> 7870495.7 | N41: =L41*8% -> 1574099.1 | O41: =(K41+M41)*F41 -> 86575452 | P41: =(L41+N41)*F41 -> 21250338
...
