Workbook
Name _??: BlankMacro1
Name _??????1: BlankMacro1
Name _??????2: BlankMacro1
Name _??????3: BlankMacro1
Name _??????4: BlankMacro1
Name _??????5: BlankMacro1
Name _??????6: BlankMacro1
Name __: #REF!
Name __??: BlankMacro1
Name __??????1: BlankMacro1
Name __??????2: BlankMacro1
Name __??????3: BlankMacro1
Name __??????4: BlankMacro1
Name __??????5: BlankMacro1
Name __??????6: BlankMacro1
Name ___??: BlankMacro1
Name ___??????1: BlankMacro1
Name ___??????2: BlankMacro1
Name ___??????3: BlankMacro1
Name ___??????4: BlankMacro1
Name ___??????5: BlankMacro1
Name ___??????6: BlankMacro1
Name ____??: BlankMacro1
Name ____??????1: BlankMacro1
Name ____??????2: BlankMacro1
Name ____??????3: BlankMacro1
Name ____??????4: BlankMacro1
Name ____??????5: BlankMacro1
Name ____??????6: BlankMacro1
Name ________________________________________PPP3: #REF!
Name ________________________________________PPP33: #REF!
Name ________________________________________ppp34: #REF!
Name ________________________________________ppp3444: #REF!
Name ______________________________________P3: #REF!
Name ____________________________a1: {"'Sheet1'!$L$16"}
Name ____________________________PPP3: #REF!
Name ____________________________PPP33: #REF!
Name ____________________________ppp34: #REF!
Name ____________________________ppp3444: #REF!
Name __________________________a1: {"'Sheet1'!$L$16"}
Name __________________________P3: #REF!
Name __________________________PPP3: #REF!
Name __________________________PPP33: #REF!
Name __________________________ppp34: #REF!
Name __________________________ppp3444: #REF!
Name _________________________a1: {"'Sheet1'!$L$16"}
Name _________________________PPP3: #REF!
Name _________________________PPP33: #REF!
Name _________________________ppp34: #REF!
Name _________________________ppp3444: #REF!
Name ________________________a1: {"'Sheet1'!$L$16"}
Name ________________________Goi8: {"'Sheet1'!$L$16"}
Name ________________________P3: #REF!
Name ________________________SCL4: {"'Sheet1'!$L$16"}
Name _______________________a1: {"'Sheet1'!$L$16"}
Name _______________________Goi8: {"'Sheet1'!$L$16"}
Name _______________________P3: #REF!
Name _______________________SCL4: {"'Sheet1'!$L$16"}
Name ______________________a1: {"'Sheet1'!$L$16"}
Name ______________________Goi8: {"'Sheet1'!$L$16"}

Sheet TH
A1: STT | B1: CỤM/BLOCK | C1: GIÁ TRỊ TRƯỚC VAT | D1: VAT | E1: GIÁ TRỊ SAU VAT | F1: THaCo
A2: 1 | B2: A22 | C2: ='A22'!O73 -> 2.1982406e+09 | D2: =C2*0.08 -> 1.7585925e+08 | E2: =C2+D2 -> 2.3740998e+09 | F2: ='A22'!S73 -> 2578591000 | G2: =F2*0.08 -> 206287280 | H2: =G2+F2 -> 2784878280
A3: =A2+1 -> 2 | B3: A05 | C3: ='A05'!O69 -> 2.0603566e+09 | D3: =C3*0.08 -> 1.6482853e+08 | E3: =C3+D3 -> 2.2251851e+09 | F3: ='A05'!R69 -> 2249620000 | G3: =F3*0.08 -> 179969600 | H3: =G3+F3 -> 2429589600
A4: =A3+1 -> 3 | B4: A06 | C4: ='A06'!O82 -> 2.3053299e+09 | D4: =C4*0.08 -> 1.8442639e+08 | E4: =C4+D4 -> 2.4897563e+09 | F4: ='A06'!R82 -> 1692590000 | G4: =F4*0.08 -> 135407200 | H4: =G4+F4 -> 1827997200
A5: =A4+1 -> 4 | B5: A07 | C5: ='A07'!O86 -> 2.4069867e+09 | D5: =C5*0.08 -> 1.9255894e+08 | E5: =C5+D5 -> 2.5995457e+09 | F5: ='A07'!R86 -> 2478842000 | G5: =F5*0.08 -> 198307360 | H5: =G5+F5 -> 2677149360
A6: CỘNG | C6: =SUM(C2:C5) -> 8.9709138e+09 | D6: =SUM(D2:D5) -> 7.176731e+08 | E6: =SUM(E2:E5) -> 9.6885869e+09 | H6: =SUM(H2:H5) -> 9719614440
H7: =H6-E6 -> 31027547

Sheet A22
C2: CÔNG TY CỔ PHẦN TẬP ĐOÀN QUỐC TẾ SLAND
C3: VPGD: SỐ 49, Ngõ 1295 Giải Phóng, Phường Hoàng Mai, TP Hà Nội
C4: Nhà máy: Thôn Nhân Hiền- xã Thường Tín - TP Hà Nội
C5: Hotline: 082 5577 999
A6: BẢNG BÁO GIÁ
A7: Khách hàng : CÔNG TY CỔ PHẦN XÂY DỰNG & KỸ THUẬT KD VIỆT NAM | M7: Seri number Số hiệu | P7: BG1_SLAND_KDVN_PCCC NHA A22
A8: Địa chỉ : | M8: Sales executive PT Kinh doanh | P8: Ms Nhài
A9: Người nhận : | M9: Mobile Điện thoại | P9: 0945588248
A10: Email: | C10: Số điện thoại : | M10: Dự án | N10: NHÀ A22
A11: STT | B11: Danh mục sản phẩm | C11: Model | D11: Thương hiệu | E11: Kích thước (mm) | I11: Modul | J11: L | K11: Độ dày (m) | L11: Unit Đơn vị | M11: Q'ty Số lượng | N11: Price Đơn giá | O11: Total price Thành tiền | P11: Remarks Ghi chú
D12: Thương hiệu | E12: A1 | F12: A2 | G12: B1 | H12: B2
E13: Face size | G13: Neck size
A15: =+[23]l7!A15 -> 1 | B15: 棟強排煙系統 Hút khói sự cố
A16: =+[23]l7!A16 -> 2 | B16: 百叶风口 Cửa Louver KT 4500x1000 尺寸50x50箱钢门框、Z形条系，75mm宽铝合金，各条均匀间隔 40mm，同步配件，浅灰色面漆 khung cửa thép hộp KT50x50, hệ nan chữ Z hợp kim nhôm rộng 75mm, các nan cách đều 40mm, phụ kiện đồng bộ, sơn dầu hoàn thiện màu xám nhạt | C16: WL+LCCT | D16: SWIND | E16: 4500 | F16: 1000 | G16: =+E16-50 -> 4450 | H16: =+F16-50 -> 950 | L16: 個 Cái | M16: 54 | N16: 5396600 | O16: =+N16*M16 -> 291416400 | P16: Louver nan Z cố định chia modul khi sản xuất+ LCCT | Q16: 5600000 | R16: 百叶风口 Cửa Louver KT 4500x1000 尺寸50x50箱钢门框、Z形条系，75mm宽铝合金，各条均匀间隔 40mm，同步配件，浅灰色面漆 khung cửa thép hộp KT50x50, hệ nan chữ Z hợp kim nhôm rộng 75mm, các nan cách đều 40mm, phụ kiện đồng bộ, sơn dầu hoàn thiện màu xám nhạt | S16: =Q16*M16 -> 302400000
A17: =+[23]l7!A17 -> 3 | B17: 百叶风口 Cửa Louver KT 4000x1500 尺寸50x50箱钢门框、Z形条系，75mm宽铝合金，各条均匀间隔 40mm，同步配件，浅灰色面漆 khung cửa thép hộp KT50x50, hệ nan chữ Z hợp kim nhôm rộng 75mm, các nan cách đều 40mm, phụ kiện đồng bộ, sơn dầu hoàn thiện màu xám nhạt | C17: WL+LCCT | D17: SWIND | E17: 4000 | F17: 1500 | G17: =+E17-50 -> 3950 | H17: =+F17-50 -> 1450 | L17: 個 Cái | M17: 45 | N17: 7069700 | O17: =+N17*M17 -> 3.181365e+08 | P17: Louver nan Z cố định chia modul khi sản xuất+ LCCT | Q17: 7300000 | R17: 百叶风口 Cửa Louver KT 4000x1500 尺寸50x50箱钢门框、Z形条系，75mm宽铝合金，各条均匀间隔 40mm，同步配件，浅灰色面漆 khung cửa thép hộp KT50x50, hệ nan chữ Z hợp kim nhôm rộng 75mm, các nan cách đều 40mm, phụ kiện đồng bộ, sơn dầu hoàn thiện màu xám nhạt | S17: =Q17*M17 -> 328500000
A18: =+[23]l7!A18 -> 4 | B18: 百叶风口 Cửa Louver KT 4000x1000 尺寸50x50箱钢门框、Z形条系，75mm宽铝合金，各条均匀间隔 40mm，同步配件，浅灰色面漆 khung cửa thép hộp KT50x50, hệ nan chữ Z hợp kim nhôm rộng 75mm, các nan cách đều 40mm, phụ kiện đồng bộ, sơn dầu hoàn thiện màu xám nhạt | C18: WL+LCCT | D18: SWIND | E18: 4000 | F18: 1000 | G18: =+E18-50 -> 3950 | H18: =+F18-50 -> 950 | L18: 個 Cái | M18: 8 | N18: 4803700 | O18: =+N18*M18 -> 38429600 | P18: Louver nan Z cố định chia modul khi sản xuất+ LCCT | Q18: 4910000 | R18: 百叶风口 Cửa Louver KT 4000x1000 尺寸50x50箱钢门框、Z形条系，75mm宽铝合金，各条均匀间隔 40mm，同步配件，浅灰色面漆 khung cửa thép hộp KT50x50, hệ nan chữ Z hợp kim nhôm rộng 75mm, các nan cách đều 40mm, phụ kiện đồng bộ, sơn dầu hoàn thiện màu xám nhạt | S18: =Q18*M18 -> 39280000
A19: =+[23]l7!A19 -> 5 | B19: 百叶风口 Cửa Louver KT 3500x500 尺寸50x50箱钢门框、Z形条系，75mm宽铝合金，各条均匀间隔 40mm，同步配件，浅灰色面漆 khung cửa thép hộp KT50x50, hệ nan chữ Z hợp kim nhôm rộng 75mm, các nan cách đều 40mm, phụ kiện đồng bộ, sơn dầu hoàn thiện màu xám nhạt | C19: WL+LCCT | D19: SWIND | E19: 3500 | F19: 500 | G19: =+E19-50 -> 3450 | H19: =+F19-50 -> 450 | L19: 個 Cái | M19: 1 | N19: 2226400 | O19: =+N19*M19 -> 2226400 | P19: Louver nan Z cố định chia modul khi sản xuất+ LCCT | Q19: 2250000 | R19: 百叶风口 Cửa Louver KT 3500x500 尺寸50x50箱钢门框、Z形条系，75mm宽铝合金，各条均匀间隔 40mm，同步配件，浅灰色面漆 khung cửa thép hộp KT50x50, hệ nan chữ Z hợp kim nhôm rộng 75mm, các nan cách đều 40mm, phụ kiện đồng bộ, sơn dầu hoàn thiện màu xám nhạt | S19: =Q19*M19 -> 2250000
A20: =+[23]l7!A20 -> 6 | B20: 百叶风口 Cửa Louver KT 3000x2000 尺寸50x50箱钢门框、Z形条系，75mm宽铝合金，各条均匀间隔 40mm，同步配件，浅灰色面漆 khung cửa thép hộp KT50x50, hệ nan chữ Z hợp kim nhôm rộng 75mm, các nan cách đều 40mm, phụ kiện đồng bộ, sơn dầu hoàn thiện màu xám nhạt | C20: WL+LCCT | D20: SWIND | E20: 3000 | F20: 2000 | G20: =+E20-50 -> 2950 | H20: =+F20-50 -> 1950 | L20: 個 Cái | M20: 0 | N20: 7030100 | O20: =+N20*M20 -> 0 | P20: Louver nan Z cố định chia modul khi sản xuất+ LCCT | Q20: 7020000 | R20: 百叶风口 Cửa Louver KT 3000x2000 尺寸50x50箱钢门框、Z形条系，75mm宽铝合金，各条均匀间隔 40mm，同步配件，浅灰色面漆 khung cửa thép hộp KT50x50, hệ nan chữ Z hợp kim nhôm rộng 75mm, các nan cách đều 40mm, phụ kiện đồng bộ, sơn dầu hoàn thiện màu xám nhạt | S20: =Q20*M20 -> 0
A21: =+[23]l7!A21 -> 7 | B21: 百叶风口 Cửa Louver KT 2400x1600 尺寸50x50箱钢门框、Z形条系，75mm宽铝合金，各条均匀间隔 40mm，同步配件，浅灰色面漆 khung cửa thép hộp KT50x50, hệ nan chữ Z hợp kim nhôm rộng 75mm, các nan cách đều 40mm, phụ kiện đồng bộ, sơn dầu hoàn thiện màu xám nhạt | C21: WL+LCCT | D21: SWIND | E21: 2400 | F21: 1600 | G21: =+E21-50 -> 2350 | H21: =+F21-50 -> 1550 | L21: 個 Cái | M21: 24 | N21: 4528700 | O21: =+N21*M21 -> 108688800 | P21: Louver nan Z cố định + LCCT | Q21: 4890000 | R21: 百叶风口 Cửa Louver KT 2400x1600 尺寸50x50箱钢门框、Z形条系，75mm宽铝合金，各条均匀间隔 40mm，同步配件，浅灰色面漆 khung cửa thép hộp KT50x50, hệ nan chữ Z hợp kim nhôm rộng 75mm, các nan cách đều 40mm, phụ kiện đồng bộ, sơn dầu hoàn thiện màu xám nhạt | S21: =Q21*M21 -> 117360000
A22: =+[23]l7!A22 -> 8 | B22: 百叶风口 Cửa Louver KT 2000x1300 尺寸50x50箱钢门框、Z形条系，75mm宽铝合金，各条均匀间隔 40mm，同步配件，浅灰色面漆 khung cửa thép hộp KT50x50, hệ nan chữ Z hợp kim nhôm rộng 75mm, các nan cách đều 40mm, phụ kiện đồng bộ, sơn dầu hoàn thiện màu xám nhạt | C22: WL+LCCT | D22: SWIND | E22: 2000 | F22: 1300 | G22: =+E22-50 -> 1950 | H22: =+F22-50 -> 1250 | L22: 個 Cái | M22: 1 | N22: 3161400 | O22: =+N22*M22 -> 3161400 | P22: Louver nan Z cố định + LCCT | Q22: 3210000 | R22: 百叶风口 Cửa Louver KT 2000x1300 尺寸50x50箱钢门框、Z形条系，75mm宽铝合金，各条均匀间隔 40mm，同步配件，浅灰色面漆 khung cửa thép hộp KT50x50, hệ nan chữ Z hợp kim nhôm rộng 75mm, các nan cách đều 40mm, phụ kiện đồng bộ, sơn dầu hoàn thiện màu xám nhạt | S22: =Q22*M22 -> 3210000
A23: =+[23]l7!A23 -> 9 | B23: 百叶风口 Cửa Louver KT 2000x1000 尺寸50x50箱钢门框、Z形条系，75mm宽铝合金，各条均匀间隔 40mm，同步配件，浅灰色面漆 khung cửa thép hộp KT50x50, hệ nan chữ Z hợp kim nhôm rộng 75mm, các nan cách đều 40mm, phụ kiện đồng bộ, sơn dầu hoàn thiện màu xám nhạt | C23: WL+LCCT | D23: SWIND | E23: 2000 | F23: 1000 | G23: =+E23-50 -> 1950 | H23: =+F23-50 -> 950 | L23: 個 Cái | M23: 10 | N23: 2435400 | O23: =+N23*M23 -> 24354000 | P23: Louver nan Z cố định + LCCT | Q23: 2450000 | R23: 百叶风口 Cửa Louver KT 2000x1000 尺寸50x50箱钢门框、Z形条系，75mm宽铝合金，各条均匀间隔 40mm，同步配件，浅灰色面漆 khung cửa thép hộp KT50x50, hệ nan chữ Z hợp kim nhôm rộng 75mm, các nan cách đều 40mm, phụ kiện đồng bộ, sơn dầu hoàn thiện màu xám nhạt | S23: =Q23*M23 -> 24500000
A24: =+[23]l7!A24 -> 10 | B24: 百叶风口 Cửa Louver KT 2000x800 尺寸50x50箱钢门框、Z形条系，75mm宽铝合金，各条均匀间隔 40mm，同步配件，浅灰色面漆 khung cửa thép hộp KT50x50, hệ nan chữ Z hợp kim nhôm rộng 75mm, các nan cách đều 40mm, phụ kiện đồng bộ, sơn dầu hoàn thiện màu xám nhạt | C24: WL+LCCT | D24: SWIND | E24: 2000 | F24: 800 | G24: =+E24-50 -> 1950 | H24: =+F24-50 -> 750 | L24: 個 Cái | M24: 12 | N24: 2016300 | O24: =+N24*M24 -> 24195600 | P24: Louver nan Z cố định + LCCT | Q24: 2000000 | R24: 百叶风口 Cửa Louver KT 2000x800 尺寸50x50箱钢门框、Z形条系，75mm宽铝合金，各条均匀间隔 40mm，同步配件，浅灰色面漆 khung cửa thép hộp KT50x50, hệ nan chữ Z hợp kim nhôm rộng 75mm, các nan cách đều 40mm, phụ kiện đồng bộ, sơn dầu hoàn thiện màu xám nhạt | S24: =Q24*M24 -> 24000000
A25: =+[23]l7!A25 -> 11 | B25: 百叶风口 Cửa Louver KT 1500x1500 尺寸50x50箱钢门框、Z形条系，75mm宽铝合金，各条均匀间隔 40mm，同步配件，浅灰色面漆 khung cửa thép hộp KT50x50, hệ nan chữ Z hợp kim nhôm rộng 75mm, các nan cách đều 40mm, phụ kiện đồng bộ, sơn dầu hoàn thiện màu xám nhạt | C25: WL+LCCT | D25: SWIND | E25: 1500 | F25: 1500 | G25: =+E25-50 -> 1450 | H25: =+F25-50 -> 1450 | L25: 個 Cái | M25: 10 | N25: 2708200 | O25: =+N25*M25 -> 27082000 | P25: Louver nan Z cố định + LCCT | Q25: 2860000 | R25: 百叶风口 Cửa Louver KT 1500x1500 尺寸50x50箱钢门框、Z形条系，75mm宽铝合金，各条均匀间隔 40mm，同步配件，浅灰色面漆 khung cửa thép hộp KT50x50, hệ nan chữ Z hợp kim nhôm rộng 75mm, các nan cách đều 40mm, phụ kiện đồng bộ, sơn dầu hoàn thiện màu xám nhạt | S25: =Q25*M25 -> 28600000
A26: =+[23]l7!A26 -> 12 | B26: 百叶风口 Cửa Louver KT 1000x1500 尺寸50x50箱钢门框、Z形条系，75mm宽铝合金，各条均匀间隔 40mm，同步配件，浅灰色面漆 khung cửa thép hộp KT50x50, hệ nan chữ Z hợp kim nhôm rộng 75mm, các nan cách đều 40mm, phụ kiện đồng bộ, sơn dầu hoàn thiện màu xám nhạt | C26: WL+LCCT | D26: SWIND | E26: 1000 | F26: 1500 | G26: =+E26-50 -> 950 | H26: =+F26-50 -> 1450 | L26: 個 Cái | M26: 1 | N26: 1835900 | O26: =+N26*M26 -> 1835900 | P26: Louver nan Z cố định + LCCT | Q26: 2000000 | R26: 百叶风口 Cửa Louver KT 1000x1500 尺寸50x50箱钢门框、Z形条系，75mm宽铝合金，各条均匀间隔 40mm，同步配件，浅灰色面漆 khung cửa thép hộp KT50x50, hệ nan chữ Z hợp kim nhôm rộng 75mm, các nan cách đều 40mm, phụ kiện đồng bộ, sơn dầu hoàn thiện màu xám nhạt | S26: =Q26*M26 -> 2000000
A27: =+[23]l7!A27 -> 13 | B27: 百叶风口 Cửa Louver KT 1200x1000 尺寸50x50箱钢门框、Z形条系，75mm宽铝合金，各条均匀间隔 40mm，同步配件，浅灰色面漆 khung cửa thép hộp KT50x50, hệ nan chữ Z hợp kim nhôm rộng 75mm, các nan cách đều 40mm, phụ kiện đồng bộ, sơn dầu hoàn thiện màu xám nhạt | C27: WL+LCCT | D27: SWIND | E27: 1200 | F27: 1000 | G27: =+E27-50 -> 1150 | H27: =+F27-50 -> 950 | L27: 個 Cái | M27: 10 | N27: 1487200 | O27: =+N27*M27 -> 14872000 | P27: Louver nan Z cố định + LCCT | Q27: 1540000 | R27: 百叶风口 Cửa Louver KT 1200x1000 尺寸50x50箱钢门框、Z形条系，75mm宽铝合金，各条均匀间隔 40mm，同步配件，浅灰色面漆 khung cửa thép hộp KT50x50, hệ nan chữ Z hợp kim nhôm rộng 75mm, các nan cách đều 40mm, phụ kiện đồng bộ, sơn dầu hoàn thiện màu xám nhạt | S27: =Q27*M27 -> 15400000
... A30: =+[23]l7!A30 -> 16 | B30: 風門含SEG 1200x600+OBD 流量調節閥含配件及安裝Cửa gió kèm van điều chỉnh lưu lượng SEG 1200x600+OBD Bao gồm nhân công phụ kiện lắp đặt | C30: SDG+OBD | D30: SWIND | E30: 1200 | F30: 600 | G30: =+E30-50 -> 1150 | H30: =+F30-50 -> 550 | L30: 個 Cái | M30: 32 | N30: 1051600 | O30: =+N30*M30 -> 33651200 | P30: Cửa gió 1 lớp nan thẳng bầu dục + van OBD | Q30: 1230000 | R30: 風門含SEG 1200x600+OBD 流量調節閥含配件及安裝Cửa gió kèm van điều chỉnh lưu lượng SEG 1200x600+OBD Bao gồm nhân công phụ kiện lắp đặt | S30: =Q30*M30 -> 39360000
B31: 風門含SEG 600x600+OBD 流量調節閥含配件及安裝Cửa gió kèm van điều chỉnh lưu lượng SEG 600x600+OBD Bao gồm nhân công phụ kiện lắp đặt | C31: SDG+OBD | D31: SWIND | E31: 600 | F31: 600 | G31: =+E31-50 -> 550 | H31: =+F31-50 -> 550 | L31: 個 Cái | M31: 10 | N31: 556600 | O31: =+N31*M31 -> 5566000 | P31: Cửa gió 1 lớp nan thẳng bầu dục + van OBD | Q31: 590000 | R31: 風門含SEG 600x600+OBD 流量調節閥含配件及安裝Cửa gió kèm van điều chỉnh lưu lượng SEG 600x600+OBD Bao gồm nhân công phụ kiện lắp đặt | S31: =Q31*M31 -> 5900000
A32: =+[23]l7!A32 -> 1 | B32: 空調鍍鋅鐵皮排風管 1400x700mm, δ=1.15mm 含製作及安裝 Ống thoát gió bằng tôn mạ kẽm 1400x700mm , δ=1.15mm bao gồm gia công chế tạo và lắp đặt. | L32: m2 | M32: 742 | O32: =+N32*M32 -> 0 | R32: 空調鍍鋅鐵皮排風管 1400x700mm, δ=1.15mm 含製作及安裝 Ống thoát gió bằng tôn mạ kẽm 1400x700mm , δ=1.15mm bao gồm gia công chế tạo và lắp đặt. | S32: =Q32*M32 -> 0
A33: =+[23]l7!A33 -> 2 | B33: 空調鍍鋅鐵皮排風管 1000x350mm, δ=1.15mm 含製作及安裝 Ống thoát gió bằng tôn mạ kẽm 1000x350mm , δ=1.15mm bao gồm gia công chế tạo và lắp đặt. | L33: m2 | M33: 319 | O33: =+N33*M33 -> 0 | R33: 空調鍍鋅鐵皮排風管 1000x350mm, δ=1.15mm 含製作及安裝 Ống thoát gió bằng tôn mạ kẽm 1000x350mm , δ=1.15mm bao gồm gia công chế tạo và lắp đặt. | S33: =Q33*M33 -> 0
A34: =+[23]l7!A34 -> 3 | B34: 空調鍍鋅鐵皮排風管1200x400mm EI45, 含製作及安裝 （含越南消防及救護-救難警察局檢定費用） Ống thoát gió bằng tôn mạ kẽm 1200x400mm, EI45, bao gồm gia công chế tạo và lắp đặt. （Bao gồm chi phí kiểm định của cục cảnh sát pccc & CNCH Việt Nam) | L34: m2 | M34: 821 | O34: =+N34*M34 -> 0 | R34: 空調鍍鋅鐵皮排風管1200x400mm EI45, 含製作及安裝 （含越南消防及救護-救難警察局檢定費用） Ống thoát gió bằng tôn mạ kẽm 1200x400mm, EI45, bao gồm gia công chế tạo và lắp đặt. （Bao gồm chi phí kiểm định của cục cảnh sát pccc & CNCH Việt Nam) | S34: =Q34*M34 -> 0
A35: =+[23]l7!A35 -> 3 | B35: 空調鍍鋅鐵皮排風管1600x400mm EI45, 含製作及安裝 （含越南消防及救護-救難警察局檢定費用） Ống thoát gió bằng tôn mạ kẽm 1600x400mm, EI45, bao gồm gia công chế tạo và lắp đặt. （Bao gồm chi phí kiểm định của cục cảnh sát pccc & CNCH Việt Nam) | L35: m2 | M35: 151 | O35: =+N35*M35 -> 0 | R35: 空調鍍鋅鐵皮排風管1600x400mm EI45, 含製作及安裝 （含越南消防及救護-救難警察局檢定費用） Ống thoát gió bằng tôn mạ kẽm 1600x400mm, EI45, bao gồm gia công chế tạo và lắp đặt. （Bao gồm chi phí kiểm định của cục cảnh sát pccc & CNCH Việt Nam) | S35: =Q35*M35 -> 0
A36: =+[23]l7!A36 -> 4 | B36: 空調鍍鋅鐵皮排風管1800x400mm EI45, 含製作及安裝 （含越南消防及救護-救難警察局檢定費用） Ống thoát gió bằng tôn mạ kẽm 1800x400mm, EI45, bao gồm gia công chế tạo và lắp đặt. （Bao gồm chi phí kiểm định của cục cảnh sát pccc & CNCH Việt Nam) | L36: m2 | M36: 671 | O36: =+N36*M36 -> 0 | R36: 空調鍍鋅鐵皮排風管1800x400mm EI45, 含製作及安裝 （含越南消防及救護-救難警察局檢定費用） Ống thoát gió bằng tôn mạ kẽm 1800x400mm, EI45, bao gồm gia công chế tạo và lắp đặt. （Bao gồm chi phí kiểm định của cục cảnh sát pccc & CNCH Việt Nam) | S36: =Q36*M36 -> 0
A37: =+[23]l7!A37 -> 5 | B37: 空調鍍鋅鐵皮排風管2000x400mm EI45, 含製作及安裝 （含越南消防及救護-救難警察局檢定費用） Ống thoát gió bằng tôn mạ kẽm 2000x400mm, EI45, bao gồm gia công chế tạo và lắp đặt. （Bao gồm chi phí kiểm định của cục cảnh sát pccc & CNCH Việt Nam) | L37: m2 | M37: 808 | O37: =+N37*M37 -> 0 | R37: 空調鍍鋅鐵皮排風管2000x400mm EI45, 含製作及安裝 （含越南消防及救護-救難警察局檢定費用） Ống thoát gió bằng tôn mạ kẽm 2000x400mm, EI45, bao gồm gia công chế tạo và lắp đặt. （Bao gồm chi phí kiểm định của cục cảnh sát pccc & CNCH Việt Nam) | S37: =Q37*M37 -> 0
A38: =+[23]l7!A38 -> 6 | B38: 空調鍍鋅鐵皮排風管2000x400mm EI120, 含製作及安裝 （含越南消防及救護-救難警察局檢定費用） Ống thoát gió bằng tôn mạ kẽm 2000x400mm, EI120, bao gồm gia công chế tạo và lắp đặt. （Bao gồm chi phí kiểm định của cục cảnh sát pccc & CNCH Việt Nam) | L38: m2 | M38: 140 | O38: =+N38*M38 -> 0 | R38: 空調鍍鋅鐵皮排風管2000x400mm EI120, 含製作及安裝 （含越南消防及救護-救難警察局檢定費用） Ống thoát gió bằng tôn mạ kẽm 2000x400mm, EI120, bao gồm gia công chế tạo và lắp đặt. （Bao gồm chi phí kiểm định của cục cảnh sát pccc & CNCH Việt Nam) | S38: =Q38*M38 -> 0
A39: =+[23]l7!A39 -> 7 | B39: 空調鍍鋅鐵皮排風管700x350mm EI30, 含製作及安裝 （含越南消防及救護-救難警察局檢定費用） Ống thoát gió bằng tôn mạ kẽm 700x350mm, EI30,bao gồm gia công chế tạo và lắp đặt. （Bao gồm chi phí kiểm định của cục cảnh sát pccc & CNCH Việt Nam) | L39: m2 | M39: 276 | O39: =+N39*M39 -> 0 | R39: 空調鍍鋅鐵皮排風管700x350mm EI30, 含製作及安裝 （含越南消防及救護-救難警察局檢定費用） Ống thoát gió bằng tôn mạ kẽm 700x350mm, EI30,bao gồm gia công chế tạo và lắp đặt. （Bao gồm chi phí kiểm định của cục cảnh sát pccc & CNCH Việt Nam) | S39: =Q39*M39 -> 0
A40: =+[23]l7!A40 -> 8 | B40: 空調鍍鋅鐵皮排風管1000x350mm EI30, 含製作及安裝 （含越南消防及救護-救難警察局檢定費用） Ống thoát gió bằng tôn mạ kẽm 1000x350mm, EI30, bao gồm gia công chế tạo và lắp đặt. （Bao gồm chi phí kiểm định của cục cảnh sát pccc & CNCH Việt Nam) | L40: m2 | M40: 138 | O40: =+N40*M40 -> 0 | R40: 空調鍍鋅鐵皮排風管1000x350mm EI30, 含製作及安裝 （含越南消防及救護-救難警察局檢定費用） Ống thoát gió bằng tôn mạ kẽm 1000x350mm, EI30, bao gồm gia công chế tạo và lắp đặt. （Bao gồm chi phí kiểm định của cục cảnh sát pccc & CNCH Việt Nam) | S40: =Q40*M40 -> 0
A41: =+[23]l7!A41 -> 9 | B41: 大小頭、彎頭、三通等連接配件，含安裝Phụ kiện kết nối côn, cút, tê…. bao gồm lắp đặt | L41: Khoản 式 | M41: 1 | O41: =+N41*M41 -> 0 | R41: 大小頭、彎頭、三通等連接配件，含安裝Phụ kiện kết nối côn, cút, tê…. bao gồm lắp đặt | S41: =Q41*M41 -> 0
A42: =+[23]l7!A42 -> 10 | B42: MFD單葉閥2000x400 ，on/off DC 24v電動機, EI45 Van MFD 1 lá 2000x400, động cơ điện on/off DC 24v, EI45 | C42: SWIND-1.03- MFD-EI90 | D42: SWIND | E42: 2000 | F42: 400 | I42: 2 | J42: 200 | K42: 1.15 | L42: Cái 個 | M42: 11 | N42: 9387821.2 | O42: =+N42*M42 -> 1.0326603e+08 | P42: - Van ngăn cháy động cơ - Tiêu chuẩn EI 90 - 2 đầu bích TDC - Gắn kèm động cơ ON-OFF 5Nm, Hãng KLB - Sản xuất theo BCTN số 4651/VLXD-TBMT | Q42: 7920000 | R42: MFD單葉閥2000x400 ，on/off DC 24v電動機, EI45 Van MFD 1 lá 2000x400, động cơ điện on/off DC 24v, EI45 | S42: =Q42*M42 -> 87120000
A43: =+[23]l7!A43 -> 11 | B43: MFD單葉閥1800x400 ，on/off DC 24v電動機, EI45 Van MFD 1 lá 1800x400, động cơ điện on/off DC 24v, EI45 | C43: SWIND-1.03- MFD-EI90 | D43: SWIND | E43: 1800 | F43: 400 | I43: 2 | J43: 200 | K43: 1.15 | L43: Cái 個 | M43: 5 | N43: 8957893.3 | O43: =+N43*M43 -> 44789467 | P43: - Van ngăn cháy động cơ - Tiêu chuẩn EI 90 - 2 đầu bích TDC - Gắn kèm động cơ ON-OFF 5Nm, Hãng KLB - Sản xuất theo BCTN số 4651/VLXD-TBMT | Q43: 7700000 | R43: MFD單葉閥1800x400 ，on/off DC 24v電動機, EI45 Van MFD 1 lá 1800x400, động cơ điện on/off DC 24v, EI45 | S43: =Q43*M43 -> 38500000
A44: =+[23]l7!A44 -> 12 | B44: MFD單葉閥1000x350 ，on/off DC 24v電動機, EI45 Van MFD 1 lá 1000x350, động cơ điện on/off DC 24v, EI45 | C44: SWIND-1.03- MFD-EI90 | D44: SWIND | E44: 1000 | F44: 350 | J44: 200 | K44: 1.15 | L44: Cái 個 | M44: 6 | N44: 4531029 | O44: =+N44*M44 -> 27186174 | P44: - Van ngăn cháy động cơ - Tiêu chuẩn EI 90 - 2 đầu bích TDC - Gắn kèm động cơ ON-OFF 5Nm, Hãng KLB - Sản xuất theo BCTN số 4651/VLXD-TBMT | Q44: 4030000 | R44: MFD單葉閥1000x350 ，on/off DC 24v電動機, EI45 Van MFD 1 lá 1000x350, động cơ điện on/off DC 24v, EI45 | S44: =Q44*M44 -> 24180000
...

Sheet A05
C2: CÔNG TY CỔ PHẦN TẬP ĐOÀN QUỐC TẾ SLAND
C3: VPGD: SỐ 49, Ngõ 1295 Giải Phóng, Phường Hoàng Mai, TP Hà Nội
C4: Nhà máy: Thôn Nhân Hiền- xã Thường Tín - TP Hà Nội
C5: Hotline: 082 5577 999
A6: BẢNG BÁO GIÁ
A7: Khách hàng : CÔNG TY CỔ PHẦN XÂY DỰNG & KỸ THUẬT KD VIỆT NAM | M7: Seri number Số hiệu | P7: BG2_SLAND_KDVN_PCCC NHA A05
A8: Địa chỉ : | M8: Sales executive PT Kinh doanh | P8: Ms Nhài
A9: Người nhận : | M9: Mobile Điện thoại | P9: 0945588248
A10: Email: | C10: Số điện thoại : | M10: Dự án | N10: NHÀ A05
A11: STT | B11: Danh mục sản phẩm | C11: Model | D11: Thương hiệu | E11: Kích thước (mm) | I11: Modul | J11: L | K11: Độ dày (m) | L11: Unit Đơn vị | M11: Q'ty Số lượng | N11: Price Đơn giá | O11: Total price Thành tiền | P11: Remarks Ghi chú
D12: Thương hiệu | E12: A1 | F12: A2 | G12: B1 | H12: B2
E13: Face size | G13: Neck size
A15: WL | B15: 百叶风口 4500x800 Cửa Louver KT 4500x800 尺寸50x50箱钢门框、Z形条系，75mm宽铝合金，各条均匀间隔 40mm，同步配件，浅灰色面漆 khung cửa thép hộp KT50x50, hệ nan chữ Z hợp kim nhôm rộng 75mm, các nan cách đều 40mm, phụ kiện đồng bộ, sơn dầu hoàn thiện màu xám nhạt | C15: WL | D15: SWIND | E15: 4500 | F15: 800 | G15: 4450 | H15: 750 | L15: 個 Cái | M15: 57 | N15: 4468200 | O15: =N15*M15 -> 254687400 | P15: Louver nan Z khung nan nhôm sơn tĩnh điện Chia modul khi sản xuất | Q15: 4490000 | R15: =Q15*M15 -> 255930000
A16: WL | B16: 百叶风口 2000x2000 Cửa Louver 2000x2000 尺寸50x50箱钢门框、Z形条系，75mm宽铝合金，各条均匀间隔 40mm，同步配件，浅灰色面漆 khung cửa thép hộp KT50x50, hệ nan chữ Z hợp kim nhôm rộng 75mm, các nan cách đều 40mm, phụ kiện đồng bộ, sơn dầu hoàn thiện màu xám nhạt | C16: WL | D16: SWIND | E16: 2000 | F16: 2000 | G16: =E16-50 -> 1950 | H16: =F16-50 -> 1950 | L16: 個 Cái | M16: 11 | N16: 4725600 | O16: =N16*M16 -> 51981600 | P16: Louver nan Z khung nan nhôm sơn tĩnh điện | Q16: 4890000 | R16: =Q16*M16 -> 53790000
A17: WL | B17: 百叶风口 2000x1000 Cửa Louver 2000x1000 尺寸50x50箱钢门框、Z形条系，75mm宽铝合金，各条均匀间隔 40mm，同步配件，浅灰色面漆 khung cửa thép hộp KT50x50, hệ nan chữ Z hợp kim nhôm rộng 75mm, các nan cách đều 40mm, phụ kiện đồng bộ, sơn dầu hoàn thiện màu xám nhạt | C17: WL | D17: SWIND | E17: 2000 | F17: 1000 | G17: 1950 | H17: 950 | L17: 個 Cái | M17: 7 | N17: 2435400 | O17: =N17*M17 -> 17047800 | P17: Louver nan Z khung nan nhôm sơn tĩnh điện | Q17: 2450000 | R17: =Q17*M17 -> 17150000
A18: WL | B18: 百叶风口 1500x1500 Cửa Louver 1500x1500 尺寸50x50箱钢门框、Z形条系，75mm宽铝合金，各条均匀间隔 40mm，同步配件，浅灰色面漆 khung cửa thép hộp KT50x50, hệ nan chữ Z hợp kim nhôm rộng 75mm, các nan cách đều 40mm, phụ kiện đồng bộ, sơn dầu hoàn thiện màu xám nhạt | C18: WL | D18: SWIND | E18: 1500 | F18: 1500 | G18: 1450 | H18: 1450 | L18: 個 Cái | M18: 54 | N18: 2708200 | O18: =N18*M18 -> 146242800 | P18: Louver nan Z khung nan nhôm sơn tĩnh điện | Q18: 2860000 | R18: =Q18*M18 -> 154440000
A19: WL | B19: 百叶风口 1000x1000 Cửa Louver 1000x1000 尺寸50x50箱钢门框、Z形条系，75mm宽铝合金，各条均匀间隔 40mm，同步配件，浅灰色面漆 khung cửa thép hộp KT50x50, hệ nan chữ Z hợp kim nhôm rộng 75mm, các nan cách đều 40mm, phụ kiện đồng bộ, sơn dầu hoàn thiện màu xám nhạt | C19: WL | D19: SWIND | E19: 1000 | F19: 1000 | G19: 950 | H19: 950 | L19: 個 Cái | M19: 12 | N19: 1250700 | O19: =N19*M19 -> 15008400 | P19: Louver nan Z khung nan nhôm sơn tĩnh điện | Q19: 1320000 | R19: =Q19*M19 -> 15840000
A20: WL | B20: 百叶风口 1000x700 Cửa Louver 1000x700 尺寸50x50箱钢门框、Z形条系，75mm宽铝合金，各条均匀间隔 40mm，同步配件，浅灰色面漆 khung cửa thép hộp KT50x50, hệ nan chữ Z hợp kim nhôm rộng 75mm, các nan cách đều 40mm, phụ kiện đồng bộ, sơn dầu hoàn thiện màu xám nhạt | C20: WL | D20: SWIND | E20: 1000 | F20: 700 | G20: =E20-50 -> 950 | H20: =F20-50 -> 650 | L20: 個 Cái | M20: 2 | N20: 880000 | O20: =N20*M20 -> 1760000 | P20: Louver nan Z khung nan nhôm sơn tĩnh điện | Q20: 920000 | R20: =Q20*M20 -> 1840000
A21: SDG | B21: 風門含SEG 1200x600+OBD 流量調節閥含配件及安裝Cửa gió kèm van điều chỉnh lưu lượng SEG 1200x600+OBD Bao gồm nhân công phụ kiện lắp đặt | C21: SDG+OBD | D21: SWIND | E21: 1200 | F21: 600 | G21: 1150 | H21: 550 | L21: 個 Cái | M21: 140 | N21: 1051600 | O21: =N21*M21 -> 147224000 | P21: Cửa gió 1 lớp nan thẳng bầu dục + van OBD | Q21: 1230000 | R21: =Q21*M21 -> 172200000
A22: SDG | B22: 風門含SEG 600x600+OBD 流量調節閥含配件及安裝Cửa gió kèm van điều chỉnh lưu lượng SEG 600x600+OBD Bao gồm nhân công phụ kiện lắp đặt | C22: SDG+OBD | D22: SWIND | E22: 600 | F22: 600 | G22: 550 | H22: 550 | L22: 個 Cái | M22: 14 | N22: 556600 | O22: =N22*M22 -> 7792400 | P22: Cửa gió 1 lớp nan thẳng bầu dục + van OBD | Q22: 590000 | R22: =Q22*M22 -> 8260000
A23: SDG | B23: 風門含PAG 500x500 流量調節閥含配件及安裝 Cửa gió kèm van điều chỉnh lưu lượng PAG 500x500 Bao gồm nhân công phụ kiện lắp đặt | C23: SDG+OBD | D23: SWIND | E23: 500 | F23: 500 | G23: 450 | H23: 450 | L23: Cái 個 | M23: 32 | N23: 408100 | O23: =N23*M23 -> 13059200 | P23: Cửa gió 1 lớp nan thẳng bầu dục + van OBD | Q23: 530000 | R23: =Q23*M23 -> 16960000
A24: Ống chữ nhật | B24: 空調鍍鋅鐵皮排風管 1400x700mm, δ=1.15mm 含製作及安裝 Ống thoát gió bằng tôn mạ kẽm 1400x700mm , δ=1.15mm bao gồm gia công chế tạo và lắp đặt. | L24: m2 | M24: 1696 | O24: =N24*M24 -> 0 | R24: =Q24*M24 -> 0
A25: Ống chữ nhật | B25: 空調鍍鋅鐵皮排風管 1000x600mm, δ=1.15mm 含製作及安裝 Ống thoát gió bằng tôn mạ kẽm 1000x600mm , δ=1.15mm bao gồm gia công chế tạo và lắp đặt. | L25: m2 | M25: 791 | O25: =N25*M25 -> 0 | R25: =Q25*M25 -> 0
A26: Ống chữ nhật | B26: 空調鍍鋅鐵皮排風管 1000x350mm, δ=1.15mm 含製作及安裝 Ống thoát gió bằng tôn mạ kẽm 1000x350mm , δ=1.15mm bao gồm gia công chế tạo và lắp đặt. | L26: m2 | M26: 118 | O26: =N26*M26 -> 0 | R26: =Q26*M26 -> 0
A27: Ống chữ nhật | B27: 空調鍍鋅鐵皮排風管 600x600mm, δ=0.75mm 含製作及安裝 Ống thoát gió bằng tôn mạ kẽm 600x600mm , δ=0.75mm bao gồm gia công chế tạo và lắp đặt. | L27: m2 | M27: 523 | O27: =N27*M27 -> 0 | R27: =Q27*M27 -> 0
A28: Ống chữ nhật | B28: 空調鍍鋅鐵皮排風管1200x400mm EI45, δ=0.75mm含製作及安裝 （含越南消防及救護-救難警察局檢定費用） Ống thoát gió bằng tôn mạ kẽm 1200x400mm, EI45, δ=0.75mm bao gồm gia công chế tạo và lắp đặt. （Bao gồm chi phí kiểm định của cục cảnh sát pccc & CNCH Việt Nam) | L28: m2 | M28: 4369 | O28: =N28*M28 -> 0 | R28: =Q28*M28 -> 0
A29: Ống chữ nhật | B29: 空調鍍鋅鐵皮排風管1600x400mm EI45 含製作及安裝 （含越南消防及救護-救難警察局檢定費用） Ống thoát gió bằng tôn mạ kẽm 1600x400mm, EI45 bao gồm gia công chế tạo và lắp đặt. （Bao gồm chi phí kiểm định của cục cảnh sát pccc & CNCH Việt Nam) | L29: m2 | M29: 275 | O29: =N29*M29 -> 0 | R29: =Q29*M29 -> 0
A30: Ống chữ nhật | B30: 空調鍍鋅鐵皮排風管1800x400mm EI45 含製作及安裝 （含越南消防及救護-救難警察局檢定費用） Ống thoát gió bằng tôn mạ kẽm 1800x400mm, EI45 bao gồm gia công chế tạo và lắp đặt. （Bao gồm chi phí kiểm định của cục cảnh sát pccc & CNCH Việt Nam) | L30: m2 | M30: 3185 | O30: =N30*M30 -> 0 | R30: =Q30*M30 -> 0
A31: Ống chữ nhật | B31: 空調鍍鋅鐵皮排風管2000x400mm EI45 含製作及安裝 （含越南消防及救護-救難警察局檢定費用） Ống thoát gió bằng tôn mạ kẽm 2000x400mm, EI45 bao gồm gia công chế tạo và lắp đặt. （Bao gồm chi phí kiểm định của cục cảnh sát pccc & CNCH Việt Nam) | L31: m2 | M31: 4557 | O31: =N31*M31 -> 0 | R31: =Q31*M31 -> 0
A32: Ống chữ nhật | B32: 空調鍍鋅鐵皮排風管500x500mm EI30 含製作及安裝 （含越南消防及救護-救難警察局檢定費用） Ống thoát gió bằng tôn mạ kẽm 500x500mm, EI30 bao gồm gia công chế tạo và lắp đặt. （Bao gồm chi phí kiểm định của cục cảnh sát pccc & CNCH Việt Nam) | L32: m2 | M32: 31 | O32: =N32*M32 -> 0 | R32: =Q32*M32 -> 0
A33: Ống chữ nhật | B33: 空調鍍鋅鐵皮排風管700x300mm EI30 含製作及安裝 （含越南消防及救護-救難警察局檢定費用） Ống thoát gió bằng tôn mạ kẽm 700x300mm, EI30 bao gồm gia công chế tạo và lắp đặt. （Bao gồm chi phí kiểm định của cục cảnh sát pccc & CNCH Việt Nam) | L33: m2 | M33: 102 | O33: =N33*M33 -> 0 | R33: =Q33*M33 -> 0
A34: Ống chữ nhật | B34: 空調鍍鋅鐵皮排風管700x350mm EI30 含製作及安裝 （含越南消防及救護-救難警察局檢定費用） Ống thoát gió bằng tôn mạ kẽm 700x350mm, EI30 bao gồm gia công chế tạo và lắp đặt. （Bao gồm chi phí kiểm định của cục cảnh sát pccc & CNCH Việt Nam) | L34: m2 | M34: 571 | O34: =N34*M34 -> 0 | R34: =Q34*M34 -> 0
A35: Ống chữ nhật | B35: 空調鍍鋅鐵皮排風管1000x350mm EI30 含製作及安裝 （含越南消防及救護-救難警察局檢定費用） Ống thoát gió bằng tôn mạ kẽm 1000x350mm, EI30 bao gồm gia công chế tạo và lắp đặt. （Bao gồm chi phí kiểm định của cục cảnh sát pccc & CNCH Việt Nam) | L35: m2 | M35: 208 | O35: =N35*M35 -> 0 | R35: =Q35*M35 -> 0
A36: Ống chữ nhật | B36: 空調鍍鋅鐵皮排風管1500x50mm EI30 含製作及安裝 （含越南消防及救護-救難警察局檢定費用） Ống thoát gió bằng tôn mạ kẽm 1500x500mm, EI30 bao gồm gia công chế tạo và lắp đặt. （Bao gồm chi phí kiểm định của cục cảnh sát pccc & CNCH Việt Nam) | L36: m2 | M36: 900 | O36: =N36*M36 -> 0 | R36: =Q36*M36 -> 0
B37: 大小頭、彎頭、三通等連接配件，含安裝Phụ kiện kết nối côn, cút, tê…. bao gồm lắp đặt | L37: Khoản 式 | M37: 1 | O37: =N37*M37 -> 0 | R37: =Q37*M37 -> 0
A38: MFD - EI | B38: MFD單葉閥2000x400 ，on/off DC 24v電動機, EI45 Van MFD 1 lá 2000x400, động cơ điện on/off DC 24v, EI45 | C38: SWIND-1.03- MFD-EI90 | D38: SWIND | E38: 2000 | F38: 400 | G38: 1000 | H38: 400 | I38: 2 | J38: 200 | K38: 1.15 | L38: Cái 個 | M38: 48 | N38: 9387821.2 | O38: =N38*M38 -> 4.5061542e+08 | P38: - Van ngăn cháy động cơ - Tiêu chuẩn EI 90 - 2 đầu bích TDC - Gắn kèm động cơ ON-OFF 5Nm, Hãng KLB - Sản xuất theo BCTN số 4651/VLXD-TBMT | Q38: 7920000 | R38: =Q38*M38 -> 380160000
A39: MFD - EI | B39: MFD單葉閥1200x400 ，on/off DC 24v電動機, EI45 Van MFD 1 lá 1200x400, động cơ điện on/off DC 24v, EI45 | C39: SWIND-1.03- MFD-EI90 | D39: SWIND | E39: 1200 | F39: 400 | J39: 200 | K39: 1.15 | L39: Cái 個 | M39: 8 | N39: 5123838.5 | O39: =N39*M39 -> 40990708 | P39: - Van ngăn cháy động cơ - Tiêu chuẩn EI 90 - 2 đầu bích TDC - Gắn kèm động cơ ON-OFF 5Nm, Hãng KLB - Sản xuất theo BCTN số 4651/VLXD-TBMT | Q39: 4300000 | R39: =Q39*M39 -> 34400000
A40: MFD - EI | B40: MFD單葉閥1000x350 ，on/off DC 24v電動機, EI45 Van MFD 1 lá 1000x350, động cơ điện on/off DC 24v, EI45 | C40: SWIND-1.03- MFD-EI90 | D40: SWIND | E40: 1000 | F40: 350 | J40: 200 | K40: 1.15 | L40: Cái 個 | M40: 7 | N40: 4531029 | O40: =N40*M40 -> 31717203 | P40: - Van ngăn cháy động cơ - Tiêu chuẩn EI 90 - 2 đầu bích TDC - Gắn kèm động cơ ON-OFF 5Nm, Hãng KLB - Sản xuất theo BCTN số 4651/VLXD-TBMT | Q40: 4030000 | R40: =Q40*M40 -> 28210000
A41: MFD - EI | B41: MFD單葉閥700x300 ，on/off DC 24v電動機, EI45 Van MFD 1 lá 700x300, động cơ điện on/off DC 24v, EI45 | C41: SWIND-1.03- MFD-EI90 | D41: SWIND | E41: 700 | F41: 300 | J41: 200 | K41: 1.15 | L41: Cái 個 | M41: 2 | N41: 3678194.3 | O41: =N41*M41 -> 7356388.6 | P41: - Van ngăn cháy động cơ - Tiêu chuẩn EI 90 - 2 đầu bích TDC - Gắn kèm động cơ ON-OFF 5Nm, Hãng KLB - Sản xuất theo BCTN số 4651/VLXD-TBMT | Q41: 3680000 | R41: =Q41*M41 -> 7360000
A42: MD | B42: MD單葉閥4500x800 ，on/off DC 24v電動機 Van MD 1 lá 4500x800, động cơ điện on/off DC 24v | C42: MD | D42: SWIND | E42: 4500 | F42: 800 | J42: 200 | K42: 1.15 | L42: Cái 個 | M42: 57 | N42: 7168875 | O42: =N42*M42 -> 408625875 | P42: Van MD chia 4 modul, 4 động cơ KLB/VIWECO 24V -10N | Q42: 9546000 | R42: =Q42*M42 -> 544122000
...

Sheet A06
C2: CÔNG TY CỔ PHẦN TẬP ĐOÀN QUỐC TẾ SLAND
C3: VPGD: SỐ 49, Ngõ 1295 Giải Phóng, Phường Hoàng Mai, TP Hà Nội
C4: Nhà máy: Thôn Nhân Hiền- xã Thường Tín - TP Hà Nội
C5: Hotline: 082 5577 999
A6: BẢNG BÁO GIÁ
A7: Khách hàng : CÔNG TY CỔ PHẦN XÂY DỰNG & KỸ THUẬT KD VIỆT NAM | M7: Seri number Số hiệu | P7: BG3_SLAND_KDVN_PCCC NHA A06
A8: Địa chỉ : | M8: Sales executive PT Kinh doanh | P8: Ms Nhài
A9: Người nhận : | M9: Mobile Điện thoại | P9: 0945588248
A10: Email: | C10: Số điện thoại : | M10: Dự án | N10: NHÀ A06
A11: STT | B11: Danh mục sản phẩm | C11: Model | D11: Thương hiệu | E11: Kích thước (mm) | I11: Modul | J11: L | K11: Độ dày (m) | L11: Unit Đơn vị | M11: Q'ty Số lượng | N11: Price Đơn giá | O11: Total price Thành tiền | P11: Remarks Ghi chú
D12: Thương hiệu | E12: A1 | F12: A2 | G12: B1 | H12: B2
E13: Face size | G13: Neck size
A15: =+[23]l7!A15 -> 1 | B15: =+[24]BG!C13 -> Cửa gió nan KT 4500x1000 尺寸50x50箱钢门框、Z形条系，75mm宽铝合金，各条均匀间隔 40mm，同步配件，浅灰色面漆 khung cửa thép hộp KT50x50, hệ nan chữ Z hợp kim nhôm rộng 75mm, các nan cách đều 40mm, phụ kiện đồng bộ, sơn dầu hoàn thiện màu xám nhạt | C15: WL+LCCT | D15: SWIND | E15: 4500 | F15: 1000 | G15: =+E15-50 -> 4450 | H15: =+F15-50 -> 950 | L15: =+[24]BG!L13 -> 個 Cái | M15: =+[24]BG!M13 -> 61 | N15: 5396600 | O15: =+N15*M15 -> 329192600 | P15: Louver nan Z cố định+ LCCT | Q15: 5600000
A16: =+[23]l7!A16 -> 2 | B16: =+[24]BG!C14 -> Cửa gió nan KT 4500x800 尺寸50x50箱钢门框、Z形条系，75mm宽铝合金，各条均匀间隔 40mm，同步配件，浅灰色面漆 khung cửa thép hộp KT50x50, hệ nan chữ Z hợp kim nhôm rộng 75mm, các nan cách đều 40mm, phụ kiện đồng bộ, sơn dầu hoàn thiện màu xám nhạt | C16: WL+LCCT | D16: SWIND | E16: 4500 | F16: 800 | G16: =+E16-50 -> 4450 | H16: =+F16-50 -> 750 | L16: =+[24]BG!L14 -> 個 Cái | M16: =+[24]BG!M14 -> 0 | N16: 4468200 | O16: =+N16*M16 -> 0 | P16: Louver nan Z cố định+ LCCT | Q16: 4490000
A17: =+[23]l7!A17 -> 3 | B17: =+[24]BG!C15 -> Cửa gió nan KT 4500x700 尺寸50x50箱钢门框、Z形条系，75mm宽铝合金，各条均匀间隔 40mm，同步配件，浅灰色面漆 khung cửa thép hộp KT50x50, hệ nan chữ Z hợp kim nhôm rộng 75mm, các nan cách đều 40mm, phụ kiện đồng bộ, sơn dầu hoàn thiện màu xám nhạt | C17: WL+LCCT | D17: SWIND | E17: 4500 | F17: 700 | G17: =+E17-50 -> 4450 | H17: =+F17-50 -> 650 | L17: =+[24]BG!L15 -> 個 Cái | M17: =+[24]BG!M15 -> 11 | N17: 3778500 | O17: =+N17*M17 -> 41563500 | P17: Louver nan Z cố định+ LCCT | Q17: 3980000
A18: =+[23]l7!A18 -> 4 | B18: =+[24]BG!C16 -> Cửa gió nan KT 2500x1800 尺寸50x50箱钢门框、Z形条系，75mm宽铝合金，各条均匀间隔 40mm，同步配件，浅灰色面漆 khung cửa thép hộp KT50x50, hệ nan chữ Z hợp kim nhôm rộng 75mm, các nan cách đều 40mm, phụ kiện đồng bộ, sơn dầu hoàn thiện màu xám nhạt | C18: WL+LCCT | D18: SWIND | E18: 2500 | F18: 1800 | G18: =+E18-50 -> 2450 | H18: =+F18-50 -> 1750 | L18: =+[24]BG!L16 -> 個 Cái | M18: =+[24]BG!M16 -> 10 | N18: 5358100 | O18: =+N18*M18 -> 53581000 | P18: Louver nan Z cố định+ LCCT | Q18: 5480000
A19: =+[23]l7!A19 -> 5 | B19: =+[24]BG!C17 -> Cửa gió nan KT 2000x2000 尺寸50x50箱钢门框、Z形条系，75mm宽铝合金，各条均匀间隔 40mm，同步配件，浅灰色面漆 khung cửa thép hộp KT50x50, hệ nan chữ Z hợp kim nhôm rộng 75mm, các nan cách đều 40mm, phụ kiện đồng bộ, sơn dầu hoàn thiện màu xám nhạt | C19: WL+LCCT | D19: SWIND | E19: 2000 | F19: 2000 | G19: =+E19-50 -> 1950 | H19: =+F19-50 -> 1950 | L19: =+[24]BG!L17 -> 個 Cái | M19: =+[24]BG!M17 -> 5 | N19: 4725600 | O19: =+N19*M19 -> 23628000 | P19: Louver nan Z cố định+ LCCT | Q19: 4890000
A20: =+[23]l7!A20 -> 6 | B20: =+[24]BG!C18 -> Cửa gió nan KT 2000x1800 尺寸50x50箱钢门框、Z形条系，75mm宽铝合金，各条均匀间隔 40mm，同步配件，浅灰色面漆 khung cửa thép hộp KT50x50, hệ nan chữ Z hợp kim nhôm rộng 75mm, các nan cách đều 40mm, phụ kiện đồng bộ, sơn dầu hoàn thiện màu xám nhạt | C20: WL+LCCT | D20: SWIND | E20: 2000 | F20: 1800 | G20: =+E20-50 -> 1950 | H20: =+F20-50 -> 1750 | L20: =+[24]BG!L18 -> 個 Cái | M20: =+[24]BG!M18 -> 2 | N20: 4307600 | O20: =+N20*M20 -> 8615200 | P20: Louver nan Z cố định+ LCCT | Q20: 4490000
A21: =+[23]l7!A21 -> 7 | B21: =+[24]BG!C19 -> Cửa gió nan KT 2000x1000 尺寸50x50箱钢门框、Z形条系，75mm宽铝合金，各条均匀间隔 40mm，同步配件，浅灰色面漆 khung cửa thép hộp KT50x50, hệ nan chữ Z hợp kim nhôm rộng 75mm, các nan cách đều 40mm, phụ kiện đồng bộ, sơn dầu hoàn thiện màu xám nhạt | C21: WL+LCCT | D21: SWIND | E21: 2000 | F21: 1000 | G21: =+E21-50 -> 1950 | H21: =+F21-50 -> 950 | L21: =+[24]BG!L19 -> 個 Cái | M21: =+[24]BG!M19 -> 7 | N21: 2435400 | O21: =+N21*M21 -> 17047800 | P21: Louver nan Z cố định+ LCCT | Q21: 2450000
A22: =+[23]l7!A22 -> 8 | B22: =+[24]BG!C20 -> Cửa gió nan KT 1500x1500 尺寸50x50箱钢门框、Z形条系，75mm宽铝合金，各条均匀间隔 40mm，同步配件，浅灰色面漆 khung cửa thép hộp KT50x50, hệ nan chữ Z hợp kim nhôm rộng 75mm, các nan cách đều 40mm, phụ kiện đồng bộ, sơn dầu hoàn thiện màu xám nhạt | C22: WL+LCCT | D22: SWIND | E22: 1500 | F22: 1500 | G22: =+E22-50 -> 1450 | H22: =+F22-50 -> 1450 | L22: =+[24]BG!L20 -> 個 Cái | M22: =+[24]BG!M20 -> 26 | N22: 2708200 | O22: =+N22*M22 -> 70413200 | P22: Louver nan Z cố định+ LCCT | Q22: 2860000
A23: =+[23]l7!A23 -> 9 | B23: =+[24]BG!C21 -> Cửa gió nan KT 1000x1000 尺寸50x50箱钢门框、Z形条系，75mm宽铝合金，各条均匀间隔 40mm，同步配件，浅灰色面漆 khung cửa thép hộp KT50x50, hệ nan chữ Z hợp kim nhôm rộng 75mm, các nan cách đều 40mm, phụ kiện đồng bộ, sơn dầu hoàn thiện màu xám nhạt | C23: WL+LCCT | D23: SWIND | E23: 1000 | F23: 1000 | G23: =+E23-50 -> 950 | H23: =+F23-50 -> 950 | L23: =+[24]BG!L21 -> 個 Cái | M23: =+[24]BG!M21 -> 12 | N23: 1250700 | O23: =+N23*M23 -> 15008400 | P23: Louver nan Z cố định+ LCCT | Q23: 1320000
A24: =+[23]l7!A24 -> 10 | B24: =+[24]BG!C22 -> Cửa gió nan KT 1000x700 尺寸50x50箱钢门框、Z形条系，75mm宽铝合金，各条均匀间隔 40mm，同步配件，浅灰色面漆 khung cửa thép hộp KT50x50, hệ nan chữ Z hợp kim nhôm rộng 75mm, các nan cách đều 40mm, phụ kiện đồng bộ, sơn dầu hoàn thiện màu xám nhạt | C24: WL+LCCT | D24: SWIND | E24: 1000 | F24: 700 | G24: =+E24-50 -> 950 | H24: =+F24-50 -> 650 | L24: =+[24]BG!L22 -> 個 Cái | M24: =+[24]BG!M22 -> 37 | N24: 880000 | O24: =+N24*M24 -> 32560000 | P24: Louver nan Z cố định+ LCCT | Q24: 920000
A25: =+[23]l7!A25 -> 11 | B25: =+[24]BG!C23 -> Cửa gió nan KT 800x1500 尺寸50x50箱钢门框、Z形条系，75mm宽铝合金，各条均匀间隔 40mm，同步配件，浅灰色面漆 khung cửa thép hộp KT50x50, hệ nan chữ Z hợp kim nhôm rộng 75mm, các nan cách đều 40mm, phụ kiện đồng bộ, sơn dầu hoàn thiện màu xám nhạt | C25: WL+LCCT | D25: SWIND | E25: 800 | F25: 1500 | G25: =+E25-50 -> 750 | H25: =+F25-50 -> 1450 | L25: =+[24]BG!L23 -> 個 Cái | M25: =+[24]BG!M23 -> 1 | N25: 1338480 | O25: =+N25*M25 -> 1338480 | P25: Louver nan Z cố định+ LCCT | Q25: 1520000
A26: =+[23]l7!A26 -> 12 | B26: =+[24]BG!C24 -> 風門含SEG 1200x600+OBD 流量調節閥含配件及安裝Cửa gió kèm van điều chỉnh lưu lượng SEG 1200x600+OBD Bao gồm nhân công phụ kiện lắp đặt | C26: SDG+OBD | D26: SWIND | E26: 1200 | F26: 600 | G26: =+E26-50 -> 1150 | H26: =+F26-50 -> 550 | L26: =+[24]BG!L24 -> 個 Cái | M26: =+[24]BG!M24 -> 164 | N26: 1051600 | O26: =+N26*M26 -> 172462400 | P26: Cửa gió 1 lớp nan bầu dục cố định kèm van OBD | Q26: 1230000
... A28: =+[23]l7!A28 -> 14 | B28: =+[24]BG!C26 -> 風門含PAG 500x500 流量調節閥含配件及安裝 Cửa gió kèm van điều chỉnh lưu lượng PAG 500x500 Bao gồm nhân công phụ kiện lắp đặt | C28: SDG+OBD | D28: SWIND | E28: 500 | F28: 500 | G28: =+E28-50 -> 450 | H28: =+F28-50 -> 450 | L28: =+[24]BG!L26 -> Cái 個 | M28: =+[24]BG!M26 -> 42 | N28: 408100 | O28: =+N28*M28 -> 17140200 | P28: Cửa gió 1 lớp nan bầu dục cố định kèm van OBD | Q28: 530000
A29: =+[23]l7!A29 -> 15 | B29: =+[24]BG!C27 -> 空調鍍鋅鐵皮排風管 1400x700mm, δ=1.15mm 含製作及安裝 Ống thoát gió bằng tôn mạ kẽm 1400x700mm , δ=1.15mm bao gồm gia công chế tạo và lắp đặt. | L29: =+[24]BG!L27 -> m2 | M29: =+[24]BG!M27 -> 1560 | O29: =+N29*M29 -> 0
A30: =+[23]l7!A30 -> 16 | B30: =+[24]BG!C28 -> 空調鍍鋅鐵皮排風管 1400x500mm, δ=1.15mm 含製作及安裝 Ống thoát gió bằng tôn mạ kẽm 1400x500mm , δ=1.15mm bao gồm gia công chế tạo và lắp đặt. | L30: =+[24]BG!L28 -> m2 | M30: =+[24]BG!M28 -> 32 | O30: =+N30*M30 -> 0
B31: =+[24]BG!C29 -> 空調鍍鋅鐵皮排風管 1000x600mm, δ=1.15mm 含製作及安裝 Ống thoát gió bằng tôn mạ kẽm 1000x600mm , δ=1.15mm bao gồm gia công chế tạo và lắp đặt. | L31: =+[24]BG!L29 -> m2 | M31: =+[24]BG!M29 -> 863 | O31: =+N31*M31 -> 0
A32: =+[23]l7!A32 -> 1 | B32: =+[24]BG!C30 -> 空調鍍鋅鐵皮排風管 1000x500mm, δ=1.15mm 含製作及安裝 Ống thoát gió bằng tôn mạ kẽm 1000x500mm , δ=1.15mm bao gồm gia công chế tạo và lắp đặt. | L32: =+[24]BG!L30 -> m2 | M32: =+[24]BG!M30 -> 144 | O32: =+N32*M32 -> 0
A33: =+[23]l7!A33 -> 2 | B33: =+[24]BG!C31 -> 空調鍍鋅鐵皮排風管 1000x350mm, δ=1.15mm 含製作及安裝 Ống thoát gió bằng tôn mạ kẽm 1000x350mm , δ=1.15mm bao gồm gia công chế tạo và lắp đặt. | L33: =+[24]BG!L31 -> m2 | M33: =+[24]BG!M31 -> 116 | O33: =+N33*M33 -> 0
A34: =+[23]l7!A34 -> 3 | B34: =+[24]BG!C32 -> 空調鍍鋅鐵皮排風管 600x600mm, δ=0.75mm 含製作及安裝 Ống thoát gió bằng tôn mạ kẽm 600x600mm , δ=0.75mm bao gồm gia công chế tạo và lắp đặt. | L34: =+[24]BG!L32 -> m2 | M34: =+[24]BG!M32 -> 539 | O34: =+N34*M34 -> 0
A35: =+[23]l7!A35 -> 3 | B35: =+[24]BG!C33 -> 空調鍍鋅鐵皮排風管 500x500mm, δ=0.75mm 含製作及安裝 Ống thoát gió bằng tôn mạ kẽm 500x500mm , δ=0.75mm bao gồm gia công chế tạo và lắp đặt. | L35: =+[24]BG!L33 -> m2 | M35: =+[24]BG!M33 -> 54 | O35: =+N35*M35 -> 0
A36: =+[23]l7!A36 -> 4 | B36: =+[24]BG!C34 -> 空調鍍鋅鐵皮排風管1200x400mm EI45, 含製作及安裝 （含越南消防及救護-救難警察局檢定費用） Ống thoát gió bằng tôn mạ kẽm 1200x400mm, EI45,bao gồm gia công chế tạo và lắp đặt. （Bao gồm chi phí kiểm định của cục cảnh sát pccc & CNCH Việt Nam) | L36: =+[24]BG!L34 -> m2 | M36: =+[24]BG!M34 -> 6703 | O36: =+N36*M36 -> 0
A37: =+[23]l7!A37 -> 5 | B37: =+[24]BG!C35 -> 空調鍍鋅鐵皮排風管1600x400mm ,EI45, 含製作及安裝 （含越南消防及救護-救難警察局檢定費用） Ống thoát gió bằng tôn mạ kẽm 1600x400mm, EI45, bao gồm gia công chế tạo và lắp đặt. （Bao gồm chi phí kiểm định của cục cảnh sát pccc & CNCH Việt Nam) | L37: =+[24]BG!L35 -> m2 | M37: =+[24]BG!M35 -> 88 | O37: =+N37*M37 -> 0
A38: =+[23]l7!A38 -> 6 | B38: =+[24]BG!C36 -> 空調鍍鋅鐵皮排風管1800x400mm EI45, 含製作及安裝 （含越南消防及救護-救難警察局檢定費用） Ống thoát gió bằng tôn mạ kẽm 1800x400mm, EI45, bao gồm gia công chế tạo và lắp đặt. （Bao gồm chi phí kiểm định của cục cảnh sát pccc & CNCH Việt Nam) | L38: =+[24]BG!L36 -> m2 | M38: =+[24]BG!M36 -> 1235 | O38: =+N38*M38 -> 0
A39: =+[23]l7!A39 -> 7 | B39: =+[24]BG!C37 -> 空調鍍鋅鐵皮排風管2000x400mm EI45, 含製作及安裝 （含越南消防及救護-救難警察局檢定費用） Ống thoát gió bằng tôn mạ kẽm 2000x400mm, EI45, bao gồm gia công chế tạo và lắp đặt. （Bao gồm chi phí kiểm định của cục cảnh sát pccc & CNCH Việt Nam) | L39: =+[24]BG!L37 -> m2 | M39: =+[24]BG!M37 -> 5200 | O39: =+N39*M39 -> 0
A40: =+[23]l7!A40 -> 8 | B40: =+[24]BG!C38 -> 空調鍍鋅鐵皮排風管1500x500mm EI30, 含製作及安裝 （含越南消防及救護-救難警察局檢定費用） Ống thoát gió bằng tôn mạ kẽm 1500x500mm, EI30, bao gồm gia công chế tạo và lắp đặt. （Bao gồm chi phí kiểm định của cục cảnh sát pccc & CNCH Việt Nam) | L40: =+[24]BG!L38 -> m2 | M40: =+[24]BG!M38 -> 570 | O40: =+N40*M40 -> 0
A41: =+[23]l7!A41 -> 9 | B41: =+[24]BG!C39 -> 空調鍍鋅鐵皮排風管500x500mm EI30, 含製作及安裝 （含越南消防及救護-救難警察局檢定費用） Ống thoát gió bằng tôn mạ kẽm 500x500mm, EI30, bao gồm gia công chế tạo và lắp đặt. （Bao gồm chi phí kiểm định của cục cảnh sát pccc & CNCH Việt Nam) | L41: =+[24]BG!L39 -> m2 | M41: =+[24]BG!M39 -> 39 | O41: =+N41*M41 -> 0
A42: =+[23]l7!A42 -> 10 | B42: =+[24]BG!C40 -> 空調鍍鋅鐵皮排風管700x350mm EI30, 含製作及安裝 （含越南消防及救護-救難警察局檢定費用） Ống thoát gió bằng tôn mạ kẽm 700x350mm, EI30, bao gồm gia công chế tạo và lắp đặt. （Bao gồm chi phí kiểm định của cục cảnh sát pccc & CNCH Việt Nam) | L42: =+[24]BG!L40 -> m2 | M42: =+[24]BG!M40 -> 476 | O42: =+N42*M42 -> 0
A43: =+[23]l7!A43 -> 11 | B43: =+[24]BG!C41 -> 空調鍍鋅鐵皮排風管1000x350mm EI30, 含製作及安裝 （含越南消防及救護-救難警察局檢定費用） Ống thoát gió bằng tôn mạ kẽm 1000x350mm, EI30, bao gồm gia công chế tạo và lắp đặt. （Bao gồm chi phí kiểm định của cục cảnh sát pccc & CNCH Việt Nam) | L43: =+[24]BG!L41 -> m2 | M43: =+[24]BG!M41 -> 232 | O43: =+N43*M43 -> 0
...

Sheet A07
C2: CÔNG TY CỔ PHẦN TẬP ĐOÀN QUỐC TẾ SLAND
C3: VPGD: SỐ 49, Ngõ 1295 Giải Phóng, Phường Hoàng Mai, TP Hà Nội
C4: Nhà máy: Thôn Nhân Hiền- xã Thường Tín - TP Hà Nội
C5: Hotline: 082 5577 999
A6: BẢNG BÁO GIÁ
A7: Khách hàng : CÔNG TY CỔ PHẦN XÂY DỰNG & KỸ THUẬT KD VIỆT NAM | M7: Seri number Số hiệu | P7: BG4_SLAND_KDVN_PCCC NHA A07
A8: Địa chỉ : | M8: Sales executive PT Kinh doanh | P8: Ms Nhài
A9: Người nhận : | M9: Mobile Điện thoại | P9: 0945588248
A10: Email: | C10: Số điện thoại : | M10: Dự án | N10: NHÀ A07
A11: STT | B11: Danh mục sản phẩm | C11: Model | D11: Thương hiệu | E11: Kích thước (mm) | I11: Modul | J11: L | K11: Độ dày (m) | L11: Unit Đơn vị | M11: Q'ty Số lượng | N11: Price Đơn giá | O11: Total price Thành tiền | P11: Remarks Ghi chú
D12: Thương hiệu | E12: A1 | F12: A2 | G12: B1 | H12: B2
E13: Face size | G13: Neck size
A15: =+[23]l7!A15 -> 1 | B15: =+[25]BG!C13 -> 百叶风口 4700x1500 Cửa Louver KT 4700x1500 尺寸50x50箱钢门框、Z形条系，75mm宽铝合金，各条均匀间隔 40mm，同步配件，浅灰色面漆 khung cửa thép hộp KT50x50, hệ nan chữ Z hợp kim nhôm rộng 75mm, các nan cách đều 40mm, phụ kiện đồng bộ, sơn dầu hoàn thiện màu xám nhạt | C15: WL+LCCT | D15: SWIND | E15: 4700 | F15: 1500 | G15: =+E15-50 -> 4650 | H15: =+F15-50 -> 1450 | L15: =+[25]BG!L13 -> 個 Cái | M15: =+[25]BG!M13 -> 2 | N15: 8290700 | O15: =+N15*M15 -> 16581400 | P15: Louver nan Z cố định+ LCCT | Q15: 8840000 | R15: =Q15*M15 -> 17680000
A16: =+[23]l7!A16 -> 2 | B16: =+[25]BG!C14 -> 百叶风口 4500x1000 Cửa Louver KT 4500x1000 尺寸50x50箱钢门框、Z形条系，75mm宽铝合金，各条均匀间隔 40mm，同步配件，浅灰色面漆 khung cửa thép hộp KT50x50, hệ nan chữ Z hợp kim nhôm rộng 75mm, các nan cách đều 40mm, phụ kiện đồng bộ, sơn dầu hoàn thiện màu xám nhạt | C16: WL+LCCT | D16: SWIND | E16: 4500 | F16: 1000 | G16: =+E16-50 -> 4450 | H16: =+F16-50 -> 950 | L16: =+[25]BG!L14 -> 個 Cái | M16: =+[25]BG!M14 -> 26 | N16: 5396600 | O16: =+N16*M16 -> 140311600 | P16: Louver nan Z cố định+ LCCT | Q16: 5600000 | R16: =Q16*M16 -> 145600000
A17: =+[23]l7!A17 -> 3 | B17: =+[25]BG!C15 -> 百叶风口 4500x800 Cửa Louver KT 4500x800 尺寸50x50箱钢门框、Z形条系，75mm宽铝合金，各条均匀间隔 40mm，同步配件，浅灰色面漆 khung cửa thép hộp KT50x50, hệ nan chữ Z hợp kim nhôm rộng 75mm, các nan cách đều 40mm, phụ kiện đồng bộ, sơn dầu hoàn thiện màu xám nhạt | C17: WL+LCCT | D17: SWIND | E17: 4500 | F17: 800 | G17: =+E17-50 -> 4450 | H17: =+F17-50 -> 750 | L17: =+[25]BG!L15 -> 個 Cái | M17: =+[25]BG!M15 -> 16 | N17: 4468200 | O17: =+N17*M17 -> 71491200 | P17: Louver nan Z cố định+ LCCT | Q17: 4490000 | R17: =Q17*M17 -> 71840000
A18: =+[23]l7!A18 -> 4 | B18: =+[25]BG!C16 -> 百叶风口 3500x1600 Cửa Louver KT 3500x1600 尺寸50x50箱钢门框、Z形条系，75mm宽铝合金，各条均匀间隔 40mm，同步配件，浅灰色面漆 khung cửa thép hộp KT50x50, hệ nan chữ Z hợp kim nhôm rộng 75mm, các nan cách đều 40mm, phụ kiện đồng bộ, sơn dầu hoàn thiện màu xám nhạt | C18: WL+LCCT | D18: SWIND | E18: 3500 | F18: 1600 | G18: =+E18-50 -> 3450 | H18: =+F18-50 -> 1550 | L18: =+[25]BG!L16 -> 個 Cái | M18: =+[25]BG!M16 -> 2 | N18: 6559300 | O18: =+N18*M18 -> 13118600 | P18: Louver nan Z cố định+ LCCT | Q18: 7200000 | R18: =Q18*M18 -> 14400000
A19: =+[23]l7!A19 -> 5 | B19: =+[25]BG!C17 -> 百叶风口 2500x1500 Cửa Louver KT 2500x1500 尺寸50x50箱钢门框、Z形条系，75mm宽铝合金，各条均匀间隔 40mm，同步配件，浅灰色面漆 khung cửa thép hộp KT50x50, hệ nan chữ Z hợp kim nhôm rộng 75mm, các nan cách đều 40mm, phụ kiện đồng bộ, sơn dầu hoàn thiện màu xám nhạt | C19: WL+LCCT | D19: SWIND | E19: 2500 | F19: 1500 | G19: =+E19-50 -> 2450 | H19: =+F19-50 -> 1450 | L19: =+[25]BG!L17 -> 個 Cái | M19: =+[25]BG!M17 -> 2 | N19: 4452800 | O19: =+N19*M19 -> 8905600 | P19: Louver nan Z cố định+ LCCT | Q19: 4740000 | R19: =Q19*M19 -> 9480000
A20: =+[23]l7!A20 -> 6 | B20: =+[25]BG!C18 -> 百叶风口 2300x1500 Cửa Louver KT 2300x1500 尺寸50x50箱钢门框、Z形条系，75mm宽铝合金，各条均匀间隔 40mm，同步配件，浅灰色面漆 khung cửa thép hộp KT50x50, hệ nan chữ Z hợp kim nhôm rộng 75mm, các nan cách đều 40mm, phụ kiện đồng bộ, sơn dầu hoàn thiện màu xám nhạt | C20: WL+LCCT | D20: SWIND | E20: 2300 | F20: 1500 | G20: =+E20-50 -> 2250 | H20: =+F20-50 -> 1450 | L20: =+[25]BG!L18 -> 個 Cái | M20: =+[25]BG!M18 -> 2 | N20: 4104100 | O20: =+N20*M20 -> 8208200 | P20: Louver nan Z cố định+ LCCT | Q20: 4310000 | R20: =Q20*M20 -> 8620000
A21: =+[23]l7!A21 -> 7 | B21: =+[25]BG!C19 -> 百叶风口 2000x1500 Cửa Louver KT 2000x1500 尺寸50x50箱钢门框、Z形条系，75mm宽铝合金，各条均匀间隔 40mm，同步配件，浅灰色面漆 khung cửa thép hộp KT50x50, hệ nan chữ Z hợp kim nhôm rộng 75mm, các nan cách đều 40mm, phụ kiện đồng bộ, sơn dầu hoàn thiện màu xám nhạt | C21: WL+LCCT | D21: SWIND | E21: 2000 | F21: 1500 | G21: =+E21-50 -> 1950 | H21: =+F21-50 -> 1450 | L21: =+[25]BG!L19 -> 個 Cái | M21: =+[25]BG!M19 -> 4 | N21: 3580500 | O21: =+N21*M21 -> 14322000 | P21: Louver nan Z cố định+ LCCT | Q21: 3650000 | R21: =Q21*M21 -> 14600000
A22: =+[23]l7!A22 -> 8 | B22: =+[25]BG!C20 -> 百叶风口 1500x1500 Cửa Louver KT 1500x1500 尺寸50x50箱钢门框、Z形条系，75mm宽铝合金，各条均匀间隔 40mm，同步配件，浅灰色面漆 khung cửa thép hộp KT50x50, hệ nan chữ Z hợp kim nhôm rộng 75mm, các nan cách đều 40mm, phụ kiện đồng bộ, sơn dầu hoàn thiện màu xám nhạt | C22: WL+LCCT | D22: SWIND | E22: 1500 | F22: 1500 | G22: =+E22-50 -> 1450 | H22: =+F22-50 -> 1450 | L22: =+[25]BG!L20 -> 個 Cái | M22: =+[25]BG!M20 -> 33 | N22: 2708200 | O22: =+N22*M22 -> 89370600 | P22: Louver nan Z cố định+ LCCT | Q22: 2860000 | R22: =Q22*M22 -> 94380000
A23: =+[23]l7!A23 -> 9 | B23: =+[25]BG!C21 -> 百叶风口 1300x700 Cửa Louver KT 1300x700 尺寸50x50箱钢门框、Z形条系，75mm宽铝合金，各条均匀间隔 40mm，同步配件，浅灰色面漆 khung cửa thép hộp KT50x50, hệ nan chữ Z hợp kim nhôm rộng 75mm, các nan cách đều 40mm, phụ kiện đồng bộ, sơn dầu hoàn thiện màu xám nhạt | C23: WL+LCCT | D23: SWIND | E23: 1300 | F23: 700 | G23: =+E23-50 -> 1250 | H23: =+F23-50 -> 650 | L23: =+[25]BG!L21 -> 個 Cái | M23: =+[25]BG!M21 -> 8 | N23: 1128600 | O23: =+N23*M23 -> 9028800 | P23: Louver nan Z cố định+ LCCT | Q23: 1170000 | R23: =Q23*M23 -> 9360000
A24: =+[23]l7!A24 -> 10 | B24: =+[25]BG!C22 -> 百叶风口 1000x1000 Cửa Louver KT 1000x1000 尺寸50x50箱钢门框、Z形条系，75mm宽铝合金，各条均匀间隔 40mm，同步配件，浅灰色面漆 khung cửa thép hộp KT50x50, hệ nan chữ Z hợp kim nhôm rộng 75mm, các nan cách đều 40mm, phụ kiện đồng bộ, sơn dầu hoàn thiện màu xám nhạt | C24: WL+LCCT | D24: SWIND | E24: 1000 | F24: 1000 | G24: =+E24-50 -> 950 | H24: =+F24-50 -> 950 | L24: =+[25]BG!L22 -> 個 Cái | M24: =+[25]BG!M22 -> 12 | N24: 1250700 | O24: =+N24*M24 -> 15008400 | P24: Louver nan Z cố định+ LCCT | Q24: 1320000 | R24: =Q24*M24 -> 15840000
A25: =+[23]l7!A25 -> 11 | B25: =+[25]BG!C23 -> 百叶风口 1000x700 Cửa Louver KT 1000x700 尺寸50x50箱钢门框、Z形条系，75mm宽铝合金，各条均匀间隔 40mm，同步配件，浅灰色面漆 khung cửa thép hộp KT50x50, hệ nan chữ Z hợp kim nhôm rộng 75mm, các nan cách đều 40mm, phụ kiện đồng bộ, sơn dầu hoàn thiện màu xám nhạt | C25: WL+LCCT | D25: SWIND | E25: 1000 | F25: 700 | G25: =+E25-50 -> 950 | H25: =+F25-50 -> 650 | L25: =+[25]BG!L23 -> 個 Cái | M25: =+[25]BG!M23 -> 16 | N25: 880000 | O25: =+N25*M25 -> 14080000 | P25: Louver nan Z cố định+ LCCT | Q25: 920000 | R25: =Q25*M25 -> 14720000
A26: =+[23]l7!A26 -> 12 | B26: =+[25]BG!C24 -> 風門含SEG 1200x600+OBD 流量調節閥含配件及安裝Cửa gió kèm van điều chỉnh lưu lượng SEG 1200x600+OBD Bao gồm nhân công phụ kiện lắp đặt | C26: SDG+OBD | D26: SWIND | E26: 1200 | F26: 600 | G26: =+E26-50 -> 1150 | H26: =+F26-50 -> 550 | L26: =+[25]BG!L24 -> 個 Cái | M26: =+[25]BG!M24 -> 168 | N26: 1051600 | O26: =+N26*M26 -> 176668800 | P26: Cửa gió 1 lớp nan thẳng bầu dục + van OBD | Q26: 1230000 | R26: =Q26*M26 -> 206640000
... A28: =+[23]l7!A28 -> 14 | B28: =+[25]BG!C26 -> 風門含PAG 500x500 流量調節閥含配件及安裝 Cửa gió kèm van điều chỉnh lưu lượng PAG 500x500 Bao gồm nhân công phụ kiện lắp đặt | C28: SDG+OBD | D28: SWIND | E28: 500 | F28: 500 | G28: =+E28-50 -> 450 | H28: =+F28-50 -> 450 | L28: =+[25]BG!L26 -> Cái 個 | M28: =+[25]BG!M26 -> 42 | N28: 408100 | O28: =+N28*M28 -> 17140200 | P28: Cửa gió 1 lớp nan thẳng bầu dục + van OBD | Q28: 530000 | R28: =Q28*M28 -> 22260000
A29: =+[23]l7!A29 -> 15 | B29: =+[25]BG!C27 -> 空調鍍鋅鐵皮排風管 4000x500mm, δ=1.15mm 含製作及安裝 Ống thoát gió bằng tôn mạ kẽm 4000x500mm , δ=1.15mm bao gồm gia công chế tạo và lắp đặt. | L29: =+[25]BG!L27 -> m2 | M29: =+[25]BG!M27 -> 70 | O29: =+N29*M29 -> 0 | R29: =Q29*M29 -> 0
A30: =+[23]l7!A30 -> 16 | B30: =+[25]BG!C28 -> 空調鍍鋅鐵皮排風管 3000x300mm, δ=1.15mm 含製作及安裝 Ống thoát gió bằng tôn mạ kẽm 3000x300mm , δ=1.15mm bao gồm gia công chế tạo và lắp đặt. | L30: =+[25]BG!L28 -> m2 | M30: =+[25]BG!M28 -> 0 | O30: =+N30*M30 -> 0 | R30: =Q30*M30 -> 0
B31: =+[25]BG!C29 -> 空調鍍鋅鐵皮排風管 2000x500mm, δ=1.15mm 含製作及安裝 Ống thoát gió bằng tôn mạ kẽm 2000x500mm , δ=1.15mm bao gồm gia công chế tạo và lắp đặt. | L31: =+[25]BG!L29 -> m2 | M31: =+[25]BG!M29 -> 248 | O31: =+N31*M31 -> 0 | R31: =Q31*M31 -> 0
A32: =+[23]l7!A32 -> 1 | B32: =+[25]BG!C30 -> 空調鍍鋅鐵皮排風管 1200x500mm, δ=0.95mm 含製作及安裝 Ống thoát gió bằng tôn mạ kẽm 1200x500mm , δ=0.95mm bao gồm gia công chế tạo và lắp đặt. | L32: =+[25]BG!L30 -> m2 | M32: =+[25]BG!M30 -> 94 | O32: =+N32*M32 -> 0 | R32: =Q32*M32 -> 0
A33: =+[23]l7!A33 -> 2 | B33: =+[25]BG!C31 -> 空調鍍鋅鐵皮排風管 1050x1200mm, δ=0.95mm 含製作及安裝 Ống thoát gió bằng tôn mạ kẽm 1050x1200mm , δ=0.95mm bao gồm gia công chế tạo và lắp đặt. | L33: =+[25]BG!L31 -> m2 | M33: =+[25]BG!M31 -> 1597 | O33: =+N33*M33 -> 0 | R33: =Q33*M33 -> 0
A34: =+[23]l7!A34 -> 3 | B34: =+[25]BG!C32 -> 空調鍍鋅鐵皮排風管 550x1200mm, δ=0.95mm 含製作及安裝 Ống thoát gió bằng tôn mạ kẽm 550x1200mm , δ=0.95mm bao gồm gia công chế tạo và lắp đặt. | L34: =+[25]BG!L32 -> m2 | M34: =+[25]BG!M32 -> 1363 | O34: =+N34*M34 -> 0 | R34: =Q34*M34 -> 0
A35: =+[23]l7!A35 -> 3 | B35: =+[25]BG!C33 -> 空調鍍鋅鐵皮排風管 400x1200mm, δ=0.95mm 含製作及安裝 Ống thoát gió bằng tôn mạ kẽm 400x1200mm , δ=0.95mm bao gồm gia công chế tạo và lắp đặt. | L35: =+[25]BG!L33 -> m2 | M35: =+[25]BG!M33 -> 132 | O35: =+N35*M35 -> 0 | R35: =Q35*M35 -> 0
A36: =+[23]l7!A36 -> 4 | B36: =+[25]BG!C34 -> 空調鍍鋅鐵皮排風管 800x500mm, δ=0.95mm 含製作及安裝 Ống thoát gió bằng tôn mạ kẽm 800x500mm , δ=0.95mm bao gồm gia công chế tạo và lắp đặt. | L36: =+[25]BG!L34 -> m2 | M36: =+[25]BG!M34 -> 72 | O36: =+N36*M36 -> 0 | R36: =Q36*M36 -> 0
A37: =+[23]l7!A37 -> 5 | B37: =+[25]BG!C35 -> 空調鍍鋅鐵皮排風管 500x500mm, δ=0.75mm 含製作及安裝 Ống thoát gió bằng tôn mạ kẽm 500x500mm , δ=0.75mm bao gồm gia công chế tạo và lắp đặt. | L37: =+[25]BG!L35 -> m2 | M37: =+[25]BG!M35 -> 47 | O37: =+N37*M37 -> 0 | R37: =Q37*M37 -> 0
A38: =+[23]l7!A38 -> 6 | B38: =+[25]BG!C36 -> 空調鍍鋅鐵皮排風管2200x350mm EI45, 含製作及安裝 （含越南消防及救護-救難警察局檢定費用） Ống thoát gió bằng tôn mạ kẽm 2200x350mm, EI45, bao gồm gia công chế tạo và lắp đặt. （Bao gồm chi phí kiểm định của cục cảnh sát pccc & CNCH Việt Nam) | L38: =+[25]BG!L36 -> m2 | M38: =+[25]BG!M36 -> 8632.26 | O38: =+N38*M38 -> 0 | R38: =Q38*M38 -> 0
A39: =+[23]l7!A39 -> 7 | B39: =+[25]BG!C37 -> 空調鍍鋅鐵皮排風管2000x350mm EI45, 含製作及安裝 （含越南消防及救護-救難警察局檢定費用） Ống thoát gió bằng tôn mạ kẽm 2000x350mm, EI45, bao gồm gia công chế tạo và lắp đặt. （Bao gồm chi phí kiểm định của cục cảnh sát pccc & CNCH Việt Nam) | L39: =+[25]BG!L37 -> m2 | M39: =+[25]BG!M37 -> 207 | O39: =+N39*M39 -> 0 | R39: =Q39*M39 -> 0
A40: =+[23]l7!A40 -> 8 | B40: =+[25]BG!C38 -> 空調鍍鋅鐵皮排風管1800x350mm EI45, 含製作及安裝 （含越南消防及救護-救難警察局檢定費用） Ống thoát gió bằng tôn mạ kẽm 1800x350mm, EI45, bao gồm gia công chế tạo và lắp đặt. （Bao gồm chi phí kiểm định của cục cảnh sát pccc & CNCH Việt Nam) | L40: =+[25]BG!L38 -> m2 | M40: =+[25]BG!M38 -> 209 | O40: =+N40*M40 -> 0 | R40: =Q40*M40 -> 0
A41: =+[23]l7!A41 -> 9 | B41: =+[25]BG!C39 -> 空調鍍鋅鐵皮排風管1500x350mm EI45, 含製作及安裝 （含越南消防及救護-救難警察局檢定費用） Ống thoát gió bằng tôn mạ kẽm 1500x350mm, EI45, bao gồm gia công chế tạo và lắp đặt. （Bao gồm chi phí kiểm định của cục cảnh sát pccc & CNCH Việt Nam) | L41: =+[25]BG!L39 -> m2 | M41: =+[25]BG!M39 -> 3042 | O41: =+N41*M41 -> 0 | R41: =Q41*M41 -> 0
A42: =+[23]l7!A42 -> 10 | B42: =+[25]BG!C40 -> 空調鍍鋅鐵皮排風管1200x300mm EI45, 含製作及安裝 （含越南消防及救護-救難警察局檢定費用） Ống thoát gió bằng tôn mạ kẽm 1200x300mm, EI45, bao gồm gia công chế tạo và lắp đặt. （Bao gồm chi phí kiểm định của cục cảnh sát pccc & CNCH Việt Nam) | L42: =+[25]BG!L40 -> m2 | M42: =+[25]BG!M40 -> 347 | O42: =+N42*M42 -> 0 | R42: =Q42*M42 -> 0
A43: =+[23]l7!A43 -> 11 | B43: =+[25]BG!C41 -> 空調鍍鋅鐵皮排風管700x300mm EI45, 含製作及安裝 （含越南消防及救護-救難警察局檢定費用） Ống thoát gió bằng tôn mạ kẽm 700x300mm, EI45, bao gồm gia công chế tạo và lắp đặt. （Bao gồm chi phí kiểm định của cục cảnh sát pccc & CNCH Việt Nam) | L43: =+[25]BG!L41 -> m2 | M43: =+[25]BG!M41 -> 759 | O43: =+N43*M43 -> 0 | R43: =Q43*M43 -> 0
...
