Workbook

Sheet 00_TONG_HOP_BAO_GIA
A1: STT | B1: ITEM_ID | C1: PHÂN NHÓM | D1: TÊN SẢN PHẨM | E1: QUY CÁCH (WxH) | F1: ĐVT | G1: SỐ LƯỢNG | H1: CP VẬT TƯ ỐNG | I1: CP VẬT TƯ CỬA | J1: CP VẬT TƯ VAN | K1: TỔNG CP VẬT TƯ | L1: NHÂN CÔNG (25%) | M1: CP XƯỞNG (10%) | N1: TỔNG GIÁ VỐN | O1: GIÁ VỐN / ĐVT | P1: MARGIN (%) | Q1: ĐƠN GIÁ BÁN | R1: THÀNH TIỀN (VNĐ)
A2: 1 | B2: SW-DUCT-001 | C2: ỐNG GIÓ | D2: Tole tráng kẽm dày 0.58mm (dùng cho ống gió có a, b <400mm) | E2: 0.58mm | F2: m2 | G2: 5757.003 | H2: =SUMIF('01_BOC_TACH_ONG'!B:B, B2, '01_BOC_TACH_ONG'!K:K) | I2: =SUMIF('02_BOC_TACH_CUA'!B:B, B2, '02_BOC_TACH_CUA'!K:K) | J2: =SUMIF('03_BOC_TACH_VAN'!B:B, B2, '03_BOC_TACH_VAN'!K:K) | K2: =SUM(H2:J2) | L2: =K2*0.25 | M2: =K2*0.10 | N2: =K2+L2+M2 | O2: =IF(G2>0, N2/G2, 0) | P2: 0.18 | Q2: =O2*(1+P2) | R2: =G2*Q2
A3: 2 | B3: SW-DUCT-002 | C3: ỐNG GIÓ | D3: Tole tráng kẽm dày 0.75mm (dùng cho ống gió có 600<a, b<=1000mm) | E3: 0.75mm | F3: m2 | G3: 2103.6067 | H3: =SUMIF('01_BOC_TACH_ONG'!B:B, B3, '01_BOC_TACH_ONG'!K:K) | I3: =SUMIF('02_BOC_TACH_CUA'!B:B, B3, '02_BOC_TACH_CUA'!K:K) | J3: =SUMIF('03_BOC_TACH_VAN'!B:B, B3, '03_BOC_TACH_VAN'!K:K) | K3: =SUM(H3:J3) | L3: =K3*0.25 | M3: =K3*0.10 | N3: =K3+L3+M3 | O3: =IF(G3>0, N3/G3, 0) | P3: 0.18 | Q3: =O3*(1+P3) | R3: =G3*Q3
A4: 3 | B4: SW-DUCT-003 | C4: ỐNG GIÓ | D4: Tole tráng kẽm dày 0.95mm (dùng cho ống gió có 1000<a, b<=2000mm) | E4: 0.95mm | F4: m2 | G4: 1568.0175 | H4: =SUMIF('01_BOC_TACH_ONG'!B:B, B4, '01_BOC_TACH_ONG'!K:K) | I4: =SUMIF('02_BOC_TACH_CUA'!B:B, B4, '02_BOC_TACH_CUA'!K:K) | J4: =SUMIF('03_BOC_TACH_VAN'!B:B, B4, '03_BOC_TACH_VAN'!K:K) | K4: =SUM(H4:J4) | L4: =K4*0.25 | M4: =K4*0.10 | N4: =K4+L4+M4 | O4: =IF(G4>0, N4/G4, 0) | P4: 0.18 | Q4: =O4*(1+P4) | R4: =G4*Q4
A5: 4 | B5: SW-DUCT-004 | C5: ỐNG GIÓ | D5: Tole tráng kẽm dày 0.58mm (dùng cho ống gió có a, b <400mm) | E5: 0.58mm | F5: m2 | G5: 3836.0875 | H5: =SUMIF('01_BOC_TACH_ONG'!B:B, B5, '01_BOC_TACH_ONG'!K:K) | I5: =SUMIF('02_BOC_TACH_CUA'!B:B, B5, '02_BOC_TACH_CUA'!K:K) | J5: =SUMIF('03_BOC_TACH_VAN'!B:B, B5, '03_BOC_TACH_VAN'!K:K) | K5: =SUM(H5:J5) | L5: =K5*0.25 | M5: =K5*0.10 | N5: =K5+L5+M5 | O5: =IF(G5>0, N5/G5, 0) | P5: 0.18 | Q5: =O5*(1+P5) | R5: =G5*Q5
A6: 5 | B6: SW-DUCT-005 | C6: ỐNG GIÓ | D6: Tole tráng kẽm dày 0.75mm (dùng cho ống gió có 600<a, b<=1000mm) | E6: 0.75mm | F6: m2 | G6: 347.93 | H6: =SUMIF('01_BOC_TACH_ONG'!B:B, B6, '01_BOC_TACH_ONG'!K:K) | I6: =SUMIF('02_BOC_TACH_CUA'!B:B, B6, '02_BOC_TACH_CUA'!K:K) | J6: =SUMIF('03_BOC_TACH_VAN'!B:B, B6, '03_BOC_TACH_VAN'!K:K) | K6: =SUM(H6:J6) | L6: =K6*0.25 | M6: =K6*0.10 | N6: =K6+L6+M6 | O6: =IF(G6>0, N6/G6, 0) | P6: 0.18 | Q6: =O6*(1+P6) | R6: =G6*Q6
A7: 6 | B7: SW-DUCT-006 | C7: ỐNG GIÓ | D7: Thép không gỉ dày 1.15 mm cho hút, thải khói bếp (inox 304) | E7: 1.15mm | F7: m2 | G7: 189.595 | H7: =SUMIF('01_BOC_TACH_ONG'!B:B, B7, '01_BOC_TACH_ONG'!K:K) | I7: =SUMIF('02_BOC_TACH_CUA'!B:B, B7, '02_BOC_TACH_CUA'!K:K) | J7: =SUMIF('03_BOC_TACH_VAN'!B:B, B7, '03_BOC_TACH_VAN'!K:K) | K7: =SUM(H7:J7) | L7: =K7*0.25 | M7: =K7*0.10 | N7: =K7+L7+M7 | O7: =IF(G7>0, N7/G7, 0) | P7: 0.18 | Q7: =O7*(1+P7) | R7: =G7*Q7
A8: 7 | B8: SW-DUCT-007 | C8: ỐNG GIÓ | D8: Tole tráng kẽm dày 0.58mm (dùng cho ống gió có a, b <400mm) | E8: 0.58mm | F8: m2 | G8: 2180.8378 | H8: =SUMIF('01_BOC_TACH_ONG'!B:B, B8, '01_BOC_TACH_ONG'!K:K) | I8: =SUMIF('02_BOC_TACH_CUA'!B:B, B8, '02_BOC_TACH_CUA'!K:K) | J8: =SUMIF('03_BOC_TACH_VAN'!B:B, B8, '03_BOC_TACH_VAN'!K:K) | K8: =SUM(H8:J8) | L8: =K8*0.25 | M8: =K8*0.10 | N8: =K8+L8+M8 | O8: =IF(G8>0, N8/G8, 0) | P8: 0.18 | Q8: =O8*(1+P8) | R8: =G8*Q8
A9: 8 | B9: SW-DUCT-008 | C9: ỐNG GIÓ | D9: Tole tráng kẽm dày 0.75mm (dùng cho ống gió có 600<a, b<=1000mm) | E9: 0.75mm | F9: m2 | G9: 1705.355 | H9: =SUMIF('01_BOC_TACH_ONG'!B:B, B9, '01_BOC_TACH_ONG'!K:K) | I9: =SUMIF('02_BOC_TACH_CUA'!B:B, B9, '02_BOC_TACH_CUA'!K:K) | J9: =SUMIF('03_BOC_TACH_VAN'!B:B, B9, '03_BOC_TACH_VAN'!K:K) | K9: =SUM(H9:J9) | L9: =K9*0.25 | M9: =K9*0.10 | N9: =K9+L9+M9 | O9: =IF(G9>0, N9/G9, 0) | P9: 0.18 | Q9: =O9*(1+P9) | R9: =G9*Q9
A10: 9 | B10: SW-DUCT-009 | C10: ỐNG GIÓ | D10: Tole tráng kẽm dày 1.15mm (dùng cho ống gió có a, b>2000 mm) | E10: 1.15mm | F10: m2 | G10: 1058.41 | H10: =SUMIF('01_BOC_TACH_ONG'!B:B, B10, '01_BOC_TACH_ONG'!K:K) | I10: =SUMIF('02_BOC_TACH_CUA'!B:B, B10, '02_BOC_TACH_CUA'!K:K) | J10: =SUMIF('03_BOC_TACH_VAN'!B:B, B10, '03_BOC_TACH_VAN'!K:K) | K10: =SUM(H10:J10) | L10: =K10*0.25 | M10: =K10*0.10 | N10: =K10+L10+M10 | O10: =IF(G10>0, N10/G10, 0) | P10: 0.18 | Q10: =O10*(1+P10) | R10: =G10*Q10
A11: 10 | B11: SW-DUCT-010 | C11: ỐNG GIÓ | D11: Tole tráng kẽm dày 0.58mm (dùng cho ống gió có a, b <400mm) | E11: 0.58mm | F11: m2 | G11: 434.5 | H11: =SUMIF('01_BOC_TACH_ONG'!B:B, B11, '01_BOC_TACH_ONG'!K:K) | I11: =SUMIF('02_BOC_TACH_CUA'!B:B, B11, '02_BOC_TACH_CUA'!K:K) | J11: =SUMIF('03_BOC_TACH_VAN'!B:B, B11, '03_BOC_TACH_VAN'!K:K) | K11: =SUM(H11:J11) | L11: =K11*0.25 | M11: =K11*0.10 | N11: =K11+L11+M11 | O11: =IF(G11>0, N11/G11, 0) | P11: 0.18 | Q11: =O11*(1+P11) | R11: =G11*Q11
A12: 11 | B12: SW-DUCT-011 | C12: ỐNG GIÓ | D12: Tole tráng kẽm dày 0.75mm (dùng cho ống gió có 600<a, b<=1000mm) | E12: 0.75mm | F12: m2 | G12: 682.18 | H12: =SUMIF('01_BOC_TACH_ONG'!B:B, B12, '01_BOC_TACH_ONG'!K:K) | I12: =SUMIF('02_BOC_TACH_CUA'!B:B, B12, '02_BOC_TACH_CUA'!K:K) | J12: =SUMIF('03_BOC_TACH_VAN'!B:B, B12, '03_BOC_TACH_VAN'!K:K) | K12: =SUM(H12:J12) | L12: =K12*0.25 | M12: =K12*0.10 | N12: =K12+L12+M12 | O12: =IF(G12>0, N12/G12, 0) | P12: 0.18 | Q12: =O12*(1+P12) | R12: =G12*Q12
A13: 12 | B13: SW-DUCT-012 | C13: ỐNG GIÓ | D13: Ống gió chống cháy cho ống gió hút khói, tăng áp và phụ kiện EI60 kết nối nẹp TDC cấu tạo Tôn Hoa Sen mạ kẽm Z275 dày 0.75mm + 1 Tấm KHS.HF.Mpro14 dày 14mm. | E13: 0.75mm | F13: m2 | G13: 339.41 | H13: =SUMIF('01_BOC_TACH_ONG'!B:B, B13, '01_BOC_TACH_ONG'!K:K) | I13: =SUMIF('02_BOC_TACH_CUA'!B:B, B13, '02_BOC_TACH_CUA'!K:K) | J13: =SUMIF('03_BOC_TACH_VAN'!B:B, B13, '03_BOC_TACH_VAN'!K:K) | K13: =SUM(H13:J13) | L13: =K13*0.25 | M13: =K13*0.10 | N13: =K13+L13+M13 | O13: =IF(G13>0, N13/G13, 0) | P13: 0.18 | Q13: =O13*(1+P13) | R13: =G13*Q13
... A606: 605 | B606: SW-DIFF-605 | C606: CỬA GIÓ | D606: Chi phí vận chuyển | E606: - | F606: Gói | G606: 1 | H606: =SUMIF('01_BOC_TACH_ONG'!B:B, B606, '01_BOC_TACH_ONG'!K:K) | I606: =SUMIF('02_BOC_TACH_CUA'!B:B, B606, '02_BOC_TACH_CUA'!K:K) | J606: =SUMIF('03_BOC_TACH_VAN'!B:B, B606, '03_BOC_TACH_VAN'!K:K) | K606: =SUM(H606:J606) | L606: =K606*0.25 | M606: =K606*0.10 | N606: =K606+L606+M606 | O606: =IF(G606>0, N606/G606, 0) | P606: 0.18 | Q606: =O606*(1+P606) | R606: =G606*Q606

Sheet 01_BOC_TACH_ONG
A1: SUB_KEY | B1: PARENT_ITEM_ID | C1: TÊN CẤU KIỆN | D1: PHÂN LOẠI | E1: MÃ VẬT TƯ (MAT_ID) | F1: ĐVT | G1: ĐỊNH MỨC / 1 SP | H1: SL DỰ ÁN | I1: TỔNG NHU CẦU | J1: ĐƠN GIÁ GỐC | K1: THÀNH TIỀN (VNĐ) | L1: GHI CHÚ KỸ THUẬT
A2: SW-DUCT-001-BODY | B2: SW-DUCT-001 | C2: Thân ống gió bích TDF (0.58mm) | D2: TÔN_CUỘN_MẠ_KẼM | E2: MAT-STEEL-PN-0.58 | F2: kg | G2: 2.6202743 | H2: =XLOOKUP(B2, '00_TONG_HOP_BAO_GIA'!B:B, '00_TONG_HOP_BAO_GIA'!G:G, 1) | I2: =G2*H2 | J2: =XLOOKUP(E2, '06_BANG_GIA_VAT_TU_AP_DUNG'!B:B, '06_BANG_GIA_VAT_TU_AP_DUNG'!C:C, "LỖI_MÃ_VT") | K2: =I2*J2 | L2: Chu vi phôi 2.030m, Dài phôi 0.270m
A3: SW-DUCT-002-BODY | B3: SW-DUCT-002 | C3: Thân ống gió bích TDF (0.58mm) | D3: TÔN_CUỘN_MẠ_KẼM | E3: MAT-STEEL-PN-0.58 | F3: kg | G3: 2.6202743 | H3: =XLOOKUP(B3, '00_TONG_HOP_BAO_GIA'!B:B, '00_TONG_HOP_BAO_GIA'!G:G, 1) | I3: =G3*H3 | J3: =XLOOKUP(E3, '06_BANG_GIA_VAT_TU_AP_DUNG'!B:B, '06_BANG_GIA_VAT_TU_AP_DUNG'!C:C, "LỖI_MÃ_VT") | K3: =I3*J3 | L3: Chu vi phôi 2.030m, Dài phôi 0.270m
A4: SW-DUCT-003-BODY | B4: SW-DUCT-003 | C4: Thân ống gió bích TDF (0.58mm) | D4: TÔN_CUỘN_MẠ_KẼM | E4: MAT-STEEL-PN-0.58 | F4: kg | G4: 2.6202743 | H4: =XLOOKUP(B4, '00_TONG_HOP_BAO_GIA'!B:B, '00_TONG_HOP_BAO_GIA'!G:G, 1) | I4: =G4*H4 | J4: =XLOOKUP(E4, '06_BANG_GIA_VAT_TU_AP_DUNG'!B:B, '06_BANG_GIA_VAT_TU_AP_DUNG'!C:C, "LỖI_MÃ_VT") | K4: =I4*J4 | L4: Chu vi phôi 2.030m, Dài phôi 0.270m
A5: SW-DUCT-004-BODY | B5: SW-DUCT-004 | C5: Thân ống gió bích TDF (0.58mm) | D5: TÔN_CUỘN_MẠ_KẼM | E5: MAT-STEEL-PN-0.58 | F5: kg | G5: 2.6202743 | H5: =XLOOKUP(B5, '00_TONG_HOP_BAO_GIA'!B:B, '00_TONG_HOP_BAO_GIA'!G:G, 1) | I5: =G5*H5 | J5: =XLOOKUP(E5, '06_BANG_GIA_VAT_TU_AP_DUNG'!B:B, '06_BANG_GIA_VAT_TU_AP_DUNG'!C:C, "LỖI_MÃ_VT") | K5: =I5*J5 | L5: Chu vi phôi 2.030m, Dài phôi 0.270m
A6: SW-DUCT-005-BODY | B6: SW-DUCT-005 | C6: Thân ống gió bích TDF (0.58mm) | D6: TÔN_CUỘN_MẠ_KẼM | E6: MAT-STEEL-PN-0.58 | F6: kg | G6: 2.6202743 | H6: =XLOOKUP(B6, '00_TONG_HOP_BAO_GIA'!B:B, '00_TONG_HOP_BAO_GIA'!G:G, 1) | I6: =G6*H6 | J6: =XLOOKUP(E6, '06_BANG_GIA_VAT_TU_AP_DUNG'!B:B, '06_BANG_GIA_VAT_TU_AP_DUNG'!C:C, "LỖI_MÃ_VT") | K6: =I6*J6 | L6: Chu vi phôi 2.030m, Dài phôi 0.270m
A7: SW-DUCT-006-BODY | B7: SW-DUCT-006 | C7: Thân ống gió bích TDF (0.58mm) | D7: TÔN_CUỘN_MẠ_KẼM | E7: MAT-STEEL-PN-0.58 | F7: kg | G7: 2.6202743 | H7: =XLOOKUP(B7, '00_TONG_HOP_BAO_GIA'!B:B, '00_TONG_HOP_BAO_GIA'!G:G, 1) | I7: =G7*H7 | J7: =XLOOKUP(E7, '06_BANG_GIA_VAT_TU_AP_DUNG'!B:B, '06_BANG_GIA_VAT_TU_AP_DUNG'!C:C, "LỖI_MÃ_VT") | K7: =I7*J7 | L7: Chu vi phôi 2.030m, Dài phôi 0.270m
A8: SW-DUCT-007-BODY | B8: SW-DUCT-007 | C8: Thân ống gió bích TDF (0.58mm) | D8: TÔN_CUỘN_MẠ_KẼM | E8: MAT-STEEL-PN-0.58 | F8: kg | G8: 2.6202743 | H8: =XLOOKUP(B8, '00_TONG_HOP_BAO_GIA'!B:B, '00_TONG_HOP_BAO_GIA'!G:G, 1) | I8: =G8*H8 | J8: =XLOOKUP(E8, '06_BANG_GIA_VAT_TU_AP_DUNG'!B:B, '06_BANG_GIA_VAT_TU_AP_DUNG'!C:C, "LỖI_MÃ_VT") | K8: =I8*J8 | L8: Chu vi phôi 2.030m, Dài phôi 0.270m
A9: SW-DUCT-008-BODY | B9: SW-DUCT-008 | C9: Thân ống gió bích TDF (0.58mm) | D9: TÔN_CUỘN_MẠ_KẼM | E9: MAT-STEEL-PN-0.58 | F9: kg | G9: 2.6202743 | H9: =XLOOKUP(B9, '00_TONG_HOP_BAO_GIA'!B:B, '00_TONG_HOP_BAO_GIA'!G:G, 1) | I9: =G9*H9 | J9: =XLOOKUP(E9, '06_BANG_GIA_VAT_TU_AP_DUNG'!B:B, '06_BANG_GIA_VAT_TU_AP_DUNG'!C:C, "LỖI_MÃ_VT") | K9: =I9*J9 | L9: Chu vi phôi 2.030m, Dài phôi 0.270m
A10: SW-DUCT-009-BODY | B10: SW-DUCT-009 | C10: Thân ống gió bích TDF (0.58mm) | D10: TÔN_CUỘN_MẠ_KẼM | E10: MAT-STEEL-PN-0.58 | F10: kg | G10: 2.6202743 | H10: =XLOOKUP(B10, '00_TONG_HOP_BAO_GIA'!B:B, '00_TONG_HOP_BAO_GIA'!G:G, 1) | I10: =G10*H10 | J10: =XLOOKUP(E10, '06_BANG_GIA_VAT_TU_AP_DUNG'!B:B, '06_BANG_GIA_VAT_TU_AP_DUNG'!C:C, "LỖI_MÃ_VT") | K10: =I10*J10 | L10: Chu vi phôi 2.030m, Dài phôi 0.270m
A11: SW-DUCT-010-BODY | B11: SW-DUCT-010 | C11: Thân ống gió bích TDF (0.58mm) | D11: TÔN_CUỘN_MẠ_KẼM | E11: MAT-STEEL-PN-0.58 | F11: kg | G11: 2.6202743 | H11: =XLOOKUP(B11, '00_TONG_HOP_BAO_GIA'!B:B, '00_TONG_HOP_BAO_GIA'!G:G, 1) | I11: =G11*H11 | J11: =XLOOKUP(E11, '06_BANG_GIA_VAT_TU_AP_DUNG'!B:B, '06_BANG_GIA_VAT_TU_AP_DUNG'!C:C, "LỖI_MÃ_VT") | K11: =I11*J11 | L11: Chu vi phôi 2.030m, Dài phôi 0.270m
A12: SW-DUCT-011-BODY | B12: SW-DUCT-011 | C12: Thân ống gió bích TDF (0.58mm) | D12: TÔN_CUỘN_MẠ_KẼM | E12: MAT-STEEL-PN-0.58 | F12: kg | G12: 2.6202743 | H12: =XLOOKUP(B12, '00_TONG_HOP_BAO_GIA'!B:B, '00_TONG_HOP_BAO_GIA'!G:G, 1) | I12: =G12*H12 | J12: =XLOOKUP(E12, '06_BANG_GIA_VAT_TU_AP_DUNG'!B:B, '06_BANG_GIA_VAT_TU_AP_DUNG'!C:C, "LỖI_MÃ_VT") | K12: =I12*J12 | L12: Chu vi phôi 2.030m, Dài phôi 0.270m
A13: SW-DUCT-012-BODY | B13: SW-DUCT-012 | C13: Thân ống gió bích TDF (0.58mm) | D13: TÔN_CUỘN_MẠ_KẼM | E13: MAT-STEEL-PN-0.58 | F13: kg | G13: 2.6202743 | H13: =XLOOKUP(B13, '00_TONG_HOP_BAO_GIA'!B:B, '00_TONG_HOP_BAO_GIA'!G:G, 1) | I13: =G13*H13 | J13: =XLOOKUP(E13, '06_BANG_GIA_VAT_TU_AP_DUNG'!B:B, '06_BANG_GIA_VAT_TU_AP_DUNG'!C:C, "LỖI_MÃ_VT") | K13: =I13*J13 | L13: Chu vi phôi 2.030m, Dài phôi 0.270m
... A22: SW-DUCT-021-BODY | B22: SW-DUCT-021 | C22: Thân ống gió bích TDF (0.58mm) | D22: TÔN_CUỘN_MẠ_KẼM | E22: MAT-STEEL-PN-0.58 | F22: kg | G22: 2.6202743 | H22: =XLOOKUP(B22, '00_TONG_HOP_BAO_GIA'!B:B, '00_TONG_HOP_BAO_GIA'!G:G, 1) | I22: =G22*H22 | J22: =XLOOKUP(E22, '06_BANG_GIA_VAT_TU_AP_DUNG'!B:B, '06_BANG_GIA_VAT_TU_AP_DUNG'!C:C, "LỖI_MÃ_VT") | K22: =I22*J22 | L22: Chu vi phôi 2.030m, Dài phôi 0.270m

Sheet 02_BOC_TACH_CUA
A1: SUB_KEY | B1: PARENT_ITEM_ID | C1: TÊN CẤU KIỆN | D1: PHÂN LOẠI | E1: MÃ VẬT TƯ (MAT_ID) | F1: ĐVT | G1: ĐỊNH MỨC / 1 SP | H1: SL DỰ ÁN | I1: TỔNG NHU CẦU | J1: ĐƠN GIÁ GỐC | K1: THÀNH TIỀN (VNĐ) | L1: GHI CHÚ KỸ THUẬT
A2: SW-DIFF-091-FRAME | B2: SW-DIFF-091 | C2: Khung nhôm định hình (Z) | D2: NHÔM_ĐỊNH_HÌNH | E2: MAT-ALU-KHUNG-Z-2-LOP | F2: kg | G2: 0.28602 | H2: =XLOOKUP(B2, '00_TONG_HOP_BAO_GIA'!B:B, '00_TONG_HOP_BAO_GIA'!G:G, 1) | I2: =G2*H2 | J2: =XLOOKUP(E2, '06_BANG_GIA_VAT_TU_AP_DUNG'!B:B, '06_BANG_GIA_VAT_TU_AP_DUNG'!C:C, "LỖI_MÃ_VT") | K2: =I2*J2 | L2: Dài cắt 1.26m @ 0.227kg/m
A3: SW-DIFF-091-BLADE | B3: SW-DIFF-091 | C3: Nan nhôm định hình (Z) | D3: NHÔM_ĐỊNH_HÌNH | E3: MAT-ALU-NAN-Z-DAY | F3: kg | G3: 0.528612 | H3: =XLOOKUP(B3, '00_TONG_HOP_BAO_GIA'!B:B, '00_TONG_HOP_BAO_GIA'!G:G, 1) | I3: =G3*H3 | J3: =XLOOKUP(E3, '06_BANG_GIA_VAT_TU_AP_DUNG'!B:B, '06_BANG_GIA_VAT_TU_AP_DUNG'!C:C, "LỖI_MÃ_VT") | K3: =I3*J3 | L3: 8 nan dài 2.44m @ 0.217kg/m
A4: SW-DIFF-091-ACCESSORY | B4: SW-DIFF-091 | C4: Phụ kiện lắp ghép / Ke góc cửa gió | D4: PHỤ_KIỆN_CỬA | E4: MAT-DOOR-ACCESSORY | F4: Bộ | G4: 1 | H4: =XLOOKUP(B4, '00_TONG_HOP_BAO_GIA'!B:B, '00_TONG_HOP_BAO_GIA'!G:G, 1) | I4: =G4*H4 | J4: =XLOOKUP(E4, '06_BANG_GIA_VAT_TU_AP_DUNG'!B:B, '06_BANG_GIA_VAT_TU_AP_DUNG'!C:C, "LỖI_MÃ_VT") | K4: =I4*J4 | L4: 4 ke góc chìm và vít ghép khung
A5: SW-DIFF-091-PAINT | B5: SW-DIFF-091 | C5: Sơn tĩnh điện tiêu chuẩn Polyester | D5: SƠN_TĨNH_ĐIỆN | E5: MAT-PAINT-POWDER | F5: m2 | G5: 0.135 | H5: =XLOOKUP(B5, '00_TONG_HOP_BAO_GIA'!B:B, '00_TONG_HOP_BAO_GIA'!G:G, 1) | I5: =G5*H5 | J5: =XLOOKUP(E5, '06_BANG_GIA_VAT_TU_AP_DUNG'!B:B, '06_BANG_GIA_VAT_TU_AP_DUNG'!C:C, "LỖI_MÃ_VT") | K5: =I5*J5 | L5: Diện tích phủ sơn 0.135m2
A6: SW-DIFF-166-FRAME | B6: SW-DIFF-166 | C6: Khung nhôm định hình (BD) | D6: NHÔM_ĐỊNH_HÌNH | E6: MAT-ALU-KHUNG-BD | F6: kg | G6: 0.126 | H6: =XLOOKUP(B6, '00_TONG_HOP_BAO_GIA'!B:B, '00_TONG_HOP_BAO_GIA'!G:G, 1) | I6: =G6*H6 | J6: =XLOOKUP(E6, '06_BANG_GIA_VAT_TU_AP_DUNG'!B:B, '06_BANG_GIA_VAT_TU_AP_DUNG'!C:C, "LỖI_MÃ_VT") | K6: =I6*J6 | L6: Dài cắt 0.63m @ 0.2kg/m
A7: SW-DIFF-166-BLADE | B7: SW-DIFF-166 | C7: Nan nhôm định hình (BD) | D7: NHÔM_ĐỊNH_HÌNH | E7: MAT-ALU-NAN-BD | F7: kg | G7: 0.046284 | H7: =XLOOKUP(B7, '00_TONG_HOP_BAO_GIA'!B:B, '00_TONG_HOP_BAO_GIA'!G:G, 1) | I7: =G7*H7 | J7: =XLOOKUP(E7, '06_BANG_GIA_VAT_TU_AP_DUNG'!B:B, '06_BANG_GIA_VAT_TU_AP_DUNG'!C:C, "LỖI_MÃ_VT") | K7: =I7*J7 | L7: 4 nan dài 0.80m @ 0.058kg/m
A8: SW-DIFF-166-ACCESSORY | B8: SW-DIFF-166 | C8: Phụ kiện lắp ghép / Ke góc cửa gió | D8: PHỤ_KIỆN_CỬA | E8: MAT-DOOR-ACCESSORY | F8: Bộ | G8: 1 | H8: =XLOOKUP(B8, '00_TONG_HOP_BAO_GIA'!B:B, '00_TONG_HOP_BAO_GIA'!G:G, 1) | I8: =G8*H8 | J8: =XLOOKUP(E8, '06_BANG_GIA_VAT_TU_AP_DUNG'!B:B, '06_BANG_GIA_VAT_TU_AP_DUNG'!C:C, "LỖI_MÃ_VT") | K8: =I8*J8 | L8: 4 ke góc chìm và vít ghép khung
A9: SW-DIFF-166-PAINT | B9: SW-DIFF-166 | C9: Sơn tĩnh điện tiêu chuẩn Polyester | D9: SƠN_TĨNH_ĐIỆN | E9: MAT-PAINT-POWDER | F9: m2 | G9: 0.03 | H9: =XLOOKUP(B9, '00_TONG_HOP_BAO_GIA'!B:B, '00_TONG_HOP_BAO_GIA'!G:G, 1) | I9: =G9*H9 | J9: =XLOOKUP(E9, '06_BANG_GIA_VAT_TU_AP_DUNG'!B:B, '06_BANG_GIA_VAT_TU_AP_DUNG'!C:C, "LỖI_MÃ_VT") | K9: =I9*J9 | L9: Diện tích phủ sơn 0.030m2
A10: SW-DIFF-167-FRAME | B10: SW-DIFF-167 | C10: Khung nhôm định hình (BD) | D10: NHÔM_ĐỊNH_HÌNH | E10: MAT-ALU-KHUNG-BD | F10: kg | G10: 0.147 | H10: =XLOOKUP(B10, '00_TONG_HOP_BAO_GIA'!B:B, '00_TONG_HOP_BAO_GIA'!G:G, 1) | I10: =G10*H10 | J10: =XLOOKUP(E10, '06_BANG_GIA_VAT_TU_AP_DUNG'!B:B, '06_BANG_GIA_VAT_TU_AP_DUNG'!C:C, "LỖI_MÃ_VT") | K10: =I10*J10 | L10: Dài cắt 0.73m @ 0.2kg/m
A11: SW-DIFF-167-BLADE | B11: SW-DIFF-167 | C11: Nan nhôm định hình (BD) | D11: NHÔM_ĐỊNH_HÌNH | E11: MAT-ALU-NAN-BD | F11: kg | G11: 0.069426 | H11: =XLOOKUP(B11, '00_TONG_HOP_BAO_GIA'!B:B, '00_TONG_HOP_BAO_GIA'!G:G, 1) | I11: =G11*H11 | J11: =XLOOKUP(E11, '06_BANG_GIA_VAT_TU_AP_DUNG'!B:B, '06_BANG_GIA_VAT_TU_AP_DUNG'!C:C, "LỖI_MÃ_VT") | K11: =I11*J11 | L11: 6 nan dài 1.20m @ 0.058kg/m
A12: SW-DIFF-167-ACCESSORY | B12: SW-DIFF-167 | C12: Phụ kiện lắp ghép / Ke góc cửa gió | D12: PHỤ_KIỆN_CỬA | E12: MAT-DOOR-ACCESSORY | F12: Bộ | G12: 1 | H12: =XLOOKUP(B12, '00_TONG_HOP_BAO_GIA'!B:B, '00_TONG_HOP_BAO_GIA'!G:G, 1) | I12: =G12*H12 | J12: =XLOOKUP(E12, '06_BANG_GIA_VAT_TU_AP_DUNG'!B:B, '06_BANG_GIA_VAT_TU_AP_DUNG'!C:C, "LỖI_MÃ_VT") | K12: =I12*J12 | L12: 4 ke góc chìm và vít ghép khung
A13: SW-DIFF-167-PAINT | B13: SW-DIFF-167 | C13: Sơn tĩnh điện tiêu chuẩn Polyester | D13: SƠN_TĨNH_ĐIỆN | E13: MAT-PAINT-POWDER | F13: m2 | G13: 0.045 | H13: =XLOOKUP(B13, '00_TONG_HOP_BAO_GIA'!B:B, '00_TONG_HOP_BAO_GIA'!G:G, 1) | I13: =G13*H13 | J13: =XLOOKUP(E13, '06_BANG_GIA_VAT_TU_AP_DUNG'!B:B, '06_BANG_GIA_VAT_TU_AP_DUNG'!C:C, "LỖI_MÃ_VT") | K13: =I13*J13 | L13: Diện tích phủ sơn 0.045m2
... A65: SW-DIFF-589-PAINT | B65: SW-DIFF-589 | C65: Sơn tĩnh điện tiêu chuẩn Polyester | D65: SƠN_TĨNH_ĐIỆN | E65: MAT-PAINT-POWDER | F65: m2 | G65: 2.30625 | H65: =XLOOKUP(B65, '00_TONG_HOP_BAO_GIA'!B:B, '00_TONG_HOP_BAO_GIA'!G:G, 1) | I65: =G65*H65 | J65: =XLOOKUP(E65, '06_BANG_GIA_VAT_TU_AP_DUNG'!B:B, '06_BANG_GIA_VAT_TU_AP_DUNG'!C:C, "LỖI_MÃ_VT") | K65: =I65*J65 | L65: Diện tích phủ sơn 2.306m2

Sheet 03_BOC_TACH_VAN
A1: SUB_KEY | B1: PARENT_ITEM_ID | C1: TÊN CẤU KIỆN | D1: PHÂN LOẠI | E1: MÃ VẬT TƯ (MAT_ID) | F1: ĐVT | G1: ĐỊNH MỨC / 1 SP | H1: SL DỰ ÁN | I1: TỔNG NHU CẦU | J1: ĐƠN GIÁ GỐC | K1: THÀNH TIỀN (VNĐ) | L1: GHI CHÚ KỸ THUẬT
A2: SW-DAMPER-022-BODY | B2: SW-DAMPER-022 | C2: Thân vỏ van VCD bích TDF (0.75mm) | D2: TÔN_CUỘN_MẠ_KẼM | E2: MAT-STEEL-PN-0.75 | F2: kg | G2: 0.761607 | H2: =XLOOKUP(B2, '00_TONG_HOP_BAO_GIA'!B:B, '00_TONG_HOP_BAO_GIA'!G:G, 1) | I2: =G2*H2 | J2: =XLOOKUP(E2, '06_BANG_GIA_VAT_TU_AP_DUNG'!B:B, '06_BANG_GIA_VAT_TU_AP_DUNG'!C:C, "LỖI_MÃ_VT") | K2: =I2*J2 | L2: Kích thước vỏ 100.0x100.0x210mm
A3: SW-DAMPER-022-BLADE | B3: SW-DAMPER-022 | C3: Lá cánh van (1 cánh overlap) | D3: TÔN_CUỘN_MẠ_KẼM | E3: MAT-STEEL-PN-0.75 | F3: kg | G3: 0.076302 | H3: =XLOOKUP(B3, '00_TONG_HOP_BAO_GIA'!B:B, '00_TONG_HOP_BAO_GIA'!G:G, 1) | I3: =G3*H3 | J3: =XLOOKUP(E3, '06_BANG_GIA_VAT_TU_AP_DUNG'!B:B, '06_BANG_GIA_VAT_TU_AP_DUNG'!C:C, "LỖI_MÃ_VT") | K3: =I3*J3 | L3: 1 cánh cao 120mm
A4: SW-DAMPER-022-AXLE | B4: SW-DAMPER-022 | C4: Trục Sus 201 D10 | D4: PHỤ_KIỆN_VAN | E4: MAT-DAMPER-TRUC-SUS-201-D10 | F4: m | G4: 0.16 | H4: =XLOOKUP(B4, '00_TONG_HOP_BAO_GIA'!B:B, '00_TONG_HOP_BAO_GIA'!G:G, 1) | I4: =G4*H4 | J4: =XLOOKUP(E4, '06_BANG_GIA_VAT_TU_AP_DUNG'!B:B, '06_BANG_GIA_VAT_TU_AP_DUNG'!C:C, "LỖI_MÃ_VT") | K4: =I4*J4 | L4: 1 trục dài 160mm
A5: SW-DAMPER-022-BEARING | B5: SW-DAMPER-022 | C5: Bạc đồng D10 | D5: PHỤ_KIỆN_VAN | E5: MAT-DAMPER-BAC-DONG-D10 | F5: Đôi | G5: 1 | H5: =XLOOKUP(B5, '00_TONG_HOP_BAO_GIA'!B:B, '00_TONG_HOP_BAO_GIA'!G:G, 1) | I5: =G5*H5 | J5: =XLOOKUP(E5, '06_BANG_GIA_VAT_TU_AP_DUNG'!B:B, '06_BANG_GIA_VAT_TU_AP_DUNG'!C:C, "LỖI_MÃ_VT") | K5: =I5*J5 | L5: 1 đôi bạc đỡ 2 bên thân
A6: SW-DAMPER-022-HANDLE | B6: SW-DAMPER-022 | C6: Tay gạt nhỏ | D6: PHỤ_KIỆN_VAN | E6: MAT-DAMPER-TAY-GAT-NHO | F6: Bộ | G6: 1 | H6: =XLOOKUP(B6, '00_TONG_HOP_BAO_GIA'!B:B, '00_TONG_HOP_BAO_GIA'!G:G, 1) | I6: =G6*H6 | J6: =XLOOKUP(E6, '06_BANG_GIA_VAT_TU_AP_DUNG'!B:B, '06_BANG_GIA_VAT_TU_AP_DUNG'!C:C, "LỖI_MÃ_VT") | K6: =I6*J6 | L6: Tay gạt khóa vị trí nan (S=0.01m2)
A7: SW-DAMPER-023-BODY | B7: SW-DAMPER-023 | C7: Thân vỏ van VCD bích TDF (0.75mm) | D7: TÔN_CUỘN_MẠ_KẼM | E7: MAT-STEEL-PN-0.75 | F7: kg | G7: 0.9346995 | H7: =XLOOKUP(B7, '00_TONG_HOP_BAO_GIA'!B:B, '00_TONG_HOP_BAO_GIA'!G:G, 1) | I7: =G7*H7 | J7: =XLOOKUP(E7, '06_BANG_GIA_VAT_TU_AP_DUNG'!B:B, '06_BANG_GIA_VAT_TU_AP_DUNG'!C:C, "LỖI_MÃ_VT") | K7: =I7*J7 | L7: Kích thước vỏ 150.0x100.0x210mm
A8: SW-DAMPER-023-BLADE | B8: SW-DAMPER-023 | C8: Lá cánh van (1 cánh overlap) | D8: TÔN_CUỘN_MẠ_KẼM | E8: MAT-STEEL-PN-0.75 | F8: kg | G8: 0.114453 | H8: =XLOOKUP(B8, '00_TONG_HOP_BAO_GIA'!B:B, '00_TONG_HOP_BAO_GIA'!G:G, 1) | I8: =G8*H8 | J8: =XLOOKUP(E8, '06_BANG_GIA_VAT_TU_AP_DUNG'!B:B, '06_BANG_GIA_VAT_TU_AP_DUNG'!C:C, "LỖI_MÃ_VT") | K8: =I8*J8 | L8: 1 cánh cao 120mm
A9: SW-DAMPER-023-AXLE | B9: SW-DAMPER-023 | C9: Trục Sus 201 D10 | D9: PHỤ_KIỆN_VAN | E9: MAT-DAMPER-TRUC-SUS-201-D10 | F9: m | G9: 0.21 | H9: =XLOOKUP(B9, '00_TONG_HOP_BAO_GIA'!B:B, '00_TONG_HOP_BAO_GIA'!G:G, 1) | I9: =G9*H9 | J9: =XLOOKUP(E9, '06_BANG_GIA_VAT_TU_AP_DUNG'!B:B, '06_BANG_GIA_VAT_TU_AP_DUNG'!C:C, "LỖI_MÃ_VT") | K9: =I9*J9 | L9: 1 trục dài 210mm
A10: SW-DAMPER-023-BEARING | B10: SW-DAMPER-023 | C10: Bạc đồng D10 | D10: PHỤ_KIỆN_VAN | E10: MAT-DAMPER-BAC-DONG-D10 | F10: Đôi | G10: 1 | H10: =XLOOKUP(B10, '00_TONG_HOP_BAO_GIA'!B:B, '00_TONG_HOP_BAO_GIA'!G:G, 1) | I10: =G10*H10 | J10: =XLOOKUP(E10, '06_BANG_GIA_VAT_TU_AP_DUNG'!B:B, '06_BANG_GIA_VAT_TU_AP_DUNG'!C:C, "LỖI_MÃ_VT") | K10: =I10*J10 | L10: 1 đôi bạc đỡ 2 bên thân
A11: SW-DAMPER-023-HANDLE | B11: SW-DAMPER-023 | C11: Tay gạt nhỏ | D11: PHỤ_KIỆN_VAN | E11: MAT-DAMPER-TAY-GAT-NHO | F11: Bộ | G11: 1 | H11: =XLOOKUP(B11, '00_TONG_HOP_BAO_GIA'!B:B, '00_TONG_HOP_BAO_GIA'!G:G, 1) | I11: =G11*H11 | J11: =XLOOKUP(E11, '06_BANG_GIA_VAT_TU_AP_DUNG'!B:B, '06_BANG_GIA_VAT_TU_AP_DUNG'!C:C, "LỖI_MÃ_VT") | K11: =I11*J11 | L11: Tay gạt khóa vị trí nan (S=0.01m2)
A12: SW-DAMPER-024-BODY | B12: SW-DAMPER-024 | C12: Thân vỏ van VCD bích TDF (0.75mm) | D12: TÔN_CUỘN_MẠ_KẼM | E12: MAT-STEEL-PN-0.75 | F12: kg | G12: 1.107792 | H12: =XLOOKUP(B12, '00_TONG_HOP_BAO_GIA'!B:B, '00_TONG_HOP_BAO_GIA'!G:G, 1) | I12: =G12*H12 | J12: =XLOOKUP(E12, '06_BANG_GIA_VAT_TU_AP_DUNG'!B:B, '06_BANG_GIA_VAT_TU_AP_DUNG'!C:C, "LỖI_MÃ_VT") | K12: =I12*J12 | L12: Kích thước vỏ 150.0x150.0x210mm
A13: SW-DAMPER-024-BLADE | B13: SW-DAMPER-024 | C13: Lá cánh van (1 cánh overlap) | D13: TÔN_CUỘN_MẠ_KẼM | E13: MAT-STEEL-PN-0.75 | F13: kg | G13: 0.16214175 | H13: =XLOOKUP(B13, '00_TONG_HOP_BAO_GIA'!B:B, '00_TONG_HOP_BAO_GIA'!G:G, 1) | I13: =G13*H13 | J13: =XLOOKUP(E13, '06_BANG_GIA_VAT_TU_AP_DUNG'!B:B, '06_BANG_GIA_VAT_TU_AP_DUNG'!C:C, "LỖI_MÃ_VT") | K13: =I13*J13 | L13: 1 cánh cao 170mm
... A2503: SW-DAMPER-603-ACTUATOR | B2503: SW-DAMPER-603 | C2503: Model: NACA 2-05 (5Nm, 220VAC) | D2503: ĐỘNG_CƠ_VÀ_CẢM_BIẾN | E2503: MAT-ACTUATOR-NACA-2-05 | F2503: Cái | G2503: 1 | H2503: =XLOOKUP(B2503, '00_TONG_HOP_BAO_GIA'!B:B, '00_TONG_HOP_BAO_GIA'!G:G, 1) | I2503: =G2503*H2503 | J2503: =XLOOKUP(E2503, '06_BANG_GIA_VAT_TU_AP_DUNG'!B:B, '06_BANG_GIA_VAT_TU_AP_DUNG'!C:C, "LỖI_MÃ_VT") | K2503: =I2503*J2503 | L2503: Tiết diện van 0.02m2

Sheet 05_DANH_MUC_KY_THUAT_GOC
A1: STT | B1: MAT_ID | C1: PHÂN LOẠI | D1: TÊN VẬT TƯ | E1: ĐVT | F1: BAREM KỸ THUẬT | G1: NGUỒN ĐỐI SOÁT
A2: 1 | B2: MAT-STEEL-DONGBU-0.50 | C2: TÔN_CUỘN_MẠ_KẼM | D2: TÔN DONGBU 0.50mm | E2: kg | F2: 3.925 kg/m2 | G2: Vat tu tôn!R5C2
A3: 2 | B3: MAT-STEEL-DONGBU-0.60 | C3: TÔN_CUỘN_MẠ_KẼM | D3: TÔN DONGBU 0.60mm | E3: kg | F3: 4.71 kg/m2 | G3: Vat tu tôn!R6C2
A4: 3 | B4: MAT-STEEL-DONGBU-0.80 | C4: TÔN_CUỘN_MẠ_KẼM | D4: TÔN DONGBU 0.80mm | E4: kg | F4: 6.28 kg/m2 | G4: Vat tu tôn!R7C2
A5: 4 | B5: MAT-STEEL-DONGBU-1.00 | C5: TÔN_CUỘN_MẠ_KẼM | D5: TÔN DONGBU 1.00mm | E5: kg | F5: 7.85 kg/m2 | G5: Vat tu tôn!R8C2
A6: 5 | B6: MAT-STEEL-DONGBU-1.20 | C6: TÔN_CUỘN_MẠ_KẼM | D6: TÔN DONGBU 1.20mm | E6: kg | F6: 9.42 kg/m2 | G6: Vat tu tôn!R9C2
A7: 6 | B7: MAT-STEEL-DONGBU-1.50 | C7: TÔN_CUỘN_MẠ_KẼM | D7: TÔN DONGBU 1.50mm | E7: kg | F7: 11.775 kg/m2 | G7: Vat tu tôn!R10C2
A8: 7 | B8: MAT-STEEL-DONGBU-2.00 | C8: TÔN_CUỘN_MẠ_KẼM | D8: TÔN DONGBU 2.00mm | E8: kg | F8: 15.7 kg/m2 | G8: Vat tu tôn!R11C2
A9: 8 | B9: MAT-STEEL-VNSTEEL-0.35 | C9: TÔN_CUỘN_MẠ_KẼM | D9: TÔN THĂNG LONG VNSTEEL 0.35mm | E9: kg | F9: 3.15 kg/m2 | G9: Vat tu tôn!R5C7
A10: 9 | B10: MAT-STEEL-VNSTEEL-0.40 | C10: TÔN_CUỘN_MẠ_KẼM | D10: TÔN THĂNG LONG VNSTEEL 0.40mm | E10: kg | F10: 3.72 kg/m2 | G10: Vat tu tôn!R6C7
A11: 10 | B11: MAT-STEEL-VNSTEEL-0.42 | C11: TÔN_CUỘN_MẠ_KẼM | D11: TÔN THĂNG LONG VNSTEEL 0.42mm | E11: kg | F11: 3.91 kg/m2 | G11: Vat tu tôn!R7C7
A12: 11 | B12: MAT-STEEL-VNSTEEL-0.47 | C12: TÔN_CUỘN_MẠ_KẼM | D12: TÔN THĂNG LONG VNSTEEL 0.47mm | E12: kg | F12: 4.38 kg/m2 | G12: Vat tu tôn!R8C7
A13: 12 | B13: MAT-STEEL-VNSTEEL-0.50 | C13: TÔN_CUỘN_MẠ_KẼM | D13: TÔN THĂNG LONG VNSTEEL 0.50mm | E13: kg | F13: 4.66 kg/m2 | G13: Vat tu tôn!R9C7
... A44: 43 | B44: MAT-STEEL-BLUESCOPE-1.15 | C44: TÔN_CUỘN_MẠ_KẼM | D44: TÔN BLUESCOPE 1.15mm | E44: kg | F44: 9.027 kg/m2 | G44: Vat tu tôn!R9C24
A45: 44 | B45: MAT-INOX-SUS304-0-5 | C45: INOX | D45: Inox Sus304-0.5 | E45: kg | G45: Vat tu tôn!R5C29
A46: 45 | B46: MAT-INOX-SUS304-0-6 | C46: INOX | D46: Inox Sus304-0.6 | E46: kg | G46: Vat tu tôn!R6C29
A47: 46 | B47: MAT-INOX-SUS304-0-7 | C47: INOX | D47: Inox Sus304-0.7 | E47: kg | G47: Vat tu tôn!R7C29
A48: 47 | B48: MAT-INOX-SUS304-0-8 | C48: INOX | D48: Inox Sus304-0.8 | E48: kg | G48: Vat tu tôn!R8C29
A49: 48 | B49: MAT-INOX-SUS304-0-9 | C49: INOX | D49: Inox Sus304-0.9 | E49: kg | G49: Vat tu tôn!R9C29
A50: 49 | B50: MAT-INOX-SUS304-1-0 | C50: INOX | D50: Inox Sus304-1,0 | E50: kg | G50: Vat tu tôn!R10C29
A51: 50 | B51: MAT-INOX-SUS304-1-2 | C51: INOX | D51: Inox Sus304-1,2 | E51: kg | G51: Vat tu tôn!R11C29
A52: 51 | B52: MAT-INOX-SUS430-0-5 | C52: INOX | D52: Inox Sus430-0.5 | E52: kg | G52: Vat tu tôn!R12C29
A53: 52 | B53: MAT-INOX-SUS430-0-6 | C53: INOX | D53: Inox Sus430-0.6 | E53: kg | G53: Vat tu tôn!R13C29
A54: 53 | B54: MAT-INOX-SUS430-0-7 | C54: INOX | D54: Inox Sus430-0.7 | E54: kg | G54: Vat tu tôn!R14C29
A55: 54 | B55: MAT-INOX-SUS430-0-8 | C55: INOX | D55: Inox Sus430-0.8 | E55: kg | G55: Vat tu tôn!R15C29
A56: 55 | B56: MAT-INOX-SUS430-0-9 | C56: INOX | D56: Inox Sus430-0.9 | E56: kg | G56: Vat tu tôn!R16C29
... A102: 101 | B102: MAT-INSUL-MOTOR-VAN-AP-SUAT | C102: VẬT_LIỆU_TIÊU_ÂM | D102: Motor van áp suất | E102: m2 | G102: Vat tu tôn!R10C41
A103: 102 | B103: MAT-ALU-NAN-BD | C103: NHÔM_ĐỊNH_HÌNH | D103: Nhôm định hình NAN BD | E103: kg | F103: 0.058 kg/m | G103: BG Cửa (rút gọn)!R3C2
A104: 103 | B104: MAT-ALU-NAN-T | C104: NHÔM_ĐỊNH_HÌNH | D104: Nhôm định hình NAN T | E104: kg | F104: 0.078 kg/m | G104: BG Cửa (rút gọn)!R4C2
A105: 104 | B105: MAT-ALU-KHUNG-BD | C105: NHÔM_ĐỊNH_HÌNH | D105: Nhôm định hình KHUNG BD | E105: kg | F105: 0.2 kg/m | G105: BG Cửa (rút gọn)!R5C2
A106: 105 | B106: MAT-ALU-KHUNG-BD-Z-MONG | C106: NHÔM_ĐỊNH_HÌNH | D106: Nhôm định hình KHUNG BD+ Z MỎNG | E106: kg | F106: 0.173 kg/m | G106: BG Cửa (rút gọn)!R6C2
A107: 106 | B107: MAT-ALU-NAN-Z-DAY | C107: NHÔM_ĐỊNH_HÌNH | D107: Nhôm định hình NAN Z DÀY | E107: kg | F107: 0.217 kg/m | G107: BG Cửa (rút gọn)!R7C2
A108: 107 | B108: MAT-ALU-NAN-Z-MONG | C108: NHÔM_ĐỊNH_HÌNH | D108: Nhôm định hình NAN Z MỎNG | E108: kg | F108: 0.16 kg/m | G108: BG Cửa (rút gọn)!R8C2
A109: 108 | B109: MAT-ALU-KHUNG-Z-2-LOP | C109: NHÔM_ĐỊNH_HÌNH | D109: Nhôm định hình KHUNG Z+2 LỚP | E109: kg | F109: 0.227 kg/m | G109: BG Cửa (rút gọn)!R9C2
A110: 109 | B110: MAT-ALU-NAN-OBD | C110: NHÔM_ĐỊNH_HÌNH | D110: Nhôm định hình NAN OBD | E110: kg | F110: 0.11 kg/m | G110: BG Cửa (rút gọn)!R10C2
A111: 110 | B111: MAT-ALU-KHUNG-OBD | C111: NHÔM_ĐỊNH_HÌNH | D111: Nhôm định hình KHUNG OBD | E111: kg | F111: 0.158 kg/m | G111: BG Cửa (rút gọn)!R11C2
A112: 111 | B112: MAT-ALU-NAN-BD-EUS02 | C112: NHÔM_ĐỊNH_HÌNH | D112: Nhôm định hình NAN BD EUS 02 | E112: kg | F112: 0.071 kg/m | G112: BG Cửa (rút gọn)!R14C2
A113: 112 | B113: MAT-ALU-KHUNG-BD-EUS01 | C113: NHÔM_ĐỊNH_HÌNH | D113: Nhôm định hình KHUNG BD EUS 01 | E113: kg | F113: 0.206 kg/m | G113: BG Cửa (rút gọn)!R15C2
A114: 113 | B114: MAT-ALU-NAN-Z-EUS05 | C114: NHÔM_ĐỊNH_HÌNH | D114: Nhôm định hình NAN Z EUS 05 | E114: kg | F114: 0.162 kg/m | G114: BG Cửa (rút gọn)!R16C2
... A117: 116 | B117: MAT-ALU-KHUNG-OBD-EUS10 | C117: NHÔM_ĐỊNH_HÌNH | D117: Nhôm định hình KHUNG OBD EUS 10 | E117: kg | F117: 0.141 kg/m | G117: BG Cửa (rút gọn)!R19C2
...

Sheet 06_BANG_GIA_VAT_TU_AP_DUNG
A1: STT | B1: MAT_ID | C1: ĐƠN GIÁ GỐC (VNĐ)
A2: 1 | B2: MAT-STEEL-DONGBU-0.50 | C2: 26000
A3: 2 | B3: MAT-STEEL-DONGBU-0.60 | C3: 26000
A4: 3 | B4: MAT-STEEL-DONGBU-0.80 | C4: 26000
A5: 4 | B5: MAT-STEEL-DONGBU-1.00 | C5: 26000
A6: 5 | B6: MAT-STEEL-DONGBU-1.20 | C6: 26000
A7: 6 | B7: MAT-STEEL-DONGBU-1.50 | C7: 26000
A8: 7 | B8: MAT-STEEL-DONGBU-2.00 | C8: 26000
A9: 8 | B9: MAT-STEEL-VNSTEEL-0.35 | C9: 23800
A10: 9 | B10: MAT-STEEL-VNSTEEL-0.40 | C10: 23550
A11: 10 | B11: MAT-STEEL-VNSTEEL-0.42 | C11: 23400
A12: 11 | B12: MAT-STEEL-VNSTEEL-0.47 | C12: 23200
A13: 12 | B13: MAT-STEEL-VNSTEEL-0.50 | C13: 23200
... A161: 160 | B161: MAT-INSUL-TON-LO-D10-40 | C161: 130000
