Workbook

Sheet BẢNG BÁO GIÁ TIÊU CHUẨN
C2: CÔNG TY CỔ PHẦN TẬP ĐOÀN QUỐC TẾ SLAND
C3: VPGD: SỐ 49, Ngõ 1295 Giải Phóng, Phường Hoàng Mai, TP Hà Nội
C4: Nhà máy: Thôn Nhân Hiền - xã Thường Tín - TP Hà Nội
C5: Hotline: 082 5577 999
A6: BẢNG BÁO GIÁ (BẢNG BÁO GIÁ THIẾT BỊ VÀ VẬT TƯ HVAC (TIÊU CHUẨN BOQ))
A7: Khách hàng : | M7: Số hiệu
A8: Địa chỉ : | M8: PT Kinh doanh
A9: Người nhận : | M9: Điện thoại
A10: Email: | C10: Số điện thoại : | M10: Dự án
A11: STT | B11: Danh mục sản phẩm | C11: Model | D11: Thương hiệu | E11: Kích thước (mm) | I11: Modul | J11: L | K11: Độ dày (mm) | L11: Unit Đơn vị | M11: Q'ty Số lượng | N11: Đơn Giá (VNĐ) | O11: Total price Thành tiền | P11: Remarks Ghi chú
E12: A1 | F12: A2 | G12: B1 | H12: B2
E13: Face size | G13: Neck size
A14: IV | B14: HỆ THỐNG CẤP NGUỒN THÔNG GIÓ
B15: Tủ điện TĐ-M-QTG | L15: Tủ | M15: 2
B16: Cáp điện CU/PVC/PVC 3x2,5 mm2 | L16: m | M16: 200
B17: Dây PVC 1x2.5 mm2 | L17: m | M17: 200
B18: Vật tư phụ | L18: Lô | M18: 1
B19: PHẦN CHUNG
B20: HỆ THỐNG ĐIỀU HOÀ PHÒNG AN NINH, PHÒNG TRỰC PCCC VÀ VP BAN QUẢN LÝ
B21: Điều hoà cục bộ, 1 chiều lạnh, công suất 2.5 Kw | L21: Bộ | M21: 2
B22: Ống đồng D6.4, dày 0.8mm kèm bảo ôn | L22: m | M22: 11
B23: Ống đồng D9.5, dày 0.8mm kèm bảo ôn | L23: m | M23: 11
B24: Ống nước ngưng uPVC D21 kèm bảo ôn | L24: m | M24: 20
B25: Dây link dàn nóng và dàn lạnh 4xCu/Pvc/Pvc 1x2.5mm2 | L25: m | M25: 12
B26: Giá treo cục nóng điều hoà | L26: Bộ | M26: 2
B27: Vật tư phụ | L27: Lô | M27: 1
B28: HỆ THỐNG HÚT MÙI WC, HÚT RÁC, TRỰC PCCC
A29: 1 | B29: Thiết bị
B30: Quạt hút vệ sinh: - Quạt gắn trần Lưu lượng: 150 m3/h - Cột áp: 50 Pa | L30: Bộ | M30: 4
B31: Quạt hút vệ sinh: - Quạt gắn trần Lưu lượng: 250 m3/h - Cột áp: 50 Pa | L31: Bộ | M31: 1
B32: Quạt hút rác: - Quạt hướng trục - Lưu lượng: 3100 m3/h - Cột áp: 200 Pa | L32: Bộ | M32: 2
A33: 2 | B33: Bạt mềm đầu quạt | L33: Bộ | M33: 2
A34: 3 | B34: Ống gió
B35: D100 | L35: m | M35: 14
B36: D150 | L36: m | M36: 3
B37: 300x300 | L37: m | M37: 29
B38: 400x300 | L38: m | M38: 41
A39: 4 | B39: Phụ kiện ống gió | L39: Lô | M39: 1
A40: 5 | B40: Cửa gió
B41: Cửa gió nan thẳng kèm van gió OBD & hộp gió, 200x200 | C41: SDG+O | D41: SWIND | E41: 200 | F41: 200 | G41: 150 | H41: 150 | L41: Bộ | M41: 36 | N41: =ROUND('00_TONG_HOP_BAO_GIA'!Q2, 0) | O41: =ROUNDUP(N41*M41, -2) | P41: Cửa nan bầu dục 1 lớp kèm van OBD. Không tính box do nhà thầu tự thi công
...

Sheet 00_TONG_HOP_BAO_GIA
A1: STT | B1: ITEM_ID | C1: PHÂN NHÓM | D1: TÊN SẢN PHẨM | E1: QUY CÁCH (WxH) | F1: ĐVT | G1: SỐ LƯỢNG | H1: CP VẬT TƯ ỐNG | I1: CP VẬT TƯ CỬA | J1: CP VẬT TƯ VAN | K1: TỔNG CP VẬT TƯ | L1: NHÂN CÔNG (25%) | M1: CP XƯỞNG (10%) | N1: TỔNG GIÁ VỐN | O1: GIÁ VỐN / ĐVT | P1: MARGIN (%) | Q1: ĐƠN GIÁ BÁN | R1: THÀNH TIỀN (VNĐ) | S1: GHI CHÚ
A2: 1 | B2: SW-DIFF-001 | C2: CỬA GIÓ | D2: Cửa gió nan thẳng kèm van gió OBD & hộp gió, 200x200 | E2: 200x200 | F2: Bộ | G2: 36 | H2: =SUMIF('01_BOC_TACH_ONG'!$B$2:$B$5000, B2, '01_BOC_TACH_ONG'!$K$2:$K$5000) | I2: =SUMIF('02_BOC_TACH_CUA'!$B$2:$B$5000, B2, '02_BOC_TACH_CUA'!$K$2:$K$5000) | J2: =SUMIF('03_BOC_TACH_VAN'!$B$2:$B$5000, B2, '03_BOC_TACH_VAN'!$K$2:$K$5000) | K2: =SUM(H2:J2) | L2: =(K2-SUMIFS('03_BOC_TACH_VAN'!$K$2:$K$5000, '03_BOC_TACH_VAN'!$B$2:$B$5000, B2, '03_BOC_TACH_VAN'!$D$2:$D$5000, "ĐỘNG_CƠ_VÀ_CẢM_BIẾN"))*0.25 | M2: =(K2-SUMIFS('03_BOC_TACH_VAN'!$K$2:$K$5000, '03_BOC_TACH_VAN'!$B$2:$B$5000, B2, '03_BOC_TACH_VAN'!$D$2:$D$5000, "ĐỘNG_CƠ_VÀ_CẢM_BIẾN"))*0.10 | N2: =K2+L2+M2 | O2: =IF(G2>0, N2/G2, 0) | P2: 0.18 | Q2: =IF(G2>0, ((N2-SUMIFS('03_BOC_TACH_VAN'!$K$2:$K$5000, '03_BOC_TACH_VAN'!$B$2:$B$5000, B2, '03_BOC_TACH_VAN'!$D$2:$D$5000, "ĐỘNG_CƠ_VÀ_CẢM_BIẾN"))*(1+P2)+SUMIFS('03_BOC_TACH_VAN'!$K$2:$K$5000, '03_BOC_TACH_VAN'!$B$2:$B$5000, B2, '03_BOC_TACH_VAN'!$D$2:$D$5000, "ĐỘNG_CƠ_VÀ_CẢM_BIẾN"))/G2, 0) | R2: =G2*Q2 | S2: Cửa nan bầu dục 1 lớp kèm van OBD. Không tính box do nhà thầu tự thi công
A3: 2 | B3: SW-DIFF-002 | C3: CỬA GIÓ | D3: Cửa gió nan Z kèm lưới chắn côn trùng & hộp gió, 500x200 | E3: 500x200 | F3: Bộ | G3: 2 | H3: =SUMIF('01_BOC_TACH_ONG'!$B$2:$B$5000, B3, '01_BOC_TACH_ONG'!$K$2:$K$5000) | I3: =SUMIF('02_BOC_TACH_CUA'!$B$2:$B$5000, B3, '02_BOC_TACH_CUA'!$K$2:$K$5000) | J3: =SUMIF('03_BOC_TACH_VAN'!$B$2:$B$5000, B3, '03_BOC_TACH_VAN'!$K$2:$K$5000) | K3: =SUM(H3:J3) | L3: =(K3-SUMIFS('03_BOC_TACH_VAN'!$K$2:$K$5000, '03_BOC_TACH_VAN'!$B$2:$B$5000, B3, '03_BOC_TACH_VAN'!$D$2:$D$5000, "ĐỘNG_CƠ_VÀ_CẢM_BIẾN"))*0.25 | M3: =(K3-SUMIFS('03_BOC_TACH_VAN'!$K$2:$K$5000, '03_BOC_TACH_VAN'!$B$2:$B$5000, B3, '03_BOC_TACH_VAN'!$D$2:$D$5000, "ĐỘNG_CƠ_VÀ_CẢM_BIẾN"))*0.10 | N3: =K3+L3+M3 | O3: =IF(G3>0, N3/G3, 0) | P3: 0.18 | Q3: =IF(G3>0, ((N3-SUMIFS('03_BOC_TACH_VAN'!$K$2:$K$5000, '03_BOC_TACH_VAN'!$B$2:$B$5000, B3, '03_BOC_TACH_VAN'!$D$2:$D$5000, "ĐỘNG_CƠ_VÀ_CẢM_BIẾN"))*(1+P3)+SUMIFS('03_BOC_TACH_VAN'!$K$2:$K$5000, '03_BOC_TACH_VAN'!$B$2:$B$5000, B3, '03_BOC_TACH_VAN'!$D$2:$D$5000, "ĐỘNG_CƠ_VÀ_CẢM_BIẾN"))/G3, 0) | R3: =G3*Q3 | S3: Louver nan Z ngoài trời kèm lưới chắn côn trùng Inox 304. Không tính box do nhà thầu tự thi công
A4: 3 | B4: SW-DAMPER-003 | C4: VAN GIÓ | D4: Van gió Van chặn lửa, FD 200x200 | E4: 200x200 | F4: Bộ | G4: 36 | H4: =SUMIF('01_BOC_TACH_ONG'!$B$2:$B$5000, B4, '01_BOC_TACH_ONG'!$K$2:$K$5000) | I4: =SUMIF('02_BOC_TACH_CUA'!$B$2:$B$5000, B4, '02_BOC_TACH_CUA'!$K$2:$K$5000) | J4: =SUMIF('03_BOC_TACH_VAN'!$B$2:$B$5000, B4, '03_BOC_TACH_VAN'!$K$2:$K$5000) | K4: =SUM(H4:J4) | L4: =(K4-SUMIFS('03_BOC_TACH_VAN'!$K$2:$K$5000, '03_BOC_TACH_VAN'!$B$2:$B$5000, B4, '03_BOC_TACH_VAN'!$D$2:$D$5000, "ĐỘNG_CƠ_VÀ_CẢM_BIẾN"))*0.25 | M4: =(K4-SUMIFS('03_BOC_TACH_VAN'!$K$2:$K$5000, '03_BOC_TACH_VAN'!$B$2:$B$5000, B4, '03_BOC_TACH_VAN'!$D$2:$D$5000, "ĐỘNG_CƠ_VÀ_CẢM_BIẾN"))*0.10 | N4: =K4+L4+M4 | O4: =IF(G4>0, N4/G4, 0) | P4: 0.18 | Q4: =IF(G4>0, ((N4-SUMIFS('03_BOC_TACH_VAN'!$K$2:$K$5000, '03_BOC_TACH_VAN'!$B$2:$B$5000, B4, '03_BOC_TACH_VAN'!$D$2:$D$5000, "ĐỘNG_CƠ_VÀ_CẢM_BIẾN"))*(1+P4)+SUMIFS('03_BOC_TACH_VAN'!$K$2:$K$5000, '03_BOC_TACH_VAN'!$B$2:$B$5000, B4, '03_BOC_TACH_VAN'!$D$2:$D$5000, "ĐỘNG_CƠ_VÀ_CẢM_BIẾN"))/G4, 0) | R4: =G4*Q4 | S4: - Van chặn lửa cầu chì - Tiêu chuẩn EI 120 - 2 đầu bích TDC - gắn cầu chì 70-74 độ C - Sản xuất theo BCTN số: 4761/VLXD-TBMT
A5: 4 | B5: SW-DIFF-004 | C5: CỬA GIÓ | D5: Cửa gió nan thẳng kèm van gió OBD & hộp gió, 200x200 | E5: 200x200 | F5: Bộ | G5: 18 | H5: =SUMIF('01_BOC_TACH_ONG'!$B$2:$B$5000, B5, '01_BOC_TACH_ONG'!$K$2:$K$5000) | I5: =SUMIF('02_BOC_TACH_CUA'!$B$2:$B$5000, B5, '02_BOC_TACH_CUA'!$K$2:$K$5000) | J5: =SUMIF('03_BOC_TACH_VAN'!$B$2:$B$5000, B5, '03_BOC_TACH_VAN'!$K$2:$K$5000) | K5: =SUM(H5:J5) | L5: =(K5-SUMIFS('03_BOC_TACH_VAN'!$K$2:$K$5000, '03_BOC_TACH_VAN'!$B$2:$B$5000, B5, '03_BOC_TACH_VAN'!$D$2:$D$5000, "ĐỘNG_CƠ_VÀ_CẢM_BIẾN"))*0.25 | M5: =(K5-SUMIFS('03_BOC_TACH_VAN'!$K$2:$K$5000, '03_BOC_TACH_VAN'!$B$2:$B$5000, B5, '03_BOC_TACH_VAN'!$D$2:$D$5000, "ĐỘNG_CƠ_VÀ_CẢM_BIẾN"))*0.10 | N5: =K5+L5+M5 | O5: =IF(G5>0, N5/G5, 0) | P5: 0.18 | Q5: =IF(G5>0, ((N5-SUMIFS('03_BOC_TACH_VAN'!$K$2:$K$5000, '03_BOC_TACH_VAN'!$B$2:$B$5000, B5, '03_BOC_TACH_VAN'!$D$2:$D$5000, "ĐỘNG_CƠ_VÀ_CẢM_BIẾN"))*(1+P5)+SUMIFS('03_BOC_TACH_VAN'!$K$2:$K$5000, '03_BOC_TACH_VAN'!$B$2:$B$5000, B5, '03_BOC_TACH_VAN'!$D$2:$D$5000, "ĐỘNG_CƠ_VÀ_CẢM_BIẾN"))/G5, 0) | R5: =G5*Q5 | S5: Cửa nan bầu dục 1 lớp kèm van OBD. Không tính box do nhà thầu tự thi công
A6: 5 | B6: SW-DAMPER-005 | C6: VAN GIÓ | D6: Van gió Van chặn lửa, FD 150x150 | E6: 150x150 | F6: Bộ | G6: 18 | H6: =SUMIF('01_BOC_TACH_ONG'!$B$2:$B$5000, B6, '01_BOC_TACH_ONG'!$K$2:$K$5000) | I6: =SUMIF('02_BOC_TACH_CUA'!$B$2:$B$5000, B6, '02_BOC_TACH_CUA'!$K$2:$K$5000) | J6: =SUMIF('03_BOC_TACH_VAN'!$B$2:$B$5000, B6, '03_BOC_TACH_VAN'!$K$2:$K$5000) | K6: =SUM(H6:J6) | L6: =(K6-SUMIFS('03_BOC_TACH_VAN'!$K$2:$K$5000, '03_BOC_TACH_VAN'!$B$2:$B$5000, B6, '03_BOC_TACH_VAN'!$D$2:$D$5000, "ĐỘNG_CƠ_VÀ_CẢM_BIẾN"))*0.25 | M6: =(K6-SUMIFS('03_BOC_TACH_VAN'!$K$2:$K$5000, '03_BOC_TACH_VAN'!$B$2:$B$5000, B6, '03_BOC_TACH_VAN'!$D$2:$D$5000, "ĐỘNG_CƠ_VÀ_CẢM_BIẾN"))*0.10 | N6: =K6+L6+M6 | O6: =IF(G6>0, N6/G6, 0) | P6: 0.18 | Q6: =IF(G6>0, ((N6-SUMIFS('03_BOC_TACH_VAN'!$K$2:$K$5000, '03_BOC_TACH_VAN'!$B$2:$B$5000, B6, '03_BOC_TACH_VAN'!$D$2:$D$5000, "ĐỘNG_CƠ_VÀ_CẢM_BIẾN"))*(1+P6)+SUMIFS('03_BOC_TACH_VAN'!$K$2:$K$5000, '03_BOC_TACH_VAN'!$B$2:$B$5000, B6, '03_BOC_TACH_VAN'!$D$2:$D$5000, "ĐỘNG_CƠ_VÀ_CẢM_BIẾN"))/G6, 0) | R6: =G6*Q6 | S6: - Van chặn lửa cầu chì - Tiêu chuẩn EI 120 - 2 đầu bích TDC - gắn cầu chì 70-74 độ C - Sản xuất theo BCTN số: 4761/VLXD-TBMT
A7: 6 | B7: SW-DAMPER-006 | C7: VAN GIÓ | D7: Van gió Van chặn lửa, MFD 150x150 | E7: 150x150 | F7: Bộ | G7: 18 | H7: =SUMIF('01_BOC_TACH_ONG'!$B$2:$B$5000, B7, '01_BOC_TACH_ONG'!$K$2:$K$5000) | I7: =SUMIF('02_BOC_TACH_CUA'!$B$2:$B$5000, B7, '02_BOC_TACH_CUA'!$K$2:$K$5000) | J7: =SUMIF('03_BOC_TACH_VAN'!$B$2:$B$5000, B7, '03_BOC_TACH_VAN'!$K$2:$K$5000) | K7: =SUM(H7:J7) | L7: =(K7-SUMIFS('03_BOC_TACH_VAN'!$K$2:$K$5000, '03_BOC_TACH_VAN'!$B$2:$B$5000, B7, '03_BOC_TACH_VAN'!$D$2:$D$5000, "ĐỘNG_CƠ_VÀ_CẢM_BIẾN"))*0.25 | M7: =(K7-SUMIFS('03_BOC_TACH_VAN'!$K$2:$K$5000, '03_BOC_TACH_VAN'!$B$2:$B$5000, B7, '03_BOC_TACH_VAN'!$D$2:$D$5000, "ĐỘNG_CƠ_VÀ_CẢM_BIẾN"))*0.10 | N7: =K7+L7+M7 | O7: =IF(G7>0, N7/G7, 0) | P7: 0.18 | Q7: =IF(G7>0, ((N7-SUMIFS('03_BOC_TACH_VAN'!$K$2:$K$5000, '03_BOC_TACH_VAN'!$B$2:$B$5000, B7, '03_BOC_TACH_VAN'!$D$2:$D$5000, "ĐỘNG_CƠ_VÀ_CẢM_BIẾN"))*(1+P7)+SUMIFS('03_BOC_TACH_VAN'!$K$2:$K$5000, '03_BOC_TACH_VAN'!$B$2:$B$5000, B7, '03_BOC_TACH_VAN'!$D$2:$D$5000, "ĐỘNG_CƠ_VÀ_CẢM_BIẾN"))/G7, 0) | R7: =G7*Q7 | S7: - Van chống cháy động cơ - Tiêu chuẩn EI 90 - 2 đầu bích TDC - Gắn kèm động cơ ON-OFF 3.5Nm, 24V (Type: đóng mở nhanh) BELIMO - Model: FSLF24V US - Sản xuất theo BCTN số 4752/VLXD-TBMT
A8: TỔNG CỘNG | H8: =SUM(H2:H7) | I8: =SUM(I2:I7) | J8: =SUM(J2:J7) | K8: =SUM(K2:K7) | L8: =SUM(L2:L7) | M8: =SUM(M2:M7) | N8: =SUM(N2:N7) | R8: =SUM(R2:R7)

Sheet 01_BOC_TACH_ONG
A1: SUB_KEY | B1: PARENT_ITEM_ID | C1: TÊN CẤU KIỆN | D1: PHÂN LOẠI | E1: MÃ VẬT TƯ (MAT_ID) | F1: ĐVT | G1: ĐỊNH MỨC / 1 SP | H1: SL DỰ ÁN | I1: TỔNG NHU CẦU | J1: ĐƠN GIÁ GỐC | K1: THÀNH TIỀN (VNĐ) | L1: GHI CHÚ KỸ THUẬT

Sheet 02_BOC_TACH_CUA
A1: SUB_KEY | B1: PARENT_ITEM_ID | C1: TÊN CẤU KIỆN | D1: PHÂN LOẠI | E1: MÃ VẬT TƯ (MAT_ID) | F1: ĐVT | G1: ĐỊNH MỨC / 1 SP | H1: SL DỰ ÁN | I1: TỔNG NHU CẦU | J1: ĐƠN GIÁ GỐC | K1: THÀNH TIỀN (VNĐ) | L1: GHI CHÚ KỸ THUẬT
A2: SW-DIFF-001-FRAME | B2: SW-DIFF-001 | C2: Khung nhôm định hình (1 lớp BD) | D2: NHÔM_ĐỊNH_HÌNH | E2: MAT-ALU-KHUNG-BD | F2: kg | G2: 0.1668339 | H2: ='00_TONG_HOP_BAO_GIA'!G2 | I2: =G2*H2 | J2: =IFERROR(INDEX('06_BANG_GIA_VAT_TU_AP_DUNG'!$E$1:$E$5000, MATCH(E2, '06_BANG_GIA_VAT_TU_AP_DUNG'!$B$1:$B$5000, 0)), 0) | K2: =I2*J2 | L2: Khung bao 200x200mm (cổ 150x150mm)
A3: SW-DIFF-001-BLADE | B3: SW-DIFF-001 | C3: Nan nhôm bầu dục (7 nan) | D3: NHÔM_ĐỊNH_HÌNH | E3: MAT-ALU-NAN-BD | F3: kg | G3: 0.062872427 | H3: ='00_TONG_HOP_BAO_GIA'!G2 | I3: =G3*H3 | J3: =IFERROR(INDEX('06_BANG_GIA_VAT_TU_AP_DUNG'!$E$1:$E$5000, MATCH(E3, '06_BANG_GIA_VAT_TU_AP_DUNG'!$B$1:$B$5000, 0)), 0) | K3: =I3*J3 | L3: Nan bầu dục @ 0.058kg/m
A4: SW-DIFF-001-ACCESSORY | B4: SW-DIFF-001 | C4: Phụ kiện lắp ghép / Ke góc cửa gió | D4: PHỤ_KIỆN_CỬA | E4: MAT-DOOR-ACCESSORY | F4: Bộ | G4: 0.03127197 | H4: ='00_TONG_HOP_BAO_GIA'!G2 | I4: =G4*H4 | J4: =IFERROR(INDEX('06_BANG_GIA_VAT_TU_AP_DUNG'!$E$1:$E$5000, MATCH(E4, '06_BANG_GIA_VAT_TU_AP_DUNG'!$B$1:$B$5000, 0)), 0) | K4: =I4*J4 | L4: 4 ke góc chìm và vít ghép khung
A5: SW-DIFF-001-PAINT | B5: SW-DIFF-001 | C5: Sơn tĩnh điện tiêu chuẩn Polyester | D5: SƠN_TĨNH_ĐIỆN | E5: MAT-PAINT-POWDER | F5: m2 | G5: 0.043076482 | H5: ='00_TONG_HOP_BAO_GIA'!G2 | I5: =G5*H5 | J5: =IFERROR(INDEX('06_BANG_GIA_VAT_TU_AP_DUNG'!$E$1:$E$5000, MATCH(E5, '06_BANG_GIA_VAT_TU_AP_DUNG'!$B$1:$B$5000, 0)), 0) | K5: =I5*J5 | L5: Sơn tĩnh điện hoàn thiện
A6: SW-DIFF-001-OBD-FRAME | B6: SW-DIFF-001 | C6: Khung nhôm van OBD gắn cửa (SOBD) | D6: NHÔM_ĐỊNH_HÌNH | E6: MAT-ALU-KHUNG-OBD | F6: kg | G6: 0.08230553 | H6: ='00_TONG_HOP_BAO_GIA'!G2 | I6: =G6*H6 | J6: =IFERROR(INDEX('06_BANG_GIA_VAT_TU_AP_DUNG'!$E$1:$E$5000, MATCH(E6, '06_BANG_GIA_VAT_TU_AP_DUNG'!$B$1:$B$5000, 0)), 0) | K6: =I6*J6 | L6: Khung OBD 150x150mm
A7: SW-DIFF-001-OBD-BLADE | B7: SW-DIFF-001 | C7: Nan nhôm & thanh truyền van OBD (SOBD) | D7: NHÔM_ĐỊNH_HÌNH | E7: MAT-ALU-NAN-OBD | F7: kg | G7: 0.048836351 | H7: ='00_TONG_HOP_BAO_GIA'!G2 | I7: =G7*H7 | J7: =IFERROR(INDEX('06_BANG_GIA_VAT_TU_AP_DUNG'!$E$1:$E$5000, MATCH(E7, '06_BANG_GIA_VAT_TU_AP_DUNG'!$B$1:$B$5000, 0)), 0) | K7: =I7*J7 | L7: Nan OBD đối xứng & thanh liên kết
A8: SW-DIFF-001-OBD-ACC | B8: SW-DIFF-001 | C8: Bánh răng nhựa & phụ kiện van OBD | D8: PHỤ_KIỆN_CỬA | E8: MAT-DOOR-ACCESSORY | F8: Bộ | G8: 0.51119903 | H8: ='00_TONG_HOP_BAO_GIA'!G2 | I8: =G8*H8 | J8: =IFERROR(INDEX('06_BANG_GIA_VAT_TU_AP_DUNG'!$E$1:$E$5000, MATCH(E8, '06_BANG_GIA_VAT_TU_AP_DUNG'!$B$1:$B$5000, 0)), 0) | K8: =I8*J8 | L8: Cơ cấu bánh răng đóng mở OBD
A9: SW-DIFF-002-FRAME | B9: SW-DIFF-002 | C9: Khung nhôm định hình Louver (SWL) | D9: NHÔM_ĐỊNH_HÌNH | E9: MAT-ALU-KHUNG-Z-2-LOP | F9: kg | G9: 0.32738178 | H9: ='00_TONG_HOP_BAO_GIA'!G3 | I9: =G9*H9 | J9: =IFERROR(INDEX('06_BANG_GIA_VAT_TU_AP_DUNG'!$E$1:$E$5000, MATCH(E9, '06_BANG_GIA_VAT_TU_AP_DUNG'!$B$1:$B$5000, 0)), 0) | K9: =I9*J9 | L9: Khung Louver phủ bì 500x200mm
A10: SW-DIFF-002-BLADE | B10: SW-DIFF-002 | C10: Nan Z Louver & thanh tăng cứng (3 nan) | D10: NHÔM_ĐỊNH_HÌNH | E10: MAT-ALU-NAN-Z-DAY | F10: kg | G10: 0.33133756 | H10: ='00_TONG_HOP_BAO_GIA'!G3 | I10: =G10*H10 | J10: =IFERROR(INDEX('06_BANG_GIA_VAT_TU_AP_DUNG'!$E$1:$E$5000, MATCH(E10, '06_BANG_GIA_VAT_TU_AP_DUNG'!$B$1:$B$5000, 0)), 0) | K10: =I10*J10 | L10: 3 nan Z dày @ 0.217kg/m + thanh giằng
A11: SW-DIFF-002-ACCESSORY | B11: SW-DIFF-002 | C11: Phụ kiện lắp ghép / Ke góc cửa gió | D11: PHỤ_KIỆN_CỬA | E11: MAT-DOOR-ACCESSORY | F11: Bộ | G11: 0.026746449 | H11: ='00_TONG_HOP_BAO_GIA'!G3 | I11: =G11*H11 | J11: =IFERROR(INDEX('06_BANG_GIA_VAT_TU_AP_DUNG'!$E$1:$E$5000, MATCH(E11, '06_BANG_GIA_VAT_TU_AP_DUNG'!$B$1:$B$5000, 0)), 0) | K11: =I11*J11 | L11: Ke góc và vít ghép khung Louver
A12: SW-DIFF-002-PAINT | B12: SW-DIFF-002 | C12: Sơn tĩnh điện tiêu chuẩn Polyester | D12: SƠN_TĨNH_ĐIỆN | E12: MAT-PAINT-POWDER | F12: m2 | G12: 0.12675509 | H12: ='00_TONG_HOP_BAO_GIA'!G3 | I12: =G12*H12 | J12: =IFERROR(INDEX('06_BANG_GIA_VAT_TU_AP_DUNG'!$E$1:$E$5000, MATCH(E12, '06_BANG_GIA_VAT_TU_AP_DUNG'!$B$1:$B$5000, 0)), 0) | K12: =I12*J12 | L12: Sơn tĩnh điện khung và nan Louver
A13: SW-DIFF-002-MESH | B13: SW-DIFF-002 | C13: Lưới chắn côn trùng Inox 304 (LCCT) | D13: PHỤ_KIỆN_CỬA | E13: MAT-MESH-INOX-304 | F13: m2 | G13: 0.041849759 | H13: ='00_TONG_HOP_BAO_GIA'!G3 | I13: =G13*H13 | J13: =IFERROR(INDEX('06_BANG_GIA_VAT_TU_AP_DUNG'!$E$1:$E$5000, MATCH(E13, '06_BANG_GIA_VAT_TU_AP_DUNG'!$B$1:$B$5000, 0)), 0) | K13: =I13*J13 | L13: Lưới chắn côn trùng cổ 450x150mm
A14: SW-DIFF-004-FRAME | B14: SW-DIFF-004 | C14: Khung nhôm định hình (1 lớp BD) | D14: NHÔM_ĐỊNH_HÌNH | E14: MAT-ALU-KHUNG-BD | F14: kg | G14: 0.1668339 | H14: ='00_TONG_HOP_BAO_GIA'!G5 | I14: =G14*H14 | J14: =IFERROR(INDEX('06_BANG_GIA_VAT_TU_AP_DUNG'!$E$1:$E$5000, MATCH(E14, '06_BANG_GIA_VAT_TU_AP_DUNG'!$B$1:$B$5000, 0)), 0) | K14: =I14*J14 | L14: Khung bao 200x200mm (cổ 150x150mm)
A15: SW-DIFF-004-BLADE | B15: SW-DIFF-004 | C15: Nan nhôm bầu dục (7 nan) | D15: NHÔM_ĐỊNH_HÌNH | E15: MAT-ALU-NAN-BD | F15: kg | G15: 0.062872427 | H15: ='00_TONG_HOP_BAO_GIA'!G5 | I15: =G15*H15 | J15: =IFERROR(INDEX('06_BANG_GIA_VAT_TU_AP_DUNG'!$E$1:$E$5000, MATCH(E15, '06_BANG_GIA_VAT_TU_AP_DUNG'!$B$1:$B$5000, 0)), 0) | K15: =I15*J15 | L15: Nan bầu dục @ 0.058kg/m
A16: SW-DIFF-004-ACCESSORY | B16: SW-DIFF-004 | C16: Phụ kiện lắp ghép / Ke góc cửa gió | D16: PHỤ_KIỆN_CỬA | E16: MAT-DOOR-ACCESSORY | F16: Bộ | G16: 0.03127197 | H16: ='00_TONG_HOP_BAO_GIA'!G5 | I16: =G16*H16 | J16: =IFERROR(INDEX('06_BANG_GIA_VAT_TU_AP_DUNG'!$E$1:$E$5000, MATCH(E16, '06_BANG_GIA_VAT_TU_AP_DUNG'!$B$1:$B$5000, 0)), 0) | K16: =I16*J16 | L16: 4 ke góc chìm và vít ghép khung
A17: SW-DIFF-004-PAINT | B17: SW-DIFF-004 | C17: Sơn tĩnh điện tiêu chuẩn Polyester | D17: SƠN_TĨNH_ĐIỆN | E17: MAT-PAINT-POWDER | F17: m2 | G17: 0.043076482 | H17: ='00_TONG_HOP_BAO_GIA'!G5 | I17: =G17*H17 | J17: =IFERROR(INDEX('06_BANG_GIA_VAT_TU_AP_DUNG'!$E$1:$E$5000, MATCH(E17, '06_BANG_GIA_VAT_TU_AP_DUNG'!$B$1:$B$5000, 0)), 0) | K17: =I17*J17 | L17: Sơn tĩnh điện hoàn thiện
A18: SW-DIFF-004-OBD-FRAME | B18: SW-DIFF-004 | C18: Khung nhôm van OBD gắn cửa (SOBD) | D18: NHÔM_ĐỊNH_HÌNH | E18: MAT-ALU-KHUNG-OBD | F18: kg | G18: 0.08230553 | H18: ='00_TONG_HOP_BAO_GIA'!G5 | I18: =G18*H18 | J18: =IFERROR(INDEX('06_BANG_GIA_VAT_TU_AP_DUNG'!$E$1:$E$5000, MATCH(E18, '06_BANG_GIA_VAT_TU_AP_DUNG'!$B$1:$B$5000, 0)), 0) | K18: =I18*J18 | L18: Khung OBD 150x150mm
A19: SW-DIFF-004-OBD-BLADE | B19: SW-DIFF-004 | C19: Nan nhôm & thanh truyền van OBD (SOBD) | D19: NHÔM_ĐỊNH_HÌNH | E19: MAT-ALU-NAN-OBD | F19: kg | G19: 0.048836351 | H19: ='00_TONG_HOP_BAO_GIA'!G5 | I19: =G19*H19 | J19: =IFERROR(INDEX('06_BANG_GIA_VAT_TU_AP_DUNG'!$E$1:$E$5000, MATCH(E19, '06_BANG_GIA_VAT_TU_AP_DUNG'!$B$1:$B$5000, 0)), 0) | K19: =I19*J19 | L19: Nan OBD đối xứng & thanh liên kết
A20: SW-DIFF-004-OBD-ACC | B20: SW-DIFF-004 | C20: Bánh răng nhựa & phụ kiện van OBD | D20: PHỤ_KIỆN_CỬA | E20: MAT-DOOR-ACCESSORY | F20: Bộ | G20: 0.51119903 | H20: ='00_TONG_HOP_BAO_GIA'!G5 | I20: =G20*H20 | J20: =IFERROR(INDEX('06_BANG_GIA_VAT_TU_AP_DUNG'!$E$1:$E$5000, MATCH(E20, '06_BANG_GIA_VAT_TU_AP_DUNG'!$B$1:$B$5000, 0)), 0) | K20: =I20*J20 | L20: Cơ cấu bánh răng đóng mở OBD

Sheet 03_BOC_TACH_VAN
A1: SUB_KEY | B1: PARENT_ITEM_ID | C1: TÊN CẤU KIỆN | D1: PHÂN LOẠI | E1: MÃ VẬT TƯ (MAT_ID) | F1: ĐVT | G1: ĐỊNH MỨC / 1 SP | H1: SL DỰ ÁN | I1: TỔNG NHU CẦU | J1: ĐƠN GIÁ GỐC | K1: THÀNH TIỀN (VNĐ) | L1: GHI CHÚ KỸ THUẬT
A2: SW-DAMPER-003-BODY | B2: SW-DAMPER-003 | C2: Thân vỏ van FD bích C30/TDF (1.15mm) | D2: TÔN_CUỘN_MẠ_KẼM | E2: MAT-STEEL-PN-1.15 | F2: kg | G2: 2.4453004 | H2: ='00_TONG_HOP_BAO_GIA'!G4 | I2: =G2*H2 | J2: =IFERROR(INDEX('06_BANG_GIA_VAT_TU_AP_DUNG'!$E$1:$E$5000, MATCH(E2, '06_BANG_GIA_VAT_TU_AP_DUNG'!$B$1:$B$5000, 0)), 0) | K2: =I2*J2 | L2: Kích thước vỏ 200x200x200mm
A3: SW-DAMPER-003-BLADE | B3: SW-DAMPER-003 | C3: Lá cánh / Tôn tấm bọc van (1 cánh) | D3: TÔN_CUỘN_MẠ_KẼM | E3: MAT-STEEL-PN-1.15 | F3: kg | G3: 0.82146649 | H3: ='00_TONG_HOP_BAO_GIA'!G4 | I3: =G3*H3 | J3: =IFERROR(INDEX('06_BANG_GIA_VAT_TU_AP_DUNG'!$E$1:$E$5000, MATCH(E3, '06_BANG_GIA_VAT_TU_AP_DUNG'!$B$1:$B$5000, 0)), 0) | K3: =I3*J3 | L3: Tôn bọc cánh & thân (1 cánh/modul)
A4: SW-DAMPER-003-AXLE | B4: SW-DAMPER-003 | C4: Trục Sus 201 D10 | D4: PHỤ_KIỆN_VAN | E4: MAT-DAMPER-TRUC-SUS-201-D10 | F4: m | G4: 0.29573704 | H4: ='00_TONG_HOP_BAO_GIA'!G4 | I4: =G4*H4 | J4: =IFERROR(INDEX('06_BANG_GIA_VAT_TU_AP_DUNG'!$E$1:$E$5000, MATCH(E4, '06_BANG_GIA_VAT_TU_AP_DUNG'!$B$1:$B$5000, 0)), 0) | K4: =I4*J4 | L4: 1 trục dài 260mm
A5: SW-DAMPER-003-BEARING | B5: SW-DAMPER-003 | C5: Bạc đồng D10 | D5: PHỤ_KIỆN_VAN | E5: MAT-DAMPER-BAC-DONG-D10 | F5: Đôi | G5: 1 | H5: ='00_TONG_HOP_BAO_GIA'!G4 | I5: =G5*H5 | J5: =IFERROR(INDEX('06_BANG_GIA_VAT_TU_AP_DUNG'!$E$1:$E$5000, MATCH(E5, '06_BANG_GIA_VAT_TU_AP_DUNG'!$B$1:$B$5000, 0)), 0) | K5: =I5*J5 | L5: 1 đôi bạc đỡ 2 bên thân
A6: SW-DAMPER-003-FUSE | B6: SW-DAMPER-003 | C6: Cầu chì nhiệt nóng chảy 70°C/74°C (Elsie/USA) | D6: PHỤ_KIỆN_VAN | E6: MAT-DAMPER-CAU-CHI-USA-1-400X400 | F6: Cái | G6: 1 | H6: ='00_TONG_HOP_BAO_GIA'!G4 | I6: =G6*H6 | J6: =IFERROR(INDEX('06_BANG_GIA_VAT_TU_AP_DUNG'!$E$1:$E$5000, MATCH(E6, '06_BANG_GIA_VAT_TU_AP_DUNG'!$B$1:$B$5000, 0)), 0) | K6: =I6*J6 | L6: Cầu chì kiểm định PCCC (1 cái)
A7: SW-DAMPER-003-FB10-BODY | B7: SW-DAMPER-003 | C7: Tấm chống cháy dày 10mm bọc thân van FD/MFD (2 lớp) | D7: VẬT_LIỆU_CÁCH_NHIỆT | E7: MAT-FIREBOARD-10MM-BODY | F7: m2 | G7: 0.54597607 | H7: ='00_TONG_HOP_BAO_GIA'!G4 | I7: =G7*H7 | J7: =IFERROR(INDEX('06_BANG_GIA_VAT_TU_AP_DUNG'!$E$1:$E$5000, MATCH(E7, '06_BANG_GIA_VAT_TU_AP_DUNG'!$B$1:$B$5000, 0)), 0) | K7: =I7*J7 | L7: Bọc 2 lớp tấm 10mm quanh thân L=300mm
A8: SW-DAMPER-003-FB20-BLADE | B8: SW-DAMPER-003 | C8: Tấm chống cháy dày 20mm làm lõi cánh van FD/MFD | D8: VẬT_LIỆU_CÁCH_NHIỆT | E8: MAT-FIREBOARD-20MM-BLADE | F8: m2 | G8: 0.045498006 | H8: ='00_TONG_HOP_BAO_GIA'!G4 | I8: =G8*H8 | J8: =IFERROR(INDEX('06_BANG_GIA_VAT_TU_AP_DUNG'!$E$1:$E$5000, MATCH(E8, '06_BANG_GIA_VAT_TU_AP_DUNG'!$B$1:$B$5000, 0)), 0) | K8: =I8*J8 | L8: Lõi cánh tấm 20mm (Cánh đơn 200x200mm)
A9: SW-DAMPER-003-FB10-BLADE | B9: SW-DAMPER-003 | C9: Tấm chống cháy dày 10mm ốp 2 mặt cánh van FD/MFD | D9: VẬT_LIỆU_CÁCH_NHIỆT | E9: MAT-FIREBOARD-10MM-BLADE | F9: m2 | G9: 0.090996012 | H9: ='00_TONG_HOP_BAO_GIA'!G4 | I9: =G9*H9 | J9: =IFERROR(INDEX('06_BANG_GIA_VAT_TU_AP_DUNG'!$E$1:$E$5000, MATCH(E9, '06_BANG_GIA_VAT_TU_AP_DUNG'!$B$1:$B$5000, 0)), 0) | K9: =I9*J9 | L9: Ốp 2 mặt cánh tấm 10mm (Cánh đơn 200x200mm)
A10: SW-DAMPER-003-SPRING-BOX | B10: SW-DAMPER-003 | C10: Hộp lò xo van chặn lửa FD/MFD | D10: PHỤ_KIỆN_VAN | E10: MAT-DAMPER-HOP-LO-XO | F10: Bộ | G10: 1 | H10: ='00_TONG_HOP_BAO_GIA'!G4 | I10: =G10*H10 | J10: =IFERROR(INDEX('06_BANG_GIA_VAT_TU_AP_DUNG'!$E$1:$E$5000, MATCH(E10, '06_BANG_GIA_VAT_TU_AP_DUNG'!$B$1:$B$5000, 0)), 0) | K10: =I10*J10 | L10: Hộp lò xo cơ cấu đóng sập (1 bộ)
A11: SW-DAMPER-003-SILICON-BOLT | B11: SW-DAMPER-003 | C11: Silicon chống cháy + bu lông, ốc vít van FD/MFD | D11: PHỤ_KIỆN_VAN | E11: MAT-DAMPER-SILICON-BULONG-VIT | F11: Bộ | G11: 1 | H11: ='00_TONG_HOP_BAO_GIA'!G4 | I11: =G11*H11 | J11: =IFERROR(INDEX('06_BANG_GIA_VAT_TU_AP_DUNG'!$E$1:$E$5000, MATCH(E11, '06_BANG_GIA_VAT_TU_AP_DUNG'!$B$1:$B$5000, 0)), 0) | K11: =I11*J11 | L11: Keo silicon chống cháy & phụ kiện lắp ghép (1 bộ)
A12: SW-DAMPER-005-BODY | B12: SW-DAMPER-005 | C12: Thân vỏ van FD bích C30/TDF (1.15mm) | D12: TÔN_CUỘN_MẠ_KẼM | E12: MAT-STEEL-PN-1.15 | F12: kg | G12: 1.8542934 | H12: ='00_TONG_HOP_BAO_GIA'!G6 | I12: =G12*H12 | J12: =IFERROR(INDEX('06_BANG_GIA_VAT_TU_AP_DUNG'!$E$1:$E$5000, MATCH(E12, '06_BANG_GIA_VAT_TU_AP_DUNG'!$B$1:$B$5000, 0)), 0) | K12: =I12*J12 | L12: Kích thước vỏ 150x150x200mm
A13: SW-DAMPER-005-BLADE | B13: SW-DAMPER-005 | C13: Lá cánh / Tôn tấm bọc van (1 cánh) | D13: TÔN_CUỘN_MẠ_KẼM | E13: MAT-STEEL-PN-1.15 | F13: kg | G13: 0.45989419 | H13: ='00_TONG_HOP_BAO_GIA'!G6 | I13: =G13*H13 | J13: =IFERROR(INDEX('06_BANG_GIA_VAT_TU_AP_DUNG'!$E$1:$E$5000, MATCH(E13, '06_BANG_GIA_VAT_TU_AP_DUNG'!$B$1:$B$5000, 0)), 0) | K13: =I13*J13 | L13: Tôn bọc cánh & thân (1 cánh/modul)
A14: SW-DAMPER-005-AXLE | B14: SW-DAMPER-005 | C14: Trục Sus 201 D10 | D14: PHỤ_KIỆN_VAN | E14: MAT-DAMPER-TRUC-SUS-201-D10 | F14: m | G14: 0.23773723 | H14: ='00_TONG_HOP_BAO_GIA'!G6 | I14: =G14*H14 | J14: =IFERROR(INDEX('06_BANG_GIA_VAT_TU_AP_DUNG'!$E$1:$E$5000, MATCH(E14, '06_BANG_GIA_VAT_TU_AP_DUNG'!$B$1:$B$5000, 0)), 0) | K14: =I14*J14 | L14: 1 trục dài 210mm
A15: SW-DAMPER-005-BEARING | B15: SW-DAMPER-005 | C15: Bạc đồng D10 | D15: PHỤ_KIỆN_VAN | E15: MAT-DAMPER-BAC-DONG-D10 | F15: Đôi | G15: 1 | H15: ='00_TONG_HOP_BAO_GIA'!G6 | I15: =G15*H15 | J15: =IFERROR(INDEX('06_BANG_GIA_VAT_TU_AP_DUNG'!$E$1:$E$5000, MATCH(E15, '06_BANG_GIA_VAT_TU_AP_DUNG'!$B$1:$B$5000, 0)), 0) | K15: =I15*J15 | L15: 1 đôi bạc đỡ 2 bên thân
A16: SW-DAMPER-005-FUSE | B16: SW-DAMPER-005 | C16: Cầu chì nhiệt nóng chảy 70°C/74°C (Elsie/USA) | D16: PHỤ_KIỆN_VAN | E16: MAT-DAMPER-CAU-CHI-USA-1-400X400 | F16: Cái | G16: 1 | H16: ='00_TONG_HOP_BAO_GIA'!G6 | I16: =G16*H16 | J16: =IFERROR(INDEX('06_BANG_GIA_VAT_TU_AP_DUNG'!$E$1:$E$5000, MATCH(E16, '06_BANG_GIA_VAT_TU_AP_DUNG'!$B$1:$B$5000, 0)), 0) | K16: =I16*J16 | L16: Cầu chì kiểm định PCCC (1 cái)
A17: SW-DAMPER-005-FB10-BODY | B17: SW-DAMPER-005 | C17: Tấm chống cháy dày 10mm bọc thân van FD/MFD (2 lớp) | D17: VẬT_LIỆU_CÁCH_NHIỆT | E17: MAT-FIREBOARD-10MM-BODY | F17: m2 | G17: 0.40754954 | H17: ='00_TONG_HOP_BAO_GIA'!G6 | I17: =G17*H17 | J17: =IFERROR(INDEX('06_BANG_GIA_VAT_TU_AP_DUNG'!$E$1:$E$5000, MATCH(E17, '06_BANG_GIA_VAT_TU_AP_DUNG'!$B$1:$B$5000, 0)), 0) | K17: =I17*J17 | L17: Bọc 2 lớp tấm 10mm quanh thân L=300mm
A18: SW-DAMPER-005-FB20-BLADE | B18: SW-DAMPER-005 | C18: Tấm chống cháy dày 20mm làm lõi cánh van FD/MFD | D18: VẬT_LIỆU_CÁCH_NHIỆT | E18: MAT-FIREBOARD-20MM-BLADE | F18: m2 | G18: 0.025471846 | H18: ='00_TONG_HOP_BAO_GIA'!G6 | I18: =G18*H18 | J18: =IFERROR(INDEX('06_BANG_GIA_VAT_TU_AP_DUNG'!$E$1:$E$5000, MATCH(E18, '06_BANG_GIA_VAT_TU_AP_DUNG'!$B$1:$B$5000, 0)), 0) | K18: =I18*J18 | L18: Lõi cánh tấm 20mm (Cánh đơn 150x150mm)
A19: SW-DAMPER-005-FB10-BLADE | B19: SW-DAMPER-005 | C19: Tấm chống cháy dày 10mm ốp 2 mặt cánh van FD/MFD | D19: VẬT_LIỆU_CÁCH_NHIỆT | E19: MAT-FIREBOARD-10MM-BLADE | F19: m2 | G19: 0.050943693 | H19: ='00_TONG_HOP_BAO_GIA'!G6 | I19: =G19*H19 | J19: =IFERROR(INDEX('06_BANG_GIA_VAT_TU_AP_DUNG'!$E$1:$E$5000, MATCH(E19, '06_BANG_GIA_VAT_TU_AP_DUNG'!$B$1:$B$5000, 0)), 0) | K19: =I19*J19 | L19: Ốp 2 mặt cánh tấm 10mm (Cánh đơn 150x150mm)
A20: SW-DAMPER-005-SPRING-BOX | B20: SW-DAMPER-005 | C20: Hộp lò xo van chặn lửa FD/MFD | D20: PHỤ_KIỆN_VAN | E20: MAT-DAMPER-HOP-LO-XO | F20: Bộ | G20: 1 | H20: ='00_TONG_HOP_BAO_GIA'!G6 | I20: =G20*H20 | J20: =IFERROR(INDEX('06_BANG_GIA_VAT_TU_AP_DUNG'!$E$1:$E$5000, MATCH(E20, '06_BANG_GIA_VAT_TU_AP_DUNG'!$B$1:$B$5000, 0)), 0) | K20: =I20*J20 | L20: Hộp lò xo cơ cấu đóng sập (1 bộ)
A21: SW-DAMPER-005-SILICON-BOLT | B21: SW-DAMPER-005 | C21: Silicon chống cháy + bu lông, ốc vít van FD/MFD | D21: PHỤ_KIỆN_VAN | E21: MAT-DAMPER-SILICON-BULONG-VIT | F21: Bộ | G21: 1 | H21: ='00_TONG_HOP_BAO_GIA'!G6 | I21: =G21*H21 | J21: =IFERROR(INDEX('06_BANG_GIA_VAT_TU_AP_DUNG'!$E$1:$E$5000, MATCH(E21, '06_BANG_GIA_VAT_TU_AP_DUNG'!$B$1:$B$5000, 0)), 0) | K21: =I21*J21 | L21: Keo silicon chống cháy & phụ kiện lắp ghép (1 bộ)
A22: SW-DAMPER-006-BODY | B22: SW-DAMPER-006 | C22: Thân vỏ van MFD bích C30/TDF (1.15mm) | D22: TÔN_CUỘN_MẠ_KẼM | E22: MAT-STEEL-PN-1.15 | F22: kg | G22: 2.4776332 | H22: ='00_TONG_HOP_BAO_GIA'!G7 | I22: =G22*H22 | J22: =IFERROR(INDEX('06_BANG_GIA_VAT_TU_AP_DUNG'!$E$1:$E$5000, MATCH(E22, '06_BANG_GIA_VAT_TU_AP_DUNG'!$B$1:$B$5000, 0)), 0) | K22: =I22*J22 | L22: Kích thước vỏ 150x150x200mm
A23: SW-DAMPER-006-BLADE | B23: SW-DAMPER-006 | C23: Lá cánh / Tôn tấm bọc van (1 cánh) | D23: TÔN_CUỘN_MẠ_KẼM | E23: MAT-STEEL-PN-1.15 | F23: kg | G23: 0.61449235 | H23: ='00_TONG_HOP_BAO_GIA'!G7 | I23: =G23*H23 | J23: =IFERROR(INDEX('06_BANG_GIA_VAT_TU_AP_DUNG'!$E$1:$E$5000, MATCH(E23, '06_BANG_GIA_VAT_TU_AP_DUNG'!$B$1:$B$5000, 0)), 0) | K23: =I23*J23 | L23: Tôn bọc cánh & thân (1 cánh/modul)
A24: SW-DAMPER-006-AXLE | B24: SW-DAMPER-006 | C24: Trục Sus 201 D10 | D24: PHỤ_KIỆN_VAN | E24: MAT-DAMPER-TRUC-SUS-201-D10 | F24: m | G24: 0.31765505 | H24: ='00_TONG_HOP_BAO_GIA'!G7 | I24: =G24*H24 | J24: =IFERROR(INDEX('06_BANG_GIA_VAT_TU_AP_DUNG'!$E$1:$E$5000, MATCH(E24, '06_BANG_GIA_VAT_TU_AP_DUNG'!$B$1:$B$5000, 0)), 0) | K24: =I24*J24 | L24: 1 trục dài 210mm
A25: SW-DAMPER-006-BEARING | B25: SW-DAMPER-006 | C25: Bạc đồng D10 | D25: PHỤ_KIỆN_VAN | E25: MAT-DAMPER-BAC-DONG-D10 | F25: Đôi | G25: 1 | H25: ='00_TONG_HOP_BAO_GIA'!G7 | I25: =G25*H25 | J25: =IFERROR(INDEX('06_BANG_GIA_VAT_TU_AP_DUNG'!$E$1:$E$5000, MATCH(E25, '06_BANG_GIA_VAT_TU_AP_DUNG'!$B$1:$B$5000, 0)), 0) | K25: =I25*J25 | L25: 1 đôi bạc đỡ 2 bên thân
A26: SW-DAMPER-006-ACTUATOR | B26: SW-DAMPER-006 | C26: Động cơ chặn lửa ON/OFF 3.5Nm, 230V/24V (BELIMO FSLF24 / FSLF230) | D26: ĐỘNG_CƠ_VÀ_CẢM_BIẾN | E26: MAT-ACTUATOR-BELIMO-FSLF24 | F26: Cái | G26: 1 | H26: ='00_TONG_HOP_BAO_GIA'!G7 | I26: =G26*H26 | J26: =IFERROR(INDEX('06_BANG_GIA_VAT_TU_AP_DUNG'!$E$1:$E$5000, MATCH(E26, '06_BANG_GIA_VAT_TU_AP_DUNG'!$B$1:$B$5000, 0)), 0) | K26: =I26*J26 | L26: Động cơ lò xo phản hồi MFD (1 bộ)
A27: SW-DAMPER-006-FB10-BODY | B27: SW-DAMPER-006 | C27: Tấm chống cháy dày 10mm bọc thân van FD/MFD (2 lớp) | D27: VẬT_LIỆU_CÁCH_NHIỆT | E27: MAT-FIREBOARD-10MM-BODY | F27: m2 | G27: 0.54455152 | H27: ='00_TONG_HOP_BAO_GIA'!G7 | I27: =G27*H27 | J27: =IFERROR(INDEX('06_BANG_GIA_VAT_TU_AP_DUNG'!$E$1:$E$5000, MATCH(E27, '06_BANG_GIA_VAT_TU_AP_DUNG'!$B$1:$B$5000, 0)), 0) | K27: =I27*J27 | L27: Bọc 2 lớp tấm 10mm quanh thân L=300mm
A28: SW-DAMPER-006-FB20-BLADE | B28: SW-DAMPER-006 | C28: Tấm chống cháy dày 20mm làm lõi cánh van FD/MFD | D28: VẬT_LIỆU_CÁCH_NHIỆT | E28: MAT-FIREBOARD-20MM-BLADE | F28: m2 | G28: 0.03403447 | H28: ='00_TONG_HOP_BAO_GIA'!G7 | I28: =G28*H28 | J28: =IFERROR(INDEX('06_BANG_GIA_VAT_TU_AP_DUNG'!$E$1:$E$5000, MATCH(E28, '06_BANG_GIA_VAT_TU_AP_DUNG'!$B$1:$B$5000, 0)), 0) | K28: =I28*J28 | L28: Lõi cánh tấm 20mm (Cánh đơn 150x150mm)
A29: SW-DAMPER-006-FB10-BLADE | B29: SW-DAMPER-006 | C29: Tấm chống cháy dày 10mm ốp 2 mặt cánh van FD/MFD | D29: VẬT_LIỆU_CÁCH_NHIỆT | E29: MAT-FIREBOARD-10MM-BLADE | F29: m2 | G29: 0.06806894 | H29: ='00_TONG_HOP_BAO_GIA'!G7 | I29: =G29*H29 | J29: =IFERROR(INDEX('06_BANG_GIA_VAT_TU_AP_DUNG'!$E$1:$E$5000, MATCH(E29, '06_BANG_GIA_VAT_TU_AP_DUNG'!$B$1:$B$5000, 0)), 0) | K29: =I29*J29 | L29: Ốp 2 mặt cánh tấm 10mm (Cánh đơn 150x150mm)
A30: SW-DAMPER-006-SPRING-BOX | B30: SW-DAMPER-006 | C30: Hộp lò xo van chặn lửa FD/MFD | D30: PHỤ_KIỆN_VAN | E30: MAT-DAMPER-HOP-LO-XO | F30: Bộ | G30: 1 | H30: ='00_TONG_HOP_BAO_GIA'!G7 | I30: =G30*H30 | J30: =IFERROR(INDEX('06_BANG_GIA_VAT_TU_AP_DUNG'!$E$1:$E$5000, MATCH(E30, '06_BANG_GIA_VAT_TU_AP_DUNG'!$B$1:$B$5000, 0)), 0) | K30: =I30*J30 | L30: Hộp lò xo cơ cấu đóng sập (1 bộ)
A31: SW-DAMPER-006-SILICON-BOLT | B31: SW-DAMPER-006 | C31: Silicon chống cháy + bu lông, ốc vít van FD/MFD | D31: PHỤ_KIỆN_VAN | E31: MAT-DAMPER-SILICON-BULONG-VIT | F31: Bộ | G31: 1 | H31: ='00_TONG_HOP_BAO_GIA'!G7 | I31: =G31*H31 | J31: =IFERROR(INDEX('06_BANG_GIA_VAT_TU_AP_DUNG'!$E$1:$E$5000, MATCH(E31, '06_BANG_GIA_VAT_TU_AP_DUNG'!$B$1:$B$5000, 0)), 0) | K31: =I31*J31 | L31: Keo silicon chống cháy & phụ kiện lắp ghép (1 bộ)

Sheet 05_DANH_MUC_KY_THUAT_GOC
A1: STT | B1: MAT_ID | C1: PHÂN LOẠI | D1: TÊN VẬT TƯ | E1: ĐVT | F1: BAREM KỸ THUẬT | G1: NGUỒN ĐỐI SOÁT
A2: 1 | B2: MAT-STEEL-DONGBU-0.50 | C2: TÔN_CUỘN_MẠ_KẼM | D2: TÔN DONGBU 0.50mm | E2: kg | F2: 3.925 kg/m2 | G2: Vat tu tôn!R5C2
A3: 2 | B3: MAT-STEEL-DONGBU-0.60 | C3: TÔN_CUỘN_MẠ_KẼM | D3: TÔN DONGBU 0.60mm | E3: kg | F3: 4.71 kg/m2 | G3: Vat tu tôn!R6C2
A4: 3 | B4: MAT-STEEL-DONGBU-0.80 | C4: TÔN_CUỘN_MẠ_KẼM | D4: TÔN DONGBU 0.80mm | E4: kg | F4: 6.28 kg/m2 | G4: Vat tu tôn!R7C2
A5: 4 | B5: MAT-STEEL-DONGBU-1.00 | C5: TÔN_CUỘN_MẠ_KẼM | D5: TÔN DONGBU 1.00mm | E5: kg | F5: 7.85 kg/m2 | G5: Vat tu tôn!R8C2
A6: 5 | B6: MAT-STEEL-DONGBU-1.20 | C6: TÔN_CUỘN_MẠ_KẼM | D6: TÔN DONGBU 1.20mm | E6: kg | F6: 9.42 kg/m2 | G6: Vat tu tôn!R9C2
A7: 6 | B7: MAT-STEEL-DONGBU-1.50 | C7: TÔN_CUỘN_MẠ_KẼM | D7: TÔN DONGBU 1.50mm | E7: kg | F7: 11.775 kg/m2 | G7: Vat tu tôn!R10C2
A8: 7 | B8: MAT-STEEL-DONGBU-2.00 | C8: TÔN_CUỘN_MẠ_KẼM | D8: TÔN DONGBU 2.00mm | E8: kg | F8: 15.7 kg/m2 | G8: Vat tu tôn!R11C2
A9: 8 | B9: MAT-STEEL-VNSTEEL-0.35 | C9: TÔN_CUỘN_MẠ_KẼM | D9: TÔN THĂNG LONG VNSTEEL 0.35mm | E9: kg | F9: 3.15 kg/m2 | G9: Vat tu tôn!R5C7
A10: 9 | B10: MAT-STEEL-VNSTEEL-0.40 | C10: TÔN_CUỘN_MẠ_KẼM | D10: TÔN THĂNG LONG VNSTEEL 0.40mm | E10: kg | F10: 3.72 kg/m2 | G10: Vat tu tôn!R6C7
A11: 10 | B11: MAT-STEEL-VNSTEEL-0.42 | C11: TÔN_CUỘN_MẠ_KẼM | D11: TÔN THĂNG LONG VNSTEEL 0.42mm | E11: kg | F11: 3.91 kg/m2 | G11: Vat tu tôn!R7C7
A12: 11 | B12: MAT-STEEL-VNSTEEL-0.47 | C12: TÔN_CUỘN_MẠ_KẼM | D12: TÔN THĂNG LONG VNSTEEL 0.47mm | E12: kg | F12: 4.38 kg/m2 | G12: Vat tu tôn!R8C7
A13: 12 | B13: MAT-STEEL-VNSTEEL-0.50 | C13: TÔN_CUỘN_MẠ_KẼM | D13: TÔN THĂNG LONG VNSTEEL 0.50mm | E13: kg | F13: 4.66 kg/m2 | G13: Vat tu tôn!R9C7
... A43: 42 | B43: MAT-STEEL-BLUESCOPE-1.15 | C43: TÔN_CUỘN_MẠ_KẼM | D43: TÔN BLUESCOPE 1.15mm | E43: kg | F43: 9.027 kg/m2 | G43: Vat tu tôn!R9C24
A44: 43 | B44: MAT-INOX-SUS304-0-5 | C44: INOX | D44: Inox Sus304-0.5 | E44: kg | G44: Vat tu tôn!R5C29
A45: 44 | B45: MAT-INOX-SUS304-0-6 | C45: INOX | D45: Inox Sus304-0.6 | E45: kg | G45: Vat tu tôn!R6C29
A46: 45 | B46: MAT-INOX-SUS304-0-7 | C46: INOX | D46: Inox Sus304-0.7 | E46: kg | G46: Vat tu tôn!R7C29
A47: 46 | B47: MAT-INOX-SUS304-0-8 | C47: INOX | D47: Inox Sus304-0.8 | E47: kg | G47: Vat tu tôn!R8C29
A48: 47 | B48: MAT-INOX-SUS304-0-9 | C48: INOX | D48: Inox Sus304-0.9 | E48: kg | G48: Vat tu tôn!R9C29
A49: 48 | B49: MAT-INOX-SUS304-1-0 | C49: INOX | D49: Inox Sus304-1,0 | E49: kg | G49: Vat tu tôn!R10C29
A50: 49 | B50: MAT-INOX-SUS304-1-2 | C50: INOX | D50: Inox Sus304-1,2 | E50: kg | G50: Vat tu tôn!R11C29
A51: 50 | B51: MAT-INOX-SUS430-0-5 | C51: INOX | D51: Inox Sus430-0.5 | E51: kg | G51: Vat tu tôn!R12C29
A52: 51 | B52: MAT-INOX-SUS430-0-6 | C52: INOX | D52: Inox Sus430-0.6 | E52: kg | G52: Vat tu tôn!R13C29
A53: 52 | B53: MAT-INOX-SUS430-0-7 | C53: INOX | D53: Inox Sus430-0.7 | E53: kg | G53: Vat tu tôn!R14C29
A54: 53 | B54: MAT-INOX-SUS430-0-8 | C54: INOX | D54: Inox Sus430-0.8 | E54: kg | G54: Vat tu tôn!R15C29
A55: 54 | B55: MAT-INOX-SUS430-0-9 | C55: INOX | D55: Inox Sus430-0.9 | E55: kg | G55: Vat tu tôn!R16C29
... A101: 100 | B101: MAT-INSUL-MOTOR-VAN-AP-SUAT | C101: VẬT_LIỆU_TIÊU_ÂM | D101: Motor van áp suất | E101: m2 | G101: Vat tu tôn!R10C41
A102: 101 | B102: MAT-ALU-NAN-BD | C102: NHÔM_ĐỊNH_HÌNH | D102: Nhôm định hình NAN BD | E102: kg | F102: 0.058 kg/m | G102: BG Cửa (rút gọn)!R3C2
A103: 102 | B103: MAT-ALU-NAN-T | C103: NHÔM_ĐỊNH_HÌNH | D103: Nhôm định hình NAN T | E103: kg | F103: 0.078 kg/m | G103: BG Cửa (rút gọn)!R4C2
A104: 103 | B104: MAT-ALU-KHUNG-BD | C104: NHÔM_ĐỊNH_HÌNH | D104: Nhôm định hình KHUNG BD | E104: kg | F104: 0.2 kg/m | G104: BG Cửa (rút gọn)!R5C2
A105: 104 | B105: MAT-ALU-KHUNG-BD-Z-MONG | C105: NHÔM_ĐỊNH_HÌNH | D105: Nhôm định hình KHUNG BD+ Z MỎNG | E105: kg | F105: 0.173 kg/m | G105: BG Cửa (rút gọn)!R6C2
A106: 105 | B106: MAT-ALU-NAN-Z-DAY | C106: NHÔM_ĐỊNH_HÌNH | D106: Nhôm định hình NAN Z DÀY | E106: kg | F106: 0.217 kg/m | G106: BG Cửa (rút gọn)!R7C2
A107: 106 | B107: MAT-ALU-NAN-Z-MONG | C107: NHÔM_ĐỊNH_HÌNH | D107: Nhôm định hình NAN Z MỎNG | E107: kg | F107: 0.16 kg/m | G107: BG Cửa (rút gọn)!R8C2
A108: 107 | B108: MAT-ALU-KHUNG-Z-2-LOP | C108: NHÔM_ĐỊNH_HÌNH | D108: Nhôm định hình KHUNG Z+2 LỚP | E108: kg | F108: 0.227 kg/m | G108: BG Cửa (rút gọn)!R9C2
A109: 108 | B109: MAT-ALU-NAN-OBD | C109: NHÔM_ĐỊNH_HÌNH | D109: Nhôm định hình NAN OBD | E109: kg | F109: 0.11 kg/m | G109: BG Cửa (rút gọn)!R10C2
A110: 109 | B110: MAT-ALU-KHUNG-OBD | C110: NHÔM_ĐỊNH_HÌNH | D110: Nhôm định hình KHUNG OBD | E110: kg | F110: 0.158 kg/m | G110: BG Cửa (rút gọn)!R11C2
A111: 110 | B111: MAT-ALU-NAN-BD-EUS02 | C111: NHÔM_ĐỊNH_HÌNH | D111: Nhôm định hình NAN BD EUS 02 | E111: kg | F111: 0.071 kg/m | G111: BG Cửa (rút gọn)!R14C2
A112: 111 | B112: MAT-ALU-KHUNG-BD-EUS01 | C112: NHÔM_ĐỊNH_HÌNH | D112: Nhôm định hình KHUNG BD EUS 01 | E112: kg | F112: 0.206 kg/m | G112: BG Cửa (rút gọn)!R15C2
A113: 112 | B113: MAT-ALU-NAN-Z-EUS05 | C113: NHÔM_ĐỊNH_HÌNH | D113: Nhôm định hình NAN Z EUS 05 | E113: kg | F113: 0.162 kg/m | G113: BG Cửa (rút gọn)!R16C2
... A116: 115 | B116: MAT-ALU-KHUNG-OBD-EUS10 | C116: NHÔM_ĐỊNH_HÌNH | D116: Nhôm định hình KHUNG OBD EUS 10 | E116: kg | F116: 0.141 kg/m | G116: BG Cửa (rút gọn)!R19C2
...

Sheet 06_BANG_GIA_VAT_TU_AP_DUNG
A1: STT | B1: MAT_ID | C1: TÊN VẬT TƯ | D1: PHÂN LOẠI | E1: ĐƠN GIÁ GỐC (VNĐ)
A2: 1 | B2: MAT-STEEL-DONGBU-0.50 | C2: TÔN DONGBU 0.50mm | D2: TÔN_CUỘN_MẠ_KẼM | E2: 26000
A3: 2 | B3: MAT-STEEL-DONGBU-0.60 | C3: TÔN DONGBU 0.60mm | D3: TÔN_CUỘN_MẠ_KẼM | E3: 26000
A4: 3 | B4: MAT-STEEL-DONGBU-0.80 | C4: TÔN DONGBU 0.80mm | D4: TÔN_CUỘN_MẠ_KẼM | E4: 26000
A5: 4 | B5: MAT-STEEL-DONGBU-1.00 | C5: TÔN DONGBU 1.00mm | D5: TÔN_CUỘN_MẠ_KẼM | E5: 26000
A6: 5 | B6: MAT-STEEL-DONGBU-1.20 | C6: TÔN DONGBU 1.20mm | D6: TÔN_CUỘN_MẠ_KẼM | E6: 26000
A7: 6 | B7: MAT-STEEL-DONGBU-1.50 | C7: TÔN DONGBU 1.50mm | D7: TÔN_CUỘN_MẠ_KẼM | E7: 26000
A8: 7 | B8: MAT-STEEL-DONGBU-2.00 | C8: TÔN DONGBU 2.00mm | D8: TÔN_CUỘN_MẠ_KẼM | E8: 26000
A9: 8 | B9: MAT-STEEL-VNSTEEL-0.35 | C9: TÔN THĂNG LONG VNSTEEL 0.35mm | D9: TÔN_CUỘN_MẠ_KẼM | E9: 23800
A10: 9 | B10: MAT-STEEL-VNSTEEL-0.40 | C10: TÔN THĂNG LONG VNSTEEL 0.40mm | D10: TÔN_CUỘN_MẠ_KẼM | E10: 23550
A11: 10 | B11: MAT-STEEL-VNSTEEL-0.42 | C11: TÔN THĂNG LONG VNSTEEL 0.42mm | D11: TÔN_CUỘN_MẠ_KẼM | E11: 23400
A12: 11 | B12: MAT-STEEL-VNSTEEL-0.47 | C12: TÔN THĂNG LONG VNSTEEL 0.47mm | D12: TÔN_CUỘN_MẠ_KẼM | E12: 23200
A13: 12 | B13: MAT-STEEL-VNSTEEL-0.50 | C13: TÔN THĂNG LONG VNSTEEL 0.50mm | D13: TÔN_CUỘN_MẠ_KẼM | E13: 23200
... A206: 205 | B206: MAT-KHAC-LUOI_BAO_VE | C206: Lưới bảo vệ | D206: THƯƠNG_MẠI_TỰ_ĐỘNG | E206: 165000
