Workbook
Name \a: #N/A
Name \N: #REF!
Name \s: #N/A
Name \Z: #REF!
Name _: #REF!
Name _??: NA()
Name _??_1: NA()
Name _??_1_1: NA()
Name _??_1_2: NA()
Name _??_1_3: NA()
Name _??_1_4: NA()
Name _??_1_5: NA()
Name _??_6: NA()
Name _??_7: NA()
Name _??_9: NA()
Name _?1: NA()
Name _?1_1: NA()
Name _?1_1_1: NA()
Name _?1_1_2: NA()
Name _?1_1_3: NA()
Name _?1_1_4: NA()
Name _?1_1_5: NA()
Name _?1_6: NA()
Name _?1_7: NA()
Name _?1_9: NA()
Name _?271: NA()
Name _?271_1: NA()
Name _?271_1_1: NA()
Name _?271_1_2: NA()
Name _?271_1_3: NA()
Name _?271_1_4: NA()
Name _?271_1_5: NA()
Name _?271_6: NA()
Name _?271_7: NA()
Name _?271_9: NA()
Name ____DIV3: #REF!
Name ____DIV4: #REF!
Name ___DIV10: #REF!
Name ___DIV15: #REF!
Name ___DIV3: #REF!
Name ___DIV4: #REF!
Name ___DIV5: #REF!
Name ___DIV7: #REF!
Name ___DIV8: #REF!
Name ___DIV9: #REF!
Name ___TB1: #REF!
Name __10: #REF!
Name __12: #REF!
Name __14: #REF!
Name __16: #REF!
Name __18: #REF!
Name __20: #REF!
Name __22: #REF!
Name __24: #REF!
Name __26: #REF!
Name __28: #REF!
Name __30: #REF!
Name __32: #REF!
Name __34: #REF!
Name __36: #REF!

Sheet BG Đơn Cánh ĐC FSLF 24V
C2: CÔNG TY CỔ PHẦN TẬP ĐOÀN QUỐC TẾ SLAND
C3: VPGD: SỐ 49, Ngõ 1295 Giải Phóng, Phường Hoàng Mai, TP Hà Nội
C4: Nhà máy: Thôn Nhân Hiền - xã Thường Tín - TP Hà Nội
C5: Hotline: 082 5577 999
A6: BẢNG BÁO GIÁ (PHƯƠNG ÁN 1: VAN MFD ĐƠN CÁNH - ĐỘNG CƠ BELIMO FSLF24V)
A7: Khách hàng : | M7: Số hiệu
A8: Địa chỉ : | M8: PT Kinh doanh
A9: Người nhận : | M9: Điện thoại
A10: Email: | C10: Số điện thoại : | M10: Dự án
A11: STT | B11: Danh mục sản phẩm | C11: Model | D11: Thương hiệu | E11: Kích thước (mm) | I11: Modul | J11: L | K11: Độ dày (mm) | L11: Unit Đơn vị | M11: Q'ty Số lượng | N11: Đơn Giá (VNĐ) | O11: Total price Thành tiền | P11: Remarks Ghi chú
E12: A1 | F12: A2 | G12: B1 | H12: B2
E13: Face size | G13: Neck size
B14: HỆ THỐNG HÚT KHÓI HẦM XE, HÚT KHÓI SỰ CỐ
A15: 1 | B15: Canvas loại chống cháy cho quạt TAHK | C15: CANVAS | D15: SWIND | E15: Ø | F15: 1000 | J15: 200 | L15: cái | M15: 15 | N15: =ROUND('00_TONG_HOP_BAO_GIA'!Q2, 0) | O15: =N15*M15 | P15: Khớp nối mềm vải bạt chống cháy
A16: 2 | B16: Canvas loại chống cháy cho quạt TAHK | C16: CANVAS | D16: SWIND | E16: Ø | F16: 900 | J16: 200 | L16: cái | M16: 40 | N16: =ROUND('00_TONG_HOP_BAO_GIA'!Q3, 0) | O16: =N16*M16 | P16: Khớp nối mềm vải bạt chống cháy
A17: 3 | B17: Canvas loại chống cháy cho quạt TAHK | C17: CANVAS | D17: SWIND | E17: Ø | F17: 800 | J17: 200 | L17: cái | M17: 40 | N17: =ROUND('00_TONG_HOP_BAO_GIA'!Q4, 0) | O17: =N17*M17 | P17: Khớp nối mềm vải bạt chống cháy
A18: 4 | B18: Canvas loại chống cháy cho quạt TAHK | C18: CANVAS | D18: SWIND | E18: Ø | F18: 710 | J18: 200 | L18: cái | M18: 16 | N18: =ROUND('00_TONG_HOP_BAO_GIA'!Q5, 0) | O18: =N18*M18 | P18: Khớp nối mềm vải bạt chống cháy
A19: 5 | B19: Canvas loại chống cháy cho quạt TAHK | C19: CANVAS | D19: SWIND | E19: Ø | F19: 560 | J19: 200 | L19: cái | M19: 16 | N19: =ROUND('00_TONG_HOP_BAO_GIA'!Q6, 0) | O19: =N19*M19 | P19: Khớp nối mềm vải bạt chống cháy
A20: 6 | B20: Canvas loại thường cho quạt thông gió | C20: CANVAS | D20: SWIND | E20: Ø | F20: 1000 | J20: 200 | L20: cái | M20: 32 | N20: =ROUND('00_TONG_HOP_BAO_GIA'!Q7, 0) | O20: =N20*M20 | P20: Khớp nối mềm vải bạt chống cháy
A21: 7 | B21: Canvas loại thường cho quạt thông gió | C21: CANVAS | D21: SWIND | E21: Ø | F21: 560 | J21: 200 | L21: cái | M21: 24 | N21: =ROUND('00_TONG_HOP_BAO_GIA'!Q8, 0) | O21: =N21*M21 | P21: Khớp nối mềm vải bạt chống cháy
A22: 8 | B22: Van 1 chiều NRD 1250x1250 (EI60) | C22: NRD | D22: SWIND | E22: 1250 | F22: 1250 | G22: 625 | H22: 1250 | I22: 2 | J22: 200 | K22: 1.15 | L22: Cái | M22: 6 | N22: =ROUND('00_TONG_HOP_BAO_GIA'!Q9, 0) | O22: =N22*M22 | P22: Van 1 chiều bọc tấm cách nhiệt dày 10mm KHS
A23: 9 | B23: Van 1 chiều NRD 1700x600 (EI60) | C23: NRD | D23: SWIND | E23: 1700 | F23: 600 | G23: 850 | H23: 600 | I23: 2 | J23: 200 | K23: 0.95 | L23: Cái | M23: 2 | N23: =ROUND('00_TONG_HOP_BAO_GIA'!Q10, 0) | O23: =N23*M23 | P23: Van 1 chiều bọc tấm cách nhiệt dày 10mm KHS
A24: 10 | B24: Van 1 chiều NRD 1200x350 (EI60) | C24: NRD | D24: SWIND | E24: 1200 | F24: 350 | G24: 600 | H24: 350 | I24: 2 | J24: 200 | K24: 0.75 | L24: Cái | M24: 1 | N24: =ROUND('00_TONG_HOP_BAO_GIA'!Q11, 0) | O24: =N24*M24 | P24: Van 1 chiều bọc tấm cách nhiệt dày 10mm KHS
A25: 11 | B25: Van ngăn cháy MFD 1250x1250 (EI60) | C25: SWIND-1.02-MFD-EI90 | D25: SWIND | E25: 1250 | F25: 1250 | G25: 1250 | H25: 625 | I25: 2 | J25: 200 | K25: 1.15 | L25: Cái | M25: 6 | N25: =ROUND(('00_TONG_HOP_BAO_GIA'!Q12-7400000)*0.450035+7400000, 0) | O25: =N25*M25 | P25: - Van chống cháy động cơ - Tiêu chuẩn EI 90 - 2 đầu bích TDC - Gắn kèm động cơ ON-OFF 3.5Nm, 24V (Type: đóng mở nhanh) BELIMO - Model: FSLF24V US - Sản xuất theo BCTN số 4752/VLXD-TBMT - Chia 2 modul khi sản xuất
A26: 12 | B26: Van ngăn cháy MFD 1700x600 (EI60) | C26: SWIND-1.02-MFD-EI90 | D26: SWIND | E26: 1700 | F26: 600 | G26: 850 | H26: 600 | I26: 2 | J26: 200 | K26: 1.15 | L26: Cái | M26: 2 | N26: =ROUND(('00_TONG_HOP_BAO_GIA'!Q13-7400000)*0.564159+7400000, 0) | O26: =N26*M26 | P26: - Van chống cháy động cơ - Tiêu chuẩn EI 90 - 2 đầu bích TDC - Gắn kèm động cơ ON-OFF 3.5Nm, 24V (Type: đóng mở nhanh) BELIMO - Model: FSLF24V US - Sản xuất theo BCTN số 4752/VLXD-TBMT - Chia 2 modul khi sản xuất
A27: 13 | B27: Van ngăn cháy MFD 1200x350 (EI60) | C27: SWIND-1.02-MFD-EI90 | D27: SWIND | E27: 1200 | F27: 350 | J27: 200 | K27: 1.15 | L27: Cái | M27: 1 | N27: =ROUND(('00_TONG_HOP_BAO_GIA'!Q14-3700000)*0.721030+3700000, 0) | O27: =N27*M27 | P27: - Van chống cháy động cơ - Tiêu chuẩn EI 90 - 2 đầu bích TDC - Gắn kèm động cơ ON-OFF 3.5Nm, 24V (Type: đóng mở nhanh) BELIMO - Model: FSLF24V US - Sản xuất theo BCTN số 4752/VLXD-TBMT
A28: 14 | B28: Van ngăn cháy MFD 950x400 (EI30) | C28: SWIND-1.02-MFD-EI90 | D28: SWIND | E28: 950 | F28: 400 | J28: 200 | K28: 1.15 | L28: Cái | M28: 3 | N28: =ROUND(('00_TONG_HOP_BAO_GIA'!Q15-3700000)*0.718482+3700000, 0) | O28: =N28*M28 | P28: - Van chống cháy động cơ - Tiêu chuẩn EI 90 - 2 đầu bích TDC - Gắn kèm động cơ ON-OFF 3.5Nm, 24V (Type: đóng mở nhanh) BELIMO - Model: FSLF24V US - Sản xuất theo BCTN số 4752/VLXD-TBMT
A29: 15 | B29: Van ngăn cháy MFD 950x500 (EI30) | C29: SWIND-1.02-MFD-EI90 | D29: SWIND | E29: 950 | F29: 500 | J29: 200 | K29: 1.15 | L29: Cái | M29: 6 | N29: =ROUND(('00_TONG_HOP_BAO_GIA'!Q16-3700000)*0.571537+3700000, 0) | O29: =N29*M29 | P29: - Van chống cháy động cơ - Tiêu chuẩn EI 90 - 2 đầu bích TDC - Gắn kèm động cơ ON-OFF 3.5Nm, 24V (Type: đóng mở nhanh) BELIMO - Model: FSLF24V US - Sản xuất theo BCTN số 4752/VLXD-TBMT
A30: 16 | B30: Van ngăn cháy MFD 950x200 (EI30) | C30: SWIND-1.02-MFD-EI90 | D30: SWIND | E30: 950 | F30: 200 | J30: 200 | K30: 1.15 | L30: Cái | M30: 9 | N30: =ROUND(('00_TONG_HOP_BAO_GIA'!Q17-3700000)*1.000000+3700000, 0) | O30: =N30*M30 | P30: - Van chống cháy động cơ - Tiêu chuẩn EI 90 - 2 đầu bích TDC - Gắn kèm động cơ ON-OFF 3.5Nm, 24V (Type: đóng mở nhanh) BELIMO - Model: FSLF24V US - Sản xuất theo BCTN số 4752/VLXD-TBMT
A31: 17 | B31: Van ngăn cháy MFD 950x300 (EI30) | C31: SWIND-1.02-MFD-EI90 | D31: SWIND | E31: 950 | F31: 300 | J31: 200 | K31: 1.15 | L31: Cái | M31: 12 | N31: =ROUND(('00_TONG_HOP_BAO_GIA'!Q18-3700000)*0.734150+3700000, 0) | O31: =N31*M31 | P31: - Van chống cháy động cơ - Tiêu chuẩn EI 90 - 2 đầu bích TDC - Gắn kèm động cơ ON-OFF 3.5Nm, 24V (Type: đóng mở nhanh) BELIMO - Model: FSLF24V US - Sản xuất theo BCTN số 4752/VLXD-TBMT
A32: 18 | B32: Van chỉnh lưu lượng VCD 2000x500 (EI60) | C32: VCD | D32: SWIND | E32: 2000 | F32: 500 | G32: 1000 | H32: 500 | I32: 2 | J32: 200 | K32: 1.15 | L32: Cái | M32: 1 | N32: =ROUND('00_TONG_HOP_BAO_GIA'!Q19, 0) | O32: =N32*M32 | P32: Van tay gạt bọc tấm cách nhiệt KHS 10mm
A33: 19 | B33: Van chỉnh lưu lượng VCD 1300x400 (EI60) | C33: VCD | D33: SWIND | E33: 1300 | F33: 400 | G33: 650 | H33: 400 | I33: 2 | J33: 200 | K33: 0.75 | L33: Cái | M33: 2 | N33: =ROUND('00_TONG_HOP_BAO_GIA'!Q20, 0) | O33: =N33*M33 | P33: Van tay gạt bọc tấm cách nhiệt KHS 10mm
A34: 20 | B34: Van chỉnh lưu lượng VCD 1600x400 (EI60) | C34: VCD | D34: SWIND | E34: 1600 | F34: 400 | G34: 800 | H34: 400 | I34: 2 | J34: 200 | K34: 0.95 | L34: Cái | M34: 1 | N34: =ROUND('00_TONG_HOP_BAO_GIA'!Q21, 0) | O34: =N34*M34 | P34: Van tay gạt bọc tấm cách nhiệt KHS 10mm
A35: 21 | B35: Van chỉnh lưu lượng VCD 1600x450 (EI60) | C35: VCD | D35: SWIND | E35: 1600 | F35: 450 | G35: 800 | H35: 450 | I35: 2 | J35: 200 | K35: 0.95 | L35: Cái | M35: 1 | N35: =ROUND('00_TONG_HOP_BAO_GIA'!Q22, 0) | O35: =N35*M35 | P35: Van tay gạt bọc tấm cách nhiệt KHS 10mm
A36: 22 | B36: Van chỉnh lưu lượng VCD 900x350 (EI60) | C36: VCD | D36: SWIND | E36: 900 | F36: 350 | J36: 200 | K36: 0.95 | L36: Cái | M36: 5 | N36: =ROUND('00_TONG_HOP_BAO_GIA'!Q23, 0) | O36: =N36*M36 | P36: Van tay gạt bọc tấm cách nhiệt KHS 10mm
A37: 23 | B37: Van chỉnh lưu lượng VCD 600x300 (EI60) | C37: VCD | D37: SWIND | E37: 600 | F37: 300 | J37: 200 | K37: 0.75 | L37: Cái | M37: 1 | N37: =ROUND('00_TONG_HOP_BAO_GIA'!Q24, 0) | O37: =N37*M37 | P37: Van tay gạt bọc tấm cách nhiệt KHS 10mm
A38: 24 | B38: Miệng gió hút khói EAG 600x300+OBD | C38: ECG+O | D38: SWIND | E38: 600 | F38: 300 | G38: 550 | H38: 250 | L38: Cái | M38: 112 | N38: =ROUND('00_TONG_HOP_BAO_GIA'!Q25, 0) | O38: =N38*M38 | P38: Cửa nan sọt trứng kèm van OBD
A39: 25 | B39: Miệng gió hút khói SEG 1200x600+OBD | C39: SDG+O | D39: SWIND | E39: 1200 | F39: 600 | G39: 1150 | H39: 550 | L39: Cái | M39: 2 | N39: =ROUND('00_TONG_HOP_BAO_GIA'!Q26, 0) | O39: =N39*M39 | P39: Cửa nan bầu dục 1 lớp kèm van OBD
A40: 26 | B40: Miệng gió hút khói SEAG 1000x600+OBD | C40: SDG+O | D40: SWIND | E40: 1000 | F40: 600 | G40: 950 | H40: 550 | L40: Cái | M40: 52 | N40: =ROUND('00_TONG_HOP_BAO_GIA'!Q27, 0) | O40: =N40*M40 | P40: Cửa nan bầu dục 1 lớp kèm van OBD
A41: 27 | B41: Louver EAL 7500x500+IS | C41: WL+N | D41: SWIND | E41: 7500 | F41: 500 | G41: 7450 | H41: 450 | L41: Cái | M41: 1 | N41: =ROUND('00_TONG_HOP_BAO_GIA'!Q28, 0) | O41: =N41*M41 | P41: Louver nan Z + LCCT
...

Sheet BG Đa Cánh BFN 24
C2: CÔNG TY CỔ PHẦN TẬP ĐOÀN QUỐC TẾ SLAND
C3: VPGD: SỐ 49, Ngõ 1295 Giải Phóng, Phường Hoàng Mai, TP Hà Nội
C4: Nhà máy: Thôn Nhân Hiền - xã Thường Tín - TP Hà Nội
C5: Hotline: 082 5577 999
A6: BẢNG BÁO GIÁ (PHƯƠNG ÁN 2: VAN MFD ĐA CÁNH - ĐỘNG CƠ BELIMO BFN24)
A7: Khách hàng : | M7: Số hiệu
A8: Địa chỉ : | M8: PT Kinh doanh
A9: Người nhận : | M9: Điện thoại
A10: Email: | C10: Số điện thoại : | M10: Dự án
A11: STT | B11: Danh mục sản phẩm | C11: Model | D11: Thương hiệu | E11: Kích thước (mm) | I11: Modul | J11: L | K11: Độ dày (mm) | L11: Unit Đơn vị | M11: Q'ty Số lượng | N11: Đơn Giá (VNĐ) | O11: Total price Thành tiền | P11: Remarks Ghi chú
E12: A1 | F12: A2 | G12: B1 | H12: B2
E13: Face size | G13: Neck size
B14: HỆ THỐNG HÚT KHÓI HẦM XE, HÚT KHÓI SỰ CỐ
A15: 1 | B15: Canvas loại chống cháy cho quạt TAHK | C15: CANVAS | D15: SWIND | E15: Ø | F15: 1000 | J15: 200 | L15: cái | M15: 15 | N15: =ROUND('00_TONG_HOP_BAO_GIA'!Q2, 0) | O15: =N15*M15 | P15: Khớp nối mềm vải bạt chống cháy
A16: 2 | B16: Canvas loại chống cháy cho quạt TAHK | C16: CANVAS | D16: SWIND | E16: Ø | F16: 900 | J16: 200 | L16: cái | M16: 40 | N16: =ROUND('00_TONG_HOP_BAO_GIA'!Q3, 0) | O16: =N16*M16 | P16: Khớp nối mềm vải bạt chống cháy
A17: 3 | B17: Canvas loại chống cháy cho quạt TAHK | C17: CANVAS | D17: SWIND | E17: Ø | F17: 800 | J17: 200 | L17: cái | M17: 40 | N17: =ROUND('00_TONG_HOP_BAO_GIA'!Q4, 0) | O17: =N17*M17 | P17: Khớp nối mềm vải bạt chống cháy
A18: 4 | B18: Canvas loại chống cháy cho quạt TAHK | C18: CANVAS | D18: SWIND | E18: Ø | F18: 710 | J18: 200 | L18: cái | M18: 16 | N18: =ROUND('00_TONG_HOP_BAO_GIA'!Q5, 0) | O18: =N18*M18 | P18: Khớp nối mềm vải bạt chống cháy
A19: 5 | B19: Canvas loại chống cháy cho quạt TAHK | C19: CANVAS | D19: SWIND | E19: Ø | F19: 560 | J19: 200 | L19: cái | M19: 16 | N19: =ROUND('00_TONG_HOP_BAO_GIA'!Q6, 0) | O19: =N19*M19 | P19: Khớp nối mềm vải bạt chống cháy
A20: 6 | B20: Canvas loại thường cho quạt thông gió | C20: CANVAS | D20: SWIND | E20: Ø | F20: 1000 | J20: 200 | L20: cái | M20: 32 | N20: =ROUND('00_TONG_HOP_BAO_GIA'!Q7, 0) | O20: =N20*M20 | P20: Khớp nối mềm vải bạt chống cháy
A21: 7 | B21: Canvas loại thường cho quạt thông gió | C21: CANVAS | D21: SWIND | E21: Ø | F21: 560 | J21: 200 | L21: cái | M21: 24 | N21: =ROUND('00_TONG_HOP_BAO_GIA'!Q8, 0) | O21: =N21*M21 | P21: Khớp nối mềm vải bạt chống cháy
A22: 8 | B22: Van 1 chiều NRD 1250x1250 (EI60) | C22: NRD | D22: SWIND | E22: 1250 | F22: 1250 | G22: 625 | H22: 1250 | I22: 2 | J22: 200 | K22: 1.15 | L22: Cái | M22: 6 | N22: =ROUND('00_TONG_HOP_BAO_GIA'!Q9, 0) | O22: =N22*M22 | P22: Van 1 chiều bọc tấm cách nhiệt dày 10mm KHS
A23: 9 | B23: Van 1 chiều NRD 1700x600 (EI60) | C23: NRD | D23: SWIND | E23: 1700 | F23: 600 | G23: 850 | H23: 600 | I23: 2 | J23: 200 | K23: 0.95 | L23: Cái | M23: 2 | N23: =ROUND('00_TONG_HOP_BAO_GIA'!Q10, 0) | O23: =N23*M23 | P23: Van 1 chiều bọc tấm cách nhiệt dày 10mm KHS
A24: 10 | B24: Van 1 chiều NRD 1200x350 (EI60) | C24: NRD | D24: SWIND | E24: 1200 | F24: 350 | G24: 600 | H24: 350 | I24: 2 | J24: 200 | K24: 0.75 | L24: Cái | M24: 1 | N24: =ROUND('00_TONG_HOP_BAO_GIA'!Q11, 0) | O24: =N24*M24 | P24: Van 1 chiều bọc tấm cách nhiệt dày 10mm KHS
A25: 11 | B25: Van ngăn cháy MFD 1250x1250 (EI60) | C25: SWIND-1.05- MFD-EI120 | D25: SWIND | E25: 1250 | F25: 1250 | G25: 1250 | H25: 625 | I25: 2 | J25: 200 | K25: 1.15 | L25: Cái | M25: 6 | N25: =ROUND('00_TONG_HOP_BAO_GIA'!Q12, 0) | O25: =N25*M25 | P25: - Van động cơ SWIND-MFD - Tiêu chuẩn EI 120 - 2 đầu bích TDC - Gắn kèm động cơ ON-OFF 9Nm, 24V BELIMO - Model: BFN 24 - Sản xuất theo BCTN số 2390/VLXD-TBMT - Van chia đa cánh - Chia 2 modul khi sản xuất
A26: 12 | B26: Van ngăn cháy MFD 1700x600 (EI60) | C26: SWIND-1.05- MFD-EI120 | D26: SWIND | E26: 1700 | F26: 600 | G26: 850 | H26: 600 | I26: 2 | J26: 200 | K26: 1.15 | L26: Cái | M26: 2 | N26: =ROUND('00_TONG_HOP_BAO_GIA'!Q13, 0) | O26: =N26*M26 | P26: - Van động cơ SWIND-MFD - Tiêu chuẩn EI 120 - 2 đầu bích TDC - Gắn kèm động cơ ON-OFF 9Nm, 24V BELIMO - Model: BFN 24 - Sản xuất theo BCTN số 2390/VLXD-TBMT - Van chia đa cánh - Chia 2 modul khi sản xuất
A27: 13 | B27: Van ngăn cháy MFD 1200x350 (EI60) | C27: SWIND-1.05- MFD-EI120 | D27: SWIND | E27: 1200 | F27: 350 | J27: 200 | K27: 1.15 | L27: Cái | M27: 1 | N27: =ROUND('00_TONG_HOP_BAO_GIA'!Q14, 0) | O27: =N27*M27 | P27: - Van động cơ SWIND-MFD - Tiêu chuẩn EI 120 - 2 đầu bích TDC - Gắn kèm động cơ ON-OFF 9Nm, 24V BELIMO - Model: BFN 24 - Sản xuất theo BCTN số 2390/VLXD-TBMT - Van chia đa cánh
A28: 14 | B28: Van ngăn cháy MFD 950x400 (EI30) | C28: SWIND-1.05- MFD-EI120 | D28: SWIND | E28: 950 | F28: 400 | J28: 200 | K28: 1.15 | L28: Cái | M28: 3 | N28: =ROUND('00_TONG_HOP_BAO_GIA'!Q15, 0) | O28: =N28*M28 | P28: - Van động cơ SWIND-MFD - Tiêu chuẩn EI 120 - 2 đầu bích TDC - Gắn kèm động cơ ON-OFF 9Nm, 24V BELIMO - Model: BFN 24 - Sản xuất theo BCTN số 2390/VLXD-TBMT - Van chia đa cánh
A29: 15 | B29: Van ngăn cháy MFD 950x500 (EI30) | C29: SWIND-1.05- MFD-EI120 | D29: SWIND | E29: 950 | F29: 500 | J29: 200 | K29: 1.15 | L29: Cái | M29: 6 | N29: =ROUND('00_TONG_HOP_BAO_GIA'!Q16, 0) | O29: =N29*M29 | P29: - Van động cơ SWIND-MFD - Tiêu chuẩn EI 120 - 2 đầu bích TDC - Gắn kèm động cơ ON-OFF 9Nm, 24V BELIMO - Model: BFN 24 - Sản xuất theo BCTN số 2390/VLXD-TBMT - Van chia đa cánh
A30: 16 | B30: Van ngăn cháy MFD 950x200 (EI30) | C30: SWIND-1.05- MFD-EI120 | D30: SWIND | E30: 950 | F30: 200 | J30: 200 | K30: 1.15 | L30: Cái | M30: 9 | N30: =ROUND('00_TONG_HOP_BAO_GIA'!Q17, 0) | O30: =N30*M30 | P30: - Van động cơ SWIND-MFD - Tiêu chuẩn EI 120 - 2 đầu bích TDC - Gắn kèm động cơ ON-OFF 9Nm, 24V BELIMO - Model: BFN 24 - Sản xuất theo BCTN số 2390/VLXD-TBMT - Van 1 cánh
A31: 17 | B31: Van ngăn cháy MFD 950x300 (EI30) | C31: SWIND-1.05- MFD-EI120 | D31: SWIND | E31: 950 | F31: 300 | J31: 200 | K31: 1.15 | L31: Cái | M31: 12 | N31: =ROUND('00_TONG_HOP_BAO_GIA'!Q18, 0) | O31: =N31*M31 | P31: - Van động cơ SWIND-MFD - Tiêu chuẩn EI 120 - 2 đầu bích TDC - Gắn kèm động cơ ON-OFF 9Nm, 24V BELIMO - Model: BFN 24 - Sản xuất theo BCTN số 2390/VLXD-TBMT - Van chia đa cánh
A32: 18 | B32: Van chỉnh lưu lượng VCD 2000x500 (EI60) | C32: VCD | D32: SWIND | E32: 2000 | F32: 500 | G32: 1000 | H32: 500 | I32: 2 | J32: 200 | K32: 1.15 | L32: Cái | M32: 1 | N32: =ROUND('00_TONG_HOP_BAO_GIA'!Q19, 0) | O32: =N32*M32 | P32: Van tay gạt bọc tấm cách nhiệt KHS 10mm
A33: 19 | B33: Van chỉnh lưu lượng VCD 1300x400 (EI60) | C33: VCD | D33: SWIND | E33: 1300 | F33: 400 | G33: 650 | H33: 400 | I33: 2 | J33: 200 | K33: 0.75 | L33: Cái | M33: 2 | N33: =ROUND('00_TONG_HOP_BAO_GIA'!Q20, 0) | O33: =N33*M33 | P33: Van tay gạt bọc tấm cách nhiệt KHS 10mm
A34: 20 | B34: Van chỉnh lưu lượng VCD 1600x400 (EI60) | C34: VCD | D34: SWIND | E34: 1600 | F34: 400 | G34: 800 | H34: 400 | I34: 2 | J34: 200 | K34: 0.95 | L34: Cái | M34: 1 | N34: =ROUND('00_TONG_HOP_BAO_GIA'!Q21, 0) | O34: =N34*M34 | P34: Van tay gạt bọc tấm cách nhiệt KHS 10mm
A35: 21 | B35: Van chỉnh lưu lượng VCD 1600x450 (EI60) | C35: VCD | D35: SWIND | E35: 1600 | F35: 450 | G35: 800 | H35: 450 | I35: 2 | J35: 200 | K35: 0.95 | L35: Cái | M35: 1 | N35: =ROUND('00_TONG_HOP_BAO_GIA'!Q22, 0) | O35: =N35*M35 | P35: Van tay gạt bọc tấm cách nhiệt KHS 10mm
A36: 22 | B36: Van chỉnh lưu lượng VCD 900x350 (EI60) | C36: VCD | D36: SWIND | E36: 900 | F36: 350 | J36: 200 | K36: 0.95 | L36: Cái | M36: 5 | N36: =ROUND('00_TONG_HOP_BAO_GIA'!Q23, 0) | O36: =N36*M36 | P36: Van tay gạt bọc tấm cách nhiệt KHS 10mm
A37: 23 | B37: Van chỉnh lưu lượng VCD 600x300 (EI60) | C37: VCD | D37: SWIND | E37: 600 | F37: 300 | J37: 200 | K37: 0.75 | L37: Cái | M37: 1 | N37: =ROUND('00_TONG_HOP_BAO_GIA'!Q24, 0) | O37: =N37*M37 | P37: Van tay gạt bọc tấm cách nhiệt KHS 10mm
A38: 24 | B38: Miệng gió hút khói EAG 600x300+OBD | C38: ECG+O | D38: SWIND | E38: 600 | F38: 300 | G38: 550 | H38: 250 | L38: Cái | M38: 112 | N38: =ROUND('00_TONG_HOP_BAO_GIA'!Q25, 0) | O38: =N38*M38 | P38: Cửa nan sọt trứng kèm van OBD
A39: 25 | B39: Miệng gió hút khói SEG 1200x600+OBD | C39: SDG+O | D39: SWIND | E39: 1200 | F39: 600 | G39: 1150 | H39: 550 | L39: Cái | M39: 2 | N39: =ROUND('00_TONG_HOP_BAO_GIA'!Q26, 0) | O39: =N39*M39 | P39: Cửa nan bầu dục 1 lớp kèm van OBD
A40: 26 | B40: Miệng gió hút khói SEAG 1000x600+OBD | C40: SDG+O | D40: SWIND | E40: 1000 | F40: 600 | G40: 950 | H40: 550 | L40: Cái | M40: 52 | N40: =ROUND('00_TONG_HOP_BAO_GIA'!Q27, 0) | O40: =N40*M40 | P40: Cửa nan bầu dục 1 lớp kèm van OBD
A41: 27 | B41: Louver EAL 7500x500+IS | C41: WL+N | D41: SWIND | E41: 7500 | F41: 500 | G41: 7450 | H41: 450 | L41: Cái | M41: 1 | N41: =ROUND('00_TONG_HOP_BAO_GIA'!Q28, 0) | O41: =N41*M41 | P41: Louver nan Z + LCCT
...

Sheet 00_BANG_CHAO_GIA
A1: BILL: HỆ THỐNG ĐHKK & THÔNG GIÓ
A3: STT | B3: MÔ TẢ CÔNG TÁC | C3: MÃ HIỆU | D3: NHÃN HIỆU | E3: XUẤT XỨ | F3: LỌC | G3: Đơn vị | H3: Khối lượng | I3: ĐƠN GIÁ | L3: THÀNH TIỀN | O3: GHI CHÚ
I4: VẬT TƯ | J4: NHÂN CÔNG | K4: TỔNG | L4: VẬT TƯ | M4: NHÂN CÔNG | N4: TỔNG
A5: A | B5: HỆ THỐNG THÔNG GIÓ | F5: M
A6: A1 | B6: HỆ THỐNG HÚT KHÓI HẦM XE, HÚT KHÓI SỰ CỐ | F6: M
A7: =SUBTOTAL(3,$G7:G$7) | B7: Quạt hướng trục CEF-B2-Z1-01~02 5290/9430 l/s @ 500/1350 Pa, chống cháy 300°C trong 2h, | C7: CEF | D7: Fantech (ELTA Fans), Systemair, Wolter, Kruger | F7: QUẠT | G7: Cái | H7: 2
A8: =SUBTOTAL(3,$G$7:G8) | B8: Quạt hướng trục CEF-B2-Z2-01~02 5490/8910 l/s @ 600/1350 Pa, chống cháy 300°C trong 2h | C8: CEF | D8: Fantech (ELTA Fans), Systemair, Wolter, Kruger | F8: QUẠT | G8: Cái | H8: 2
A9: =SUBTOTAL(3,$G$7:G9) | B9: Quạt hướng trục CEF-B1-Z1-01~02 5590/8385 l/s @ 600/1350 Pa, chống cháy 300°C trong 2h | C9: CEF | D9: Fantech (ELTA Fans), Systemair, Wolter, Kruger | F9: QUẠT | G9: Cái | H9: 2
A10: =SUBTOTAL(3,$G$7:G10) | B10: Quạt hướng trục CEF-B1-Z2-01~02 5135/7700 l/s @ 600/1350 Pa, chống cháy 300°C trong 2h | C10: CEF | D10: Fantech (ELTA Fans), Systemair, Wolter, Kruger | F10: QUẠT | G10: Cái | H10: 2
A11: =SUBTOTAL(3,$G$7:G11) | B11: Quạt hướng trục SEF-B1-Z2-01 4800 l/s @ 500 Pa, chống cháy 300°C trong 2h | C11: SEF | D11: Fantech (ELTA Fans), Systemair, Wolter, Kruger | F11: QUẠT | G11: Cái | H11: 1
A12: =SUBTOTAL(3,$G$7:G12) | B12: Quạt hướng trục SEF-A1.1-03F-01~02 7400 l/s @ 400 Pa, chống cháy 300°C trong 2h | C12: SEF | D12: Fantech (ELTA Fans), Systemair, Wolter, Kruger | F12: QUẠT | G12: Cái | H12: 2
A13: =SUBTOTAL(3,$G$7:G13) | B13: Quạt hướng trục SEF-A1.2-03F-01~02 6700 l/s @ 500 Pa, chống cháy 300°C trong 2h | C13: SEF | D13: Fantech (ELTA Fans), Systemair, Wolter, Kruger | F13: QUẠT | G13: Cái | H13: 2
A14: =SUBTOTAL(3,$G$7:G14) | B14: Quạt hướng trục SEF-A1.2-03F-03 5100 l/s @ 500 Pa, chống cháy 300°C trong 2h | C14: SEF | D14: Fantech (ELTA Fans), Systemair, Wolter, Kruger | F14: QUẠT | G14: Cái | H14: 1
A15: =SUBTOTAL(3,$G$7:G15) | B15: Quạt hướng trục SEF-A1.3-03F-01~03 4800 l/s @ 500 Pa, chống cháy 300°C trong 2h | C15: SEF | D15: Fantech (ELTA Fans), Systemair, Wolter, Kruger | F15: QUẠT | G15: Cái | H15: 3
A16: =SUBTOTAL(3,$G$7:G16) | B16: Quạt hướng trục SEF-A1.3-03F-04 4800 l/s @ 450 Pa, chống cháy 300°C trong 2h | C16: SEF | D16: Fantech (ELTA Fans), Systemair, Wolter, Kruger | F16: QUẠT | G16: Cái | H16: 1
A17: =SUBTOTAL(3,$G$7:G17) | B17: Quạt hướng trục SEF-A1.3-03F-05~07 4800 l/s @ 500 Pa, chống cháy 300°C trong 2h | C17: SEF | D17: Fantech (ELTA Fans), Systemair, Wolter, Kruger | F17: QUẠT | G17: Cái | H17: 3
A18: =SUBTOTAL(3,$G$7:G18) | B18: Quạt hướng trục SEF-A1.3-10F-01 7100 l/s @ 600 Pa, chống cháy 300°C trong 2h | C18: SEF | D18: Fantech (ELTA Fans), Systemair, Wolter, Kruger | F18: QUẠT | G18: Cái | H18: 1
A19: =SUBTOTAL(3,$G$7:G19) | B19: Quạt hướng trục SEF-A1.2-12F-01 8800 l/s @ 650 Pa, chống cháy 300°C trong 2h | C19: SEF | D19: Fantech (ELTA Fans), Systemair, Wolter, Kruger | F19: QUẠT | G19: Cái | H19: 1
A20: =SUBTOTAL(3,$G$7:G20) | B20: Quạt hướng trục SEF-A1.1-RF-01 8100 l/s @ 650 Pa, chống cháy 300°C trong 2h | C20: SEF | D20: Fantech (ELTA Fans), Systemair, Wolter, Kruger | F20: QUẠT | G20: Cái | H20: 1
B21: Canvas loại chống cháy cho quạt TAHK | C21: D1000, L=200mm | F21: CANVAS | G21: cái | H21: 15 | I21: =IF('00_TONG_HOP_BAO_GIA'!G2>0, ('00_TONG_HOP_BAO_GIA'!K2 + '00_TONG_HOP_BAO_GIA'!M2) * (1 + '00_TONG_HOP_BAO_GIA'!P2) / '00_TONG_HOP_BAO_GIA'!G2, 0) | J21: =IF('00_TONG_HOP_BAO_GIA'!G2>0, '00_TONG_HOP_BAO_GIA'!L2 * (1 + '00_TONG_HOP_BAO_GIA'!P2) / '00_TONG_HOP_BAO_GIA'!G2, 0) | K21: ='00_TONG_HOP_BAO_GIA'!Q2 | L21: =('00_TONG_HOP_BAO_GIA'!K2 + '00_TONG_HOP_BAO_GIA'!M2) * (1 + '00_TONG_HOP_BAO_GIA'!P2) | M21: ='00_TONG_HOP_BAO_GIA'!L2 * (1 + '00_TONG_HOP_BAO_GIA'!P2) | N21: ='00_TONG_HOP_BAO_GIA'!R2 | O21: =IF(K21=0, "CẢNH BÁO: Đơn giá = 0. Tra cứu lại Sheet 06!", '00_TONG_HOP_BAO_GIA'!S2)
B22: Canvas loại chống cháy cho quạt TAHK | C22: D900, L=200mm | F22: CANVAS | G22: cái | H22: 40 | I22: =IF('00_TONG_HOP_BAO_GIA'!G3>0, ('00_TONG_HOP_BAO_GIA'!K3 + '00_TONG_HOP_BAO_GIA'!M3) * (1 + '00_TONG_HOP_BAO_GIA'!P3) / '00_TONG_HOP_BAO_GIA'!G3, 0) | J22: =IF('00_TONG_HOP_BAO_GIA'!G3>0, '00_TONG_HOP_BAO_GIA'!L3 * (1 + '00_TONG_HOP_BAO_GIA'!P3) / '00_TONG_HOP_BAO_GIA'!G3, 0) | K22: ='00_TONG_HOP_BAO_GIA'!Q3 | L22: =('00_TONG_HOP_BAO_GIA'!K3 + '00_TONG_HOP_BAO_GIA'!M3) * (1 + '00_TONG_HOP_BAO_GIA'!P3) | M22: ='00_TONG_HOP_BAO_GIA'!L3 * (1 + '00_TONG_HOP_BAO_GIA'!P3) | N22: ='00_TONG_HOP_BAO_GIA'!R3 | O22: =IF(K22=0, "CẢNH BÁO: Đơn giá = 0. Tra cứu lại Sheet 06!", '00_TONG_HOP_BAO_GIA'!S3)
B23: Canvas loại chống cháy cho quạt TAHK | C23: D800, L=200mm | F23: CANVAS | G23: cái | H23: 40 | I23: =IF('00_TONG_HOP_BAO_GIA'!G4>0, ('00_TONG_HOP_BAO_GIA'!K4 + '00_TONG_HOP_BAO_GIA'!M4) * (1 + '00_TONG_HOP_BAO_GIA'!P4) / '00_TONG_HOP_BAO_GIA'!G4, 0) | J23: =IF('00_TONG_HOP_BAO_GIA'!G4>0, '00_TONG_HOP_BAO_GIA'!L4 * (1 + '00_TONG_HOP_BAO_GIA'!P4) / '00_TONG_HOP_BAO_GIA'!G4, 0) | K23: ='00_TONG_HOP_BAO_GIA'!Q4 | L23: =('00_TONG_HOP_BAO_GIA'!K4 + '00_TONG_HOP_BAO_GIA'!M4) * (1 + '00_TONG_HOP_BAO_GIA'!P4) | M23: ='00_TONG_HOP_BAO_GIA'!L4 * (1 + '00_TONG_HOP_BAO_GIA'!P4) | N23: ='00_TONG_HOP_BAO_GIA'!R4 | O23: =IF(K23=0, "CẢNH BÁO: Đơn giá = 0. Tra cứu lại Sheet 06!", '00_TONG_HOP_BAO_GIA'!S4)
B24: Canvas loại chống cháy cho quạt TAHK | C24: D710, L=200mm | F24: CANVAS | G24: cái | H24: 16 | I24: =IF('00_TONG_HOP_BAO_GIA'!G5>0, ('00_TONG_HOP_BAO_GIA'!K5 + '00_TONG_HOP_BAO_GIA'!M5) * (1 + '00_TONG_HOP_BAO_GIA'!P5) / '00_TONG_HOP_BAO_GIA'!G5, 0) | J24: =IF('00_TONG_HOP_BAO_GIA'!G5>0, '00_TONG_HOP_BAO_GIA'!L5 * (1 + '00_TONG_HOP_BAO_GIA'!P5) / '00_TONG_HOP_BAO_GIA'!G5, 0) | K24: ='00_TONG_HOP_BAO_GIA'!Q5 | L24: =('00_TONG_HOP_BAO_GIA'!K5 + '00_TONG_HOP_BAO_GIA'!M5) * (1 + '00_TONG_HOP_BAO_GIA'!P5) | M24: ='00_TONG_HOP_BAO_GIA'!L5 * (1 + '00_TONG_HOP_BAO_GIA'!P5) | N24: ='00_TONG_HOP_BAO_GIA'!R5 | O24: =IF(K24=0, "CẢNH BÁO: Đơn giá = 0. Tra cứu lại Sheet 06!", '00_TONG_HOP_BAO_GIA'!S5)
B25: Canvas loại chống cháy cho quạt TAHK | C25: D560, L=200mm | F25: CANVAS | G25: cái | H25: 16 | I25: =IF('00_TONG_HOP_BAO_GIA'!G6>0, ('00_TONG_HOP_BAO_GIA'!K6 + '00_TONG_HOP_BAO_GIA'!M6) * (1 + '00_TONG_HOP_BAO_GIA'!P6) / '00_TONG_HOP_BAO_GIA'!G6, 0) | J25: =IF('00_TONG_HOP_BAO_GIA'!G6>0, '00_TONG_HOP_BAO_GIA'!L6 * (1 + '00_TONG_HOP_BAO_GIA'!P6) / '00_TONG_HOP_BAO_GIA'!G6, 0) | K25: ='00_TONG_HOP_BAO_GIA'!Q6 | L25: =('00_TONG_HOP_BAO_GIA'!K6 + '00_TONG_HOP_BAO_GIA'!M6) * (1 + '00_TONG_HOP_BAO_GIA'!P6) | M25: ='00_TONG_HOP_BAO_GIA'!L6 * (1 + '00_TONG_HOP_BAO_GIA'!P6) | N25: ='00_TONG_HOP_BAO_GIA'!R6 | O25: =IF(K25=0, "CẢNH BÁO: Đơn giá = 0. Tra cứu lại Sheet 06!", '00_TONG_HOP_BAO_GIA'!S6)
B26: Canvas loại thường cho quạt thông gió | C26: D1000, L=200mm | F26: CANVAS | G26: cái | H26: 32 | I26: =IF('00_TONG_HOP_BAO_GIA'!G7>0, ('00_TONG_HOP_BAO_GIA'!K7 + '00_TONG_HOP_BAO_GIA'!M7) * (1 + '00_TONG_HOP_BAO_GIA'!P7) / '00_TONG_HOP_BAO_GIA'!G7, 0) | J26: =IF('00_TONG_HOP_BAO_GIA'!G7>0, '00_TONG_HOP_BAO_GIA'!L7 * (1 + '00_TONG_HOP_BAO_GIA'!P7) / '00_TONG_HOP_BAO_GIA'!G7, 0) | K26: ='00_TONG_HOP_BAO_GIA'!Q7 | L26: =('00_TONG_HOP_BAO_GIA'!K7 + '00_TONG_HOP_BAO_GIA'!M7) * (1 + '00_TONG_HOP_BAO_GIA'!P7) | M26: ='00_TONG_HOP_BAO_GIA'!L7 * (1 + '00_TONG_HOP_BAO_GIA'!P7) | N26: ='00_TONG_HOP_BAO_GIA'!R7 | O26: =IF(K26=0, "CẢNH BÁO: Đơn giá = 0. Tra cứu lại Sheet 06!", '00_TONG_HOP_BAO_GIA'!S7)
B27: Canvas loại thường cho quạt thông gió | C27: D560, L=200mm | F27: CANVAS | G27: cái | H27: 24 | I27: =IF('00_TONG_HOP_BAO_GIA'!G8>0, ('00_TONG_HOP_BAO_GIA'!K8 + '00_TONG_HOP_BAO_GIA'!M8) * (1 + '00_TONG_HOP_BAO_GIA'!P8) / '00_TONG_HOP_BAO_GIA'!G8, 0) | J27: =IF('00_TONG_HOP_BAO_GIA'!G8>0, '00_TONG_HOP_BAO_GIA'!L8 * (1 + '00_TONG_HOP_BAO_GIA'!P8) / '00_TONG_HOP_BAO_GIA'!G8, 0) | K27: ='00_TONG_HOP_BAO_GIA'!Q8 | L27: =('00_TONG_HOP_BAO_GIA'!K8 + '00_TONG_HOP_BAO_GIA'!M8) * (1 + '00_TONG_HOP_BAO_GIA'!P8) | M27: ='00_TONG_HOP_BAO_GIA'!L8 * (1 + '00_TONG_HOP_BAO_GIA'!P8) | N27: ='00_TONG_HOP_BAO_GIA'!R8 | O27: =IF(K27=0, "CẢNH BÁO: Đơn giá = 0. Tra cứu lại Sheet 06!", '00_TONG_HOP_BAO_GIA'!S8)
A28: =SUBTOTAL(3,$G$7:G28) | B28: Tiêu âm quạt | D28: SX tại Việt Nam theo bản vẽ thiết kế | E28: Việt Nam (SX theo bản vẽ thiết kế) | F28: QUẠT | G28: Bộ | H28: 16
A29: =SUBTOTAL(3,$G$7:G29) | B29: Van 1 chiều NRD 1250x1250 (EI60) | C29: NRD | D29: NSCA, Evegreen, Swind | E29: Việt Nam / Singapore | G29: Cái | H29: 6 | I29: =IF('00_TONG_HOP_BAO_GIA'!G9>0, ('00_TONG_HOP_BAO_GIA'!K9 + '00_TONG_HOP_BAO_GIA'!M9) * (1 + '00_TONG_HOP_BAO_GIA'!P9) / '00_TONG_HOP_BAO_GIA'!G9, 0) | J29: =IF('00_TONG_HOP_BAO_GIA'!G9>0, '00_TONG_HOP_BAO_GIA'!L9 * (1 + '00_TONG_HOP_BAO_GIA'!P9) / '00_TONG_HOP_BAO_GIA'!G9, 0) | K29: ='00_TONG_HOP_BAO_GIA'!Q9 | L29: =('00_TONG_HOP_BAO_GIA'!K9 + '00_TONG_HOP_BAO_GIA'!M9) * (1 + '00_TONG_HOP_BAO_GIA'!P9) | M29: ='00_TONG_HOP_BAO_GIA'!L9 * (1 + '00_TONG_HOP_BAO_GIA'!P9) | N29: ='00_TONG_HOP_BAO_GIA'!R9 | O29: =IF(K29=0, "CẢNH BÁO: Đơn giá = 0. Tra cứu lại Sheet 06!", '00_TONG_HOP_BAO_GIA'!S9)
A30: =SUBTOTAL(3,$G$7:G30) | B30: Van 1 chiều NRD 1700x600 (EI60) | C30: NRD | D30: NSCA, Evegreen, Swind | E30: Việt Nam / Singapore | G30: Cái | H30: 2 | I30: =IF('00_TONG_HOP_BAO_GIA'!G10>0, ('00_TONG_HOP_BAO_GIA'!K10 + '00_TONG_HOP_BAO_GIA'!M10) * (1 + '00_TONG_HOP_BAO_GIA'!P10) / '00_TONG_HOP_BAO_GIA'!G10, 0) | J30: =IF('00_TONG_HOP_BAO_GIA'!G10>0, '00_TONG_HOP_BAO_GIA'!L10 * (1 + '00_TONG_HOP_BAO_GIA'!P10) / '00_TONG_HOP_BAO_GIA'!G10, 0) | K30: ='00_TONG_HOP_BAO_GIA'!Q10 | L30: =('00_TONG_HOP_BAO_GIA'!K10 + '00_TONG_HOP_BAO_GIA'!M10) * (1 + '00_TONG_HOP_BAO_GIA'!P10) | M30: ='00_TONG_HOP_BAO_GIA'!L10 * (1 + '00_TONG_HOP_BAO_GIA'!P10) | N30: ='00_TONG_HOP_BAO_GIA'!R10 | O30: =IF(K30=0, "CẢNH BÁO: Đơn giá = 0. Tra cứu lại Sheet 06!", '00_TONG_HOP_BAO_GIA'!S10)
A31: =SUBTOTAL(3,$G$7:G31) | B31: Van 1 chiều NRD 1200x350 (EI60) | C31: NRD | D31: NSCA, Evegreen, Swind | E31: Việt Nam / Singapore | G31: Cái | H31: 1 | I31: =IF('00_TONG_HOP_BAO_GIA'!G11>0, ('00_TONG_HOP_BAO_GIA'!K11 + '00_TONG_HOP_BAO_GIA'!M11) * (1 + '00_TONG_HOP_BAO_GIA'!P11) / '00_TONG_HOP_BAO_GIA'!G11, 0) | J31: =IF('00_TONG_HOP_BAO_GIA'!G11>0, '00_TONG_HOP_BAO_GIA'!L11 * (1 + '00_TONG_HOP_BAO_GIA'!P11) / '00_TONG_HOP_BAO_GIA'!G11, 0) | K31: ='00_TONG_HOP_BAO_GIA'!Q11 | L31: =('00_TONG_HOP_BAO_GIA'!K11 + '00_TONG_HOP_BAO_GIA'!M11) * (1 + '00_TONG_HOP_BAO_GIA'!P11) | M31: ='00_TONG_HOP_BAO_GIA'!L11 * (1 + '00_TONG_HOP_BAO_GIA'!P11) | N31: ='00_TONG_HOP_BAO_GIA'!R11 | O31: =IF(K31=0, "CẢNH BÁO: Đơn giá = 0. Tra cứu lại Sheet 06!", '00_TONG_HOP_BAO_GIA'!S11)
A32: =SUBTOTAL(3,$G$7:G32) | B32: Van ngăn cháy MFD 1250x1250 (EI60) | C32: MFD | D32: Van: NSCA, Evegreen, Swind, tđ ĐC: Belimo, Johnson Controls, tđ | E32: Việt Nam / Singapore | G32: Cái | H32: 6 | I32: =IF('00_TONG_HOP_BAO_GIA'!G12>0, ('00_TONG_HOP_BAO_GIA'!K12 + '00_TONG_HOP_BAO_GIA'!M12) * (1 + '00_TONG_HOP_BAO_GIA'!P12) / '00_TONG_HOP_BAO_GIA'!G12, 0) | J32: =IF('00_TONG_HOP_BAO_GIA'!G12>0, '00_TONG_HOP_BAO_GIA'!L12 * (1 + '00_TONG_HOP_BAO_GIA'!P12) / '00_TONG_HOP_BAO_GIA'!G12, 0) | K32: ='00_TONG_HOP_BAO_GIA'!Q12 | L32: =('00_TONG_HOP_BAO_GIA'!K12 + '00_TONG_HOP_BAO_GIA'!M12) * (1 + '00_TONG_HOP_BAO_GIA'!P12) | M32: ='00_TONG_HOP_BAO_GIA'!L12 * (1 + '00_TONG_HOP_BAO_GIA'!P12) | N32: ='00_TONG_HOP_BAO_GIA'!R12 | O32: =IF(K32=0, "CẢNH BÁO: Đơn giá = 0. Tra cứu lại Sheet 06!", '00_TONG_HOP_BAO_GIA'!S12)
A33: =SUBTOTAL(3,$G$7:G33) | B33: Van ngăn cháy MFD 1700x600 (EI60) | C33: MFD | D33: Van: NSCA, Evegreen, Swind, tđ ĐC: Belimo, Johnson Controls, tđ | E33: Việt Nam / Singapore | G33: Cái | H33: 2 | I33: =IF('00_TONG_HOP_BAO_GIA'!G13>0, ('00_TONG_HOP_BAO_GIA'!K13 + '00_TONG_HOP_BAO_GIA'!M13) * (1 + '00_TONG_HOP_BAO_GIA'!P13) / '00_TONG_HOP_BAO_GIA'!G13, 0) | J33: =IF('00_TONG_HOP_BAO_GIA'!G13>0, '00_TONG_HOP_BAO_GIA'!L13 * (1 + '00_TONG_HOP_BAO_GIA'!P13) / '00_TONG_HOP_BAO_GIA'!G13, 0) | K33: ='00_TONG_HOP_BAO_GIA'!Q13 | L33: =('00_TONG_HOP_BAO_GIA'!K13 + '00_TONG_HOP_BAO_GIA'!M13) * (1 + '00_TONG_HOP_BAO_GIA'!P13) | M33: ='00_TONG_HOP_BAO_GIA'!L13 * (1 + '00_TONG_HOP_BAO_GIA'!P13) | N33: ='00_TONG_HOP_BAO_GIA'!R13 | O33: =IF(K33=0, "CẢNH BÁO: Đơn giá = 0. Tra cứu lại Sheet 06!", '00_TONG_HOP_BAO_GIA'!S13)
A34: =SUBTOTAL(3,$G$7:G34) | B34: Van ngăn cháy MFD 1200x350 (EI60) | C34: MFD | D34: Van: NSCA, Evegreen, Swind, tđ ĐC: Belimo, Johnson Controls, tđ | E34: Việt Nam / Singapore | G34: Cái | H34: 1 | I34: =IF('00_TONG_HOP_BAO_GIA'!G14>0, ('00_TONG_HOP_BAO_GIA'!K14 + '00_TONG_HOP_BAO_GIA'!M14) * (1 + '00_TONG_HOP_BAO_GIA'!P14) / '00_TONG_HOP_BAO_GIA'!G14, 0) | J34: =IF('00_TONG_HOP_BAO_GIA'!G14>0, '00_TONG_HOP_BAO_GIA'!L14 * (1 + '00_TONG_HOP_BAO_GIA'!P14) / '00_TONG_HOP_BAO_GIA'!G14, 0) | K34: ='00_TONG_HOP_BAO_GIA'!Q14 | L34: =('00_TONG_HOP_BAO_GIA'!K14 + '00_TONG_HOP_BAO_GIA'!M14) * (1 + '00_TONG_HOP_BAO_GIA'!P14) | M34: ='00_TONG_HOP_BAO_GIA'!L14 * (1 + '00_TONG_HOP_BAO_GIA'!P14) | N34: ='00_TONG_HOP_BAO_GIA'!R14 | O34: =IF(K34=0, "CẢNH BÁO: Đơn giá = 0. Tra cứu lại Sheet 06!", '00_TONG_HOP_BAO_GIA'!S14)
A35: =SUBTOTAL(3,$G$7:G35) | B35: Van ngăn cháy MFD 950x400 (EI30) | C35: MFD | D35: Van: NSCA, Evegreen, Swind, tđ ĐC: Belimo, Johnson Controls, tđ | E35: Việt Nam / Singapore | G35: Cái | H35: 3 | I35: =IF('00_TONG_HOP_BAO_GIA'!G15>0, ('00_TONG_HOP_BAO_GIA'!K15 + '00_TONG_HOP_BAO_GIA'!M15) * (1 + '00_TONG_HOP_BAO_GIA'!P15) / '00_TONG_HOP_BAO_GIA'!G15, 0) | J35: =IF('00_TONG_HOP_BAO_GIA'!G15>0, '00_TONG_HOP_BAO_GIA'!L15 * (1 + '00_TONG_HOP_BAO_GIA'!P15) / '00_TONG_HOP_BAO_GIA'!G15, 0) | K35: ='00_TONG_HOP_BAO_GIA'!Q15 | L35: =('00_TONG_HOP_BAO_GIA'!K15 + '00_TONG_HOP_BAO_GIA'!M15) * (1 + '00_TONG_HOP_BAO_GIA'!P15) | M35: ='00_TONG_HOP_BAO_GIA'!L15 * (1 + '00_TONG_HOP_BAO_GIA'!P15) | N35: ='00_TONG_HOP_BAO_GIA'!R15 | O35: =IF(K35=0, "CẢNH BÁO: Đơn giá = 0. Tra cứu lại Sheet 06!", '00_TONG_HOP_BAO_GIA'!S15)
A36: =SUBTOTAL(3,$G$7:G36) | B36: Van ngăn cháy MFD 950x500 (EI30) | C36: MFD | D36: Van: NSCA, Evegreen, Swind, tđ ĐC: Belimo, Johnson Controls, tđ | E36: Việt Nam / Singapore | G36: Cái | H36: 6 | I36: =IF('00_TONG_HOP_BAO_GIA'!G16>0, ('00_TONG_HOP_BAO_GIA'!K16 + '00_TONG_HOP_BAO_GIA'!M16) * (1 + '00_TONG_HOP_BAO_GIA'!P16) / '00_TONG_HOP_BAO_GIA'!G16, 0) | J36: =IF('00_TONG_HOP_BAO_GIA'!G16>0, '00_TONG_HOP_BAO_GIA'!L16 * (1 + '00_TONG_HOP_BAO_GIA'!P16) / '00_TONG_HOP_BAO_GIA'!G16, 0) | K36: ='00_TONG_HOP_BAO_GIA'!Q16 | L36: =('00_TONG_HOP_BAO_GIA'!K16 + '00_TONG_HOP_BAO_GIA'!M16) * (1 + '00_TONG_HOP_BAO_GIA'!P16) | M36: ='00_TONG_HOP_BAO_GIA'!L16 * (1 + '00_TONG_HOP_BAO_GIA'!P16) | N36: ='00_TONG_HOP_BAO_GIA'!R16 | O36: =IF(K36=0, "CẢNH BÁO: Đơn giá = 0. Tra cứu lại Sheet 06!", '00_TONG_HOP_BAO_GIA'!S16)
A37: =SUBTOTAL(3,$G$7:G37) | B37: Van ngăn cháy MFD 950x200 (EI30) | C37: MFD | D37: Van: NSCA, Evegreen, Swind, tđ ĐC: Belimo, Johnson Controls, tđ | E37: Việt Nam / Singapore | G37: Cái | H37: 9 | I37: =IF('00_TONG_HOP_BAO_GIA'!G17>0, ('00_TONG_HOP_BAO_GIA'!K17 + '00_TONG_HOP_BAO_GIA'!M17) * (1 + '00_TONG_HOP_BAO_GIA'!P17) / '00_TONG_HOP_BAO_GIA'!G17, 0) | J37: =IF('00_TONG_HOP_BAO_GIA'!G17>0, '00_TONG_HOP_BAO_GIA'!L17 * (1 + '00_TONG_HOP_BAO_GIA'!P17) / '00_TONG_HOP_BAO_GIA'!G17, 0) | K37: ='00_TONG_HOP_BAO_GIA'!Q17 | L37: =('00_TONG_HOP_BAO_GIA'!K17 + '00_TONG_HOP_BAO_GIA'!M17) * (1 + '00_TONG_HOP_BAO_GIA'!P17) | M37: ='00_TONG_HOP_BAO_GIA'!L17 * (1 + '00_TONG_HOP_BAO_GIA'!P17) | N37: ='00_TONG_HOP_BAO_GIA'!R17 | O37: =IF(K37=0, "CẢNH BÁO: Đơn giá = 0. Tra cứu lại Sheet 06!", '00_TONG_HOP_BAO_GIA'!S17)
A38: =SUBTOTAL(3,$G$7:G38) | B38: Van ngăn cháy MFD 950x300 (EI30) | C38: MFD | D38: Van: NSCA, Evegreen, Swind, tđ ĐC: Belimo, Johnson Controls, tđ | E38: Việt Nam / Singapore | G38: Cái | H38: 12 | I38: =IF('00_TONG_HOP_BAO_GIA'!G18>0, ('00_TONG_HOP_BAO_GIA'!K18 + '00_TONG_HOP_BAO_GIA'!M18) * (1 + '00_TONG_HOP_BAO_GIA'!P18) / '00_TONG_HOP_BAO_GIA'!G18, 0) | J38: =IF('00_TONG_HOP_BAO_GIA'!G18>0, '00_TONG_HOP_BAO_GIA'!L18 * (1 + '00_TONG_HOP_BAO_GIA'!P18) / '00_TONG_HOP_BAO_GIA'!G18, 0) | K38: ='00_TONG_HOP_BAO_GIA'!Q18 | L38: =('00_TONG_HOP_BAO_GIA'!K18 + '00_TONG_HOP_BAO_GIA'!M18) * (1 + '00_TONG_HOP_BAO_GIA'!P18) | M38: ='00_TONG_HOP_BAO_GIA'!L18 * (1 + '00_TONG_HOP_BAO_GIA'!P18) | N38: ='00_TONG_HOP_BAO_GIA'!R18 | O38: =IF(K38=0, "CẢNH BÁO: Đơn giá = 0. Tra cứu lại Sheet 06!", '00_TONG_HOP_BAO_GIA'!S18)
A39: =SUBTOTAL(3,$G$7:G39) | B39: Van chỉnh lưu lượng VCD 2000x500 (EI60) | C39: VCD | D39: NSCA, Evegreen, Swind | E39: Việt Nam / Singapore | G39: Cái | H39: 1 | I39: =IF('00_TONG_HOP_BAO_GIA'!G19>0, ('00_TONG_HOP_BAO_GIA'!K19 + '00_TONG_HOP_BAO_GIA'!M19) * (1 + '00_TONG_HOP_BAO_GIA'!P19) / '00_TONG_HOP_BAO_GIA'!G19, 0) | J39: =IF('00_TONG_HOP_BAO_GIA'!G19>0, '00_TONG_HOP_BAO_GIA'!L19 * (1 + '00_TONG_HOP_BAO_GIA'!P19) / '00_TONG_HOP_BAO_GIA'!G19, 0) | K39: ='00_TONG_HOP_BAO_GIA'!Q19 | L39: =('00_TONG_HOP_BAO_GIA'!K19 + '00_TONG_HOP_BAO_GIA'!M19) * (1 + '00_TONG_HOP_BAO_GIA'!P19) | M39: ='00_TONG_HOP_BAO_GIA'!L19 * (1 + '00_TONG_HOP_BAO_GIA'!P19) | N39: ='00_TONG_HOP_BAO_GIA'!R19 | O39: =IF(K39=0, "CẢNH BÁO: Đơn giá = 0. Tra cứu lại Sheet 06!", '00_TONG_HOP_BAO_GIA'!S19)
A40: =SUBTOTAL(3,$G$7:G40) | B40: Van chỉnh lưu lượng VCD 1300x400 (EI60) | C40: VCD | D40: NSCA, Evegreen, Swind | E40: Việt Nam / Singapore | G40: Cái | H40: 2 | I40: =IF('00_TONG_HOP_BAO_GIA'!G20>0, ('00_TONG_HOP_BAO_GIA'!K20 + '00_TONG_HOP_BAO_GIA'!M20) * (1 + '00_TONG_HOP_BAO_GIA'!P20) / '00_TONG_HOP_BAO_GIA'!G20, 0) | J40: =IF('00_TONG_HOP_BAO_GIA'!G20>0, '00_TONG_HOP_BAO_GIA'!L20 * (1 + '00_TONG_HOP_BAO_GIA'!P20) / '00_TONG_HOP_BAO_GIA'!G20, 0) | K40: ='00_TONG_HOP_BAO_GIA'!Q20 | L40: =('00_TONG_HOP_BAO_GIA'!K20 + '00_TONG_HOP_BAO_GIA'!M20) * (1 + '00_TONG_HOP_BAO_GIA'!P20) | M40: ='00_TONG_HOP_BAO_GIA'!L20 * (1 + '00_TONG_HOP_BAO_GIA'!P20) | N40: ='00_TONG_HOP_BAO_GIA'!R20 | O40: =IF(K40=0, "CẢNH BÁO: Đơn giá = 0. Tra cứu lại Sheet 06!", '00_TONG_HOP_BAO_GIA'!S20)
... A52: =SUBTOTAL(3,$G$7:G52) | B52: Louver EAL 2750x750+IS | C52: EAL | D52: NSCA, Evegreen, Swind | E52: Việt Nam (SX theo bản vẽ thiết kế) | G52: Cái | H52: 2 | I52: =IF('00_TONG_HOP_BAO_GIA'!G32>0, ('00_TONG_HOP_BAO_GIA'!K32 + '00_TONG_HOP_BAO_GIA'!M32) * (1 + '00_TONG_HOP_BAO_GIA'!P32) / '00_TONG_HOP_BAO_GIA'!G32, 0) | J52: =IF('00_TONG_HOP_BAO_GIA'!G32>0, '00_TONG_HOP_BAO_GIA'!L32 * (1 + '00_TONG_HOP_BAO_GIA'!P32) / '00_TONG_HOP_BAO_GIA'!G32, 0) | K52: ='00_TONG_HOP_BAO_GIA'!Q32 | L52: =('00_TONG_HOP_BAO_GIA'!K32 + '00_TONG_HOP_BAO_GIA'!M32) * (1 + '00_TONG_HOP_BAO_GIA'!P32) | M52: ='00_TONG_HOP_BAO_GIA'!L32 * (1 + '00_TONG_HOP_BAO_GIA'!P32) | N52: ='00_TONG_HOP_BAO_GIA'!R32 | O52: =IF(K52=0, "CẢNH BÁO: Đơn giá = 0. Tra cứu lại Sheet 06!", '00_TONG_HOP_BAO_GIA'!S32)
...

Sheet 00_TONG_HOP_BAO_GIA
A1: STT | B1: ITEM_ID | C1: PHÂN NHÓM | D1: TÊN SẢN PHẨM | E1: QUY CÁCH (WxH) | F1: ĐVT | G1: SỐ LƯỢNG | H1: CP VẬT TƯ ỐNG | I1: CP VẬT TƯ CỬA | J1: CP VẬT TƯ VAN | K1: TỔNG CP VẬT TƯ | L1: NHÂN CÔNG (25%) | M1: CP XƯỞNG (10%) | N1: TỔNG GIÁ VỐN | O1: GIÁ VỐN / ĐVT | P1: MARGIN (%) | Q1: ĐƠN GIÁ BÁN | R1: THÀNH TIỀN (VNĐ) | S1: GHI CHÚ
A2: 1 | B2: SW-CV-001 | C2: KHỚP NỐI MỀM | D2: HỆ THỐNG HÚT KHÓI HẦM XE, HÚT KHÓI SỰ CỐ Canvas loại chống cháy cho quạt TAHK | E2: D1000 | F2: cái | G2: 15 | H2: =SUMIF('01_BOC_TACH_ONG'!B:B, B2, '01_BOC_TACH_ONG'!K:K) | I2: =SUMIF('02_BOC_TACH_CUA'!B:B, B2, '02_BOC_TACH_CUA'!K:K) | J2: =SUMIF('03_BOC_TACH_VAN'!B:B, B2, '03_BOC_TACH_VAN'!K:K) | K2: =SUM(H2:J2) | L2: =(K2-SUMIFS('03_BOC_TACH_VAN'!K:K, '03_BOC_TACH_VAN'!B:B, B2, '03_BOC_TACH_VAN'!D:D, "ĐỘNG_CƠ_VÀ_CẢM_BIẾN"))*0.25 | M2: =(K2-SUMIFS('03_BOC_TACH_VAN'!K:K, '03_BOC_TACH_VAN'!B:B, B2, '03_BOC_TACH_VAN'!D:D, "ĐỘNG_CƠ_VÀ_CẢM_BIẾN"))*0.10 | N2: =K2+L2+M2 | O2: =IF(G2>0, N2/G2, 0) | P2: 0.18 | Q2: =IF(G2>0, ((N2-SUMIFS('03_BOC_TACH_VAN'!K:K, '03_BOC_TACH_VAN'!B:B, B2, '03_BOC_TACH_VAN'!D:D, "ĐỘNG_CƠ_VÀ_CẢM_BIẾN"))*(1+P2)+SUMIFS('03_BOC_TACH_VAN'!K:K, '03_BOC_TACH_VAN'!B:B, B2, '03_BOC_TACH_VAN'!D:D, "ĐỘNG_CƠ_VÀ_CẢM_BIẾN"))/G2, 0) | R2: =G2*Q2
A3: 2 | B3: SW-CV-002 | C3: KHỚP NỐI MỀM | D3: HỆ THỐNG HÚT KHÓI HẦM XE, HÚT KHÓI SỰ CỐ Canvas loại chống cháy cho quạt TAHK | E3: D900 | F3: cái | G3: 40 | H3: =SUMIF('01_BOC_TACH_ONG'!B:B, B3, '01_BOC_TACH_ONG'!K:K) | I3: =SUMIF('02_BOC_TACH_CUA'!B:B, B3, '02_BOC_TACH_CUA'!K:K) | J3: =SUMIF('03_BOC_TACH_VAN'!B:B, B3, '03_BOC_TACH_VAN'!K:K) | K3: =SUM(H3:J3) | L3: =(K3-SUMIFS('03_BOC_TACH_VAN'!K:K, '03_BOC_TACH_VAN'!B:B, B3, '03_BOC_TACH_VAN'!D:D, "ĐỘNG_CƠ_VÀ_CẢM_BIẾN"))*0.25 | M3: =(K3-SUMIFS('03_BOC_TACH_VAN'!K:K, '03_BOC_TACH_VAN'!B:B, B3, '03_BOC_TACH_VAN'!D:D, "ĐỘNG_CƠ_VÀ_CẢM_BIẾN"))*0.10 | N3: =K3+L3+M3 | O3: =IF(G3>0, N3/G3, 0) | P3: 0.18 | Q3: =IF(G3>0, ((N3-SUMIFS('03_BOC_TACH_VAN'!K:K, '03_BOC_TACH_VAN'!B:B, B3, '03_BOC_TACH_VAN'!D:D, "ĐỘNG_CƠ_VÀ_CẢM_BIẾN"))*(1+P3)+SUMIFS('03_BOC_TACH_VAN'!K:K, '03_BOC_TACH_VAN'!B:B, B3, '03_BOC_TACH_VAN'!D:D, "ĐỘNG_CƠ_VÀ_CẢM_BIẾN"))/G3, 0) | R3: =G3*Q3
A4: 3 | B4: SW-CV-003 | C4: KHỚP NỐI MỀM | D4: HỆ THỐNG HÚT KHÓI HẦM XE, HÚT KHÓI SỰ CỐ Canvas loại chống cháy cho quạt TAHK | E4: D800 | F4: cái | G4: 40 | H4: =SUMIF('01_BOC_TACH_ONG'!B:B, B4, '01_BOC_TACH_ONG'!K:K) | I4: =SUMIF('02_BOC_TACH_CUA'!B:B, B4, '02_BOC_TACH_CUA'!K:K) | J4: =SUMIF('03_BOC_TACH_VAN'!B:B, B4, '03_BOC_TACH_VAN'!K:K) | K4: =SUM(H4:J4) | L4: =(K4-SUMIFS('03_BOC_TACH_VAN'!K:K, '03_BOC_TACH_VAN'!B:B, B4, '03_BOC_TACH_VAN'!D:D, "ĐỘNG_CƠ_VÀ_CẢM_BIẾN"))*0.25 | M4: =(K4-SUMIFS('03_BOC_TACH_VAN'!K:K, '03_BOC_TACH_VAN'!B:B, B4, '03_BOC_TACH_VAN'!D:D, "ĐỘNG_CƠ_VÀ_CẢM_BIẾN"))*0.10 | N4: =K4+L4+M4 | O4: =IF(G4>0, N4/G4, 0) | P4: 0.18 | Q4: =IF(G4>0, ((N4-SUMIFS('03_BOC_TACH_VAN'!K:K, '03_BOC_TACH_VAN'!B:B, B4, '03_BOC_TACH_VAN'!D:D, "ĐỘNG_CƠ_VÀ_CẢM_BIẾN"))*(1+P4)+SUMIFS('03_BOC_TACH_VAN'!K:K, '03_BOC_TACH_VAN'!B:B, B4, '03_BOC_TACH_VAN'!D:D, "ĐỘNG_CƠ_VÀ_CẢM_BIẾN"))/G4, 0) | R4: =G4*Q4
A5: 4 | B5: SW-CV-004 | C5: KHỚP NỐI MỀM | D5: HỆ THỐNG HÚT KHÓI HẦM XE, HÚT KHÓI SỰ CỐ Canvas loại chống cháy cho quạt TAHK | E5: D710 | F5: cái | G5: 16 | H5: =SUMIF('01_BOC_TACH_ONG'!B:B, B5, '01_BOC_TACH_ONG'!K:K) | I5: =SUMIF('02_BOC_TACH_CUA'!B:B, B5, '02_BOC_TACH_CUA'!K:K) | J5: =SUMIF('03_BOC_TACH_VAN'!B:B, B5, '03_BOC_TACH_VAN'!K:K) | K5: =SUM(H5:J5) | L5: =(K5-SUMIFS('03_BOC_TACH_VAN'!K:K, '03_BOC_TACH_VAN'!B:B, B5, '03_BOC_TACH_VAN'!D:D, "ĐỘNG_CƠ_VÀ_CẢM_BIẾN"))*0.25 | M5: =(K5-SUMIFS('03_BOC_TACH_VAN'!K:K, '03_BOC_TACH_VAN'!B:B, B5, '03_BOC_TACH_VAN'!D:D, "ĐỘNG_CƠ_VÀ_CẢM_BIẾN"))*0.10 | N5: =K5+L5+M5 | O5: =IF(G5>0, N5/G5, 0) | P5: 0.18 | Q5: =IF(G5>0, ((N5-SUMIFS('03_BOC_TACH_VAN'!K:K, '03_BOC_TACH_VAN'!B:B, B5, '03_BOC_TACH_VAN'!D:D, "ĐỘNG_CƠ_VÀ_CẢM_BIẾN"))*(1+P5)+SUMIFS('03_BOC_TACH_VAN'!K:K, '03_BOC_TACH_VAN'!B:B, B5, '03_BOC_TACH_VAN'!D:D, "ĐỘNG_CƠ_VÀ_CẢM_BIẾN"))/G5, 0) | R5: =G5*Q5
A6: 5 | B6: SW-CV-005 | C6: KHỚP NỐI MỀM | D6: HỆ THỐNG HÚT KHÓI HẦM XE, HÚT KHÓI SỰ CỐ Canvas loại chống cháy cho quạt TAHK | E6: D560 | F6: cái | G6: 16 | H6: =SUMIF('01_BOC_TACH_ONG'!B:B, B6, '01_BOC_TACH_ONG'!K:K) | I6: =SUMIF('02_BOC_TACH_CUA'!B:B, B6, '02_BOC_TACH_CUA'!K:K) | J6: =SUMIF('03_BOC_TACH_VAN'!B:B, B6, '03_BOC_TACH_VAN'!K:K) | K6: =SUM(H6:J6) | L6: =(K6-SUMIFS('03_BOC_TACH_VAN'!K:K, '03_BOC_TACH_VAN'!B:B, B6, '03_BOC_TACH_VAN'!D:D, "ĐỘNG_CƠ_VÀ_CẢM_BIẾN"))*0.25 | M6: =(K6-SUMIFS('03_BOC_TACH_VAN'!K:K, '03_BOC_TACH_VAN'!B:B, B6, '03_BOC_TACH_VAN'!D:D, "ĐỘNG_CƠ_VÀ_CẢM_BIẾN"))*0.10 | N6: =K6+L6+M6 | O6: =IF(G6>0, N6/G6, 0) | P6: 0.18 | Q6: =IF(G6>0, ((N6-SUMIFS('03_BOC_TACH_VAN'!K:K, '03_BOC_TACH_VAN'!B:B, B6, '03_BOC_TACH_VAN'!D:D, "ĐỘNG_CƠ_VÀ_CẢM_BIẾN"))*(1+P6)+SUMIFS('03_BOC_TACH_VAN'!K:K, '03_BOC_TACH_VAN'!B:B, B6, '03_BOC_TACH_VAN'!D:D, "ĐỘNG_CƠ_VÀ_CẢM_BIẾN"))/G6, 0) | R6: =G6*Q6
A7: 6 | B7: SW-CV-006 | C7: KHỚP NỐI MỀM | D7: HỆ THỐNG HÚT KHÓI HẦM XE, HÚT KHÓI SỰ CỐ Canvas loại thường cho quạt thông gió | E7: D1000 | F7: cái | G7: 32 | H7: =SUMIF('01_BOC_TACH_ONG'!B:B, B7, '01_BOC_TACH_ONG'!K:K) | I7: =SUMIF('02_BOC_TACH_CUA'!B:B, B7, '02_BOC_TACH_CUA'!K:K) | J7: =SUMIF('03_BOC_TACH_VAN'!B:B, B7, '03_BOC_TACH_VAN'!K:K) | K7: =SUM(H7:J7) | L7: =(K7-SUMIFS('03_BOC_TACH_VAN'!K:K, '03_BOC_TACH_VAN'!B:B, B7, '03_BOC_TACH_VAN'!D:D, "ĐỘNG_CƠ_VÀ_CẢM_BIẾN"))*0.25 | M7: =(K7-SUMIFS('03_BOC_TACH_VAN'!K:K, '03_BOC_TACH_VAN'!B:B, B7, '03_BOC_TACH_VAN'!D:D, "ĐỘNG_CƠ_VÀ_CẢM_BIẾN"))*0.10 | N7: =K7+L7+M7 | O7: =IF(G7>0, N7/G7, 0) | P7: 0.18 | Q7: =IF(G7>0, ((N7-SUMIFS('03_BOC_TACH_VAN'!K:K, '03_BOC_TACH_VAN'!B:B, B7, '03_BOC_TACH_VAN'!D:D, "ĐỘNG_CƠ_VÀ_CẢM_BIẾN"))*(1+P7)+SUMIFS('03_BOC_TACH_VAN'!K:K, '03_BOC_TACH_VAN'!B:B, B7, '03_BOC_TACH_VAN'!D:D, "ĐỘNG_CƠ_VÀ_CẢM_BIẾN"))/G7, 0) | R7: =G7*Q7
A8: 7 | B8: SW-CV-007 | C8: KHỚP NỐI MỀM | D8: HỆ THỐNG HÚT KHÓI HẦM XE, HÚT KHÓI SỰ CỐ Canvas loại thường cho quạt thông gió | E8: D560 | F8: cái | G8: 24 | H8: =SUMIF('01_BOC_TACH_ONG'!B:B, B8, '01_BOC_TACH_ONG'!K:K) | I8: =SUMIF('02_BOC_TACH_CUA'!B:B, B8, '02_BOC_TACH_CUA'!K:K) | J8: =SUMIF('03_BOC_TACH_VAN'!B:B, B8, '03_BOC_TACH_VAN'!K:K) | K8: =SUM(H8:J8) | L8: =(K8-SUMIFS('03_BOC_TACH_VAN'!K:K, '03_BOC_TACH_VAN'!B:B, B8, '03_BOC_TACH_VAN'!D:D, "ĐỘNG_CƠ_VÀ_CẢM_BIẾN"))*0.25 | M8: =(K8-SUMIFS('03_BOC_TACH_VAN'!K:K, '03_BOC_TACH_VAN'!B:B, B8, '03_BOC_TACH_VAN'!D:D, "ĐỘNG_CƠ_VÀ_CẢM_BIẾN"))*0.10 | N8: =K8+L8+M8 | O8: =IF(G8>0, N8/G8, 0) | P8: 0.18 | Q8: =IF(G8>0, ((N8-SUMIFS('03_BOC_TACH_VAN'!K:K, '03_BOC_TACH_VAN'!B:B, B8, '03_BOC_TACH_VAN'!D:D, "ĐỘNG_CƠ_VÀ_CẢM_BIẾN"))*(1+P8)+SUMIFS('03_BOC_TACH_VAN'!K:K, '03_BOC_TACH_VAN'!B:B, B8, '03_BOC_TACH_VAN'!D:D, "ĐỘNG_CƠ_VÀ_CẢM_BIẾN"))/G8, 0) | R8: =G8*Q8
A9: 8 | B9: SW-DAMPER-008 | C9: VAN GIÓ | D9: HỆ THỐNG HÚT KHÓI HẦM XE, HÚT KHÓI SỰ CỐ Van 1 chiều NRD 1250x1250 (EI60) | E9: 1250x1250 | F9: Cái | G9: 6 | H9: =SUMIF('01_BOC_TACH_ONG'!B:B, B9, '01_BOC_TACH_ONG'!K:K) | I9: =SUMIF('02_BOC_TACH_CUA'!B:B, B9, '02_BOC_TACH_CUA'!K:K) | J9: =SUMIF('03_BOC_TACH_VAN'!B:B, B9, '03_BOC_TACH_VAN'!K:K) | K9: =SUM(H9:J9) | L9: =(K9-SUMIFS('03_BOC_TACH_VAN'!K:K, '03_BOC_TACH_VAN'!B:B, B9, '03_BOC_TACH_VAN'!D:D, "ĐỘNG_CƠ_VÀ_CẢM_BIẾN"))*0.25 | M9: =(K9-SUMIFS('03_BOC_TACH_VAN'!K:K, '03_BOC_TACH_VAN'!B:B, B9, '03_BOC_TACH_VAN'!D:D, "ĐỘNG_CƠ_VÀ_CẢM_BIẾN"))*0.10 | N9: =K9+L9+M9 | O9: =IF(G9>0, N9/G9, 0) | P9: 0.18 | Q9: =IF(G9>0, ((N9-SUMIFS('03_BOC_TACH_VAN'!K:K, '03_BOC_TACH_VAN'!B:B, B9, '03_BOC_TACH_VAN'!D:D, "ĐỘNG_CƠ_VÀ_CẢM_BIẾN"))*(1+P9)+SUMIFS('03_BOC_TACH_VAN'!K:K, '03_BOC_TACH_VAN'!B:B, B9, '03_BOC_TACH_VAN'!D:D, "ĐỘNG_CƠ_VÀ_CẢM_BIẾN"))/G9, 0) | R9: =G9*Q9
A10: 9 | B10: SW-DAMPER-009 | C10: VAN GIÓ | D10: HỆ THỐNG HÚT KHÓI HẦM XE, HÚT KHÓI SỰ CỐ Van 1 chiều NRD 1700x600 (EI60) | E10: 1700x600 | F10: Cái | G10: 2 | H10: =SUMIF('01_BOC_TACH_ONG'!B:B, B10, '01_BOC_TACH_ONG'!K:K) | I10: =SUMIF('02_BOC_TACH_CUA'!B:B, B10, '02_BOC_TACH_CUA'!K:K) | J10: =SUMIF('03_BOC_TACH_VAN'!B:B, B10, '03_BOC_TACH_VAN'!K:K) | K10: =SUM(H10:J10) | L10: =(K10-SUMIFS('03_BOC_TACH_VAN'!K:K, '03_BOC_TACH_VAN'!B:B, B10, '03_BOC_TACH_VAN'!D:D, "ĐỘNG_CƠ_VÀ_CẢM_BIẾN"))*0.25 | M10: =(K10-SUMIFS('03_BOC_TACH_VAN'!K:K, '03_BOC_TACH_VAN'!B:B, B10, '03_BOC_TACH_VAN'!D:D, "ĐỘNG_CƠ_VÀ_CẢM_BIẾN"))*0.10 | N10: =K10+L10+M10 | O10: =IF(G10>0, N10/G10, 0) | P10: 0.18 | Q10: =IF(G10>0, ((N10-SUMIFS('03_BOC_TACH_VAN'!K:K, '03_BOC_TACH_VAN'!B:B, B10, '03_BOC_TACH_VAN'!D:D, "ĐỘNG_CƠ_VÀ_CẢM_BIẾN"))*(1+P10)+SUMIFS('03_BOC_TACH_VAN'!K:K, '03_BOC_TACH_VAN'!B:B, B10, '03_BOC_TACH_VAN'!D:D, "ĐỘNG_CƠ_VÀ_CẢM_BIẾN"))/G10, 0) | R10: =G10*Q10
A11: 10 | B11: SW-DAMPER-010 | C11: VAN GIÓ | D11: HỆ THỐNG HÚT KHÓI HẦM XE, HÚT KHÓI SỰ CỐ Van 1 chiều NRD 1200x350 (EI60) | E11: 1200x350 | F11: Cái | G11: 1 | H11: =SUMIF('01_BOC_TACH_ONG'!B:B, B11, '01_BOC_TACH_ONG'!K:K) | I11: =SUMIF('02_BOC_TACH_CUA'!B:B, B11, '02_BOC_TACH_CUA'!K:K) | J11: =SUMIF('03_BOC_TACH_VAN'!B:B, B11, '03_BOC_TACH_VAN'!K:K) | K11: =SUM(H11:J11) | L11: =(K11-SUMIFS('03_BOC_TACH_VAN'!K:K, '03_BOC_TACH_VAN'!B:B, B11, '03_BOC_TACH_VAN'!D:D, "ĐỘNG_CƠ_VÀ_CẢM_BIẾN"))*0.25 | M11: =(K11-SUMIFS('03_BOC_TACH_VAN'!K:K, '03_BOC_TACH_VAN'!B:B, B11, '03_BOC_TACH_VAN'!D:D, "ĐỘNG_CƠ_VÀ_CẢM_BIẾN"))*0.10 | N11: =K11+L11+M11 | O11: =IF(G11>0, N11/G11, 0) | P11: 0.18 | Q11: =IF(G11>0, ((N11-SUMIFS('03_BOC_TACH_VAN'!K:K, '03_BOC_TACH_VAN'!B:B, B11, '03_BOC_TACH_VAN'!D:D, "ĐỘNG_CƠ_VÀ_CẢM_BIẾN"))*(1+P11)+SUMIFS('03_BOC_TACH_VAN'!K:K, '03_BOC_TACH_VAN'!B:B, B11, '03_BOC_TACH_VAN'!D:D, "ĐỘNG_CƠ_VÀ_CẢM_BIẾN"))/G11, 0) | R11: =G11*Q11
A12: 11 | B12: SW-DAMPER-011 | C12: VAN GIÓ | D12: HỆ THỐNG HÚT KHÓI HẦM XE, HÚT KHÓI SỰ CỐ Van ngăn cháy MFD 1250x1250 (EI60) | E12: 1250x1250 | F12: Cái | G12: 6 | H12: =SUMIF('01_BOC_TACH_ONG'!B:B, B12, '01_BOC_TACH_ONG'!K:K) | I12: =SUMIF('02_BOC_TACH_CUA'!B:B, B12, '02_BOC_TACH_CUA'!K:K) | J12: =SUMIF('03_BOC_TACH_VAN'!B:B, B12, '03_BOC_TACH_VAN'!K:K) | K12: =SUM(H12:J12) | L12: =(K12-SUMIFS('03_BOC_TACH_VAN'!K:K, '03_BOC_TACH_VAN'!B:B, B12, '03_BOC_TACH_VAN'!D:D, "ĐỘNG_CƠ_VÀ_CẢM_BIẾN"))*0.25 | M12: =(K12-SUMIFS('03_BOC_TACH_VAN'!K:K, '03_BOC_TACH_VAN'!B:B, B12, '03_BOC_TACH_VAN'!D:D, "ĐỘNG_CƠ_VÀ_CẢM_BIẾN"))*0.10 | N12: =K12+L12+M12 | O12: =IF(G12>0, N12/G12, 0) | P12: 0.18 | Q12: =IF(G12>0, ((N12-SUMIFS('03_BOC_TACH_VAN'!K:K, '03_BOC_TACH_VAN'!B:B, B12, '03_BOC_TACH_VAN'!D:D, "ĐỘNG_CƠ_VÀ_CẢM_BIẾN"))*(1+P12)+SUMIFS('03_BOC_TACH_VAN'!K:K, '03_BOC_TACH_VAN'!B:B, B12, '03_BOC_TACH_VAN'!D:D, "ĐỘNG_CƠ_VÀ_CẢM_BIẾN"))/G12, 0) | R12: =G12*Q12
A13: 12 | B13: SW-DAMPER-012 | C13: VAN GIÓ | D13: HỆ THỐNG HÚT KHÓI HẦM XE, HÚT KHÓI SỰ CỐ Van ngăn cháy MFD 1700x600 (EI60) | E13: 1700x600 | F13: Cái | G13: 2 | H13: =SUMIF('01_BOC_TACH_ONG'!B:B, B13, '01_BOC_TACH_ONG'!K:K) | I13: =SUMIF('02_BOC_TACH_CUA'!B:B, B13, '02_BOC_TACH_CUA'!K:K) | J13: =SUMIF('03_BOC_TACH_VAN'!B:B, B13, '03_BOC_TACH_VAN'!K:K) | K13: =SUM(H13:J13) | L13: =(K13-SUMIFS('03_BOC_TACH_VAN'!K:K, '03_BOC_TACH_VAN'!B:B, B13, '03_BOC_TACH_VAN'!D:D, "ĐỘNG_CƠ_VÀ_CẢM_BIẾN"))*0.25 | M13: =(K13-SUMIFS('03_BOC_TACH_VAN'!K:K, '03_BOC_TACH_VAN'!B:B, B13, '03_BOC_TACH_VAN'!D:D, "ĐỘNG_CƠ_VÀ_CẢM_BIẾN"))*0.10 | N13: =K13+L13+M13 | O13: =IF(G13>0, N13/G13, 0) | P13: 0.18 | Q13: =IF(G13>0, ((N13-SUMIFS('03_BOC_TACH_VAN'!K:K, '03_BOC_TACH_VAN'!B:B, B13, '03_BOC_TACH_VAN'!D:D, "ĐỘNG_CƠ_VÀ_CẢM_BIẾN"))*(1+P13)+SUMIFS('03_BOC_TACH_VAN'!K:K, '03_BOC_TACH_VAN'!B:B, B13, '03_BOC_TACH_VAN'!D:D, "ĐỘNG_CƠ_VÀ_CẢM_BIẾN"))/G13, 0) | R13: =G13*Q13
... A35: 34 | B35: SW-DUCT-034 | C35: ỐNG GIÓ | D35: HỆ THỐNG HÚT KHÓI HẦM XE, HÚT KHÓI SỰ CỐ Box miệng gió 10006300 | E35: 1000x300 | F35: Cái | G35: 52 | H35: =SUMIF('01_BOC_TACH_ONG'!B:B, B35, '01_BOC_TACH_ONG'!K:K) | I35: =SUMIF('02_BOC_TACH_CUA'!B:B, B35, '02_BOC_TACH_CUA'!K:K) | J35: =SUMIF('03_BOC_TACH_VAN'!B:B, B35, '03_BOC_TACH_VAN'!K:K) | K35: =SUM(H35:J35) | L35: =(K35-SUMIFS('03_BOC_TACH_VAN'!K:K, '03_BOC_TACH_VAN'!B:B, B35, '03_BOC_TACH_VAN'!D:D, "ĐỘNG_CƠ_VÀ_CẢM_BIẾN"))*0.25 | M35: =(K35-SUMIFS('03_BOC_TACH_VAN'!K:K, '03_BOC_TACH_VAN'!B:B, B35, '03_BOC_TACH_VAN'!D:D, "ĐỘNG_CƠ_VÀ_CẢM_BIẾN"))*0.10 | N35: =K35+L35+M35 | O35: =IF(G35>0, N35/G35, 0) | P35: 0.18 | Q35: =IF(G35>0, ((N35-SUMIFS('03_BOC_TACH_VAN'!K:K, '03_BOC_TACH_VAN'!B:B, B35, '03_BOC_TACH_VAN'!D:D, "ĐỘNG_CƠ_VÀ_CẢM_BIẾN"))*(1+P35)+SUMIFS('03_BOC_TACH_VAN'!K:K, '03_BOC_TACH_VAN'!B:B, B35, '03_BOC_TACH_VAN'!D:D, "ĐỘNG_CƠ_VÀ_CẢM_BIẾN"))/G35, 0) | R35: =G35*Q35
A36: 35 | B36: SW-TRD-035 | C36: THƯƠNG MẠI | D36: HỆ THỐNG HÚT KHÓI HẦM XE, HÚT KHÓI SỰ CỐ Vật tư phụ, phụ kiện | E36: - | F36: Lô | G36: 1 | H36: =SUMIF('01_BOC_TACH_ONG'!B:B, B36, '01_BOC_TACH_ONG'!K:K) | I36: =SUMIF('02_BOC_TACH_CUA'!B:B, B36, '02_BOC_TACH_CUA'!K:K) | J36: =SUMIF('03_BOC_TACH_VAN'!B:B, B36, '03_BOC_TACH_VAN'!K:K) | K36: =SUM(H36:J36) | L36: =(K36-SUMIFS('03_BOC_TACH_VAN'!K:K, '03_BOC_TACH_VAN'!B:B, B36, '03_BOC_TACH_VAN'!D:D, "ĐỘNG_CƠ_VÀ_CẢM_BIẾN"))*0.00 | M36: =(K36-SUMIFS('03_BOC_TACH_VAN'!K:K, '03_BOC_TACH_VAN'!B:B, B36, '03_BOC_TACH_VAN'!D:D, "ĐỘNG_CƠ_VÀ_CẢM_BIẾN"))*0.02 | N36: =K36+L36+M36 | O36: =IF(G36>0, N36/G36, 0) | P36: 0.1 | Q36: =IF(G36>0, ((N36-SUMIFS('03_BOC_TACH_VAN'!K:K, '03_BOC_TACH_VAN'!B:B, B36, '03_BOC_TACH_VAN'!D:D, "ĐỘNG_CƠ_VÀ_CẢM_BIẾN"))*(1+P36)+SUMIFS('03_BOC_TACH_VAN'!K:K, '03_BOC_TACH_VAN'!B:B, B36, '03_BOC_TACH_VAN'!D:D, "ĐỘNG_CƠ_VÀ_CẢM_BIẾN"))/G36, 0) | R36: =G36*Q36 | S36: Hàng thương mại
A37: 36 | B37: SW-DUCT-036 | C37: ỐNG GIÓ | D37: Ống thông gió và phụ kiện, box miệng gió Tole 0.75mm phủ lớp mạ kẽm Z180 | E37: 0.75mm | F37: m2 | G37: 2633.4 | H37: =SUMIF('01_BOC_TACH_ONG'!B:B, B37, '01_BOC_TACH_ONG'!K:K) | I37: =SUMIF('02_BOC_TACH_CUA'!B:B, B37, '02_BOC_TACH_CUA'!K:K) | J37: =SUMIF('03_BOC_TACH_VAN'!B:B, B37, '03_BOC_TACH_VAN'!K:K) | K37: =SUM(H37:J37) | L37: =(K37-SUMIFS('03_BOC_TACH_VAN'!K:K, '03_BOC_TACH_VAN'!B:B, B37, '03_BOC_TACH_VAN'!D:D, "ĐỘNG_CƠ_VÀ_CẢM_BIẾN"))*0.25 | M37: =(K37-SUMIFS('03_BOC_TACH_VAN'!K:K, '03_BOC_TACH_VAN'!B:B, B37, '03_BOC_TACH_VAN'!D:D, "ĐỘNG_CƠ_VÀ_CẢM_BIẾN"))*0.10 | N37: =K37+L37+M37 | O37: =IF(G37>0, N37/G37, 0) | P37: 0.18 | Q37: =IF(G37>0, ((N37-SUMIFS('03_BOC_TACH_VAN'!K:K, '03_BOC_TACH_VAN'!B:B, B37, '03_BOC_TACH_VAN'!D:D, "ĐỘNG_CƠ_VÀ_CẢM_BIẾN"))*(1+P37)+SUMIFS('03_BOC_TACH_VAN'!K:K, '03_BOC_TACH_VAN'!B:B, B37, '03_BOC_TACH_VAN'!D:D, "ĐỘNG_CƠ_VÀ_CẢM_BIẾN"))/G37, 0) | R37: =G37*Q37
A38: 37 | B38: SW-DUCT-037 | C38: ỐNG GIÓ | D38: Ống thông gió và phụ kiện, box miệng gió Tole 0.95mm phủ lớp mạ kẽm Z180 | E38: 0.95mm | F38: m2 | G38: 1291.1 | H38: =SUMIF('01_BOC_TACH_ONG'!B:B, B38, '01_BOC_TACH_ONG'!K:K) | I38: =SUMIF('02_BOC_TACH_CUA'!B:B, B38, '02_BOC_TACH_CUA'!K:K) | J38: =SUMIF('03_BOC_TACH_VAN'!B:B, B38, '03_BOC_TACH_VAN'!K:K) | K38: =SUM(H38:J38) | L38: =(K38-SUMIFS('03_BOC_TACH_VAN'!K:K, '03_BOC_TACH_VAN'!B:B, B38, '03_BOC_TACH_VAN'!D:D, "ĐỘNG_CƠ_VÀ_CẢM_BIẾN"))*0.25 | M38: =(K38-SUMIFS('03_BOC_TACH_VAN'!K:K, '03_BOC_TACH_VAN'!B:B, B38, '03_BOC_TACH_VAN'!D:D, "ĐỘNG_CƠ_VÀ_CẢM_BIẾN"))*0.10 | N38: =K38+L38+M38 | O38: =IF(G38>0, N38/G38, 0) | P38: 0.18 | Q38: =IF(G38>0, ((N38-SUMIFS('03_BOC_TACH_VAN'!K:K, '03_BOC_TACH_VAN'!B:B, B38, '03_BOC_TACH_VAN'!D:D, "ĐỘNG_CƠ_VÀ_CẢM_BIẾN"))*(1+P38)+SUMIFS('03_BOC_TACH_VAN'!K:K, '03_BOC_TACH_VAN'!B:B, B38, '03_BOC_TACH_VAN'!D:D, "ĐỘNG_CƠ_VÀ_CẢM_BIẾN"))/G38, 0) | R38: =G38*Q38
A39: 38 | B39: SW-DUCT-038 | C39: ỐNG GIÓ | D39: Ống thông gió và phụ kiện, box miệng gió Tole 1.15mm phủ lớp mạ kẽm Z180 | E39: 1.15mm | F39: m2 | G39: 3070.55 | H39: =SUMIF('01_BOC_TACH_ONG'!B:B, B39, '01_BOC_TACH_ONG'!K:K) | I39: =SUMIF('02_BOC_TACH_CUA'!B:B, B39, '02_BOC_TACH_CUA'!K:K) | J39: =SUMIF('03_BOC_TACH_VAN'!B:B, B39, '03_BOC_TACH_VAN'!K:K) | K39: =SUM(H39:J39) | L39: =(K39-SUMIFS('03_BOC_TACH_VAN'!K:K, '03_BOC_TACH_VAN'!B:B, B39, '03_BOC_TACH_VAN'!D:D, "ĐỘNG_CƠ_VÀ_CẢM_BIẾN"))*0.25 | M39: =(K39-SUMIFS('03_BOC_TACH_VAN'!K:K, '03_BOC_TACH_VAN'!B:B, B39, '03_BOC_TACH_VAN'!D:D, "ĐỘNG_CƠ_VÀ_CẢM_BIẾN"))*0.10 | N39: =K39+L39+M39 | O39: =IF(G39>0, N39/G39, 0) | P39: 0.18 | Q39: =IF(G39>0, ((N39-SUMIFS('03_BOC_TACH_VAN'!K:K, '03_BOC_TACH_VAN'!B:B, B39, '03_BOC_TACH_VAN'!D:D, "ĐỘNG_CƠ_VÀ_CẢM_BIẾN"))*(1+P39)+SUMIFS('03_BOC_TACH_VAN'!K:K, '03_BOC_TACH_VAN'!B:B, B39, '03_BOC_TACH_VAN'!D:D, "ĐỘNG_CƠ_VÀ_CẢM_BIẾN"))/G39, 0) | R39: =G39*Q39
A40: 39 | B40: SW-DUCT-039 | C40: ỐNG GIÓ | D40: Ống thông gió và phụ kiện, box miệng gió Tole ZAM 1.15mm | E40: 1.15mm | F40: m2 | G40: 138 | H40: =SUMIF('01_BOC_TACH_ONG'!B:B, B40, '01_BOC_TACH_ONG'!K:K) | I40: =SUMIF('02_BOC_TACH_CUA'!B:B, B40, '02_BOC_TACH_CUA'!K:K) | J40: =SUMIF('03_BOC_TACH_VAN'!B:B, B40, '03_BOC_TACH_VAN'!K:K) | K40: =SUM(H40:J40) | L40: =(K40-SUMIFS('03_BOC_TACH_VAN'!K:K, '03_BOC_TACH_VAN'!B:B, B40, '03_BOC_TACH_VAN'!D:D, "ĐỘNG_CƠ_VÀ_CẢM_BIẾN"))*0.25 | M40: =(K40-SUMIFS('03_BOC_TACH_VAN'!K:K, '03_BOC_TACH_VAN'!B:B, B40, '03_BOC_TACH_VAN'!D:D, "ĐỘNG_CƠ_VÀ_CẢM_BIẾN"))*0.10 | N40: =K40+L40+M40 | O40: =IF(G40>0, N40/G40, 0) | P40: 0.18 | Q40: =IF(G40>0, ((N40-SUMIFS('03_BOC_TACH_VAN'!K:K, '03_BOC_TACH_VAN'!B:B, B40, '03_BOC_TACH_VAN'!D:D, "ĐỘNG_CƠ_VÀ_CẢM_BIẾN"))*(1+P40)+SUMIFS('03_BOC_TACH_VAN'!K:K, '03_BOC_TACH_VAN'!B:B, B40, '03_BOC_TACH_VAN'!D:D, "ĐỘNG_CƠ_VÀ_CẢM_BIẾN"))/G40, 0) | R40: =G40*Q40
A41: 40 | B41: SW-TRD-040 | C41: THƯƠNG MẠI | D41: Ống thông gió và phụ kiện, box miệng gió Lưới bảo vệ | E41: - | F41: cái | G41: 3 | H41: =SUMIF('01_BOC_TACH_ONG'!B:B, B41, '01_BOC_TACH_ONG'!K:K) | I41: =SUMIF('02_BOC_TACH_CUA'!B:B, B41, '02_BOC_TACH_CUA'!K:K) | J41: =SUMIF('03_BOC_TACH_VAN'!B:B, B41, '03_BOC_TACH_VAN'!K:K) | K41: =SUM(H41:J41) | L41: =(K41-SUMIFS('03_BOC_TACH_VAN'!K:K, '03_BOC_TACH_VAN'!B:B, B41, '03_BOC_TACH_VAN'!D:D, "ĐỘNG_CƠ_VÀ_CẢM_BIẾN"))*0.00 | M41: =(K41-SUMIFS('03_BOC_TACH_VAN'!K:K, '03_BOC_TACH_VAN'!B:B, B41, '03_BOC_TACH_VAN'!D:D, "ĐỘNG_CƠ_VÀ_CẢM_BIẾN"))*0.02 | N41: =K41+L41+M41 | O41: =IF(G41>0, N41/G41, 0) | P41: 0.1 | Q41: =IF(G41>0, ((N41-SUMIFS('03_BOC_TACH_VAN'!K:K, '03_BOC_TACH_VAN'!B:B, B41, '03_BOC_TACH_VAN'!D:D, "ĐỘNG_CƠ_VÀ_CẢM_BIẾN"))*(1+P41)+SUMIFS('03_BOC_TACH_VAN'!K:K, '03_BOC_TACH_VAN'!B:B, B41, '03_BOC_TACH_VAN'!D:D, "ĐỘNG_CƠ_VÀ_CẢM_BIẾN"))/G41, 0) | R41: =G41*Q41 | S41: Hàng thương mại
A42: 41 | B42: SW-TRD-041 | C42: THƯƠNG MẠI | D42: Ống thông gió và phụ kiện, box miệng gió Lớp chống cháy EI30 | E42: - | F42: m2 | G42: 3621.25 | H42: =SUMIF('01_BOC_TACH_ONG'!B:B, B42, '01_BOC_TACH_ONG'!K:K) | I42: =SUMIF('02_BOC_TACH_CUA'!B:B, B42, '02_BOC_TACH_CUA'!K:K) | J42: =SUMIF('03_BOC_TACH_VAN'!B:B, B42, '03_BOC_TACH_VAN'!K:K) | K42: =SUM(H42:J42) | L42: =(K42-SUMIFS('03_BOC_TACH_VAN'!K:K, '03_BOC_TACH_VAN'!B:B, B42, '03_BOC_TACH_VAN'!D:D, "ĐỘNG_CƠ_VÀ_CẢM_BIẾN"))*0.00 | M42: =(K42-SUMIFS('03_BOC_TACH_VAN'!K:K, '03_BOC_TACH_VAN'!B:B, B42, '03_BOC_TACH_VAN'!D:D, "ĐỘNG_CƠ_VÀ_CẢM_BIẾN"))*0.02 | N42: =K42+L42+M42 | O42: =IF(G42>0, N42/G42, 0) | P42: 0.1 | Q42: =IF(G42>0, ((N42-SUMIFS('03_BOC_TACH_VAN'!K:K, '03_BOC_TACH_VAN'!B:B, B42, '03_BOC_TACH_VAN'!D:D, "ĐỘNG_CƠ_VÀ_CẢM_BIẾN"))*(1+P42)+SUMIFS('03_BOC_TACH_VAN'!K:K, '03_BOC_TACH_VAN'!B:B, B42, '03_BOC_TACH_VAN'!D:D, "ĐỘNG_CƠ_VÀ_CẢM_BIẾN"))/G42, 0) | R42: =G42*Q42 | S42: Hàng thương mại
A43: 42 | B43: SW-TRD-042 | C43: THƯƠNG MẠI | D43: Ống thông gió và phụ kiện, box miệng gió Lớp chống cháy EI60 | E43: - | F43: m2 | G43: 2821 | H43: =SUMIF('01_BOC_TACH_ONG'!B:B, B43, '01_BOC_TACH_ONG'!K:K) | I43: =SUMIF('02_BOC_TACH_CUA'!B:B, B43, '02_BOC_TACH_CUA'!K:K) | J43: =SUMIF('03_BOC_TACH_VAN'!B:B, B43, '03_BOC_TACH_VAN'!K:K) | K43: =SUM(H43:J43) | L43: =(K43-SUMIFS('03_BOC_TACH_VAN'!K:K, '03_BOC_TACH_VAN'!B:B, B43, '03_BOC_TACH_VAN'!D:D, "ĐỘNG_CƠ_VÀ_CẢM_BIẾN"))*0.00 | M43: =(K43-SUMIFS('03_BOC_TACH_VAN'!K:K, '03_BOC_TACH_VAN'!B:B, B43, '03_BOC_TACH_VAN'!D:D, "ĐỘNG_CƠ_VÀ_CẢM_BIẾN"))*0.02 | N43: =K43+L43+M43 | O43: =IF(G43>0, N43/G43, 0) | P43: 0.1 | Q43: =IF(G43>0, ((N43-SUMIFS('03_BOC_TACH_VAN'!K:K, '03_BOC_TACH_VAN'!B:B, B43, '03_BOC_TACH_VAN'!D:D, "ĐỘNG_CƠ_VÀ_CẢM_BIẾN"))*(1+P43)+SUMIFS('03_BOC_TACH_VAN'!K:K, '03_BOC_TACH_VAN'!B:B, B43, '03_BOC_TACH_VAN'!D:D, "ĐỘNG_CƠ_VÀ_CẢM_BIẾN"))/G43, 0) | R43: =G43*Q43 | S43: Hàng thương mại
A44: 43 | B44: SW-TRD-043 | C44: THƯƠNG MẠI | D44: Ống thông gió và phụ kiện, box miệng gió Vật tư phụ, phụ kiện | E44: - | F44: Lô | G44: 1 | H44: =SUMIF('01_BOC_TACH_ONG'!B:B, B44, '01_BOC_TACH_ONG'!K:K) | I44: =SUMIF('02_BOC_TACH_CUA'!B:B, B44, '02_BOC_TACH_CUA'!K:K) | J44: =SUMIF('03_BOC_TACH_VAN'!B:B, B44, '03_BOC_TACH_VAN'!K:K) | K44: =SUM(H44:J44) | L44: =(K44-SUMIFS('03_BOC_TACH_VAN'!K:K, '03_BOC_TACH_VAN'!B:B, B44, '03_BOC_TACH_VAN'!D:D, "ĐỘNG_CƠ_VÀ_CẢM_BIẾN"))*0.00 | M44: =(K44-SUMIFS('03_BOC_TACH_VAN'!K:K, '03_BOC_TACH_VAN'!B:B, B44, '03_BOC_TACH_VAN'!D:D, "ĐỘNG_CƠ_VÀ_CẢM_BIẾN"))*0.02 | N44: =K44+L44+M44 | O44: =IF(G44>0, N44/G44, 0) | P44: 0.1 | Q44: =IF(G44>0, ((N44-SUMIFS('03_BOC_TACH_VAN'!K:K, '03_BOC_TACH_VAN'!B:B, B44, '03_BOC_TACH_VAN'!D:D, "ĐỘNG_CƠ_VÀ_CẢM_BIẾN"))*(1+P44)+SUMIFS('03_BOC_TACH_VAN'!K:K, '03_BOC_TACH_VAN'!B:B, B44, '03_BOC_TACH_VAN'!D:D, "ĐỘNG_CƠ_VÀ_CẢM_BIẾN"))/G44, 0) | R44: =G44*Q44 | S44: Hàng thương mại
A45: 44 | B45: SW-DAMPER-044 | C45: VAN GIÓ | D45: HỆ THỐNG TẠO ÁP Van 1 chiều NRD 300x200 (EI60) | E45: 300x200 | F45: Cái | G45: 1 | H45: =SUMIF('01_BOC_TACH_ONG'!B:B, B45, '01_BOC_TACH_ONG'!K:K) | I45: =SUMIF('02_BOC_TACH_CUA'!B:B, B45, '02_BOC_TACH_CUA'!K:K) | J45: =SUMIF('03_BOC_TACH_VAN'!B:B, B45, '03_BOC_TACH_VAN'!K:K) | K45: =SUM(H45:J45) | L45: =(K45-SUMIFS('03_BOC_TACH_VAN'!K:K, '03_BOC_TACH_VAN'!B:B, B45, '03_BOC_TACH_VAN'!D:D, "ĐỘNG_CƠ_VÀ_CẢM_BIẾN"))*0.25 | M45: =(K45-SUMIFS('03_BOC_TACH_VAN'!K:K, '03_BOC_TACH_VAN'!B:B, B45, '03_BOC_TACH_VAN'!D:D, "ĐỘNG_CƠ_VÀ_CẢM_BIẾN"))*0.10 | N45: =K45+L45+M45 | O45: =IF(G45>0, N45/G45, 0) | P45: 0.18 | Q45: =IF(G45>0, ((N45-SUMIFS('03_BOC_TACH_VAN'!K:K, '03_BOC_TACH_VAN'!B:B, B45, '03_BOC_TACH_VAN'!D:D, "ĐỘNG_CƠ_VÀ_CẢM_BIẾN"))*(1+P45)+SUMIFS('03_BOC_TACH_VAN'!K:K, '03_BOC_TACH_VAN'!B:B, B45, '03_BOC_TACH_VAN'!D:D, "ĐỘNG_CƠ_VÀ_CẢM_BIẾN"))/G45, 0) | R45: =G45*Q45
