Workbook
Name \a: #N/A
Name \N: #REF!
Name \s: #N/A
Name \Z: #REF!
Name _: #REF!
Name _??: NA()
Name _??_1: NA()
Name _??_1_1: NA()
Name _??_1_2: NA()
Name _??_1_3: NA()
Name _??_1_4: NA()
Name _??_1_5: NA()
Name _??_6: NA()
Name _??_7: NA()
Name _??_9: NA()
Name _?1: NA()
Name _?1_1: NA()
Name _?1_1_1: NA()
Name _?1_1_2: NA()
Name _?1_1_3: NA()
Name _?1_1_4: NA()
Name _?1_1_5: NA()
Name _?1_6: NA()
Name _?1_7: NA()
Name _?1_9: NA()
Name _?271: NA()
Name _?271_1: NA()
Name _?271_1_1: NA()
Name _?271_1_2: NA()
Name _?271_1_3: NA()
Name _?271_1_4: NA()
Name _?271_1_5: NA()
Name _?271_6: NA()
Name _?271_7: NA()
Name _?271_9: NA()
Name ____DIV3: #REF!
Name ____DIV4: #REF!
Name ___DIV10: #REF!
Name ___DIV15: #REF!
Name ___DIV3: #REF!
Name ___DIV4: #REF!
Name ___DIV5: #REF!
Name ___DIV7: #REF!
Name ___DIV8: #REF!
Name ___DIV9: #REF!
Name ___TB1: #REF!
Name __10: #REF!
Name __12: #REF!
Name __14: #REF!
Name __16: #REF!
Name __18: #REF!
Name __20: #REF!
Name __22: #REF!
Name __24: #REF!
Name __26: #REF!
Name __28: #REF!
Name __30: #REF!
Name __32: #REF!
Name __34: #REF!
Name __36: #REF!

Sheet 00_BANG_CHAO_GIA
A1: BILL: HỆ THỐNG ĐHKK & THÔNG GIÓ
A3: STT | B3: MÔ TẢ CÔNG TÁC | C3: MÃ HIỆU | D3: NHÃN HIỆU | E3: XUẤT XỨ | F3: LỌC | G3: Đơn vị | H3: Khối lượng | I3: ĐƠN GIÁ | L3: THÀNH TIỀN | O3: GHI CHÚ
I4: VẬT TƯ | J4: NHÂN CÔNG | K4: TỔNG | L4: VẬT TƯ | M4: NHÂN CÔNG | N4: TỔNG
A5: A | B5: HỆ THỐNG THÔNG GIÓ | F5: M
A6: A1 | B6: HỆ THỐNG HÚT KHÓI HẦM XE, HÚT KHÓI SỰ CỐ | F6: M
A7: =SUBTOTAL(3,$G7:G$7) | B7: Quạt hướng trục CEF-B2-Z1-01~02 5290/9430 l/s @ 500/1350 Pa, chống cháy 300°C trong 2h, | C7: CEF | D7: Fantech (ELTA Fans), Systemair, Wolter, Kruger | F7: QUẠT | G7: Cái | H7: 2 | I7: =IF('00_TONG_HOP_BAO_GIA'!G2>0, ('00_TONG_HOP_BAO_GIA'!K2 + '00_TONG_HOP_BAO_GIA'!M2) * (1 + '00_TONG_HOP_BAO_GIA'!P2) / '00_TONG_HOP_BAO_GIA'!G2, 0) | J7: =IF('00_TONG_HOP_BAO_GIA'!G2>0, '00_TONG_HOP_BAO_GIA'!L2 * (1 + '00_TONG_HOP_BAO_GIA'!P2) / '00_TONG_HOP_BAO_GIA'!G2, 0) | K7: ='00_TONG_HOP_BAO_GIA'!Q2 | L7: =('00_TONG_HOP_BAO_GIA'!K2 + '00_TONG_HOP_BAO_GIA'!M2) * (1 + '00_TONG_HOP_BAO_GIA'!P2) | M7: ='00_TONG_HOP_BAO_GIA'!L2 * (1 + '00_TONG_HOP_BAO_GIA'!P2) | N7: ='00_TONG_HOP_BAO_GIA'!R2 | O7: =IF(K7=0, "CẢNH BÁO: Đơn giá = 0. Tra cứu lại Sheet 06!", '00_TONG_HOP_BAO_GIA'!S2)
A8: =SUBTOTAL(3,$G$7:G8) | B8: Quạt hướng trục CEF-B2-Z2-01~02 5490/8910 l/s @ 600/1350 Pa, chống cháy 300°C trong 2h | C8: CEF | D8: Fantech (ELTA Fans), Systemair, Wolter, Kruger | F8: QUẠT | G8: Cái | H8: 2 | I8: =IF('00_TONG_HOP_BAO_GIA'!G3>0, ('00_TONG_HOP_BAO_GIA'!K3 + '00_TONG_HOP_BAO_GIA'!M3) * (1 + '00_TONG_HOP_BAO_GIA'!P3) / '00_TONG_HOP_BAO_GIA'!G3, 0) | J8: =IF('00_TONG_HOP_BAO_GIA'!G3>0, '00_TONG_HOP_BAO_GIA'!L3 * (1 + '00_TONG_HOP_BAO_GIA'!P3) / '00_TONG_HOP_BAO_GIA'!G3, 0) | K8: ='00_TONG_HOP_BAO_GIA'!Q3 | L8: =('00_TONG_HOP_BAO_GIA'!K3 + '00_TONG_HOP_BAO_GIA'!M3) * (1 + '00_TONG_HOP_BAO_GIA'!P3) | M8: ='00_TONG_HOP_BAO_GIA'!L3 * (1 + '00_TONG_HOP_BAO_GIA'!P3) | N8: ='00_TONG_HOP_BAO_GIA'!R3 | O8: =IF(K8=0, "CẢNH BÁO: Đơn giá = 0. Tra cứu lại Sheet 06!", '00_TONG_HOP_BAO_GIA'!S3)
A9: =SUBTOTAL(3,$G$7:G9) | B9: Quạt hướng trục CEF-B1-Z1-01~02 5590/8385 l/s @ 600/1350 Pa, chống cháy 300°C trong 2h | C9: CEF | D9: Fantech (ELTA Fans), Systemair, Wolter, Kruger | F9: QUẠT | G9: Cái | H9: 2 | I9: =IF('00_TONG_HOP_BAO_GIA'!G4>0, ('00_TONG_HOP_BAO_GIA'!K4 + '00_TONG_HOP_BAO_GIA'!M4) * (1 + '00_TONG_HOP_BAO_GIA'!P4) / '00_TONG_HOP_BAO_GIA'!G4, 0) | J9: =IF('00_TONG_HOP_BAO_GIA'!G4>0, '00_TONG_HOP_BAO_GIA'!L4 * (1 + '00_TONG_HOP_BAO_GIA'!P4) / '00_TONG_HOP_BAO_GIA'!G4, 0) | K9: ='00_TONG_HOP_BAO_GIA'!Q4 | L9: =('00_TONG_HOP_BAO_GIA'!K4 + '00_TONG_HOP_BAO_GIA'!M4) * (1 + '00_TONG_HOP_BAO_GIA'!P4) | M9: ='00_TONG_HOP_BAO_GIA'!L4 * (1 + '00_TONG_HOP_BAO_GIA'!P4) | N9: ='00_TONG_HOP_BAO_GIA'!R4 | O9: =IF(K9=0, "CẢNH BÁO: Đơn giá = 0. Tra cứu lại Sheet 06!", '00_TONG_HOP_BAO_GIA'!S4)
A10: =SUBTOTAL(3,$G$7:G10) | B10: Quạt hướng trục CEF-B1-Z2-01~02 5135/7700 l/s @ 600/1350 Pa, chống cháy 300°C trong 2h | C10: CEF | D10: Fantech (ELTA Fans), Systemair, Wolter, Kruger | F10: QUẠT | G10: Cái | H10: 2 | I10: =IF('00_TONG_HOP_BAO_GIA'!G5>0, ('00_TONG_HOP_BAO_GIA'!K5 + '00_TONG_HOP_BAO_GIA'!M5) * (1 + '00_TONG_HOP_BAO_GIA'!P5) / '00_TONG_HOP_BAO_GIA'!G5, 0) | J10: =IF('00_TONG_HOP_BAO_GIA'!G5>0, '00_TONG_HOP_BAO_GIA'!L5 * (1 + '00_TONG_HOP_BAO_GIA'!P5) / '00_TONG_HOP_BAO_GIA'!G5, 0) | K10: ='00_TONG_HOP_BAO_GIA'!Q5 | L10: =('00_TONG_HOP_BAO_GIA'!K5 + '00_TONG_HOP_BAO_GIA'!M5) * (1 + '00_TONG_HOP_BAO_GIA'!P5) | M10: ='00_TONG_HOP_BAO_GIA'!L5 * (1 + '00_TONG_HOP_BAO_GIA'!P5) | N10: ='00_TONG_HOP_BAO_GIA'!R5 | O10: =IF(K10=0, "CẢNH BÁO: Đơn giá = 0. Tra cứu lại Sheet 06!", '00_TONG_HOP_BAO_GIA'!S5)
A11: =SUBTOTAL(3,$G$7:G11) | B11: Quạt hướng trục SEF-B1-Z2-01 4800 l/s @ 500 Pa, chống cháy 300°C trong 2h | C11: SEF | D11: Fantech (ELTA Fans), Systemair, Wolter, Kruger | F11: QUẠT | G11: Cái | H11: 1 | I11: =IF('00_TONG_HOP_BAO_GIA'!G6>0, ('00_TONG_HOP_BAO_GIA'!K6 + '00_TONG_HOP_BAO_GIA'!M6) * (1 + '00_TONG_HOP_BAO_GIA'!P6) / '00_TONG_HOP_BAO_GIA'!G6, 0) | J11: =IF('00_TONG_HOP_BAO_GIA'!G6>0, '00_TONG_HOP_BAO_GIA'!L6 * (1 + '00_TONG_HOP_BAO_GIA'!P6) / '00_TONG_HOP_BAO_GIA'!G6, 0) | K11: ='00_TONG_HOP_BAO_GIA'!Q6 | L11: =('00_TONG_HOP_BAO_GIA'!K6 + '00_TONG_HOP_BAO_GIA'!M6) * (1 + '00_TONG_HOP_BAO_GIA'!P6) | M11: ='00_TONG_HOP_BAO_GIA'!L6 * (1 + '00_TONG_HOP_BAO_GIA'!P6) | N11: ='00_TONG_HOP_BAO_GIA'!R6 | O11: =IF(K11=0, "CẢNH BÁO: Đơn giá = 0. Tra cứu lại Sheet 06!", '00_TONG_HOP_BAO_GIA'!S6)
A12: =SUBTOTAL(3,$G$7:G12) | B12: Quạt hướng trục SEF-A1.1-03F-01~02 7400 l/s @ 400 Pa, chống cháy 300°C trong 2h | C12: SEF | D12: Fantech (ELTA Fans), Systemair, Wolter, Kruger | F12: QUẠT | G12: Cái | H12: 2 | I12: =IF('00_TONG_HOP_BAO_GIA'!G7>0, ('00_TONG_HOP_BAO_GIA'!K7 + '00_TONG_HOP_BAO_GIA'!M7) * (1 + '00_TONG_HOP_BAO_GIA'!P7) / '00_TONG_HOP_BAO_GIA'!G7, 0) | J12: =IF('00_TONG_HOP_BAO_GIA'!G7>0, '00_TONG_HOP_BAO_GIA'!L7 * (1 + '00_TONG_HOP_BAO_GIA'!P7) / '00_TONG_HOP_BAO_GIA'!G7, 0) | K12: ='00_TONG_HOP_BAO_GIA'!Q7 | L12: =('00_TONG_HOP_BAO_GIA'!K7 + '00_TONG_HOP_BAO_GIA'!M7) * (1 + '00_TONG_HOP_BAO_GIA'!P7) | M12: ='00_TONG_HOP_BAO_GIA'!L7 * (1 + '00_TONG_HOP_BAO_GIA'!P7) | N12: ='00_TONG_HOP_BAO_GIA'!R7 | O12: =IF(K12=0, "CẢNH BÁO: Đơn giá = 0. Tra cứu lại Sheet 06!", '00_TONG_HOP_BAO_GIA'!S7)
A13: =SUBTOTAL(3,$G$7:G13) | B13: Quạt hướng trục SEF-A1.2-03F-01~02 6700 l/s @ 500 Pa, chống cháy 300°C trong 2h | C13: SEF | D13: Fantech (ELTA Fans), Systemair, Wolter, Kruger | F13: QUẠT | G13: Cái | H13: 2 | I13: =IF('00_TONG_HOP_BAO_GIA'!G8>0, ('00_TONG_HOP_BAO_GIA'!K8 + '00_TONG_HOP_BAO_GIA'!M8) * (1 + '00_TONG_HOP_BAO_GIA'!P8) / '00_TONG_HOP_BAO_GIA'!G8, 0) | J13: =IF('00_TONG_HOP_BAO_GIA'!G8>0, '00_TONG_HOP_BAO_GIA'!L8 * (1 + '00_TONG_HOP_BAO_GIA'!P8) / '00_TONG_HOP_BAO_GIA'!G8, 0) | K13: ='00_TONG_HOP_BAO_GIA'!Q8 | L13: =('00_TONG_HOP_BAO_GIA'!K8 + '00_TONG_HOP_BAO_GIA'!M8) * (1 + '00_TONG_HOP_BAO_GIA'!P8) | M13: ='00_TONG_HOP_BAO_GIA'!L8 * (1 + '00_TONG_HOP_BAO_GIA'!P8) | N13: ='00_TONG_HOP_BAO_GIA'!R8 | O13: =IF(K13=0, "CẢNH BÁO: Đơn giá = 0. Tra cứu lại Sheet 06!", '00_TONG_HOP_BAO_GIA'!S8)
A14: =SUBTOTAL(3,$G$7:G14) | B14: Quạt hướng trục SEF-A1.2-03F-03 5100 l/s @ 500 Pa, chống cháy 300°C trong 2h | C14: SEF | D14: Fantech (ELTA Fans), Systemair, Wolter, Kruger | F14: QUẠT | G14: Cái | H14: 1 | I14: =IF('00_TONG_HOP_BAO_GIA'!G9>0, ('00_TONG_HOP_BAO_GIA'!K9 + '00_TONG_HOP_BAO_GIA'!M9) * (1 + '00_TONG_HOP_BAO_GIA'!P9) / '00_TONG_HOP_BAO_GIA'!G9, 0) | J14: =IF('00_TONG_HOP_BAO_GIA'!G9>0, '00_TONG_HOP_BAO_GIA'!L9 * (1 + '00_TONG_HOP_BAO_GIA'!P9) / '00_TONG_HOP_BAO_GIA'!G9, 0) | K14: ='00_TONG_HOP_BAO_GIA'!Q9 | L14: =('00_TONG_HOP_BAO_GIA'!K9 + '00_TONG_HOP_BAO_GIA'!M9) * (1 + '00_TONG_HOP_BAO_GIA'!P9) | M14: ='00_TONG_HOP_BAO_GIA'!L9 * (1 + '00_TONG_HOP_BAO_GIA'!P9) | N14: ='00_TONG_HOP_BAO_GIA'!R9 | O14: =IF(K14=0, "CẢNH BÁO: Đơn giá = 0. Tra cứu lại Sheet 06!", '00_TONG_HOP_BAO_GIA'!S9)
A15: =SUBTOTAL(3,$G$7:G15) | B15: Quạt hướng trục SEF-A1.3-03F-01~03 4800 l/s @ 500 Pa, chống cháy 300°C trong 2h | C15: SEF | D15: Fantech (ELTA Fans), Systemair, Wolter, Kruger | F15: QUẠT | G15: Cái | H15: 3 | I15: =IF('00_TONG_HOP_BAO_GIA'!G10>0, ('00_TONG_HOP_BAO_GIA'!K10 + '00_TONG_HOP_BAO_GIA'!M10) * (1 + '00_TONG_HOP_BAO_GIA'!P10) / '00_TONG_HOP_BAO_GIA'!G10, 0) | J15: =IF('00_TONG_HOP_BAO_GIA'!G10>0, '00_TONG_HOP_BAO_GIA'!L10 * (1 + '00_TONG_HOP_BAO_GIA'!P10) / '00_TONG_HOP_BAO_GIA'!G10, 0) | K15: ='00_TONG_HOP_BAO_GIA'!Q10 | L15: =('00_TONG_HOP_BAO_GIA'!K10 + '00_TONG_HOP_BAO_GIA'!M10) * (1 + '00_TONG_HOP_BAO_GIA'!P10) | M15: ='00_TONG_HOP_BAO_GIA'!L10 * (1 + '00_TONG_HOP_BAO_GIA'!P10) | N15: ='00_TONG_HOP_BAO_GIA'!R10 | O15: =IF(K15=0, "CẢNH BÁO: Đơn giá = 0. Tra cứu lại Sheet 06!", '00_TONG_HOP_BAO_GIA'!S10)
A16: =SUBTOTAL(3,$G$7:G16) | B16: Quạt hướng trục SEF-A1.3-03F-04 4800 l/s @ 450 Pa, chống cháy 300°C trong 2h | C16: SEF | D16: Fantech (ELTA Fans), Systemair, Wolter, Kruger | F16: QUẠT | G16: Cái | H16: 1 | I16: =IF('00_TONG_HOP_BAO_GIA'!G11>0, ('00_TONG_HOP_BAO_GIA'!K11 + '00_TONG_HOP_BAO_GIA'!M11) * (1 + '00_TONG_HOP_BAO_GIA'!P11) / '00_TONG_HOP_BAO_GIA'!G11, 0) | J16: =IF('00_TONG_HOP_BAO_GIA'!G11>0, '00_TONG_HOP_BAO_GIA'!L11 * (1 + '00_TONG_HOP_BAO_GIA'!P11) / '00_TONG_HOP_BAO_GIA'!G11, 0) | K16: ='00_TONG_HOP_BAO_GIA'!Q11 | L16: =('00_TONG_HOP_BAO_GIA'!K11 + '00_TONG_HOP_BAO_GIA'!M11) * (1 + '00_TONG_HOP_BAO_GIA'!P11) | M16: ='00_TONG_HOP_BAO_GIA'!L11 * (1 + '00_TONG_HOP_BAO_GIA'!P11) | N16: ='00_TONG_HOP_BAO_GIA'!R11 | O16: =IF(K16=0, "CẢNH BÁO: Đơn giá = 0. Tra cứu lại Sheet 06!", '00_TONG_HOP_BAO_GIA'!S11)
A17: =SUBTOTAL(3,$G$7:G17) | B17: Quạt hướng trục SEF-A1.3-03F-05~07 4800 l/s @ 500 Pa, chống cháy 300°C trong 2h | C17: SEF | D17: Fantech (ELTA Fans), Systemair, Wolter, Kruger | F17: QUẠT | G17: Cái | H17: 3 | I17: =IF('00_TONG_HOP_BAO_GIA'!G12>0, ('00_TONG_HOP_BAO_GIA'!K12 + '00_TONG_HOP_BAO_GIA'!M12) * (1 + '00_TONG_HOP_BAO_GIA'!P12) / '00_TONG_HOP_BAO_GIA'!G12, 0) | J17: =IF('00_TONG_HOP_BAO_GIA'!G12>0, '00_TONG_HOP_BAO_GIA'!L12 * (1 + '00_TONG_HOP_BAO_GIA'!P12) / '00_TONG_HOP_BAO_GIA'!G12, 0) | K17: ='00_TONG_HOP_BAO_GIA'!Q12 | L17: =('00_TONG_HOP_BAO_GIA'!K12 + '00_TONG_HOP_BAO_GIA'!M12) * (1 + '00_TONG_HOP_BAO_GIA'!P12) | M17: ='00_TONG_HOP_BAO_GIA'!L12 * (1 + '00_TONG_HOP_BAO_GIA'!P12) | N17: ='00_TONG_HOP_BAO_GIA'!R12 | O17: =IF(K17=0, "CẢNH BÁO: Đơn giá = 0. Tra cứu lại Sheet 06!", '00_TONG_HOP_BAO_GIA'!S12)
A18: =SUBTOTAL(3,$G$7:G18) | B18: Quạt hướng trục SEF-A1.3-10F-01 7100 l/s @ 600 Pa, chống cháy 300°C trong 2h | C18: SEF | D18: Fantech (ELTA Fans), Systemair, Wolter, Kruger | F18: QUẠT | G18: Cái | H18: 1 | I18: =IF('00_TONG_HOP_BAO_GIA'!G13>0, ('00_TONG_HOP_BAO_GIA'!K13 + '00_TONG_HOP_BAO_GIA'!M13) * (1 + '00_TONG_HOP_BAO_GIA'!P13) / '00_TONG_HOP_BAO_GIA'!G13, 0) | J18: =IF('00_TONG_HOP_BAO_GIA'!G13>0, '00_TONG_HOP_BAO_GIA'!L13 * (1 + '00_TONG_HOP_BAO_GIA'!P13) / '00_TONG_HOP_BAO_GIA'!G13, 0) | K18: ='00_TONG_HOP_BAO_GIA'!Q13 | L18: =('00_TONG_HOP_BAO_GIA'!K13 + '00_TONG_HOP_BAO_GIA'!M13) * (1 + '00_TONG_HOP_BAO_GIA'!P13) | M18: ='00_TONG_HOP_BAO_GIA'!L13 * (1 + '00_TONG_HOP_BAO_GIA'!P13) | N18: ='00_TONG_HOP_BAO_GIA'!R13 | O18: =IF(K18=0, "CẢNH BÁO: Đơn giá = 0. Tra cứu lại Sheet 06!", '00_TONG_HOP_BAO_GIA'!S13)
A19: =SUBTOTAL(3,$G$7:G19) | B19: Quạt hướng trục SEF-A1.2-12F-01 8800 l/s @ 650 Pa, chống cháy 300°C trong 2h | C19: SEF | D19: Fantech (ELTA Fans), Systemair, Wolter, Kruger | F19: QUẠT | G19: Cái | H19: 1 | I19: =IF('00_TONG_HOP_BAO_GIA'!G14>0, ('00_TONG_HOP_BAO_GIA'!K14 + '00_TONG_HOP_BAO_GIA'!M14) * (1 + '00_TONG_HOP_BAO_GIA'!P14) / '00_TONG_HOP_BAO_GIA'!G14, 0) | J19: =IF('00_TONG_HOP_BAO_GIA'!G14>0, '00_TONG_HOP_BAO_GIA'!L14 * (1 + '00_TONG_HOP_BAO_GIA'!P14) / '00_TONG_HOP_BAO_GIA'!G14, 0) | K19: ='00_TONG_HOP_BAO_GIA'!Q14 | L19: =('00_TONG_HOP_BAO_GIA'!K14 + '00_TONG_HOP_BAO_GIA'!M14) * (1 + '00_TONG_HOP_BAO_GIA'!P14) | M19: ='00_TONG_HOP_BAO_GIA'!L14 * (1 + '00_TONG_HOP_BAO_GIA'!P14) | N19: ='00_TONG_HOP_BAO_GIA'!R14 | O19: =IF(K19=0, "CẢNH BÁO: Đơn giá = 0. Tra cứu lại Sheet 06!", '00_TONG_HOP_BAO_GIA'!S14)
A20: =SUBTOTAL(3,$G$7:G20) | B20: Quạt hướng trục SEF-A1.1-RF-01 8100 l/s @ 650 Pa, chống cháy 300°C trong 2h | C20: SEF | D20: Fantech (ELTA Fans), Systemair, Wolter, Kruger | F20: QUẠT | G20: Cái | H20: 1 | I20: =IF('00_TONG_HOP_BAO_GIA'!G15>0, ('00_TONG_HOP_BAO_GIA'!K15 + '00_TONG_HOP_BAO_GIA'!M15) * (1 + '00_TONG_HOP_BAO_GIA'!P15) / '00_TONG_HOP_BAO_GIA'!G15, 0) | J20: =IF('00_TONG_HOP_BAO_GIA'!G15>0, '00_TONG_HOP_BAO_GIA'!L15 * (1 + '00_TONG_HOP_BAO_GIA'!P15) / '00_TONG_HOP_BAO_GIA'!G15, 0) | K20: ='00_TONG_HOP_BAO_GIA'!Q15 | L20: =('00_TONG_HOP_BAO_GIA'!K15 + '00_TONG_HOP_BAO_GIA'!M15) * (1 + '00_TONG_HOP_BAO_GIA'!P15) | M20: ='00_TONG_HOP_BAO_GIA'!L15 * (1 + '00_TONG_HOP_BAO_GIA'!P15) | N20: ='00_TONG_HOP_BAO_GIA'!R15 | O20: =IF(K20=0, "CẢNH BÁO: Đơn giá = 0. Tra cứu lại Sheet 06!", '00_TONG_HOP_BAO_GIA'!S15)
B21: Canvas loại chống cháy cho quạt TAHK | C21: D1000, L=200mm | F21: CANVAS | G21: cái | H21: 15 | I21: =IF('00_TONG_HOP_BAO_GIA'!G16>0, ('00_TONG_HOP_BAO_GIA'!K16 + '00_TONG_HOP_BAO_GIA'!M16) * (1 + '00_TONG_HOP_BAO_GIA'!P16) / '00_TONG_HOP_BAO_GIA'!G16, 0) | J21: =IF('00_TONG_HOP_BAO_GIA'!G16>0, '00_TONG_HOP_BAO_GIA'!L16 * (1 + '00_TONG_HOP_BAO_GIA'!P16) / '00_TONG_HOP_BAO_GIA'!G16, 0) | K21: ='00_TONG_HOP_BAO_GIA'!Q16 | L21: =('00_TONG_HOP_BAO_GIA'!K16 + '00_TONG_HOP_BAO_GIA'!M16) * (1 + '00_TONG_HOP_BAO_GIA'!P16) | M21: ='00_TONG_HOP_BAO_GIA'!L16 * (1 + '00_TONG_HOP_BAO_GIA'!P16) | N21: ='00_TONG_HOP_BAO_GIA'!R16 | O21: =IF(K21=0, "CẢNH BÁO: Đơn giá = 0. Tra cứu lại Sheet 06!", '00_TONG_HOP_BAO_GIA'!S16)
B22: Canvas loại chống cháy cho quạt TAHK | C22: D900, L=200mm | F22: CANVAS | G22: cái | H22: 40 | I22: =IF('00_TONG_HOP_BAO_GIA'!G17>0, ('00_TONG_HOP_BAO_GIA'!K17 + '00_TONG_HOP_BAO_GIA'!M17) * (1 + '00_TONG_HOP_BAO_GIA'!P17) / '00_TONG_HOP_BAO_GIA'!G17, 0) | J22: =IF('00_TONG_HOP_BAO_GIA'!G17>0, '00_TONG_HOP_BAO_GIA'!L17 * (1 + '00_TONG_HOP_BAO_GIA'!P17) / '00_TONG_HOP_BAO_GIA'!G17, 0) | K22: ='00_TONG_HOP_BAO_GIA'!Q17 | L22: =('00_TONG_HOP_BAO_GIA'!K17 + '00_TONG_HOP_BAO_GIA'!M17) * (1 + '00_TONG_HOP_BAO_GIA'!P17) | M22: ='00_TONG_HOP_BAO_GIA'!L17 * (1 + '00_TONG_HOP_BAO_GIA'!P17) | N22: ='00_TONG_HOP_BAO_GIA'!R17 | O22: =IF(K22=0, "CẢNH BÁO: Đơn giá = 0. Tra cứu lại Sheet 06!", '00_TONG_HOP_BAO_GIA'!S17)
B23: Canvas loại chống cháy cho quạt TAHK | C23: D800, L=200mm | F23: CANVAS | G23: cái | H23: 40 | I23: =IF('00_TONG_HOP_BAO_GIA'!G18>0, ('00_TONG_HOP_BAO_GIA'!K18 + '00_TONG_HOP_BAO_GIA'!M18) * (1 + '00_TONG_HOP_BAO_GIA'!P18) / '00_TONG_HOP_BAO_GIA'!G18, 0) | J23: =IF('00_TONG_HOP_BAO_GIA'!G18>0, '00_TONG_HOP_BAO_GIA'!L18 * (1 + '00_TONG_HOP_BAO_GIA'!P18) / '00_TONG_HOP_BAO_GIA'!G18, 0) | K23: ='00_TONG_HOP_BAO_GIA'!Q18 | L23: =('00_TONG_HOP_BAO_GIA'!K18 + '00_TONG_HOP_BAO_GIA'!M18) * (1 + '00_TONG_HOP_BAO_GIA'!P18) | M23: ='00_TONG_HOP_BAO_GIA'!L18 * (1 + '00_TONG_HOP_BAO_GIA'!P18) | N23: ='00_TONG_HOP_BAO_GIA'!R18 | O23: =IF(K23=0, "CẢNH BÁO: Đơn giá = 0. Tra cứu lại Sheet 06!", '00_TONG_HOP_BAO_GIA'!S18)
B24: Canvas loại chống cháy cho quạt TAHK | C24: D710, L=200mm | F24: CANVAS | G24: cái | H24: 16 | I24: =IF('00_TONG_HOP_BAO_GIA'!G19>0, ('00_TONG_HOP_BAO_GIA'!K19 + '00_TONG_HOP_BAO_GIA'!M19) * (1 + '00_TONG_HOP_BAO_GIA'!P19) / '00_TONG_HOP_BAO_GIA'!G19, 0) | J24: =IF('00_TONG_HOP_BAO_GIA'!G19>0, '00_TONG_HOP_BAO_GIA'!L19 * (1 + '00_TONG_HOP_BAO_GIA'!P19) / '00_TONG_HOP_BAO_GIA'!G19, 0) | K24: ='00_TONG_HOP_BAO_GIA'!Q19 | L24: =('00_TONG_HOP_BAO_GIA'!K19 + '00_TONG_HOP_BAO_GIA'!M19) * (1 + '00_TONG_HOP_BAO_GIA'!P19) | M24: ='00_TONG_HOP_BAO_GIA'!L19 * (1 + '00_TONG_HOP_BAO_GIA'!P19) | N24: ='00_TONG_HOP_BAO_GIA'!R19 | O24: =IF(K24=0, "CẢNH BÁO: Đơn giá = 0. Tra cứu lại Sheet 06!", '00_TONG_HOP_BAO_GIA'!S19)
B25: Canvas loại chống cháy cho quạt TAHK | C25: D560, L=200mm | F25: CANVAS | G25: cái | H25: 16 | I25: =IF('00_TONG_HOP_BAO_GIA'!G20>0, ('00_TONG_HOP_BAO_GIA'!K20 + '00_TONG_HOP_BAO_GIA'!M20) * (1 + '00_TONG_HOP_BAO_GIA'!P20) / '00_TONG_HOP_BAO_GIA'!G20, 0) | J25: =IF('00_TONG_HOP_BAO_GIA'!G20>0, '00_TONG_HOP_BAO_GIA'!L20 * (1 + '00_TONG_HOP_BAO_GIA'!P20) / '00_TONG_HOP_BAO_GIA'!G20, 0) | K25: ='00_TONG_HOP_BAO_GIA'!Q20 | L25: =('00_TONG_HOP_BAO_GIA'!K20 + '00_TONG_HOP_BAO_GIA'!M20) * (1 + '00_TONG_HOP_BAO_GIA'!P20) | M25: ='00_TONG_HOP_BAO_GIA'!L20 * (1 + '00_TONG_HOP_BAO_GIA'!P20) | N25: ='00_TONG_HOP_BAO_GIA'!R20 | O25: =IF(K25=0, "CẢNH BÁO: Đơn giá = 0. Tra cứu lại Sheet 06!", '00_TONG_HOP_BAO_GIA'!S20)
B26: Canvas loại thường cho quạt thông gió | C26: D1000, L=200mm | F26: CANVAS | G26: cái | H26: 32 | I26: =IF('00_TONG_HOP_BAO_GIA'!G21>0, ('00_TONG_HOP_BAO_GIA'!K21 + '00_TONG_HOP_BAO_GIA'!M21) * (1 + '00_TONG_HOP_BAO_GIA'!P21) / '00_TONG_HOP_BAO_GIA'!G21, 0) | J26: =IF('00_TONG_HOP_BAO_GIA'!G21>0, '00_TONG_HOP_BAO_GIA'!L21 * (1 + '00_TONG_HOP_BAO_GIA'!P21) / '00_TONG_HOP_BAO_GIA'!G21, 0) | K26: ='00_TONG_HOP_BAO_GIA'!Q21 | L26: =('00_TONG_HOP_BAO_GIA'!K21 + '00_TONG_HOP_BAO_GIA'!M21) * (1 + '00_TONG_HOP_BAO_GIA'!P21) | M26: ='00_TONG_HOP_BAO_GIA'!L21 * (1 + '00_TONG_HOP_BAO_GIA'!P21) | N26: ='00_TONG_HOP_BAO_GIA'!R21 | O26: =IF(K26=0, "CẢNH BÁO: Đơn giá = 0. Tra cứu lại Sheet 06!", '00_TONG_HOP_BAO_GIA'!S21)
B27: Canvas loại thường cho quạt thông gió | C27: D560, L=200mm | F27: CANVAS | G27: cái | H27: 24 | I27: =IF('00_TONG_HOP_BAO_GIA'!G22>0, ('00_TONG_HOP_BAO_GIA'!K22 + '00_TONG_HOP_BAO_GIA'!M22) * (1 + '00_TONG_HOP_BAO_GIA'!P22) / '00_TONG_HOP_BAO_GIA'!G22, 0) | J27: =IF('00_TONG_HOP_BAO_GIA'!G22>0, '00_TONG_HOP_BAO_GIA'!L22 * (1 + '00_TONG_HOP_BAO_GIA'!P22) / '00_TONG_HOP_BAO_GIA'!G22, 0) | K27: ='00_TONG_HOP_BAO_GIA'!Q22 | L27: =('00_TONG_HOP_BAO_GIA'!K22 + '00_TONG_HOP_BAO_GIA'!M22) * (1 + '00_TONG_HOP_BAO_GIA'!P22) | M27: ='00_TONG_HOP_BAO_GIA'!L22 * (1 + '00_TONG_HOP_BAO_GIA'!P22) | N27: ='00_TONG_HOP_BAO_GIA'!R22 | O27: =IF(K27=0, "CẢNH BÁO: Đơn giá = 0. Tra cứu lại Sheet 06!", '00_TONG_HOP_BAO_GIA'!S22)
A28: =SUBTOTAL(3,$G$7:G28) | B28: Tiêu âm quạt | D28: SX tại Việt Nam theo bản vẽ thiết kế | E28: Việt Nam (SX theo bản vẽ thiết kế) | F28: QUẠT | G28: Bộ | H28: 16 | I28: =IF('00_TONG_HOP_BAO_GIA'!G23>0, ('00_TONG_HOP_BAO_GIA'!K23 + '00_TONG_HOP_BAO_GIA'!M23) * (1 + '00_TONG_HOP_BAO_GIA'!P23) / '00_TONG_HOP_BAO_GIA'!G23, 0) | J28: =IF('00_TONG_HOP_BAO_GIA'!G23>0, '00_TONG_HOP_BAO_GIA'!L23 * (1 + '00_TONG_HOP_BAO_GIA'!P23) / '00_TONG_HOP_BAO_GIA'!G23, 0) | K28: ='00_TONG_HOP_BAO_GIA'!Q23 | L28: =('00_TONG_HOP_BAO_GIA'!K23 + '00_TONG_HOP_BAO_GIA'!M23) * (1 + '00_TONG_HOP_BAO_GIA'!P23) | M28: ='00_TONG_HOP_BAO_GIA'!L23 * (1 + '00_TONG_HOP_BAO_GIA'!P23) | N28: ='00_TONG_HOP_BAO_GIA'!R23 | O28: =IF(K28=0, "CẢNH BÁO: Đơn giá = 0. Tra cứu lại Sheet 06!", '00_TONG_HOP_BAO_GIA'!S23)
A29: =SUBTOTAL(3,$G$7:G29) | B29: Van 1 chiều NRD 1250x1250 (EI60) | C29: NRD | D29: NSCA, Evegreen, Swind | E29: Việt Nam / Singapore | G29: Cái | H29: 6 | I29: =IF('00_TONG_HOP_BAO_GIA'!G24>0, ('00_TONG_HOP_BAO_GIA'!K24 + '00_TONG_HOP_BAO_GIA'!M24) * (1 + '00_TONG_HOP_BAO_GIA'!P24) / '00_TONG_HOP_BAO_GIA'!G24, 0) | J29: =IF('00_TONG_HOP_BAO_GIA'!G24>0, '00_TONG_HOP_BAO_GIA'!L24 * (1 + '00_TONG_HOP_BAO_GIA'!P24) / '00_TONG_HOP_BAO_GIA'!G24, 0) | K29: ='00_TONG_HOP_BAO_GIA'!Q24 | L29: =('00_TONG_HOP_BAO_GIA'!K24 + '00_TONG_HOP_BAO_GIA'!M24) * (1 + '00_TONG_HOP_BAO_GIA'!P24) | M29: ='00_TONG_HOP_BAO_GIA'!L24 * (1 + '00_TONG_HOP_BAO_GIA'!P24) | N29: ='00_TONG_HOP_BAO_GIA'!R24 | O29: =IF(K29=0, "CẢNH BÁO: Đơn giá = 0. Tra cứu lại Sheet 06!", '00_TONG_HOP_BAO_GIA'!S24)
A30: =SUBTOTAL(3,$G$7:G30) | B30: Van 1 chiều NRD 1700x600 (EI60) | C30: NRD | D30: NSCA, Evegreen, Swind | E30: Việt Nam / Singapore | G30: Cái | H30: 2 | I30: =IF('00_TONG_HOP_BAO_GIA'!G25>0, ('00_TONG_HOP_BAO_GIA'!K25 + '00_TONG_HOP_BAO_GIA'!M25) * (1 + '00_TONG_HOP_BAO_GIA'!P25) / '00_TONG_HOP_BAO_GIA'!G25, 0) | J30: =IF('00_TONG_HOP_BAO_GIA'!G25>0, '00_TONG_HOP_BAO_GIA'!L25 * (1 + '00_TONG_HOP_BAO_GIA'!P25) / '00_TONG_HOP_BAO_GIA'!G25, 0) | K30: ='00_TONG_HOP_BAO_GIA'!Q25 | L30: =('00_TONG_HOP_BAO_GIA'!K25 + '00_TONG_HOP_BAO_GIA'!M25) * (1 + '00_TONG_HOP_BAO_GIA'!P25) | M30: ='00_TONG_HOP_BAO_GIA'!L25 * (1 + '00_TONG_HOP_BAO_GIA'!P25) | N30: ='00_TONG_HOP_BAO_GIA'!R25 | O30: =IF(K30=0, "CẢNH BÁO: Đơn giá = 0. Tra cứu lại Sheet 06!", '00_TONG_HOP_BAO_GIA'!S25)
A31: =SUBTOTAL(3,$G$7:G31) | B31: Van 1 chiều NRD 1200x350 (EI60) | C31: NRD | D31: NSCA, Evegreen, Swind | E31: Việt Nam / Singapore | G31: Cái | H31: 1 | I31: =IF('00_TONG_HOP_BAO_GIA'!G26>0, ('00_TONG_HOP_BAO_GIA'!K26 + '00_TONG_HOP_BAO_GIA'!M26) * (1 + '00_TONG_HOP_BAO_GIA'!P26) / '00_TONG_HOP_BAO_GIA'!G26, 0) | J31: =IF('00_TONG_HOP_BAO_GIA'!G26>0, '00_TONG_HOP_BAO_GIA'!L26 * (1 + '00_TONG_HOP_BAO_GIA'!P26) / '00_TONG_HOP_BAO_GIA'!G26, 0) | K31: ='00_TONG_HOP_BAO_GIA'!Q26 | L31: =('00_TONG_HOP_BAO_GIA'!K26 + '00_TONG_HOP_BAO_GIA'!M26) * (1 + '00_TONG_HOP_BAO_GIA'!P26) | M31: ='00_TONG_HOP_BAO_GIA'!L26 * (1 + '00_TONG_HOP_BAO_GIA'!P26) | N31: ='00_TONG_HOP_BAO_GIA'!R26 | O31: =IF(K31=0, "CẢNH BÁO: Đơn giá = 0. Tra cứu lại Sheet 06!", '00_TONG_HOP_BAO_GIA'!S26)
A32: =SUBTOTAL(3,$G$7:G32) | B32: Van ngăn cháy MFD 1250x1250 (EI60) | C32: MFD | D32: Van: NSCA, Evegreen, Swind, tđ ĐC: Belimo, Johnson Controls, tđ | E32: Việt Nam / Singapore | G32: Cái | H32: 6 | I32: =IF('00_TONG_HOP_BAO_GIA'!G27>0, ('00_TONG_HOP_BAO_GIA'!K27 + '00_TONG_HOP_BAO_GIA'!M27) * (1 + '00_TONG_HOP_BAO_GIA'!P27) / '00_TONG_HOP_BAO_GIA'!G27, 0) | J32: =IF('00_TONG_HOP_BAO_GIA'!G27>0, '00_TONG_HOP_BAO_GIA'!L27 * (1 + '00_TONG_HOP_BAO_GIA'!P27) / '00_TONG_HOP_BAO_GIA'!G27, 0) | K32: ='00_TONG_HOP_BAO_GIA'!Q27 | L32: =('00_TONG_HOP_BAO_GIA'!K27 + '00_TONG_HOP_BAO_GIA'!M27) * (1 + '00_TONG_HOP_BAO_GIA'!P27) | M32: ='00_TONG_HOP_BAO_GIA'!L27 * (1 + '00_TONG_HOP_BAO_GIA'!P27) | N32: ='00_TONG_HOP_BAO_GIA'!R27 | O32: =IF(K32=0, "CẢNH BÁO: Đơn giá = 0. Tra cứu lại Sheet 06!", '00_TONG_HOP_BAO_GIA'!S27)
A33: =SUBTOTAL(3,$G$7:G33) | B33: Van ngăn cháy MFD 1700x600 (EI60) | C33: MFD | D33: Van: NSCA, Evegreen, Swind, tđ ĐC: Belimo, Johnson Controls, tđ | E33: Việt Nam / Singapore | G33: Cái | H33: 2 | I33: =IF('00_TONG_HOP_BAO_GIA'!G28>0, ('00_TONG_HOP_BAO_GIA'!K28 + '00_TONG_HOP_BAO_GIA'!M28) * (1 + '00_TONG_HOP_BAO_GIA'!P28) / '00_TONG_HOP_BAO_GIA'!G28, 0) | J33: =IF('00_TONG_HOP_BAO_GIA'!G28>0, '00_TONG_HOP_BAO_GIA'!L28 * (1 + '00_TONG_HOP_BAO_GIA'!P28) / '00_TONG_HOP_BAO_GIA'!G28, 0) | K33: ='00_TONG_HOP_BAO_GIA'!Q28 | L33: =('00_TONG_HOP_BAO_GIA'!K28 + '00_TONG_HOP_BAO_GIA'!M28) * (1 + '00_TONG_HOP_BAO_GIA'!P28) | M33: ='00_TONG_HOP_BAO_GIA'!L28 * (1 + '00_TONG_HOP_BAO_GIA'!P28) | N33: ='00_TONG_HOP_BAO_GIA'!R28 | O33: =IF(K33=0, "CẢNH BÁO: Đơn giá = 0. Tra cứu lại Sheet 06!", '00_TONG_HOP_BAO_GIA'!S28)
A34: =SUBTOTAL(3,$G$7:G34) | B34: Van ngăn cháy MFD 1200x350 (EI60) | C34: MFD | D34: Van: NSCA, Evegreen, Swind, tđ ĐC: Belimo, Johnson Controls, tđ | E34: Việt Nam / Singapore | G34: Cái | H34: 1 | I34: =IF('00_TONG_HOP_BAO_GIA'!G29>0, ('00_TONG_HOP_BAO_GIA'!K29 + '00_TONG_HOP_BAO_GIA'!M29) * (1 + '00_TONG_HOP_BAO_GIA'!P29) / '00_TONG_HOP_BAO_GIA'!G29, 0) | J34: =IF('00_TONG_HOP_BAO_GIA'!G29>0, '00_TONG_HOP_BAO_GIA'!L29 * (1 + '00_TONG_HOP_BAO_GIA'!P29) / '00_TONG_HOP_BAO_GIA'!G29, 0) | K34: ='00_TONG_HOP_BAO_GIA'!Q29 | L34: =('00_TONG_HOP_BAO_GIA'!K29 + '00_TONG_HOP_BAO_GIA'!M29) * (1 + '00_TONG_HOP_BAO_GIA'!P29) | M34: ='00_TONG_HOP_BAO_GIA'!L29 * (1 + '00_TONG_HOP_BAO_GIA'!P29) | N34: ='00_TONG_HOP_BAO_GIA'!R29 | O34: =IF(K34=0, "CẢNH BÁO: Đơn giá = 0. Tra cứu lại Sheet 06!", '00_TONG_HOP_BAO_GIA'!S29)
A35: =SUBTOTAL(3,$G$7:G35) | B35: Van ngăn cháy MFD 950x400 (EI30) | C35: MFD | D35: Van: NSCA, Evegreen, Swind, tđ ĐC: Belimo, Johnson Controls, tđ | E35: Việt Nam / Singapore | G35: Cái | H35: 3 | I35: =IF('00_TONG_HOP_BAO_GIA'!G30>0, ('00_TONG_HOP_BAO_GIA'!K30 + '00_TONG_HOP_BAO_GIA'!M30) * (1 + '00_TONG_HOP_BAO_GIA'!P30) / '00_TONG_HOP_BAO_GIA'!G30, 0) | J35: =IF('00_TONG_HOP_BAO_GIA'!G30>0, '00_TONG_HOP_BAO_GIA'!L30 * (1 + '00_TONG_HOP_BAO_GIA'!P30) / '00_TONG_HOP_BAO_GIA'!G30, 0) | K35: ='00_TONG_HOP_BAO_GIA'!Q30 | L35: =('00_TONG_HOP_BAO_GIA'!K30 + '00_TONG_HOP_BAO_GIA'!M30) * (1 + '00_TONG_HOP_BAO_GIA'!P30) | M35: ='00_TONG_HOP_BAO_GIA'!L30 * (1 + '00_TONG_HOP_BAO_GIA'!P30) | N35: ='00_TONG_HOP_BAO_GIA'!R30 | O35: =IF(K35=0, "CẢNH BÁO: Đơn giá = 0. Tra cứu lại Sheet 06!", '00_TONG_HOP_BAO_GIA'!S30)
A36: =SUBTOTAL(3,$G$7:G36) | B36: Van ngăn cháy MFD 950x500 (EI30) | C36: MFD | D36: Van: NSCA, Evegreen, Swind, tđ ĐC: Belimo, Johnson Controls, tđ | E36: Việt Nam / Singapore | G36: Cái | H36: 6 | I36: =IF('00_TONG_HOP_BAO_GIA'!G31>0, ('00_TONG_HOP_BAO_GIA'!K31 + '00_TONG_HOP_BAO_GIA'!M31) * (1 + '00_TONG_HOP_BAO_GIA'!P31) / '00_TONG_HOP_BAO_GIA'!G31, 0) | J36: =IF('00_TONG_HOP_BAO_GIA'!G31>0, '00_TONG_HOP_BAO_GIA'!L31 * (1 + '00_TONG_HOP_BAO_GIA'!P31) / '00_TONG_HOP_BAO_GIA'!G31, 0) | K36: ='00_TONG_HOP_BAO_GIA'!Q31 | L36: =('00_TONG_HOP_BAO_GIA'!K31 + '00_TONG_HOP_BAO_GIA'!M31) * (1 + '00_TONG_HOP_BAO_GIA'!P31) | M36: ='00_TONG_HOP_BAO_GIA'!L31 * (1 + '00_TONG_HOP_BAO_GIA'!P31) | N36: ='00_TONG_HOP_BAO_GIA'!R31 | O36: =IF(K36=0, "CẢNH BÁO: Đơn giá = 0. Tra cứu lại Sheet 06!", '00_TONG_HOP_BAO_GIA'!S31)
A37: =SUBTOTAL(3,$G$7:G37) | B37: Van ngăn cháy MFD 950x200 (EI30) | C37: MFD | D37: Van: NSCA, Evegreen, Swind, tđ ĐC: Belimo, Johnson Controls, tđ | E37: Việt Nam / Singapore | G37: Cái | H37: 9 | I37: =IF('00_TONG_HOP_BAO_GIA'!G32>0, ('00_TONG_HOP_BAO_GIA'!K32 + '00_TONG_HOP_BAO_GIA'!M32) * (1 + '00_TONG_HOP_BAO_GIA'!P32) / '00_TONG_HOP_BAO_GIA'!G32, 0) | J37: =IF('00_TONG_HOP_BAO_GIA'!G32>0, '00_TONG_HOP_BAO_GIA'!L32 * (1 + '00_TONG_HOP_BAO_GIA'!P32) / '00_TONG_HOP_BAO_GIA'!G32, 0) | K37: ='00_TONG_HOP_BAO_GIA'!Q32 | L37: =('00_TONG_HOP_BAO_GIA'!K32 + '00_TONG_HOP_BAO_GIA'!M32) * (1 + '00_TONG_HOP_BAO_GIA'!P32) | M37: ='00_TONG_HOP_BAO_GIA'!L32 * (1 + '00_TONG_HOP_BAO_GIA'!P32) | N37: ='00_TONG_HOP_BAO_GIA'!R32 | O37: =IF(K37=0, "CẢNH BÁO: Đơn giá = 0. Tra cứu lại Sheet 06!", '00_TONG_HOP_BAO_GIA'!S32)
A38: =SUBTOTAL(3,$G$7:G38) | B38: Van ngăn cháy MFD 950x300 (EI30) | C38: MFD | D38: Van: NSCA, Evegreen, Swind, tđ ĐC: Belimo, Johnson Controls, tđ | E38: Việt Nam / Singapore | G38: Cái | H38: 12 | I38: =IF('00_TONG_HOP_BAO_GIA'!G33>0, ('00_TONG_HOP_BAO_GIA'!K33 + '00_TONG_HOP_BAO_GIA'!M33) * (1 + '00_TONG_HOP_BAO_GIA'!P33) / '00_TONG_HOP_BAO_GIA'!G33, 0) | J38: =IF('00_TONG_HOP_BAO_GIA'!G33>0, '00_TONG_HOP_BAO_GIA'!L33 * (1 + '00_TONG_HOP_BAO_GIA'!P33) / '00_TONG_HOP_BAO_GIA'!G33, 0) | K38: ='00_TONG_HOP_BAO_GIA'!Q33 | L38: =('00_TONG_HOP_BAO_GIA'!K33 + '00_TONG_HOP_BAO_GIA'!M33) * (1 + '00_TONG_HOP_BAO_GIA'!P33) | M38: ='00_TONG_HOP_BAO_GIA'!L33 * (1 + '00_TONG_HOP_BAO_GIA'!P33) | N38: ='00_TONG_HOP_BAO_GIA'!R33 | O38: =IF(K38=0, "CẢNH BÁO: Đơn giá = 0. Tra cứu lại Sheet 06!", '00_TONG_HOP_BAO_GIA'!S33)
A39: =SUBTOTAL(3,$G$7:G39) | B39: Van chỉnh lưu lượng VCD 2000x500 (EI60) | C39: VCD | D39: NSCA, Evegreen, Swind | E39: Việt Nam / Singapore | G39: Cái | H39: 1 | I39: =IF('00_TONG_HOP_BAO_GIA'!G34>0, ('00_TONG_HOP_BAO_GIA'!K34 + '00_TONG_HOP_BAO_GIA'!M34) * (1 + '00_TONG_HOP_BAO_GIA'!P34) / '00_TONG_HOP_BAO_GIA'!G34, 0) | J39: =IF('00_TONG_HOP_BAO_GIA'!G34>0, '00_TONG_HOP_BAO_GIA'!L34 * (1 + '00_TONG_HOP_BAO_GIA'!P34) / '00_TONG_HOP_BAO_GIA'!G34, 0) | K39: ='00_TONG_HOP_BAO_GIA'!Q34 | L39: =('00_TONG_HOP_BAO_GIA'!K34 + '00_TONG_HOP_BAO_GIA'!M34) * (1 + '00_TONG_HOP_BAO_GIA'!P34) | M39: ='00_TONG_HOP_BAO_GIA'!L34 * (1 + '00_TONG_HOP_BAO_GIA'!P34) | N39: ='00_TONG_HOP_BAO_GIA'!R34 | O39: =IF(K39=0, "CẢNH BÁO: Đơn giá = 0. Tra cứu lại Sheet 06!", '00_TONG_HOP_BAO_GIA'!S34)
A40: =SUBTOTAL(3,$G$7:G40) | B40: Van chỉnh lưu lượng VCD 1300x400 (EI60) | C40: VCD | D40: NSCA, Evegreen, Swind | E40: Việt Nam / Singapore | G40: Cái | H40: 2 | I40: =IF('00_TONG_HOP_BAO_GIA'!G35>0, ('00_TONG_HOP_BAO_GIA'!K35 + '00_TONG_HOP_BAO_GIA'!M35) * (1 + '00_TONG_HOP_BAO_GIA'!P35) / '00_TONG_HOP_BAO_GIA'!G35, 0) | J40: =IF('00_TONG_HOP_BAO_GIA'!G35>0, '00_TONG_HOP_BAO_GIA'!L35 * (1 + '00_TONG_HOP_BAO_GIA'!P35) / '00_TONG_HOP_BAO_GIA'!G35, 0) | K40: ='00_TONG_HOP_BAO_GIA'!Q35 | L40: =('00_TONG_HOP_BAO_GIA'!K35 + '00_TONG_HOP_BAO_GIA'!M35) * (1 + '00_TONG_HOP_BAO_GIA'!P35) | M40: ='00_TONG_HOP_BAO_GIA'!L35 * (1 + '00_TONG_HOP_BAO_GIA'!P35) | N40: ='00_TONG_HOP_BAO_GIA'!R35 | O40: =IF(K40=0, "CẢNH BÁO: Đơn giá = 0. Tra cứu lại Sheet 06!", '00_TONG_HOP_BAO_GIA'!S35)
... A52: =SUBTOTAL(3,$G$7:G52) | B52: Louver EAL 2750x750+IS | C52: EAL | D52: NSCA, Evegreen, Swind | E52: Việt Nam (SX theo bản vẽ thiết kế) | G52: Cái | H52: 2 | I52: =IF('00_TONG_HOP_BAO_GIA'!G47>0, ('00_TONG_HOP_BAO_GIA'!K47 + '00_TONG_HOP_BAO_GIA'!M47) * (1 + '00_TONG_HOP_BAO_GIA'!P47) / '00_TONG_HOP_BAO_GIA'!G47, 0) | J52: =IF('00_TONG_HOP_BAO_GIA'!G47>0, '00_TONG_HOP_BAO_GIA'!L47 * (1 + '00_TONG_HOP_BAO_GIA'!P47) / '00_TONG_HOP_BAO_GIA'!G47, 0) | K52: ='00_TONG_HOP_BAO_GIA'!Q47 | L52: =('00_TONG_HOP_BAO_GIA'!K47 + '00_TONG_HOP_BAO_GIA'!M47) * (1 + '00_TONG_HOP_BAO_GIA'!P47) | M52: ='00_TONG_HOP_BAO_GIA'!L47 * (1 + '00_TONG_HOP_BAO_GIA'!P47) | N52: ='00_TONG_HOP_BAO_GIA'!R47 | O52: =IF(K52=0, "CẢNH BÁO: Đơn giá = 0. Tra cứu lại Sheet 06!", '00_TONG_HOP_BAO_GIA'!S47)
...

Sheet 00_TONG_HOP_BAO_GIA
A1: STT | B1: ITEM_ID | C1: PHÂN NHÓM | D1: TÊN SẢN PHẨM | E1: QUY CÁCH (WxH) | F1: ĐVT | G1: SỐ LƯỢNG | H1: CP VẬT TƯ ỐNG | I1: CP VẬT TƯ CỬA | J1: CP VẬT TƯ VAN | K1: TỔNG CP VẬT TƯ | L1: NHÂN CÔNG (25%) | M1: CP XƯỞNG (10%) | N1: TỔNG GIÁ VỐN | O1: GIÁ VỐN / ĐVT | P1: MARGIN (%) | Q1: ĐƠN GIÁ BÁN | R1: THÀNH TIỀN (VNĐ) | S1: GHI CHÚ
A2: 1 | B2: SW-TRD-001 | C2: THƯƠNG MẠI | D2: HỆ THỐNG HÚT KHÓI HẦM XE, HÚT KHÓI SỰ CỐ Quạt hướng trục CEF-B2-Z1-01~02 5290/9430 l/s @ 500/1350 Pa, chống cháy 300°C trong 2h, | E2: - | F2: Cái | G2: 2 | H2: =SUMIF('01_BOC_TACH_ONG'!B:B, B2, '01_BOC_TACH_ONG'!K:K) | I2: =SUMIF('02_BOC_TACH_CUA'!B:B, B2, '02_BOC_TACH_CUA'!K:K) | J2: =SUMIF('03_BOC_TACH_VAN'!B:B, B2, '03_BOC_TACH_VAN'!K:K) | K2: =SUM(H2:J2) | L2: =K2*0.00 | M2: =K2*0.02 | N2: =K2+L2+M2 | O2: =IF(G2>0, N2/G2, 0) | P2: 0.1 | Q2: =O2*(1+P2) | R2: =G2*Q2 | S2: Hàng thương mại
A3: 2 | B3: SW-TRD-002 | C3: THƯƠNG MẠI | D3: HỆ THỐNG HÚT KHÓI HẦM XE, HÚT KHÓI SỰ CỐ Quạt hướng trục CEF-B2-Z2-01~02 5490/8910 l/s @ 600/1350 Pa, chống cháy 300°C trong 2h | E3: - | F3: Cái | G3: 2 | H3: =SUMIF('01_BOC_TACH_ONG'!B:B, B3, '01_BOC_TACH_ONG'!K:K) | I3: =SUMIF('02_BOC_TACH_CUA'!B:B, B3, '02_BOC_TACH_CUA'!K:K) | J3: =SUMIF('03_BOC_TACH_VAN'!B:B, B3, '03_BOC_TACH_VAN'!K:K) | K3: =SUM(H3:J3) | L3: =K3*0.00 | M3: =K3*0.02 | N3: =K3+L3+M3 | O3: =IF(G3>0, N3/G3, 0) | P3: 0.1 | Q3: =O3*(1+P3) | R3: =G3*Q3 | S3: Hàng thương mại
A4: 3 | B4: SW-TRD-003 | C4: THƯƠNG MẠI | D4: HỆ THỐNG HÚT KHÓI HẦM XE, HÚT KHÓI SỰ CỐ Quạt hướng trục CEF-B1-Z1-01~02 5590/8385 l/s @ 600/1350 Pa, chống cháy 300°C trong 2h | E4: - | F4: Cái | G4: 2 | H4: =SUMIF('01_BOC_TACH_ONG'!B:B, B4, '01_BOC_TACH_ONG'!K:K) | I4: =SUMIF('02_BOC_TACH_CUA'!B:B, B4, '02_BOC_TACH_CUA'!K:K) | J4: =SUMIF('03_BOC_TACH_VAN'!B:B, B4, '03_BOC_TACH_VAN'!K:K) | K4: =SUM(H4:J4) | L4: =K4*0.00 | M4: =K4*0.02 | N4: =K4+L4+M4 | O4: =IF(G4>0, N4/G4, 0) | P4: 0.1 | Q4: =O4*(1+P4) | R4: =G4*Q4 | S4: Hàng thương mại
A5: 4 | B5: SW-TRD-004 | C5: THƯƠNG MẠI | D5: HỆ THỐNG HÚT KHÓI HẦM XE, HÚT KHÓI SỰ CỐ Quạt hướng trục CEF-B1-Z2-01~02 5135/7700 l/s @ 600/1350 Pa, chống cháy 300°C trong 2h | E5: - | F5: Cái | G5: 2 | H5: =SUMIF('01_BOC_TACH_ONG'!B:B, B5, '01_BOC_TACH_ONG'!K:K) | I5: =SUMIF('02_BOC_TACH_CUA'!B:B, B5, '02_BOC_TACH_CUA'!K:K) | J5: =SUMIF('03_BOC_TACH_VAN'!B:B, B5, '03_BOC_TACH_VAN'!K:K) | K5: =SUM(H5:J5) | L5: =K5*0.00 | M5: =K5*0.02 | N5: =K5+L5+M5 | O5: =IF(G5>0, N5/G5, 0) | P5: 0.1 | Q5: =O5*(1+P5) | R5: =G5*Q5 | S5: Hàng thương mại
A6: 5 | B6: SW-TRD-005 | C6: THƯƠNG MẠI | D6: HỆ THỐNG HÚT KHÓI HẦM XE, HÚT KHÓI SỰ CỐ Quạt hướng trục SEF-B1-Z2-01 4800 l/s @ 500 Pa, chống cháy 300°C trong 2h | E6: - | F6: Cái | G6: 1 | H6: =SUMIF('01_BOC_TACH_ONG'!B:B, B6, '01_BOC_TACH_ONG'!K:K) | I6: =SUMIF('02_BOC_TACH_CUA'!B:B, B6, '02_BOC_TACH_CUA'!K:K) | J6: =SUMIF('03_BOC_TACH_VAN'!B:B, B6, '03_BOC_TACH_VAN'!K:K) | K6: =SUM(H6:J6) | L6: =K6*0.00 | M6: =K6*0.02 | N6: =K6+L6+M6 | O6: =IF(G6>0, N6/G6, 0) | P6: 0.1 | Q6: =O6*(1+P6) | R6: =G6*Q6 | S6: Hàng thương mại
A7: 6 | B7: SW-TRD-006 | C7: THƯƠNG MẠI | D7: HỆ THỐNG HÚT KHÓI HẦM XE, HÚT KHÓI SỰ CỐ Quạt hướng trục SEF-A1.1-03F-01~02 7400 l/s @ 400 Pa, chống cháy 300°C trong 2h | E7: - | F7: Cái | G7: 2 | H7: =SUMIF('01_BOC_TACH_ONG'!B:B, B7, '01_BOC_TACH_ONG'!K:K) | I7: =SUMIF('02_BOC_TACH_CUA'!B:B, B7, '02_BOC_TACH_CUA'!K:K) | J7: =SUMIF('03_BOC_TACH_VAN'!B:B, B7, '03_BOC_TACH_VAN'!K:K) | K7: =SUM(H7:J7) | L7: =K7*0.00 | M7: =K7*0.02 | N7: =K7+L7+M7 | O7: =IF(G7>0, N7/G7, 0) | P7: 0.1 | Q7: =O7*(1+P7) | R7: =G7*Q7 | S7: Hàng thương mại
A8: 7 | B8: SW-TRD-007 | C8: THƯƠNG MẠI | D8: HỆ THỐNG HÚT KHÓI HẦM XE, HÚT KHÓI SỰ CỐ Quạt hướng trục SEF-A1.2-03F-01~02 6700 l/s @ 500 Pa, chống cháy 300°C trong 2h | E8: - | F8: Cái | G8: 2 | H8: =SUMIF('01_BOC_TACH_ONG'!B:B, B8, '01_BOC_TACH_ONG'!K:K) | I8: =SUMIF('02_BOC_TACH_CUA'!B:B, B8, '02_BOC_TACH_CUA'!K:K) | J8: =SUMIF('03_BOC_TACH_VAN'!B:B, B8, '03_BOC_TACH_VAN'!K:K) | K8: =SUM(H8:J8) | L8: =K8*0.00 | M8: =K8*0.02 | N8: =K8+L8+M8 | O8: =IF(G8>0, N8/G8, 0) | P8: 0.1 | Q8: =O8*(1+P8) | R8: =G8*Q8 | S8: Hàng thương mại
A9: 8 | B9: SW-TRD-008 | C9: THƯƠNG MẠI | D9: HỆ THỐNG HÚT KHÓI HẦM XE, HÚT KHÓI SỰ CỐ Quạt hướng trục SEF-A1.2-03F-03 5100 l/s @ 500 Pa, chống cháy 300°C trong 2h | E9: - | F9: Cái | G9: 1 | H9: =SUMIF('01_BOC_TACH_ONG'!B:B, B9, '01_BOC_TACH_ONG'!K:K) | I9: =SUMIF('02_BOC_TACH_CUA'!B:B, B9, '02_BOC_TACH_CUA'!K:K) | J9: =SUMIF('03_BOC_TACH_VAN'!B:B, B9, '03_BOC_TACH_VAN'!K:K) | K9: =SUM(H9:J9) | L9: =K9*0.00 | M9: =K9*0.02 | N9: =K9+L9+M9 | O9: =IF(G9>0, N9/G9, 0) | P9: 0.1 | Q9: =O9*(1+P9) | R9: =G9*Q9 | S9: Hàng thương mại
A10: 9 | B10: SW-TRD-009 | C10: THƯƠNG MẠI | D10: HỆ THỐNG HÚT KHÓI HẦM XE, HÚT KHÓI SỰ CỐ Quạt hướng trục SEF-A1.3-03F-01~03 4800 l/s @ 500 Pa, chống cháy 300°C trong 2h | E10: - | F10: Cái | G10: 3 | H10: =SUMIF('01_BOC_TACH_ONG'!B:B, B10, '01_BOC_TACH_ONG'!K:K) | I10: =SUMIF('02_BOC_TACH_CUA'!B:B, B10, '02_BOC_TACH_CUA'!K:K) | J10: =SUMIF('03_BOC_TACH_VAN'!B:B, B10, '03_BOC_TACH_VAN'!K:K) | K10: =SUM(H10:J10) | L10: =K10*0.00 | M10: =K10*0.02 | N10: =K10+L10+M10 | O10: =IF(G10>0, N10/G10, 0) | P10: 0.1 | Q10: =O10*(1+P10) | R10: =G10*Q10 | S10: Hàng thương mại
A11: 10 | B11: SW-TRD-010 | C11: THƯƠNG MẠI | D11: HỆ THỐNG HÚT KHÓI HẦM XE, HÚT KHÓI SỰ CỐ Quạt hướng trục SEF-A1.3-03F-04 4800 l/s @ 450 Pa, chống cháy 300°C trong 2h | E11: - | F11: Cái | G11: 1 | H11: =SUMIF('01_BOC_TACH_ONG'!B:B, B11, '01_BOC_TACH_ONG'!K:K) | I11: =SUMIF('02_BOC_TACH_CUA'!B:B, B11, '02_BOC_TACH_CUA'!K:K) | J11: =SUMIF('03_BOC_TACH_VAN'!B:B, B11, '03_BOC_TACH_VAN'!K:K) | K11: =SUM(H11:J11) | L11: =K11*0.00 | M11: =K11*0.02 | N11: =K11+L11+M11 | O11: =IF(G11>0, N11/G11, 0) | P11: 0.1 | Q11: =O11*(1+P11) | R11: =G11*Q11 | S11: Hàng thương mại
A12: 11 | B12: SW-TRD-011 | C12: THƯƠNG MẠI | D12: HỆ THỐNG HÚT KHÓI HẦM XE, HÚT KHÓI SỰ CỐ Quạt hướng trục SEF-A1.3-03F-05~07 4800 l/s @ 500 Pa, chống cháy 300°C trong 2h | E12: - | F12: Cái | G12: 3 | H12: =SUMIF('01_BOC_TACH_ONG'!B:B, B12, '01_BOC_TACH_ONG'!K:K) | I12: =SUMIF('02_BOC_TACH_CUA'!B:B, B12, '02_BOC_TACH_CUA'!K:K) | J12: =SUMIF('03_BOC_TACH_VAN'!B:B, B12, '03_BOC_TACH_VAN'!K:K) | K12: =SUM(H12:J12) | L12: =K12*0.00 | M12: =K12*0.02 | N12: =K12+L12+M12 | O12: =IF(G12>0, N12/G12, 0) | P12: 0.1 | Q12: =O12*(1+P12) | R12: =G12*Q12 | S12: Hàng thương mại
A13: 12 | B13: SW-TRD-012 | C13: THƯƠNG MẠI | D13: HỆ THỐNG HÚT KHÓI HẦM XE, HÚT KHÓI SỰ CỐ Quạt hướng trục SEF-A1.3-10F-01 7100 l/s @ 600 Pa, chống cháy 300°C trong 2h | E13: - | F13: Cái | G13: 1 | H13: =SUMIF('01_BOC_TACH_ONG'!B:B, B13, '01_BOC_TACH_ONG'!K:K) | I13: =SUMIF('02_BOC_TACH_CUA'!B:B, B13, '02_BOC_TACH_CUA'!K:K) | J13: =SUMIF('03_BOC_TACH_VAN'!B:B, B13, '03_BOC_TACH_VAN'!K:K) | K13: =SUM(H13:J13) | L13: =K13*0.00 | M13: =K13*0.02 | N13: =K13+L13+M13 | O13: =IF(G13>0, N13/G13, 0) | P13: 0.1 | Q13: =O13*(1+P13) | R13: =G13*Q13 | S13: Hàng thương mại
... A15: 14 | B15: SW-TRD-014 | C15: THƯƠNG MẠI | D15: HỆ THỐNG HÚT KHÓI HẦM XE, HÚT KHÓI SỰ CỐ Quạt hướng trục SEF-A1.1-RF-01 8100 l/s @ 650 Pa, chống cháy 300°C trong 2h | E15: - | F15: Cái | G15: 1 | H15: =SUMIF('01_BOC_TACH_ONG'!B:B, B15, '01_BOC_TACH_ONG'!K:K) | I15: =SUMIF('02_BOC_TACH_CUA'!B:B, B15, '02_BOC_TACH_CUA'!K:K) | J15: =SUMIF('03_BOC_TACH_VAN'!B:B, B15, '03_BOC_TACH_VAN'!K:K) | K15: =SUM(H15:J15) | L15: =K15*0.00 | M15: =K15*0.02 | N15: =K15+L15+M15 | O15: =IF(G15>0, N15/G15, 0) | P15: 0.1 | Q15: =O15*(1+P15) | R15: =G15*Q15 | S15: Hàng thương mại
A16: 15 | B16: SW-CV-015 | C16: KHỚP NỐI MỀM | D16: HỆ THỐNG HÚT KHÓI HẦM XE, HÚT KHÓI SỰ CỐ Canvas loại chống cháy cho quạt TAHK | E16: D1000 | F16: cái | G16: 15 | H16: =SUMIF('01_BOC_TACH_ONG'!B:B, B16, '01_BOC_TACH_ONG'!K:K) | I16: =SUMIF('02_BOC_TACH_CUA'!B:B, B16, '02_BOC_TACH_CUA'!K:K) | J16: =SUMIF('03_BOC_TACH_VAN'!B:B, B16, '03_BOC_TACH_VAN'!K:K) | K16: =SUM(H16:J16) | L16: =K16*0.25 | M16: =K16*0.10 | N16: =K16+L16+M16 | O16: =IF(G16>0, N16/G16, 0) | P16: 0.18 | Q16: =O16*(1+P16) | R16: =G16*Q16
A17: 16 | B17: SW-CV-016 | C17: KHỚP NỐI MỀM | D17: HỆ THỐNG HÚT KHÓI HẦM XE, HÚT KHÓI SỰ CỐ Canvas loại chống cháy cho quạt TAHK | E17: D900 | F17: cái | G17: 40 | H17: =SUMIF('01_BOC_TACH_ONG'!B:B, B17, '01_BOC_TACH_ONG'!K:K) | I17: =SUMIF('02_BOC_TACH_CUA'!B:B, B17, '02_BOC_TACH_CUA'!K:K) | J17: =SUMIF('03_BOC_TACH_VAN'!B:B, B17, '03_BOC_TACH_VAN'!K:K) | K17: =SUM(H17:J17) | L17: =K17*0.25 | M17: =K17*0.10 | N17: =K17+L17+M17 | O17: =IF(G17>0, N17/G17, 0) | P17: 0.18 | Q17: =O17*(1+P17) | R17: =G17*Q17
A18: 17 | B18: SW-CV-017 | C18: KHỚP NỐI MỀM | D18: HỆ THỐNG HÚT KHÓI HẦM XE, HÚT KHÓI SỰ CỐ Canvas loại chống cháy cho quạt TAHK | E18: D800 | F18: cái | G18: 40 | H18: =SUMIF('01_BOC_TACH_ONG'!B:B, B18, '01_BOC_TACH_ONG'!K:K) | I18: =SUMIF('02_BOC_TACH_CUA'!B:B, B18, '02_BOC_TACH_CUA'!K:K) | J18: =SUMIF('03_BOC_TACH_VAN'!B:B, B18, '03_BOC_TACH_VAN'!K:K) | K18: =SUM(H18:J18) | L18: =K18*0.25 | M18: =K18*0.10 | N18: =K18+L18+M18 | O18: =IF(G18>0, N18/G18, 0) | P18: 0.18 | Q18: =O18*(1+P18) | R18: =G18*Q18
A19: 18 | B19: SW-CV-018 | C19: KHỚP NỐI MỀM | D19: HỆ THỐNG HÚT KHÓI HẦM XE, HÚT KHÓI SỰ CỐ Canvas loại chống cháy cho quạt TAHK | E19: D710 | F19: cái | G19: 16 | H19: =SUMIF('01_BOC_TACH_ONG'!B:B, B19, '01_BOC_TACH_ONG'!K:K) | I19: =SUMIF('02_BOC_TACH_CUA'!B:B, B19, '02_BOC_TACH_CUA'!K:K) | J19: =SUMIF('03_BOC_TACH_VAN'!B:B, B19, '03_BOC_TACH_VAN'!K:K) | K19: =SUM(H19:J19) | L19: =K19*0.25 | M19: =K19*0.10 | N19: =K19+L19+M19 | O19: =IF(G19>0, N19/G19, 0) | P19: 0.18 | Q19: =O19*(1+P19) | R19: =G19*Q19
A20: 19 | B20: SW-CV-019 | C20: KHỚP NỐI MỀM | D20: HỆ THỐNG HÚT KHÓI HẦM XE, HÚT KHÓI SỰ CỐ Canvas loại chống cháy cho quạt TAHK | E20: D560 | F20: cái | G20: 16 | H20: =SUMIF('01_BOC_TACH_ONG'!B:B, B20, '01_BOC_TACH_ONG'!K:K) | I20: =SUMIF('02_BOC_TACH_CUA'!B:B, B20, '02_BOC_TACH_CUA'!K:K) | J20: =SUMIF('03_BOC_TACH_VAN'!B:B, B20, '03_BOC_TACH_VAN'!K:K) | K20: =SUM(H20:J20) | L20: =K20*0.25 | M20: =K20*0.10 | N20: =K20+L20+M20 | O20: =IF(G20>0, N20/G20, 0) | P20: 0.18 | Q20: =O20*(1+P20) | R20: =G20*Q20
A21: 20 | B21: SW-CV-020 | C21: KHỚP NỐI MỀM | D21: HỆ THỐNG HÚT KHÓI HẦM XE, HÚT KHÓI SỰ CỐ Canvas loại thường cho quạt thông gió | E21: D1000 | F21: cái | G21: 32 | H21: =SUMIF('01_BOC_TACH_ONG'!B:B, B21, '01_BOC_TACH_ONG'!K:K) | I21: =SUMIF('02_BOC_TACH_CUA'!B:B, B21, '02_BOC_TACH_CUA'!K:K) | J21: =SUMIF('03_BOC_TACH_VAN'!B:B, B21, '03_BOC_TACH_VAN'!K:K) | K21: =SUM(H21:J21) | L21: =K21*0.25 | M21: =K21*0.10 | N21: =K21+L21+M21 | O21: =IF(G21>0, N21/G21, 0) | P21: 0.18 | Q21: =O21*(1+P21) | R21: =G21*Q21
A22: 21 | B22: SW-CV-021 | C22: KHỚP NỐI MỀM | D22: HỆ THỐNG HÚT KHÓI HẦM XE, HÚT KHÓI SỰ CỐ Canvas loại thường cho quạt thông gió | E22: D560 | F22: cái | G22: 24 | H22: =SUMIF('01_BOC_TACH_ONG'!B:B, B22, '01_BOC_TACH_ONG'!K:K) | I22: =SUMIF('02_BOC_TACH_CUA'!B:B, B22, '02_BOC_TACH_CUA'!K:K) | J22: =SUMIF('03_BOC_TACH_VAN'!B:B, B22, '03_BOC_TACH_VAN'!K:K) | K22: =SUM(H22:J22) | L22: =K22*0.25 | M22: =K22*0.10 | N22: =K22+L22+M22 | O22: =IF(G22>0, N22/G22, 0) | P22: 0.18 | Q22: =O22*(1+P22) | R22: =G22*Q22
A23: 22 | B23: SW-ACST-022 | C23: VÁCH NGĂN / HỘP TIÊU ÂM | D23: HỆ THỐNG HÚT KHÓI HẦM XE, HÚT KHÓI SỰ CỐ Tiêu âm quạt | E23: - | F23: Bộ | G23: 16 | H23: =SUMIF('01_BOC_TACH_ONG'!B:B, B23, '01_BOC_TACH_ONG'!K:K) | I23: =SUMIF('02_BOC_TACH_CUA'!B:B, B23, '02_BOC_TACH_CUA'!K:K) | J23: =SUMIF('03_BOC_TACH_VAN'!B:B, B23, '03_BOC_TACH_VAN'!K:K) | K23: =SUM(H23:J23) | L23: =K23*0.25 | M23: =K23*0.10 | N23: =K23+L23+M23 | O23: =IF(G23>0, N23/G23, 0) | P23: 0.18 | Q23: =O23*(1+P23) | R23: =G23*Q23
A24: 23 | B24: SW-DAMPER-023 | C24: VAN GIÓ | D24: HỆ THỐNG HÚT KHÓI HẦM XE, HÚT KHÓI SỰ CỐ Van 1 chiều NRD 1250x1250 (EI60) | E24: 1250x1250 | F24: Cái | G24: 6 | H24: =SUMIF('01_BOC_TACH_ONG'!B:B, B24, '01_BOC_TACH_ONG'!K:K) | I24: =SUMIF('02_BOC_TACH_CUA'!B:B, B24, '02_BOC_TACH_CUA'!K:K) | J24: =SUMIF('03_BOC_TACH_VAN'!B:B, B24, '03_BOC_TACH_VAN'!K:K) | K24: =SUM(H24:J24) | L24: =K24*0.25 | M24: =K24*0.10 | N24: =K24+L24+M24 | O24: =IF(G24>0, N24/G24, 0) | P24: 0.18 | Q24: =O24*(1+P24) | R24: =G24*Q24
A25: 24 | B25: SW-DAMPER-024 | C25: VAN GIÓ | D25: HỆ THỐNG HÚT KHÓI HẦM XE, HÚT KHÓI SỰ CỐ Van 1 chiều NRD 1700x600 (EI60) | E25: 1700x600 | F25: Cái | G25: 2 | H25: =SUMIF('01_BOC_TACH_ONG'!B:B, B25, '01_BOC_TACH_ONG'!K:K) | I25: =SUMIF('02_BOC_TACH_CUA'!B:B, B25, '02_BOC_TACH_CUA'!K:K) | J25: =SUMIF('03_BOC_TACH_VAN'!B:B, B25, '03_BOC_TACH_VAN'!K:K) | K25: =SUM(H25:J25) | L25: =K25*0.25 | M25: =K25*0.10 | N25: =K25+L25+M25 | O25: =IF(G25>0, N25/G25, 0) | P25: 0.18 | Q25: =O25*(1+P25) | R25: =G25*Q25
A26: 25 | B26: SW-DAMPER-025 | C26: VAN GIÓ | D26: HỆ THỐNG HÚT KHÓI HẦM XE, HÚT KHÓI SỰ CỐ Van 1 chiều NRD 1200x350 (EI60) | E26: 1200x350 | F26: Cái | G26: 1 | H26: =SUMIF('01_BOC_TACH_ONG'!B:B, B26, '01_BOC_TACH_ONG'!K:K) | I26: =SUMIF('02_BOC_TACH_CUA'!B:B, B26, '02_BOC_TACH_CUA'!K:K) | J26: =SUMIF('03_BOC_TACH_VAN'!B:B, B26, '03_BOC_TACH_VAN'!K:K) | K26: =SUM(H26:J26) | L26: =K26*0.25 | M26: =K26*0.10 | N26: =K26+L26+M26 | O26: =IF(G26>0, N26/G26, 0) | P26: 0.18 | Q26: =O26*(1+P26) | R26: =G26*Q26
A27: 26 | B27: SW-DAMPER-026 | C27: VAN GIÓ | D27: HỆ THỐNG HÚT KHÓI HẦM XE, HÚT KHÓI SỰ CỐ Van ngăn cháy MFD 1250x1250 (EI60) | E27: 1250x1250 | F27: Cái | G27: 6 | H27: =SUMIF('01_BOC_TACH_ONG'!B:B, B27, '01_BOC_TACH_ONG'!K:K) | I27: =SUMIF('02_BOC_TACH_CUA'!B:B, B27, '02_BOC_TACH_CUA'!K:K) | J27: =SUMIF('03_BOC_TACH_VAN'!B:B, B27, '03_BOC_TACH_VAN'!K:K) | K27: =SUM(H27:J27) | L27: =K27*0.25 | M27: =K27*0.10 | N27: =K27+L27+M27 | O27: =IF(G27>0, N27/G27, 0) | P27: 0.18 | Q27: =O27*(1+P27) | R27: =G27*Q27
... A50: 49 | B50: SW-DIFF-049 | C50: CỬA GIÓ | D50: HỆ THỐNG HÚT KHÓI HẦM XE, HÚT KHÓI SỰ CỐ Box miệng gió 10006300 | E50: - | F50: Cái | G50: 52 | H50: =SUMIF('01_BOC_TACH_ONG'!B:B, B50, '01_BOC_TACH_ONG'!K:K) | I50: =SUMIF('02_BOC_TACH_CUA'!B:B, B50, '02_BOC_TACH_CUA'!K:K) | J50: =SUMIF('03_BOC_TACH_VAN'!B:B, B50, '03_BOC_TACH_VAN'!K:K) | K50: =SUM(H50:J50) | L50: =K50*0.25 | M50: =K50*0.10 | N50: =K50+L50+M50 | O50: =IF(G50>0, N50/G50, 0) | P50: 0.18 | Q50: =O50*(1+P50) | R50: =G50*Q50
A51: 50 | B51: SW-TRD-050 | C51: THƯƠNG MẠI | D51: HỆ THỐNG HÚT KHÓI HẦM XE, HÚT KHÓI SỰ CỐ Vật tư phụ, phụ kiện | E51: - | F51: Lô | G51: 1 | H51: =SUMIF('01_BOC_TACH_ONG'!B:B, B51, '01_BOC_TACH_ONG'!K:K) | I51: =SUMIF('02_BOC_TACH_CUA'!B:B, B51, '02_BOC_TACH_CUA'!K:K) | J51: =SUMIF('03_BOC_TACH_VAN'!B:B, B51, '03_BOC_TACH_VAN'!K:K) | K51: =SUM(H51:J51) | L51: =K51*0.00 | M51: =K51*0.02 | N51: =K51+L51+M51 | O51: =IF(G51>0, N51/G51, 0) | P51: 0.1 | Q51: =O51*(1+P51) | R51: =G51*Q51 | S51: Hàng thương mại
A52: 51 | B52: SW-DUCT-051 | C52: ỐNG GIÓ | D52: Ống thông gió và phụ kiện, box miệng gió Tole 0.75mm phủ lớp mạ kẽm Z180 | E52: 0.75mm | F52: m2 | G52: 2633.4 | H52: =SUMIF('01_BOC_TACH_ONG'!B:B, B52, '01_BOC_TACH_ONG'!K:K) | I52: =SUMIF('02_BOC_TACH_CUA'!B:B, B52, '02_BOC_TACH_CUA'!K:K) | J52: =SUMIF('03_BOC_TACH_VAN'!B:B, B52, '03_BOC_TACH_VAN'!K:K) | K52: =SUM(H52:J52) | L52: =K52*0.25 | M52: =K52*0.10 | N52: =K52+L52+M52 | O52: =IF(G52>0, N52/G52, 0) | P52: 0.18 | Q52: =O52*(1+P52) | R52: =G52*Q52
A53: 52 | B53: SW-DUCT-052 | C53: ỐNG GIÓ | D53: Ống thông gió và phụ kiện, box miệng gió Tole 0.95mm phủ lớp mạ kẽm Z180 | E53: 0.95mm | F53: m2 | G53: 1291.1 | H53: =SUMIF('01_BOC_TACH_ONG'!B:B, B53, '01_BOC_TACH_ONG'!K:K) | I53: =SUMIF('02_BOC_TACH_CUA'!B:B, B53, '02_BOC_TACH_CUA'!K:K) | J53: =SUMIF('03_BOC_TACH_VAN'!B:B, B53, '03_BOC_TACH_VAN'!K:K) | K53: =SUM(H53:J53) | L53: =K53*0.25 | M53: =K53*0.10 | N53: =K53+L53+M53 | O53: =IF(G53>0, N53/G53, 0) | P53: 0.18 | Q53: =O53*(1+P53) | R53: =G53*Q53
A54: 53 | B54: SW-DUCT-053 | C54: ỐNG GIÓ | D54: Ống thông gió và phụ kiện, box miệng gió Tole 1.15mm phủ lớp mạ kẽm Z180 | E54: 1.15mm | F54: m2 | G54: 3070.55 | H54: =SUMIF('01_BOC_TACH_ONG'!B:B, B54, '01_BOC_TACH_ONG'!K:K) | I54: =SUMIF('02_BOC_TACH_CUA'!B:B, B54, '02_BOC_TACH_CUA'!K:K) | J54: =SUMIF('03_BOC_TACH_VAN'!B:B, B54, '03_BOC_TACH_VAN'!K:K) | K54: =SUM(H54:J54) | L54: =K54*0.25 | M54: =K54*0.10 | N54: =K54+L54+M54 | O54: =IF(G54>0, N54/G54, 0) | P54: 0.18 | Q54: =O54*(1+P54) | R54: =G54*Q54
A55: 54 | B55: SW-DUCT-054 | C55: ỐNG GIÓ | D55: Ống thông gió và phụ kiện, box miệng gió Tole ZAM 1.15mm | E55: 1.15mm | F55: m2 | G55: 138 | H55: =SUMIF('01_BOC_TACH_ONG'!B:B, B55, '01_BOC_TACH_ONG'!K:K) | I55: =SUMIF('02_BOC_TACH_CUA'!B:B, B55, '02_BOC_TACH_CUA'!K:K) | J55: =SUMIF('03_BOC_TACH_VAN'!B:B, B55, '03_BOC_TACH_VAN'!K:K) | K55: =SUM(H55:J55) | L55: =K55*0.25 | M55: =K55*0.10 | N55: =K55+L55+M55 | O55: =IF(G55>0, N55/G55, 0) | P55: 0.18 | Q55: =O55*(1+P55) | R55: =G55*Q55
A56: 55 | B56: SW-TRD-055 | C56: THƯƠNG MẠI | D56: Ống thông gió và phụ kiện, box miệng gió Lưới bảo vệ | E56: - | F56: cái | G56: 3 | H56: =SUMIF('01_BOC_TACH_ONG'!B:B, B56, '01_BOC_TACH_ONG'!K:K) | I56: =SUMIF('02_BOC_TACH_CUA'!B:B, B56, '02_BOC_TACH_CUA'!K:K) | J56: =SUMIF('03_BOC_TACH_VAN'!B:B, B56, '03_BOC_TACH_VAN'!K:K) | K56: =SUM(H56:J56) | L56: =K56*0.00 | M56: =K56*0.02 | N56: =K56+L56+M56 | O56: =IF(G56>0, N56/G56, 0) | P56: 0.1 | Q56: =O56*(1+P56) | R56: =G56*Q56 | S56: Hàng thương mại
A57: 56 | B57: SW-TRD-056 | C57: THƯƠNG MẠI | D57: Ống thông gió và phụ kiện, box miệng gió Lớp chống cháy EI30 | E57: - | F57: m2 | G57: 3621.25 | H57: =SUMIF('01_BOC_TACH_ONG'!B:B, B57, '01_BOC_TACH_ONG'!K:K) | I57: =SUMIF('02_BOC_TACH_CUA'!B:B, B57, '02_BOC_TACH_CUA'!K:K) | J57: =SUMIF('03_BOC_TACH_VAN'!B:B, B57, '03_BOC_TACH_VAN'!K:K) | K57: =SUM(H57:J57) | L57: =K57*0.00 | M57: =K57*0.02 | N57: =K57+L57+M57 | O57: =IF(G57>0, N57/G57, 0) | P57: 0.1 | Q57: =O57*(1+P57) | R57: =G57*Q57 | S57: Hàng thương mại
A58: 57 | B58: SW-TRD-057 | C58: THƯƠNG MẠI | D58: Ống thông gió và phụ kiện, box miệng gió Lớp chống cháy EI60 | E58: - | F58: m2 | G58: 2821 | H58: =SUMIF('01_BOC_TACH_ONG'!B:B, B58, '01_BOC_TACH_ONG'!K:K) | I58: =SUMIF('02_BOC_TACH_CUA'!B:B, B58, '02_BOC_TACH_CUA'!K:K) | J58: =SUMIF('03_BOC_TACH_VAN'!B:B, B58, '03_BOC_TACH_VAN'!K:K) | K58: =SUM(H58:J58) | L58: =K58*0.00 | M58: =K58*0.02 | N58: =K58+L58+M58 | O58: =IF(G58>0, N58/G58, 0) | P58: 0.1 | Q58: =O58*(1+P58) | R58: =G58*Q58 | S58: Hàng thương mại
A59: 58 | B59: SW-TRD-058 | C59: THƯƠNG MẠI | D59: Ống thông gió và phụ kiện, box miệng gió Vật tư phụ, phụ kiện | E59: - | F59: Lô | G59: 1 | H59: =SUMIF('01_BOC_TACH_ONG'!B:B, B59, '01_BOC_TACH_ONG'!K:K) | I59: =SUMIF('02_BOC_TACH_CUA'!B:B, B59, '02_BOC_TACH_CUA'!K:K) | J59: =SUMIF('03_BOC_TACH_VAN'!B:B, B59, '03_BOC_TACH_VAN'!K:K) | K59: =SUM(H59:J59) | L59: =K59*0.00 | M59: =K59*0.02 | N59: =K59+L59+M59 | O59: =IF(G59>0, N59/G59, 0) | P59: 0.1 | Q59: =O59*(1+P59) | R59: =G59*Q59 | S59: Hàng thương mại
A60: 59 | B60: SW-TRD-059 | C60: THƯƠNG MẠI | D60: HỆ THỐNG TẠO ÁP Quạt hướng trục BPF-B2-Z2-01 400 l/s @ 650 Pa, chống cháy 300°C trong 2h | E60: - | F60: Cái | G60: 1 | H60: =SUMIF('01_BOC_TACH_ONG'!B:B, B60, '01_BOC_TACH_ONG'!K:K) | I60: =SUMIF('02_BOC_TACH_CUA'!B:B, B60, '02_BOC_TACH_CUA'!K:K) | J60: =SUMIF('03_BOC_TACH_VAN'!B:B, B60, '03_BOC_TACH_VAN'!K:K) | K60: =SUM(H60:J60) | L60: =K60*0.00 | M60: =K60*0.02 | N60: =K60+L60+M60 | O60: =IF(G60>0, N60/G60, 0) | P60: 0.1 | Q60: =O60*(1+P60) | R60: =G60*Q60 | S60: Hàng thương mại
A61: 60 | B61: SW-TRD-060 | C61: THƯƠNG MẠI | D61: HỆ THỐNG TẠO ÁP Quạt hướng trục BPF-B2-Z2-02 1200 l/s @ 550 Pa, chống cháy 300°C trong 2h | E61: - | F61: Cái | G61: 1 | H61: =SUMIF('01_BOC_TACH_ONG'!B:B, B61, '01_BOC_TACH_ONG'!K:K) | I61: =SUMIF('02_BOC_TACH_CUA'!B:B, B61, '02_BOC_TACH_CUA'!K:K) | J61: =SUMIF('03_BOC_TACH_VAN'!B:B, B61, '03_BOC_TACH_VAN'!K:K) | K61: =SUM(H61:J61) | L61: =K61*0.00 | M61: =K61*0.02 | N61: =K61+L61+M61 | O61: =IF(G61>0, N61/G61, 0) | P61: 0.1 | Q61: =O61*(1+P61) | R61: =G61*Q61 | S61: Hàng thương mại
A62: 61 | B62: SW-TRD-061 | C62: THƯƠNG MẠI | D62: HỆ THỐNG TẠO ÁP Quạt hướng trục BPF-B2-Z2-03 4200 l/s @ 400 Pa, chống cháy 300°C trong 2h | E62: - | F62: Cái | G62: 1 | H62: =SUMIF('01_BOC_TACH_ONG'!B:B, B62, '01_BOC_TACH_ONG'!K:K) | I62: =SUMIF('02_BOC_TACH_CUA'!B:B, B62, '02_BOC_TACH_CUA'!K:K) | J62: =SUMIF('03_BOC_TACH_VAN'!B:B, B62, '03_BOC_TACH_VAN'!K:K) | K62: =SUM(H62:J62) | L62: =K62*0.00 | M62: =K62*0.02 | N62: =K62+L62+M62 | O62: =IF(G62>0, N62/G62, 0) | P62: 0.1 | Q62: =O62*(1+P62) | R62: =G62*Q62 | S62: Hàng thương mại
A63: 62 | B63: SW-TRD-062 | C63: THƯƠNG MẠI | D63: HỆ THỐNG TẠO ÁP Quạt hướng trục BPF-B2-Z2-04 4200 l/s @ 400 Pa, chống cháy 300°C trong 2h | E63: - | F63: Cái | G63: 1 | H63: =SUMIF('01_BOC_TACH_ONG'!B:B, B63, '01_BOC_TACH_ONG'!K:K) | I63: =SUMIF('02_BOC_TACH_CUA'!B:B, B63, '02_BOC_TACH_CUA'!K:K) | J63: =SUMIF('03_BOC_TACH_VAN'!B:B, B63, '03_BOC_TACH_VAN'!K:K) | K63: =SUM(H63:J63) | L63: =K63*0.00 | M63: =K63*0.02 | N63: =K63+L63+M63 | O63: =IF(G63>0, N63/G63, 0) | P63: 0.1 | Q63: =O63*(1+P63) | R63: =G63*Q63 | S63: Hàng thương mại
...

Sheet 01_BOC_TACH_ONG
A1: SUB_KEY | B1: PARENT_ITEM_ID | C1: TÊN CẤU KIỆN | D1: PHÂN LOẠI | E1: MÃ VẬT TƯ (MAT_ID) | F1: ĐVT | G1: ĐỊNH MỨC / 1 SP | H1: SL DỰ ÁN | I1: TỔNG NHU CẦU | J1: ĐƠN GIÁ GỐC | K1: THÀNH TIỀN (VNĐ) | L1: GHI CHÚ KỸ THUẬT
A2: SW-TRD-001-TM | B2: SW-TRD-001 | C2: HỆ THỐNG HÚT KHÓI HẦM XE, HÚT KHÓI SỰ CỐ Quạt hướng trục CEF-B2-Z1-01~02 5290/9430 l/s @ 500/1350 Pa, chống cháy 300°C trong 2h, | D2: THUONG_MAI | E2: MAT-THUONG_MAI-HE_THONG_HUT_KHOI_HAM_XE_HUT_K_BDCE | F2: Cái | G2: 1 | H2: =IFERROR(INDEX('00_TONG_HOP_BAO_GIA'!$G$1:$G$5000, MATCH(B2, '00_TONG_HOP_BAO_GIA'!$B$1:$B$5000, 0)), 1) | I2: =G2*H2 | J2: =IFERROR(INDEX('06_BANG_GIA_VAT_TU_AP_DUNG'!$E$1:$E$5000, MATCH(E2, '06_BANG_GIA_VAT_TU_AP_DUNG'!$B$1:$B$5000, 0)), 0) | K2: =I2*J2 | L2: Hàng thương mại mua ngoài
A3: SW-TRD-002-TM | B3: SW-TRD-002 | C3: HỆ THỐNG HÚT KHÓI HẦM XE, HÚT KHÓI SỰ CỐ Quạt hướng trục CEF-B2-Z2-01~02 5490/8910 l/s @ 600/1350 Pa, chống cháy 300°C trong 2h | D3: THUONG_MAI | E3: MAT-THUONG_MAI-HE_THONG_HUT_KHOI_HAM_XE_HUT_K_5C8C | F3: Cái | G3: 1 | H3: =IFERROR(INDEX('00_TONG_HOP_BAO_GIA'!$G$1:$G$5000, MATCH(B3, '00_TONG_HOP_BAO_GIA'!$B$1:$B$5000, 0)), 1) | I3: =G3*H3 | J3: =IFERROR(INDEX('06_BANG_GIA_VAT_TU_AP_DUNG'!$E$1:$E$5000, MATCH(E3, '06_BANG_GIA_VAT_TU_AP_DUNG'!$B$1:$B$5000, 0)), 0) | K3: =I3*J3 | L3: Hàng thương mại mua ngoài
A4: SW-TRD-003-TM | B4: SW-TRD-003 | C4: HỆ THỐNG HÚT KHÓI HẦM XE, HÚT KHÓI SỰ CỐ Quạt hướng trục CEF-B1-Z1-01~02 5590/8385 l/s @ 600/1350 Pa, chống cháy 300°C trong 2h | D4: THUONG_MAI | E4: MAT-THUONG_MAI-HE_THONG_HUT_KHOI_HAM_XE_HUT_K_85A7 | F4: Cái | G4: 1 | H4: =IFERROR(INDEX('00_TONG_HOP_BAO_GIA'!$G$1:$G$5000, MATCH(B4, '00_TONG_HOP_BAO_GIA'!$B$1:$B$5000, 0)), 1) | I4: =G4*H4 | J4: =IFERROR(INDEX('06_BANG_GIA_VAT_TU_AP_DUNG'!$E$1:$E$5000, MATCH(E4, '06_BANG_GIA_VAT_TU_AP_DUNG'!$B$1:$B$5000, 0)), 0) | K4: =I4*J4 | L4: Hàng thương mại mua ngoài
A5: SW-TRD-004-TM | B5: SW-TRD-004 | C5: HỆ THỐNG HÚT KHÓI HẦM XE, HÚT KHÓI SỰ CỐ Quạt hướng trục CEF-B1-Z2-01~02 5135/7700 l/s @ 600/1350 Pa, chống cháy 300°C trong 2h | D5: THUONG_MAI | E5: MAT-THUONG_MAI-HE_THONG_HUT_KHOI_HAM_XE_HUT_K_50BF | F5: Cái | G5: 1 | H5: =IFERROR(INDEX('00_TONG_HOP_BAO_GIA'!$G$1:$G$5000, MATCH(B5, '00_TONG_HOP_BAO_GIA'!$B$1:$B$5000, 0)), 1) | I5: =G5*H5 | J5: =IFERROR(INDEX('06_BANG_GIA_VAT_TU_AP_DUNG'!$E$1:$E$5000, MATCH(E5, '06_BANG_GIA_VAT_TU_AP_DUNG'!$B$1:$B$5000, 0)), 0) | K5: =I5*J5 | L5: Hàng thương mại mua ngoài
A6: SW-TRD-005-TM | B6: SW-TRD-005 | C6: HỆ THỐNG HÚT KHÓI HẦM XE, HÚT KHÓI SỰ CỐ Quạt hướng trục SEF-B1-Z2-01 4800 l/s @ 500 Pa, chống cháy 300°C trong 2h | D6: THUONG_MAI | E6: MAT-THUONG_MAI-HE_THONG_HUT_KHOI_HAM_XE_HUT_K_C640 | F6: Cái | G6: 1 | H6: =IFERROR(INDEX('00_TONG_HOP_BAO_GIA'!$G$1:$G$5000, MATCH(B6, '00_TONG_HOP_BAO_GIA'!$B$1:$B$5000, 0)), 1) | I6: =G6*H6 | J6: =IFERROR(INDEX('06_BANG_GIA_VAT_TU_AP_DUNG'!$E$1:$E$5000, MATCH(E6, '06_BANG_GIA_VAT_TU_AP_DUNG'!$B$1:$B$5000, 0)), 0) | K6: =I6*J6 | L6: Hàng thương mại mua ngoài
A7: SW-TRD-006-TM | B7: SW-TRD-006 | C7: HỆ THỐNG HÚT KHÓI HẦM XE, HÚT KHÓI SỰ CỐ Quạt hướng trục SEF-A1.1-03F-01~02 7400 l/s @ 400 Pa, chống cháy 300°C trong 2h | D7: THUONG_MAI | E7: MAT-THUONG_MAI-HE_THONG_HUT_KHOI_HAM_XE_HUT_K_5E99 | F7: Cái | G7: 1 | H7: =IFERROR(INDEX('00_TONG_HOP_BAO_GIA'!$G$1:$G$5000, MATCH(B7, '00_TONG_HOP_BAO_GIA'!$B$1:$B$5000, 0)), 1) | I7: =G7*H7 | J7: =IFERROR(INDEX('06_BANG_GIA_VAT_TU_AP_DUNG'!$E$1:$E$5000, MATCH(E7, '06_BANG_GIA_VAT_TU_AP_DUNG'!$B$1:$B$5000, 0)), 0) | K7: =I7*J7 | L7: Hàng thương mại mua ngoài
A8: SW-TRD-007-TM | B8: SW-TRD-007 | C8: HỆ THỐNG HÚT KHÓI HẦM XE, HÚT KHÓI SỰ CỐ Quạt hướng trục SEF-A1.2-03F-01~02 6700 l/s @ 500 Pa, chống cháy 300°C trong 2h | D8: THUONG_MAI | E8: MAT-THUONG_MAI-HE_THONG_HUT_KHOI_HAM_XE_HUT_K_0135 | F8: Cái | G8: 1 | H8: =IFERROR(INDEX('00_TONG_HOP_BAO_GIA'!$G$1:$G$5000, MATCH(B8, '00_TONG_HOP_BAO_GIA'!$B$1:$B$5000, 0)), 1) | I8: =G8*H8 | J8: =IFERROR(INDEX('06_BANG_GIA_VAT_TU_AP_DUNG'!$E$1:$E$5000, MATCH(E8, '06_BANG_GIA_VAT_TU_AP_DUNG'!$B$1:$B$5000, 0)), 0) | K8: =I8*J8 | L8: Hàng thương mại mua ngoài
A9: SW-TRD-008-TM | B9: SW-TRD-008 | C9: HỆ THỐNG HÚT KHÓI HẦM XE, HÚT KHÓI SỰ CỐ Quạt hướng trục SEF-A1.2-03F-03 5100 l/s @ 500 Pa, chống cháy 300°C trong 2h | D9: THUONG_MAI | E9: MAT-THUONG_MAI-HE_THONG_HUT_KHOI_HAM_XE_HUT_K_8FEB | F9: Cái | G9: 1 | H9: =IFERROR(INDEX('00_TONG_HOP_BAO_GIA'!$G$1:$G$5000, MATCH(B9, '00_TONG_HOP_BAO_GIA'!$B$1:$B$5000, 0)), 1) | I9: =G9*H9 | J9: =IFERROR(INDEX('06_BANG_GIA_VAT_TU_AP_DUNG'!$E$1:$E$5000, MATCH(E9, '06_BANG_GIA_VAT_TU_AP_DUNG'!$B$1:$B$5000, 0)), 0) | K9: =I9*J9 | L9: Hàng thương mại mua ngoài
A10: SW-TRD-009-TM | B10: SW-TRD-009 | C10: HỆ THỐNG HÚT KHÓI HẦM XE, HÚT KHÓI SỰ CỐ Quạt hướng trục SEF-A1.3-03F-01~03 4800 l/s @ 500 Pa, chống cháy 300°C trong 2h | D10: THUONG_MAI | E10: MAT-THUONG_MAI-HE_THONG_HUT_KHOI_HAM_XE_HUT_K_5E9C | F10: Cái | G10: 1 | H10: =IFERROR(INDEX('00_TONG_HOP_BAO_GIA'!$G$1:$G$5000, MATCH(B10, '00_TONG_HOP_BAO_GIA'!$B$1:$B$5000, 0)), 1) | I10: =G10*H10 | J10: =IFERROR(INDEX('06_BANG_GIA_VAT_TU_AP_DUNG'!$E$1:$E$5000, MATCH(E10, '06_BANG_GIA_VAT_TU_AP_DUNG'!$B$1:$B$5000, 0)), 0) | K10: =I10*J10 | L10: Hàng thương mại mua ngoài
A11: SW-TRD-010-TM | B11: SW-TRD-010 | C11: HỆ THỐNG HÚT KHÓI HẦM XE, HÚT KHÓI SỰ CỐ Quạt hướng trục SEF-A1.3-03F-04 4800 l/s @ 450 Pa, chống cháy 300°C trong 2h | D11: THUONG_MAI | E11: MAT-THUONG_MAI-HE_THONG_HUT_KHOI_HAM_XE_HUT_K_2169 | F11: Cái | G11: 1 | H11: =IFERROR(INDEX('00_TONG_HOP_BAO_GIA'!$G$1:$G$5000, MATCH(B11, '00_TONG_HOP_BAO_GIA'!$B$1:$B$5000, 0)), 1) | I11: =G11*H11 | J11: =IFERROR(INDEX('06_BANG_GIA_VAT_TU_AP_DUNG'!$E$1:$E$5000, MATCH(E11, '06_BANG_GIA_VAT_TU_AP_DUNG'!$B$1:$B$5000, 0)), 0) | K11: =I11*J11 | L11: Hàng thương mại mua ngoài
A12: SW-TRD-011-TM | B12: SW-TRD-011 | C12: HỆ THỐNG HÚT KHÓI HẦM XE, HÚT KHÓI SỰ CỐ Quạt hướng trục SEF-A1.3-03F-05~07 4800 l/s @ 500 Pa, chống cháy 300°C trong 2h | D12: THUONG_MAI | E12: MAT-THUONG_MAI-HE_THONG_HUT_KHOI_HAM_XE_HUT_K_04CF | F12: Cái | G12: 1 | H12: =IFERROR(INDEX('00_TONG_HOP_BAO_GIA'!$G$1:$G$5000, MATCH(B12, '00_TONG_HOP_BAO_GIA'!$B$1:$B$5000, 0)), 1) | I12: =G12*H12 | J12: =IFERROR(INDEX('06_BANG_GIA_VAT_TU_AP_DUNG'!$E$1:$E$5000, MATCH(E12, '06_BANG_GIA_VAT_TU_AP_DUNG'!$B$1:$B$5000, 0)), 0) | K12: =I12*J12 | L12: Hàng thương mại mua ngoài
A13: SW-TRD-012-TM | B13: SW-TRD-012 | C13: HỆ THỐNG HÚT KHÓI HẦM XE, HÚT KHÓI SỰ CỐ Quạt hướng trục SEF-A1.3-10F-01 7100 l/s @ 600 Pa, chống cháy 300°C trong 2h | D13: THUONG_MAI | E13: MAT-THUONG_MAI-HE_THONG_HUT_KHOI_HAM_XE_HUT_K_6B0C | F13: Cái | G13: 1 | H13: =IFERROR(INDEX('00_TONG_HOP_BAO_GIA'!$G$1:$G$5000, MATCH(B13, '00_TONG_HOP_BAO_GIA'!$B$1:$B$5000, 0)), 1) | I13: =G13*H13 | J13: =IFERROR(INDEX('06_BANG_GIA_VAT_TU_AP_DUNG'!$E$1:$E$5000, MATCH(E13, '06_BANG_GIA_VAT_TU_AP_DUNG'!$B$1:$B$5000, 0)), 0) | K13: =I13*J13 | L13: Hàng thương mại mua ngoài
... A533: SW-TRD-636-TM | B533: SW-TRD-636 | C533: CHI PHÍ CHUNG Chi phí chống cháy lan | D533: THUONG_MAI | E533: MAT-THUONG_MAI-CHI_PHI_CHUNG_CHI_PHI_CHONG_CH_147A | F533: Lô | G533: 1 | H533: =IFERROR(INDEX('00_TONG_HOP_BAO_GIA'!$G$1:$G$5000, MATCH(B533, '00_TONG_HOP_BAO_GIA'!$B$1:$B$5000, 0)), 1) | I533: =G533*H533 | J533: =IFERROR(INDEX('06_BANG_GIA_VAT_TU_AP_DUNG'!$E$1:$E$5000, MATCH(E533, '06_BANG_GIA_VAT_TU_AP_DUNG'!$B$1:$B$5000, 0)), 0) | K533: =I533*J533 | L533: Hàng thương mại mua ngoài

Sheet 02_BOC_TACH_CUA
A1: SUB_KEY | B1: PARENT_ITEM_ID | C1: TÊN CẤU KIỆN | D1: PHÂN LOẠI | E1: MÃ VẬT TƯ (MAT_ID) | F1: ĐVT | G1: ĐỊNH MỨC / 1 SP | H1: SL DỰ ÁN | I1: TỔNG NHU CẦU | J1: ĐƠN GIÁ GỐC | K1: THÀNH TIỀN (VNĐ) | L1: GHI CHÚ KỸ THUẬT
A2: SW-DIFF-039-FRAME | B2: SW-DIFF-039 | C2: Khung nhôm định hình (BD) | D2: NHÔM_ĐỊNH_HÌNH | E2: MAT-ALU-KHUNG-BD | F2: kg | G2: 0.378 | H2: =IFERROR(INDEX('00_TONG_HOP_BAO_GIA'!$G$1:$G$5000, MATCH(B2, '00_TONG_HOP_BAO_GIA'!$B$1:$B$5000, 0)), 1) | I2: =G2*H2 | J2: =IFERROR(INDEX('06_BANG_GIA_VAT_TU_AP_DUNG'!$E$1:$E$5000, MATCH(E2, '06_BANG_GIA_VAT_TU_AP_DUNG'!$B$1:$B$5000, 0)), 0) | K2: =I2*J2 | L2: Dài cắt 1.89m @ 0.2kg/m
A3: SW-DIFF-039-BLADE | B3: SW-DIFF-039 | C3: Nan nhôm định hình (BD) | D3: NHÔM_ĐỊNH_HÌNH | E3: MAT-ALU-NAN-BD | F3: kg | G3: 0.431172 | H3: =IFERROR(INDEX('00_TONG_HOP_BAO_GIA'!$G$1:$G$5000, MATCH(B3, '00_TONG_HOP_BAO_GIA'!$B$1:$B$5000, 0)), 1) | I3: =G3*H3 | J3: =IFERROR(INDEX('06_BANG_GIA_VAT_TU_AP_DUNG'!$E$1:$E$5000, MATCH(E3, '06_BANG_GIA_VAT_TU_AP_DUNG'!$B$1:$B$5000, 0)), 0) | K3: =I3*J3 | L3: 12 nan dài 7.43m @ 0.058kg/m
A4: SW-DIFF-039-ACCESSORY | B4: SW-DIFF-039 | C4: Phụ kiện lắp ghép / Ke góc cửa gió | D4: PHỤ_KIỆN_CỬA | E4: MAT-DOOR-ACCESSORY | F4: Bộ | G4: 1 | H4: =IFERROR(INDEX('00_TONG_HOP_BAO_GIA'!$G$1:$G$5000, MATCH(B4, '00_TONG_HOP_BAO_GIA'!$B$1:$B$5000, 0)), 1) | I4: =G4*H4 | J4: =IFERROR(INDEX('06_BANG_GIA_VAT_TU_AP_DUNG'!$E$1:$E$5000, MATCH(E4, '06_BANG_GIA_VAT_TU_AP_DUNG'!$B$1:$B$5000, 0)), 0) | K4: =I4*J4 | L4: 4 ke góc chìm và vít ghép khung
A5: SW-DIFF-039-PAINT | B5: SW-DIFF-039 | C5: Sơn tĩnh điện tiêu chuẩn Polyester | D5: SƠN_TĨNH_ĐIỆN | E5: MAT-PAINT-POWDER | F5: m2 | G5: 0.27 | H5: =IFERROR(INDEX('00_TONG_HOP_BAO_GIA'!$G$1:$G$5000, MATCH(B5, '00_TONG_HOP_BAO_GIA'!$B$1:$B$5000, 0)), 1) | I5: =G5*H5 | J5: =IFERROR(INDEX('06_BANG_GIA_VAT_TU_AP_DUNG'!$E$1:$E$5000, MATCH(E5, '06_BANG_GIA_VAT_TU_AP_DUNG'!$B$1:$B$5000, 0)), 0) | K5: =I5*J5 | L5: Diện tích phủ sơn 0.270m2
A6: SW-DIFF-040-FRAME | B6: SW-DIFF-040 | C6: Khung nhôm định hình (BD) | D6: NHÔM_ĐỊNH_HÌNH | E6: MAT-ALU-KHUNG-BD | F6: kg | G6: 0.756 | H6: =IFERROR(INDEX('00_TONG_HOP_BAO_GIA'!$G$1:$G$5000, MATCH(B6, '00_TONG_HOP_BAO_GIA'!$B$1:$B$5000, 0)), 1) | I6: =G6*H6 | J6: =IFERROR(INDEX('06_BANG_GIA_VAT_TU_AP_DUNG'!$E$1:$E$5000, MATCH(E6, '06_BANG_GIA_VAT_TU_AP_DUNG'!$B$1:$B$5000, 0)), 0) | K6: =I6*J6 | L6: Dài cắt 3.78m @ 0.2kg/m
