Workbook
Name __: #REF!
Name _________________________________________________________________________________________________________tu4: {"'Sheet1'!$L$16"}
Name _______________________________________________________________________________________________________tu4: {"'Sheet1'!$L$16"}
Name _____________________________________________________________________________________________________tu4: {"'Sheet1'!$L$16"}
Name ___________________________________________________________________________________________________tu4: {"'Sheet1'!$L$16"}
Name _________________________________________________________________________________________________tu4: {"'Sheet1'!$L$16"}
Name _______________________________________________________________________________________________tu4: {"'Sheet1'!$L$16"}
Name _____________________________________________________________________________________________tu4: {"'Sheet1'!$L$16"}
Name ___________________________________________________________________________________________tu4: {"'Sheet1'!$L$16"}
Name _________________________________________________________________________________________tu4: {"'Sheet1'!$L$16"}
Name _______________________________________________________________________________________tu4: {"'Sheet1'!$L$16"}
Name _____________________________________________________________________________________tu4: {"'Sheet1'!$L$16"}
Name ___________________________________________________________________________________tu4: {"'Sheet1'!$L$16"}
Name _________________________________________________________________________________tu4: {"'Sheet1'!$L$16"}
Name _______________________________________________________________________________tu4: {"'Sheet1'!$L$16"}
Name _____________________________________________________________________________tu4: {"'Sheet1'!$L$16"}
Name ___________________________________________________________________________tu4: {"'Sheet1'!$L$16"}
Name _________________________________________________________________________tu4: {"'Sheet1'!$L$16"}
Name _______________________________________________________________________tu4: {"'Sheet1'!$L$16"}
Name _____________________________________________________________________tu4: {"'Sheet1'!$L$16"}
Name ___________________________________________________________________tu4: {"'Sheet1'!$L$16"}
Name _________________________________________________________________tu4: {"'Sheet1'!$L$16"}
Name _______________________________________________________________tu4: {"'Sheet1'!$L$16"}
Name _____________________________________________________________tu4: {"'Sheet1'!$L$16"}
Name ___________________________________________________________tu4: {"'Sheet1'!$L$16"}
Name _________________________________________________________tu4: {"'Sheet1'!$L$16"}
Name _______________________________________________________tu4: {"'Sheet1'!$L$16"}
Name _____________________________________________________tu4: {"'Sheet1'!$L$16"}
Name ___________________________________________________tu4: {"'Sheet1'!$L$16"}
Name _________________________________________________tu4: {"'Sheet1'!$L$16"}
Name _______________________________________________tu4: {"'Sheet1'!$L$16"}
Name _____________________________________________tu4: {"'Sheet1'!$L$16"}
Name ___________________________________________tu4: {"'Sheet1'!$L$16"}
Name _________________________________________tu4: {"'Sheet1'!$L$16"}
Name ________________________________________PPP3: #REF!
Name ________________________________________PPP33: #REF!
Name ________________________________________ppp34: #REF!
Name ________________________________________ppp3444: #REF!
Name _______________________________________tu4: {"'Sheet1'!$L$16"}
Name ______________________________________P3: #REF!
Name _____________________________________tu4: {"'Sheet1'!$L$16"}
Name ___________________________________tu4: {"'Sheet1'!$L$16"}
Name __________________________________tu4: {"'Sheet1'!$L$16"}
Name _________________________________tu4: {"'Sheet1'!$L$16"}
Name _______________________________tu4: {"'Sheet1'!$L$16"}
Name _____________________________tu4: {"'Sheet1'!$L$16"}
Name ____________________________PPP3: #REF!
Name ____________________________PPP33: #REF!
Name ____________________________ppp34: #REF!
Name ____________________________ppp3444: #REF!
Name ___________________________tu4: {"'Sheet1'!$L$16"}
Name __________________________P3: #REF!
Name __________________________PPP3: #REF!
Name __________________________PPP33: #REF!
Name __________________________ppp34: #REF!
Name __________________________ppp3444: #REF!
Name _________________________PPP3: #REF!
Name _________________________PPP33: #REF!
Name _________________________ppp34: #REF!
Name _________________________ppp3444: #REF!

Sheet BG Đơn Cánh ĐC FSLF 24V
C2: CÔNG TY CỔ PHẦN TẬP ĐOÀN QUỐC TẾ SLAND
C3: VPGD: SỐ 49, Ngõ 1295 Giải Phóng, Phường Hoàng Mai, TP Hà Nội
C4: Nhà máy: Thôn Nhân Hiền - xã Thường Tín - TP Hà Nội
C5: Hotline: 082 5577 999
A6: BẢNG BÁO GIÁ (PHƯƠNG ÁN 1: VAN MFD ĐƠN CÁNH - ĐỘNG CƠ BELIMO FSLF24V)
A7: Khách hàng : | M7: Số hiệu
A8: Địa chỉ : | M8: PT Kinh doanh
A9: Người nhận : | M9: Điện thoại
A10: Email: | C10: Số điện thoại : | M10: Dự án
A11: STT | B11: Danh mục sản phẩm | C11: Model | D11: Thương hiệu | E11: Kích thước (mm) | I11: Modul | J11: L | K11: Độ dày (mm) | L11: Unit Đơn vị | M11: Q'ty Số lượng | N11: Đơn Giá (VNĐ) | O11: Total price Thành tiền | P11: Remarks Ghi chú
E12: A1 | F12: A2 | G12: B1 | H12: B2
E13: Face size | G13: Neck size
B14: VẬT TƯ THI CÔNG P1B: (số BNH-ĐXVT-P1B-29-M-Van ống hồi gió lạnh L12 - P1B)
A15: 1 | B15: Van FD 1000x1200xL200 | C15: SWIND-2.01- E-FD-EI120 | D15: SWIND | E15: 1000 | F15: 1200 | G15: 1000 | H15: 600 | I15: 2 | J15: 200 | K15: 1.15 | L15: cái | M15: 1 | N15: =ROUND('00_TONG_HOP_BAO_GIA'!Q2, 0) | O15: =N15*M15 | P15: - Van chặn lửa cầu chì - Tiêu chuẩn EI 120 - 2 đầu bích TDC - gắn cầu chì 70-74 độ C - Sản xuất theo BCTN số: 4761/VLXD-TBMT - Chia 2 modul khi sản xuất
A16: 2 | B16: Van FD 1200x700xL200 | C16: SWIND-2.01- E-FD-EI120 | D16: SWIND | E16: 1200 | F16: 700 | J16: 200 | K16: 1.15 | L16: cái | M16: 1 | N16: =ROUND('00_TONG_HOP_BAO_GIA'!Q3, 0) | O16: =N16*M16 | P16: - Van chặn lửa cầu chì - Tiêu chuẩn EI 120 - 2 đầu bích TDC - gắn cầu chì 70-74 độ C - Sản xuất theo BCTN số: 4761/VLXD-TBMT
A17: 3 | B17: Van FD 1250x1000xL200 | C17: SWIND-2.01- E-FD-EI120 | D17: SWIND | E17: 1250 | F17: 1000 | G17: 1250 | H17: 500 | I17: 2 | J17: 200 | K17: 1.15 | L17: cái | M17: 2 | N17: =ROUND('00_TONG_HOP_BAO_GIA'!Q4, 0) | O17: =N17*M17 | P17: - Van chặn lửa cầu chì - Tiêu chuẩn EI 120 - 2 đầu bích TDC - gắn cầu chì 70-74 độ C - Sản xuất theo BCTN số: 4761/VLXD-TBMT - Chia 2 modul khi sản xuất
A18: 4 | B18: Van FD 1350x900xL200 | C18: SWIND-2.01- E-FD-EI120 | D18: SWIND | E18: 1350 | F18: 900 | G18: 1350 | H18: 450 | I18: 2 | J18: 200 | K18: 1.15 | L18: cái | M18: 1 | N18: =ROUND('00_TONG_HOP_BAO_GIA'!Q5, 0) | O18: =N18*M18 | P18: - Van chặn lửa cầu chì - Tiêu chuẩn EI 120 - 2 đầu bích TDC - gắn cầu chì 70-74 độ C - Sản xuất theo BCTN số: 4761/VLXD-TBMT - Chia 2 modul khi sản xuất
A19: 5 | B19: Van FD 1350x900xL300 | C19: SWIND-2.01- E-FD-EI120 | D19: SWIND | E19: 1350 | F19: 900 | G19: 1350 | H19: 450 | I19: 2 | J19: 200 | K19: 1.15 | L19: cái | M19: 1 | N19: =ROUND('00_TONG_HOP_BAO_GIA'!Q6, 0) | O19: =N19*M19 | P19: - Van chặn lửa cầu chì - Tiêu chuẩn EI 120 - 2 đầu bích TDC - gắn cầu chì 70-74 độ C - Sản xuất theo BCTN số: 4761/VLXD-TBMT - Chia 2 modul khi sản xuất
A20: 6 | B20: Van FD 1400x1100xL200 | C20: SWIND-2.01- E-FD-EI120 | D20: SWIND | E20: 1400 | F20: 1100 | G20: 1400 | H20: 550 | I20: 2 | J20: 200 | K20: 1.15 | L20: cái | M20: 1 | N20: =ROUND('00_TONG_HOP_BAO_GIA'!Q7, 0) | O20: =N20*M20 | P20: - Van chặn lửa cầu chì - Tiêu chuẩn EI 120 - 2 đầu bích TDC - gắn cầu chì 70-74 độ C - Sản xuất theo BCTN số: 4761/VLXD-TBMT - Chia 2 modul khi sản xuất
A21: 7 | B21: Van FD 1800x700xL200 | C21: SWIND-2.01- E-FD-EI120 | D21: SWIND | E21: 1800 | F21: 700 | G21: 900 | H21: 700 | I21: 2 | J21: 200 | K21: 1.15 | L21: cái | M21: 1 | N21: =ROUND('00_TONG_HOP_BAO_GIA'!Q8, 0) | O21: =N21*M21 | P21: - Van chặn lửa cầu chì - Tiêu chuẩn EI 120 - 2 đầu bích TDC - gắn cầu chì 70-74 độ C - Sản xuất theo BCTN số: 4761/VLXD-TBMT - Chia 2 modul khi sản xuất
A22: 8 | B22: Van FD 500x400xL200 | C22: SWIND-2.01- E-FD-EI120 | D22: SWIND | E22: 500 | F22: 400 | J22: 200 | K22: 1.15 | L22: cái | M22: 2 | N22: =ROUND('00_TONG_HOP_BAO_GIA'!Q9, 0) | O22: =N22*M22 | P22: - Van chặn lửa cầu chì - Tiêu chuẩn EI 120 - 2 đầu bích TDC - gắn cầu chì 70-74 độ C - Sản xuất theo BCTN số: 4761/VLXD-TBMT
A23: 9 | B23: Van FD 700x500xL200 | C23: SWIND-2.01- E-FD-EI120 | D23: SWIND | E23: 700 | F23: 500 | J23: 200 | K23: 1.15 | L23: cái | M23: 1 | N23: =ROUND('00_TONG_HOP_BAO_GIA'!Q10, 0) | O23: =N23*M23 | P23: - Van chặn lửa cầu chì - Tiêu chuẩn EI 120 - 2 đầu bích TDC - gắn cầu chì 70-74 độ C - Sản xuất theo BCTN số: 4761/VLXD-TBMT
A24: 10 | B24: Van FD 800x1550xL200 | C24: SWIND-2.01- E-FD-EI120 | D24: SWIND | E24: 800 | F24: 1550 | G24: 800 | H24: 775 | I24: 2 | J24: 200 | K24: 1.15 | L24: cái | M24: 1 | N24: =ROUND('00_TONG_HOP_BAO_GIA'!Q11, 0) | O24: =N24*M24 | P24: - Van chặn lửa cầu chì - Tiêu chuẩn EI 120 - 2 đầu bích TDC - gắn cầu chì 70-74 độ C - Sản xuất theo BCTN số: 4761/VLXD-TBMT - Chia 2 modul khi sản xuất
B25: VẬT TƯ THI CÔNG H1: (số BNH_DXVT_H1_29_M_Van MD, FD, VCD hệ HVAC trong phòng JS/DD, K1/DD, K1/AR, K1/K1 tầng 10-19 tòa H1)
A26: 11 | B26: Van chặn lửa MFD - EI45 - Kích thước: 150x100 | C26: SWIND-2.01- E-FD-EI120 | D26: SWIND | E26: 150 | F26: 100 | G26: 150 | H26: 150 | J26: 200 | K26: 1.15 | L26: Cái | M26: 39 | N26: =ROUND('00_TONG_HOP_BAO_GIA'!Q12, 0) | O26: =N26*M26 | P26: - Van chặn lửa cầu chì - Tiêu chuẩn EI 120 - 2 đầu bích TDC - gắn cầu chì 70-74 độ C - Sản xuất theo BCTN số: 4761/VLXD-TBMT - Van thu côn 2 đầu
A27: 12 | B27: Van chặn lửa MFD - EI45 - Kích thước: 150x150 | C27: SWIND-2.01- E-FD-EI120 | D27: SWIND | E27: 150 | F27: 150 | J27: 200 | K27: 1.15 | L27: Cái | M27: 19 | N27: =ROUND('00_TONG_HOP_BAO_GIA'!Q13, 0) | O27: =N27*M27 | P27: - Van chặn lửa cầu chì - Tiêu chuẩn EI 120 - 2 đầu bích TDC - gắn cầu chì 70-74 độ C - Sản xuất theo BCTN số: 4761/VLXD-TBMT
A28: 13 | B28: Van điều chỉnh lưu lượng VCD - Kích thước: 150x100 | C28: VCD | D28: SWIND | E28: 150 | F28: 100 | J28: 200 | K28: 0.75 | L28: Cái | M28: 63 | N28: =ROUND('00_TONG_HOP_BAO_GIA'!Q14, 0) | O28: =N28*M28 | P28: Van điều chỉnh lưu lượng tay gạt tôn mạ kẽm
A29: 14 | B29: Van điều chỉnh lưu lượng VCD - Kích thước: 150x150 | C29: VCD | D29: SWIND | E29: 150 | F29: 150 | J29: 200 | K29: 0.75 | L29: Cái | M29: 23 | N29: =ROUND('00_TONG_HOP_BAO_GIA'!Q15, 0) | O29: =N29*M29 | P29: Van điều chỉnh lưu lượng tay gạt tôn mạ kẽm
A30: 15 | B30: Van điều chỉnh lưu lượng VCD - Kích thước: 300x200 | C30: VCD | D30: SWIND | E30: 300 | F30: 200 | J30: 200 | K30: 0.75 | L30: Cái | M30: 2 | N30: =ROUND('00_TONG_HOP_BAO_GIA'!Q16, 0) | O30: =N30*M30 | P30: Van điều chỉnh lưu lượng tay gạt tôn mạ kẽm
A31: 16 | B31: Van điều gió MD - Kích thước: 150x100 | C31: MD | D31: SWIND | E31: 150 | F31: 100 | J31: 200 | K31: 0.75 | L31: Cái | M31: 41 | N31: =ROUND('00_TONG_HOP_BAO_GIA'!Q17, 0) | O31: =N31*M31 | P31: Van động cơ ON-OFF BELIMO (đóng mở 150s), xuất xứ Thụy Sỹ
A32: 17 | B32: Van điều gió MD - Kích thước: 150x150 | C32: MD | D32: SWIND | E32: 150 | F32: 150 | J32: 200 | K32: 0.75 | L32: Cái | M32: 14 | N32: =ROUND('00_TONG_HOP_BAO_GIA'!Q18, 0) | O32: =N32*M32 | P32: Van động cơ ON-OFF BELIMO (đóng mở 150s), xuất xứ Thụy Sỹ
B33: Van gió, miệng gió
A34: 18 | B34: Van chặn lửa MFD - EI45 - Kích thước: 150x100 | C34: SWIND-2.01- E-FD-EI120 | D34: SWIND | E34: 150 | F34: 100 | G34: 150 | H34: 150 | J34: 200 | K34: 1.15 | L34: Cái | M34: 46 | N34: =ROUND('00_TONG_HOP_BAO_GIA'!Q19, 0) | O34: =N34*M34 | P34: - Van chặn lửa cầu chì - Tiêu chuẩn EI 120 - 2 đầu bích TDC - gắn cầu chì 70-74 độ C - Sản xuất theo BCTN số: 4761/VLXD-TBMT - Van thu côn 2 đầu
A35: 19 | B35: Van chặn lửa MFD - EI45 - Kích thước: 150x150 | C35: SWIND-2.01- E-FD-EI120 | D35: SWIND | E35: 150 | F35: 150 | J35: 200 | K35: 1.15 | L35: Cái | M35: 9 | N35: =ROUND('00_TONG_HOP_BAO_GIA'!Q20, 0) | O35: =N35*M35 | P35: - Van chặn lửa cầu chì - Tiêu chuẩn EI 120 - 2 đầu bích TDC - gắn cầu chì 70-74 độ C - Sản xuất theo BCTN số: 4761/VLXD-TBMT
A36: 20 | B36: Van điều chỉnh lưu lượng VCD - Kích thước: 150x100 | C36: VCD | D36: SWIND | E36: 150 | F36: 100 | J36: 200 | K36: 0.75 | L36: Cái | M36: 37 | N36: =ROUND('00_TONG_HOP_BAO_GIA'!Q21, 0) | O36: =N36*M36 | P36: Van điều chỉnh lưu lượng tay gạt tôn mạ kẽm
A37: 21 | B37: Van điều chỉnh lưu lượng VCD - Kích thước: 150x150 | C37: VCD | D37: SWIND | E37: 150 | F37: 150 | J37: 200 | K37: 0.75 | L37: Cái | M37: 7 | N37: =ROUND('00_TONG_HOP_BAO_GIA'!Q22, 0) | O37: =N37*M37 | P37: Van điều chỉnh lưu lượng tay gạt tôn mạ kẽm
A38: 22 | B38: Van điều gió MD - Kích thước: 150x100 | C38: MD | D38: SWIND | E38: 150 | F38: 100 | J38: 200 | K38: 0.75 | L38: Cái | M38: 55 | N38: =ROUND('00_TONG_HOP_BAO_GIA'!Q23, 0) | O38: =N38*M38 | P38: Van động cơ ON-OFF BELIMO (đóng mở 150s), xuất xứ Thụy Sỹ
A39: 23 | B39: Chi phí kiểm định | L39: lô | M39: 1 | N39: =ROUND('00_TONG_HOP_BAO_GIA'!Q24, 0) | O39: =N39*M39 | P39: Hạng mục phụ trợ / Nhà thầu tự thực hiện
A40: 24 | B40: Vận chuyển | L40: lô | M40: 1 | N40: =ROUND('00_TONG_HOP_BAO_GIA'!Q25, 0) | O40: =N40*M40 | P40: Hạng mục phụ trợ / Nhà thầu tự thực hiện
B42: TỔNG CỘNG (CHƯA BAO GỒM VAT): | O42: =SUBTOTAL(9,O14:O40)
...

Sheet BG Đa Cánh BFN 24
C2: CÔNG TY CỔ PHẦN TẬP ĐOÀN QUỐC TẾ SLAND
C3: VPGD: SỐ 49, Ngõ 1295 Giải Phóng, Phường Hoàng Mai, TP Hà Nội
C4: Nhà máy: Thôn Nhân Hiền - xã Thường Tín - TP Hà Nội
C5: Hotline: 082 5577 999
A6: BẢNG BÁO GIÁ (PHƯƠNG ÁN 2: VAN MFD ĐA CÁNH - ĐỘNG CƠ BELIMO BFN24)
A7: Khách hàng : | M7: Số hiệu
A8: Địa chỉ : | M8: PT Kinh doanh
A9: Người nhận : | M9: Điện thoại
A10: Email: | C10: Số điện thoại : | M10: Dự án
A11: STT | B11: Danh mục sản phẩm | C11: Model | D11: Thương hiệu | E11: Kích thước (mm) | I11: Modul | J11: L | K11: Độ dày (mm) | L11: Unit Đơn vị | M11: Q'ty Số lượng | N11: Đơn Giá (VNĐ) | O11: Total price Thành tiền | P11: Remarks Ghi chú
E12: A1 | F12: A2 | G12: B1 | H12: B2
E13: Face size | G13: Neck size
B14: VẬT TƯ THI CÔNG P1B: (số BNH-ĐXVT-P1B-29-M-Van ống hồi gió lạnh L12 - P1B)
A15: 1 | B15: Van FD 1000x1200xL200 | C15: SWIND-2.01- E-FD-EI120 | D15: SWIND | E15: 1000 | F15: 1200 | G15: 1000 | H15: 600 | I15: 2 | J15: 200 | K15: 1.15 | L15: cái | M15: 1 | N15: =ROUND('00_TONG_HOP_BAO_GIA'!Q2, 0) | O15: =N15*M15 | P15: - Van chặn lửa cầu chì - Tiêu chuẩn EI 120 - 2 đầu bích TDC - gắn cầu chì 70-74 độ C - Sản xuất theo BCTN số: 4761/VLXD-TBMT - Chia 2 modul khi sản xuất
A16: 2 | B16: Van FD 1200x700xL200 | C16: SWIND-2.01- E-FD-EI120 | D16: SWIND | E16: 1200 | F16: 700 | J16: 200 | K16: 1.15 | L16: cái | M16: 1 | N16: =ROUND('00_TONG_HOP_BAO_GIA'!Q3, 0) | O16: =N16*M16 | P16: - Van chặn lửa cầu chì - Tiêu chuẩn EI 120 - 2 đầu bích TDC - gắn cầu chì 70-74 độ C - Sản xuất theo BCTN số: 4761/VLXD-TBMT
A17: 3 | B17: Van FD 1250x1000xL200 | C17: SWIND-2.01- E-FD-EI120 | D17: SWIND | E17: 1250 | F17: 1000 | G17: 1250 | H17: 500 | I17: 2 | J17: 200 | K17: 1.15 | L17: cái | M17: 2 | N17: =ROUND('00_TONG_HOP_BAO_GIA'!Q4, 0) | O17: =N17*M17 | P17: - Van chặn lửa cầu chì - Tiêu chuẩn EI 120 - 2 đầu bích TDC - gắn cầu chì 70-74 độ C - Sản xuất theo BCTN số: 4761/VLXD-TBMT - Chia 2 modul khi sản xuất
A18: 4 | B18: Van FD 1350x900xL200 | C18: SWIND-2.01- E-FD-EI120 | D18: SWIND | E18: 1350 | F18: 900 | G18: 1350 | H18: 450 | I18: 2 | J18: 200 | K18: 1.15 | L18: cái | M18: 1 | N18: =ROUND('00_TONG_HOP_BAO_GIA'!Q5, 0) | O18: =N18*M18 | P18: - Van chặn lửa cầu chì - Tiêu chuẩn EI 120 - 2 đầu bích TDC - gắn cầu chì 70-74 độ C - Sản xuất theo BCTN số: 4761/VLXD-TBMT - Chia 2 modul khi sản xuất
A19: 5 | B19: Van FD 1350x900xL300 | C19: SWIND-2.01- E-FD-EI120 | D19: SWIND | E19: 1350 | F19: 900 | G19: 1350 | H19: 450 | I19: 2 | J19: 200 | K19: 1.15 | L19: cái | M19: 1 | N19: =ROUND('00_TONG_HOP_BAO_GIA'!Q6, 0) | O19: =N19*M19 | P19: - Van chặn lửa cầu chì - Tiêu chuẩn EI 120 - 2 đầu bích TDC - gắn cầu chì 70-74 độ C - Sản xuất theo BCTN số: 4761/VLXD-TBMT - Chia 2 modul khi sản xuất
A20: 6 | B20: Van FD 1400x1100xL200 | C20: SWIND-2.01- E-FD-EI120 | D20: SWIND | E20: 1400 | F20: 1100 | G20: 1400 | H20: 550 | I20: 2 | J20: 200 | K20: 1.15 | L20: cái | M20: 1 | N20: =ROUND('00_TONG_HOP_BAO_GIA'!Q7, 0) | O20: =N20*M20 | P20: - Van chặn lửa cầu chì - Tiêu chuẩn EI 120 - 2 đầu bích TDC - gắn cầu chì 70-74 độ C - Sản xuất theo BCTN số: 4761/VLXD-TBMT - Chia 2 modul khi sản xuất
A21: 7 | B21: Van FD 1800x700xL200 | C21: SWIND-2.01- E-FD-EI120 | D21: SWIND | E21: 1800 | F21: 700 | G21: 900 | H21: 700 | I21: 2 | J21: 200 | K21: 1.15 | L21: cái | M21: 1 | N21: =ROUND('00_TONG_HOP_BAO_GIA'!Q8, 0) | O21: =N21*M21 | P21: - Van chặn lửa cầu chì - Tiêu chuẩn EI 120 - 2 đầu bích TDC - gắn cầu chì 70-74 độ C - Sản xuất theo BCTN số: 4761/VLXD-TBMT - Chia 2 modul khi sản xuất
A22: 8 | B22: Van FD 500x400xL200 | C22: SWIND-2.01- E-FD-EI120 | D22: SWIND | E22: 500 | F22: 400 | J22: 200 | K22: 1.15 | L22: cái | M22: 2 | N22: =ROUND('00_TONG_HOP_BAO_GIA'!Q9, 0) | O22: =N22*M22 | P22: - Van chặn lửa cầu chì - Tiêu chuẩn EI 120 - 2 đầu bích TDC - gắn cầu chì 70-74 độ C - Sản xuất theo BCTN số: 4761/VLXD-TBMT
A23: 9 | B23: Van FD 700x500xL200 | C23: SWIND-2.01- E-FD-EI120 | D23: SWIND | E23: 700 | F23: 500 | J23: 200 | K23: 1.15 | L23: cái | M23: 1 | N23: =ROUND('00_TONG_HOP_BAO_GIA'!Q10, 0) | O23: =N23*M23 | P23: - Van chặn lửa cầu chì - Tiêu chuẩn EI 120 - 2 đầu bích TDC - gắn cầu chì 70-74 độ C - Sản xuất theo BCTN số: 4761/VLXD-TBMT
A24: 10 | B24: Van FD 800x1550xL200 | C24: SWIND-2.01- E-FD-EI120 | D24: SWIND | E24: 800 | F24: 1550 | G24: 800 | H24: 775 | I24: 2 | J24: 200 | K24: 1.15 | L24: cái | M24: 1 | N24: =ROUND('00_TONG_HOP_BAO_GIA'!Q11, 0) | O24: =N24*M24 | P24: - Van chặn lửa cầu chì - Tiêu chuẩn EI 120 - 2 đầu bích TDC - gắn cầu chì 70-74 độ C - Sản xuất theo BCTN số: 4761/VLXD-TBMT - Chia 2 modul khi sản xuất
B25: VẬT TƯ THI CÔNG H1: (số BNH_DXVT_H1_29_M_Van MD, FD, VCD hệ HVAC trong phòng JS/DD, K1/DD, K1/AR, K1/K1 tầng 10-19 tòa H1)
A26: 11 | B26: Van chặn lửa MFD - EI45 - Kích thước: 150x100 | C26: SWIND-2.01- E-FD-EI120 | D26: SWIND | E26: 150 | F26: 100 | G26: 150 | H26: 150 | J26: 200 | K26: 1.15 | L26: Cái | M26: 39 | N26: =ROUND('00_TONG_HOP_BAO_GIA'!Q12, 0) | O26: =N26*M26 | P26: - Van chặn lửa cầu chì - Tiêu chuẩn EI 120 - 2 đầu bích TDC - gắn cầu chì 70-74 độ C - Sản xuất theo BCTN số: 4761/VLXD-TBMT - Van thu côn 2 đầu
A27: 12 | B27: Van chặn lửa MFD - EI45 - Kích thước: 150x150 | C27: SWIND-2.01- E-FD-EI120 | D27: SWIND | E27: 150 | F27: 150 | J27: 200 | K27: 1.15 | L27: Cái | M27: 19 | N27: =ROUND('00_TONG_HOP_BAO_GIA'!Q13, 0) | O27: =N27*M27 | P27: - Van chặn lửa cầu chì - Tiêu chuẩn EI 120 - 2 đầu bích TDC - gắn cầu chì 70-74 độ C - Sản xuất theo BCTN số: 4761/VLXD-TBMT
A28: 13 | B28: Van điều chỉnh lưu lượng VCD - Kích thước: 150x100 | C28: VCD | D28: SWIND | E28: 150 | F28: 100 | J28: 200 | K28: 0.75 | L28: Cái | M28: 63 | N28: =ROUND('00_TONG_HOP_BAO_GIA'!Q14, 0) | O28: =N28*M28 | P28: Van điều chỉnh lưu lượng tay gạt tôn mạ kẽm
A29: 14 | B29: Van điều chỉnh lưu lượng VCD - Kích thước: 150x150 | C29: VCD | D29: SWIND | E29: 150 | F29: 150 | J29: 200 | K29: 0.75 | L29: Cái | M29: 23 | N29: =ROUND('00_TONG_HOP_BAO_GIA'!Q15, 0) | O29: =N29*M29 | P29: Van điều chỉnh lưu lượng tay gạt tôn mạ kẽm
A30: 15 | B30: Van điều chỉnh lưu lượng VCD - Kích thước: 300x200 | C30: VCD | D30: SWIND | E30: 300 | F30: 200 | J30: 200 | K30: 0.75 | L30: Cái | M30: 2 | N30: =ROUND('00_TONG_HOP_BAO_GIA'!Q16, 0) | O30: =N30*M30 | P30: Van điều chỉnh lưu lượng tay gạt tôn mạ kẽm
A31: 16 | B31: Van điều gió MD - Kích thước: 150x100 | C31: MD | D31: SWIND | E31: 150 | F31: 100 | J31: 200 | K31: 0.75 | L31: Cái | M31: 41 | N31: =ROUND('00_TONG_HOP_BAO_GIA'!Q17, 0) | O31: =N31*M31 | P31: Van động cơ ON-OFF BELIMO (đóng mở 150s), xuất xứ Thụy Sỹ
A32: 17 | B32: Van điều gió MD - Kích thước: 150x150 | C32: MD | D32: SWIND | E32: 150 | F32: 150 | J32: 200 | K32: 0.75 | L32: Cái | M32: 14 | N32: =ROUND('00_TONG_HOP_BAO_GIA'!Q18, 0) | O32: =N32*M32 | P32: Van động cơ ON-OFF BELIMO (đóng mở 150s), xuất xứ Thụy Sỹ
B33: Van gió, miệng gió
A34: 18 | B34: Van chặn lửa MFD - EI45 - Kích thước: 150x100 | C34: SWIND-2.01- E-FD-EI120 | D34: SWIND | E34: 150 | F34: 100 | G34: 150 | H34: 150 | J34: 200 | K34: 1.15 | L34: Cái | M34: 46 | N34: =ROUND('00_TONG_HOP_BAO_GIA'!Q19, 0) | O34: =N34*M34 | P34: - Van chặn lửa cầu chì - Tiêu chuẩn EI 120 - 2 đầu bích TDC - gắn cầu chì 70-74 độ C - Sản xuất theo BCTN số: 4761/VLXD-TBMT - Van thu côn 2 đầu
A35: 19 | B35: Van chặn lửa MFD - EI45 - Kích thước: 150x150 | C35: SWIND-2.01- E-FD-EI120 | D35: SWIND | E35: 150 | F35: 150 | J35: 200 | K35: 1.15 | L35: Cái | M35: 9 | N35: =ROUND('00_TONG_HOP_BAO_GIA'!Q20, 0) | O35: =N35*M35 | P35: - Van chặn lửa cầu chì - Tiêu chuẩn EI 120 - 2 đầu bích TDC - gắn cầu chì 70-74 độ C - Sản xuất theo BCTN số: 4761/VLXD-TBMT
A36: 20 | B36: Van điều chỉnh lưu lượng VCD - Kích thước: 150x100 | C36: VCD | D36: SWIND | E36: 150 | F36: 100 | J36: 200 | K36: 0.75 | L36: Cái | M36: 37 | N36: =ROUND('00_TONG_HOP_BAO_GIA'!Q21, 0) | O36: =N36*M36 | P36: Van điều chỉnh lưu lượng tay gạt tôn mạ kẽm
A37: 21 | B37: Van điều chỉnh lưu lượng VCD - Kích thước: 150x150 | C37: VCD | D37: SWIND | E37: 150 | F37: 150 | J37: 200 | K37: 0.75 | L37: Cái | M37: 7 | N37: =ROUND('00_TONG_HOP_BAO_GIA'!Q22, 0) | O37: =N37*M37 | P37: Van điều chỉnh lưu lượng tay gạt tôn mạ kẽm
A38: 22 | B38: Van điều gió MD - Kích thước: 150x100 | C38: MD | D38: SWIND | E38: 150 | F38: 100 | J38: 200 | K38: 0.75 | L38: Cái | M38: 55 | N38: =ROUND('00_TONG_HOP_BAO_GIA'!Q23, 0) | O38: =N38*M38 | P38: Van động cơ ON-OFF BELIMO (đóng mở 150s), xuất xứ Thụy Sỹ
A39: 23 | B39: Chi phí kiểm định | L39: lô | M39: 1 | N39: =ROUND('00_TONG_HOP_BAO_GIA'!Q24, 0) | O39: =N39*M39 | P39: Hạng mục phụ trợ / Nhà thầu tự thực hiện
A40: 24 | B40: Vận chuyển | L40: lô | M40: 1 | N40: =ROUND('00_TONG_HOP_BAO_GIA'!Q25, 0) | O40: =N40*M40 | P40: Hạng mục phụ trợ / Nhà thầu tự thực hiện
B42: TỔNG CỘNG (CHƯA BAO GỒM VAT): | O42: =SUBTOTAL(9,O14:O40)
...

Sheet 00_BANG_CHAO_GIA
D2: CÔNG TY CỔ PHẦN TẬP ĐOÀN QUỐC TẾ SLAND
D3: VPGD: SỐ 49, Ngõ 1295 Giải Phóng, Phường Hoàng Mai, TP Hà Nội
D4: Nhà máy: Thôn Nhân Hiền- xã Thường Tín - TP Hà Nội
D5: Hotline: 082 5577 999
A6: LỆNH SẢN XUẤT 03 - NAM VIỆT ĐƠN SỐ 43
A7: Khách hàng : | N7: Seri number Số hiệu
A8: Địa chỉ : | N8: Sales executive PT Kinh doanh | Q8: Ms Nhài
A9: Người nhận : | N9: Mobile Điện thoại | Q9: 0945588248
A10: Email: | D10: Số điện thoại : | N10: Dự án
A11: STT | B11: Tên vật tư theo hồ sơ đệ trình/Nhà cung cấp | C11: Theo Nhà Sản Xuất | D11: Model | E11: Thương hiệu | F11: Kích thước (mm) | J11: Modul | K11: L | L11: Độ dày (m) | M11: Unit Đơn vị | N11: Q'ty Số lượng | O11: Price Đơn giá | P11: Total price Thành tiền | Q11: Remarks Ghi chú
F12: A1 | G12: A2 | H12: B1 | I12: B2
F13: Face size | H13: Neck size
B15: VẬT TƯ THI CÔNG P1B: (số BNH-ĐXVT-P1B-29-M-Van ống hồi gió lạnh L12 - P1B)
B16: Van FD 1000x1200xL200 | C16: Van FD kích thước 1000x1200 L200 | D16: SWIND-2.01- E-FD-EI120 | E16: Swind | F16: 1000 | G16: 1200 | H16: 1000 | I16: =IF('00_TONG_HOP_BAO_GIA'!G2>0, ('00_TONG_HOP_BAO_GIA'!K2 + '00_TONG_HOP_BAO_GIA'!M2) * (1 + '00_TONG_HOP_BAO_GIA'!P2) / '00_TONG_HOP_BAO_GIA'!G2, 0) | J16: =IF('00_TONG_HOP_BAO_GIA'!G2>0, '00_TONG_HOP_BAO_GIA'!L2 * (1 + '00_TONG_HOP_BAO_GIA'!P2) / '00_TONG_HOP_BAO_GIA'!G2, 0) | K16: ='00_TONG_HOP_BAO_GIA'!Q2 | L16: =('00_TONG_HOP_BAO_GIA'!K2 + '00_TONG_HOP_BAO_GIA'!M2) * (1 + '00_TONG_HOP_BAO_GIA'!P2) | M16: ='00_TONG_HOP_BAO_GIA'!L2 * (1 + '00_TONG_HOP_BAO_GIA'!P2) | N16: ='00_TONG_HOP_BAO_GIA'!R2 | O16: =IF(K16=0, "CẢNH BÁO: Đơn giá = 0. Tra cứu lại Sheet 06!", '00_TONG_HOP_BAO_GIA'!S2) | P16: =O16*N16 | Q16: Van chặn lửa SWIND-E-FD - Tiêu chuẩn EI 120 2 đầu bích TDC - gắn cầu chì 72- 74 độ C Sản xuất theo BCTN số: 4761/VLXD-TBMT , chia 2 modul khi san xuat | R16: check kỹ thuật van lắp đứng hay nằm
B17: Van FD 1200x700xL200 | C17: Van FD kích thước 1200x700 L200 | D17: SWIND-2.01- E-FD-EI120 | E17: Swind | F17: 1200 | G17: 700 | I17: =IF('00_TONG_HOP_BAO_GIA'!G3>0, ('00_TONG_HOP_BAO_GIA'!K3 + '00_TONG_HOP_BAO_GIA'!M3) * (1 + '00_TONG_HOP_BAO_GIA'!P3) / '00_TONG_HOP_BAO_GIA'!G3, 0) | J17: =IF('00_TONG_HOP_BAO_GIA'!G3>0, '00_TONG_HOP_BAO_GIA'!L3 * (1 + '00_TONG_HOP_BAO_GIA'!P3) / '00_TONG_HOP_BAO_GIA'!G3, 0) | K17: ='00_TONG_HOP_BAO_GIA'!Q3 | L17: =('00_TONG_HOP_BAO_GIA'!K3 + '00_TONG_HOP_BAO_GIA'!M3) * (1 + '00_TONG_HOP_BAO_GIA'!P3) | M17: ='00_TONG_HOP_BAO_GIA'!L3 * (1 + '00_TONG_HOP_BAO_GIA'!P3) | N17: ='00_TONG_HOP_BAO_GIA'!R3 | O17: =IF(K17=0, "CẢNH BÁO: Đơn giá = 0. Tra cứu lại Sheet 06!", '00_TONG_HOP_BAO_GIA'!S3) | P17: =O17*N17 | Q17: Van chặn lửa SWIND-E-FD - Tiêu chuẩn EI 120 2 đầu bích TDC - gắn cầu chì 72- 74 độ C Sản xuất theo BCTN số: 4761/VLXD-TBMT
B18: Van FD 1250x1000xL200 | C18: Van FD kích thước 1250x1000 L200 | D18: SWIND-2.01- E-FD-EI120 | E18: Swind | F18: 1250 | G18: 1000 | H18: 1250 | I18: =IF('00_TONG_HOP_BAO_GIA'!G4>0, ('00_TONG_HOP_BAO_GIA'!K4 + '00_TONG_HOP_BAO_GIA'!M4) * (1 + '00_TONG_HOP_BAO_GIA'!P4) / '00_TONG_HOP_BAO_GIA'!G4, 0) | J18: =IF('00_TONG_HOP_BAO_GIA'!G4>0, '00_TONG_HOP_BAO_GIA'!L4 * (1 + '00_TONG_HOP_BAO_GIA'!P4) / '00_TONG_HOP_BAO_GIA'!G4, 0) | K18: ='00_TONG_HOP_BAO_GIA'!Q4 | L18: =('00_TONG_HOP_BAO_GIA'!K4 + '00_TONG_HOP_BAO_GIA'!M4) * (1 + '00_TONG_HOP_BAO_GIA'!P4) | M18: ='00_TONG_HOP_BAO_GIA'!L4 * (1 + '00_TONG_HOP_BAO_GIA'!P4) | N18: ='00_TONG_HOP_BAO_GIA'!R4 | O18: =IF(K18=0, "CẢNH BÁO: Đơn giá = 0. Tra cứu lại Sheet 06!", '00_TONG_HOP_BAO_GIA'!S4) | P18: =O18*N18 | Q18: Van chặn lửa SWIND-E-FD - Tiêu chuẩn EI 120 2 đầu bích TDC - gắn cầu chì 72- 74 độ C Sản xuất theo BCTN số: 4761/VLXD-TBMT , chia 2 modul khi san xuat
B19: Van FD 1350x900xL200 | C19: Van FD kích thước 1350x900 L200 | D19: SWIND-2.01- E-FD-EI120 | E19: Swind | F19: 1350 | G19: 900 | H19: 1350 | I19: =IF('00_TONG_HOP_BAO_GIA'!G5>0, ('00_TONG_HOP_BAO_GIA'!K5 + '00_TONG_HOP_BAO_GIA'!M5) * (1 + '00_TONG_HOP_BAO_GIA'!P5) / '00_TONG_HOP_BAO_GIA'!G5, 0) | J19: =IF('00_TONG_HOP_BAO_GIA'!G5>0, '00_TONG_HOP_BAO_GIA'!L5 * (1 + '00_TONG_HOP_BAO_GIA'!P5) / '00_TONG_HOP_BAO_GIA'!G5, 0) | K19: ='00_TONG_HOP_BAO_GIA'!Q5 | L19: =('00_TONG_HOP_BAO_GIA'!K5 + '00_TONG_HOP_BAO_GIA'!M5) * (1 + '00_TONG_HOP_BAO_GIA'!P5) | M19: ='00_TONG_HOP_BAO_GIA'!L5 * (1 + '00_TONG_HOP_BAO_GIA'!P5) | N19: ='00_TONG_HOP_BAO_GIA'!R5 | O19: =IF(K19=0, "CẢNH BÁO: Đơn giá = 0. Tra cứu lại Sheet 06!", '00_TONG_HOP_BAO_GIA'!S5) | P19: =O19*N19 | Q19: Van chặn lửa SWIND-E-FD - Tiêu chuẩn EI 120 2 đầu bích TDC - gắn cầu chì 72- 74 độ C Sản xuất theo BCTN số: 4761/VLXD-TBMT , chia 2 modul khi san xuat
B20: Van FD 1350x900xL300 | C20: Van FD kích thước 1350x900 L200 | D20: SWIND-2.01- E-FD-EI120 | E20: Swind | F20: 1350 | G20: 900 | H20: 1350 | I20: =IF('00_TONG_HOP_BAO_GIA'!G6>0, ('00_TONG_HOP_BAO_GIA'!K6 + '00_TONG_HOP_BAO_GIA'!M6) * (1 + '00_TONG_HOP_BAO_GIA'!P6) / '00_TONG_HOP_BAO_GIA'!G6, 0) | J20: =IF('00_TONG_HOP_BAO_GIA'!G6>0, '00_TONG_HOP_BAO_GIA'!L6 * (1 + '00_TONG_HOP_BAO_GIA'!P6) / '00_TONG_HOP_BAO_GIA'!G6, 0) | K20: ='00_TONG_HOP_BAO_GIA'!Q6 | L20: =('00_TONG_HOP_BAO_GIA'!K6 + '00_TONG_HOP_BAO_GIA'!M6) * (1 + '00_TONG_HOP_BAO_GIA'!P6) | M20: ='00_TONG_HOP_BAO_GIA'!L6 * (1 + '00_TONG_HOP_BAO_GIA'!P6) | N20: ='00_TONG_HOP_BAO_GIA'!R6 | O20: =IF(K20=0, "CẢNH BÁO: Đơn giá = 0. Tra cứu lại Sheet 06!", '00_TONG_HOP_BAO_GIA'!S6) | P20: =O20*N20 | Q20: Van chặn lửa SWIND-E-FD - Tiêu chuẩn EI 120 2 đầu bích TDC - gắn cầu chì 72- 74 độ C Sản xuất theo BCTN số: 4761/VLXD-TBMT , chia 2 modul khi san xuat
B21: Van FD 1400x1100xL200 | C21: Van FD kích thước 1400x1100 L200 | D21: SWIND-2.01- E-FD-EI120 | E21: Swind | F21: 1400 | G21: 1100 | H21: 1400 | I21: =IF('00_TONG_HOP_BAO_GIA'!G7>0, ('00_TONG_HOP_BAO_GIA'!K7 + '00_TONG_HOP_BAO_GIA'!M7) * (1 + '00_TONG_HOP_BAO_GIA'!P7) / '00_TONG_HOP_BAO_GIA'!G7, 0) | J21: =IF('00_TONG_HOP_BAO_GIA'!G7>0, '00_TONG_HOP_BAO_GIA'!L7 * (1 + '00_TONG_HOP_BAO_GIA'!P7) / '00_TONG_HOP_BAO_GIA'!G7, 0) | K21: ='00_TONG_HOP_BAO_GIA'!Q7 | L21: =('00_TONG_HOP_BAO_GIA'!K7 + '00_TONG_HOP_BAO_GIA'!M7) * (1 + '00_TONG_HOP_BAO_GIA'!P7) | M21: ='00_TONG_HOP_BAO_GIA'!L7 * (1 + '00_TONG_HOP_BAO_GIA'!P7) | N21: ='00_TONG_HOP_BAO_GIA'!R7 | O21: =IF(K21=0, "CẢNH BÁO: Đơn giá = 0. Tra cứu lại Sheet 06!", '00_TONG_HOP_BAO_GIA'!S7) | P21: =O21*N21 | Q21: Van chặn lửa SWIND-E-FD - Tiêu chuẩn EI 120 2 đầu bích TDC - gắn cầu chì 72- 74 độ C Sản xuất theo BCTN số: 4761/VLXD-TBMT , chia 2 modul khi san xuat | R21: báo giá cũ chưa nhân modul
B22: Van FD 1800x700xL200 | C22: Van FD kích thước 1800x700 L200 | D22: SWIND-2.01- E-FD-EI120 | E22: Swind | F22: 1800 | G22: 700 | H22: 865 | I22: =IF('00_TONG_HOP_BAO_GIA'!G8>0, ('00_TONG_HOP_BAO_GIA'!K8 + '00_TONG_HOP_BAO_GIA'!M8) * (1 + '00_TONG_HOP_BAO_GIA'!P8) / '00_TONG_HOP_BAO_GIA'!G8, 0) | J22: =IF('00_TONG_HOP_BAO_GIA'!G8>0, '00_TONG_HOP_BAO_GIA'!L8 * (1 + '00_TONG_HOP_BAO_GIA'!P8) / '00_TONG_HOP_BAO_GIA'!G8, 0) | K22: ='00_TONG_HOP_BAO_GIA'!Q8 | L22: =('00_TONG_HOP_BAO_GIA'!K8 + '00_TONG_HOP_BAO_GIA'!M8) * (1 + '00_TONG_HOP_BAO_GIA'!P8) | M22: ='00_TONG_HOP_BAO_GIA'!L8 * (1 + '00_TONG_HOP_BAO_GIA'!P8) | N22: ='00_TONG_HOP_BAO_GIA'!R8 | O22: =IF(K22=0, "CẢNH BÁO: Đơn giá = 0. Tra cứu lại Sheet 06!", '00_TONG_HOP_BAO_GIA'!S8) | P22: =O22*N22 | Q22: Van chặn lửa SWIND-E-FD - Tiêu chuẩn EI 120 2 đầu bích TDC - gắn cầu chì 72- 74 độ C Sản xuất theo BCTN số: 4761/VLXD-TBMT , chia 2 modul khi san xuat
B23: Van FD 500x400xL200 | C23: Van FD kích thước 500x400 L200 | D23: SWIND-2.01- E-FD-EI120 | E23: Swind | F23: 500 | G23: 400 | I23: =IF('00_TONG_HOP_BAO_GIA'!G9>0, ('00_TONG_HOP_BAO_GIA'!K9 + '00_TONG_HOP_BAO_GIA'!M9) * (1 + '00_TONG_HOP_BAO_GIA'!P9) / '00_TONG_HOP_BAO_GIA'!G9, 0) | J23: =IF('00_TONG_HOP_BAO_GIA'!G9>0, '00_TONG_HOP_BAO_GIA'!L9 * (1 + '00_TONG_HOP_BAO_GIA'!P9) / '00_TONG_HOP_BAO_GIA'!G9, 0) | K23: ='00_TONG_HOP_BAO_GIA'!Q9 | L23: =('00_TONG_HOP_BAO_GIA'!K9 + '00_TONG_HOP_BAO_GIA'!M9) * (1 + '00_TONG_HOP_BAO_GIA'!P9) | M23: ='00_TONG_HOP_BAO_GIA'!L9 * (1 + '00_TONG_HOP_BAO_GIA'!P9) | N23: ='00_TONG_HOP_BAO_GIA'!R9 | O23: =IF(K23=0, "CẢNH BÁO: Đơn giá = 0. Tra cứu lại Sheet 06!", '00_TONG_HOP_BAO_GIA'!S9) | P23: =O23*N23 | Q23: Van chặn lửa SWIND-E-FD - Tiêu chuẩn EI 120 2 đầu bích TDC - gắn cầu chì 72- 74 độ C Sản xuất theo BCTN số: 4761/VLXD-TBMT
B24: Van FD 700x500xL200 | C24: Van FD kích thước 700x500 L200 | D24: SWIND-2.01- E-FD-EI120 | E24: Swind | F24: 700 | G24: 500 | I24: =IF('00_TONG_HOP_BAO_GIA'!G10>0, ('00_TONG_HOP_BAO_GIA'!K10 + '00_TONG_HOP_BAO_GIA'!M10) * (1 + '00_TONG_HOP_BAO_GIA'!P10) / '00_TONG_HOP_BAO_GIA'!G10, 0) | J24: =IF('00_TONG_HOP_BAO_GIA'!G10>0, '00_TONG_HOP_BAO_GIA'!L10 * (1 + '00_TONG_HOP_BAO_GIA'!P10) / '00_TONG_HOP_BAO_GIA'!G10, 0) | K24: ='00_TONG_HOP_BAO_GIA'!Q10 | L24: =('00_TONG_HOP_BAO_GIA'!K10 + '00_TONG_HOP_BAO_GIA'!M10) * (1 + '00_TONG_HOP_BAO_GIA'!P10) | M24: ='00_TONG_HOP_BAO_GIA'!L10 * (1 + '00_TONG_HOP_BAO_GIA'!P10) | N24: ='00_TONG_HOP_BAO_GIA'!R10 | O24: =IF(K24=0, "CẢNH BÁO: Đơn giá = 0. Tra cứu lại Sheet 06!", '00_TONG_HOP_BAO_GIA'!S10) | P24: =O24*N24 | Q24: Van chặn lửa SWIND-E-FD - Tiêu chuẩn EI 120 2 đầu bích TDC - gắn cầu chì 72- 74 độ C Sản xuất theo BCTN số: 4761/VLXD-TBMT
B25: Van FD 800x1550xL200 | C25: Van FD kích thước 800x1550 L200 | D25: SWIND-2.01- E-FD-EI120 | E25: Swind | F25: 800 | G25: 1550 | H25: 800 | I25: =IF('00_TONG_HOP_BAO_GIA'!G11>0, ('00_TONG_HOP_BAO_GIA'!K11 + '00_TONG_HOP_BAO_GIA'!M11) * (1 + '00_TONG_HOP_BAO_GIA'!P11) / '00_TONG_HOP_BAO_GIA'!G11, 0) | J25: =IF('00_TONG_HOP_BAO_GIA'!G11>0, '00_TONG_HOP_BAO_GIA'!L11 * (1 + '00_TONG_HOP_BAO_GIA'!P11) / '00_TONG_HOP_BAO_GIA'!G11, 0) | K25: ='00_TONG_HOP_BAO_GIA'!Q11 | L25: =('00_TONG_HOP_BAO_GIA'!K11 + '00_TONG_HOP_BAO_GIA'!M11) * (1 + '00_TONG_HOP_BAO_GIA'!P11) | M25: ='00_TONG_HOP_BAO_GIA'!L11 * (1 + '00_TONG_HOP_BAO_GIA'!P11) | N25: ='00_TONG_HOP_BAO_GIA'!R11 | O25: =IF(K25=0, "CẢNH BÁO: Đơn giá = 0. Tra cứu lại Sheet 06!", '00_TONG_HOP_BAO_GIA'!S11) | P25: =O25*N25 | Q25: Van chặn lửa SWIND-E-FD - Tiêu chuẩn EI 120 2 đầu bích TDC - gắn cầu chì 72- 74 độ C Sản xuất theo BCTN số: 4761/VLXD-TBMT , chia 2 modul khi san xuat | R25: check kỹ thuật van lắp đứng hay nằm
B26: VẬT TƯ THI CÔNG H1: (số BNH_DXVT_H1_29_M_Van MD, FD, VCD hệ HVAC trong phòng JS/DD, K1/DD, K1/AR, K1/K1 tầng 10-19 tòa H1) | P26: =O26*N26
A27: H1 | B27: Van chặn lửa MFD - EI45 - Kích thước: 150x100 | C27: Van chặn lửa FD - Kích thước tối thiểu 150x150, độ dày tôn 1.15mm | D27: SWIND-2.01- E-FD-EI120 | E27: Swind | F27: 150 | G27: 100 | I27: =IF('00_TONG_HOP_BAO_GIA'!G12>0, ('00_TONG_HOP_BAO_GIA'!K12 + '00_TONG_HOP_BAO_GIA'!M12) * (1 + '00_TONG_HOP_BAO_GIA'!P12) / '00_TONG_HOP_BAO_GIA'!G12, 0) | J27: =IF('00_TONG_HOP_BAO_GIA'!G12>0, '00_TONG_HOP_BAO_GIA'!L12 * (1 + '00_TONG_HOP_BAO_GIA'!P12) / '00_TONG_HOP_BAO_GIA'!G12, 0) | K27: ='00_TONG_HOP_BAO_GIA'!Q12 | L27: =('00_TONG_HOP_BAO_GIA'!K12 + '00_TONG_HOP_BAO_GIA'!M12) * (1 + '00_TONG_HOP_BAO_GIA'!P12) | M27: ='00_TONG_HOP_BAO_GIA'!L12 * (1 + '00_TONG_HOP_BAO_GIA'!P12) | N27: ='00_TONG_HOP_BAO_GIA'!R12 | O27: =IF(K27=0, "CẢNH BÁO: Đơn giá = 0. Tra cứu lại Sheet 06!", '00_TONG_HOP_BAO_GIA'!S12) | P27: =O27*N27 | Q27: Van chặn lửa SWIND-E-FD - Tiêu chuẩn EI 120 2 đầu bích TDC - gắn cầu chì 72- 74 độ C Sản xuất theo BCTN số: 4761/VLXD-TBMT- kích thước tối thiểu van 150x150 làm thêm bích bù thu về 150x100
A28: H1 | B28: Van chặn lửa MFD - EI45 - Kích thước: 150x150 | C28: Van chặn lửa FD - Kích thước 150x150, độ dày tôn 1.15mm | D28: SWIND-2.01- E-FD-EI120 | E28: Swind | F28: 150 | G28: 150 | I28: =IF('00_TONG_HOP_BAO_GIA'!G13>0, ('00_TONG_HOP_BAO_GIA'!K13 + '00_TONG_HOP_BAO_GIA'!M13) * (1 + '00_TONG_HOP_BAO_GIA'!P13) / '00_TONG_HOP_BAO_GIA'!G13, 0) | J28: =IF('00_TONG_HOP_BAO_GIA'!G13>0, '00_TONG_HOP_BAO_GIA'!L13 * (1 + '00_TONG_HOP_BAO_GIA'!P13) / '00_TONG_HOP_BAO_GIA'!G13, 0) | K28: ='00_TONG_HOP_BAO_GIA'!Q13 | L28: =('00_TONG_HOP_BAO_GIA'!K13 + '00_TONG_HOP_BAO_GIA'!M13) * (1 + '00_TONG_HOP_BAO_GIA'!P13) | M28: ='00_TONG_HOP_BAO_GIA'!L13 * (1 + '00_TONG_HOP_BAO_GIA'!P13) | N28: ='00_TONG_HOP_BAO_GIA'!R13 | O28: =IF(K28=0, "CẢNH BÁO: Đơn giá = 0. Tra cứu lại Sheet 06!", '00_TONG_HOP_BAO_GIA'!S13) | P28: =O28*N28 | Q28: Van chặn lửa SWIND-E-FD - Tiêu chuẩn EI 120 2 đầu bích TDC - gắn cầu chì 72- 74 độ C Sản xuất theo BCTN số: 4761/VLXD-TBMT
A29: H1 | B29: Van điều chỉnh lưu lượng VCD - Kích thước: 150x100 | C29: Van điều chỉnh lưu lượng VCD - Kích thước 150x100, độ dày tôn 0.75mm | D29: VCD | E29: Swind | F29: 150 | G29: 100 | I29: =IF('00_TONG_HOP_BAO_GIA'!G14>0, ('00_TONG_HOP_BAO_GIA'!K14 + '00_TONG_HOP_BAO_GIA'!M14) * (1 + '00_TONG_HOP_BAO_GIA'!P14) / '00_TONG_HOP_BAO_GIA'!G14, 0) | J29: =IF('00_TONG_HOP_BAO_GIA'!G14>0, '00_TONG_HOP_BAO_GIA'!L14 * (1 + '00_TONG_HOP_BAO_GIA'!P14) / '00_TONG_HOP_BAO_GIA'!G14, 0) | K29: ='00_TONG_HOP_BAO_GIA'!Q14 | L29: =('00_TONG_HOP_BAO_GIA'!K14 + '00_TONG_HOP_BAO_GIA'!M14) * (1 + '00_TONG_HOP_BAO_GIA'!P14) | M29: ='00_TONG_HOP_BAO_GIA'!L14 * (1 + '00_TONG_HOP_BAO_GIA'!P14) | N29: ='00_TONG_HOP_BAO_GIA'!R14 | O29: =IF(K29=0, "CẢNH BÁO: Đơn giá = 0. Tra cứu lại Sheet 06!", '00_TONG_HOP_BAO_GIA'!S14) | P29: =O29*N29 | Q29: Van tay gat
A30: H1 | B30: Van điều chỉnh lưu lượng VCD - Kích thước: 150x150 | C30: Van điều chỉnh lưu lượng VCD - Kích thước 150x150, độ dày tôn 0.75mm | D30: VCD | E30: Swind | F30: 150 | G30: 150 | I30: =IF('00_TONG_HOP_BAO_GIA'!G15>0, ('00_TONG_HOP_BAO_GIA'!K15 + '00_TONG_HOP_BAO_GIA'!M15) * (1 + '00_TONG_HOP_BAO_GIA'!P15) / '00_TONG_HOP_BAO_GIA'!G15, 0) | J30: =IF('00_TONG_HOP_BAO_GIA'!G15>0, '00_TONG_HOP_BAO_GIA'!L15 * (1 + '00_TONG_HOP_BAO_GIA'!P15) / '00_TONG_HOP_BAO_GIA'!G15, 0) | K30: ='00_TONG_HOP_BAO_GIA'!Q15 | L30: =('00_TONG_HOP_BAO_GIA'!K15 + '00_TONG_HOP_BAO_GIA'!M15) * (1 + '00_TONG_HOP_BAO_GIA'!P15) | M30: ='00_TONG_HOP_BAO_GIA'!L15 * (1 + '00_TONG_HOP_BAO_GIA'!P15) | N30: ='00_TONG_HOP_BAO_GIA'!R15 | O30: =IF(K30=0, "CẢNH BÁO: Đơn giá = 0. Tra cứu lại Sheet 06!", '00_TONG_HOP_BAO_GIA'!S15) | P30: =O30*N30 | Q30: Van tay gat
A31: H1 | B31: Van điều chỉnh lưu lượng VCD - Kích thước: 300x200 | C31: Van điều chỉnh lưu lượng VCD - Kích thước 300x200, độ dày tôn 0.75mm | D31: VCD | E31: Swind | F31: 300 | G31: 200 | I31: =IF('00_TONG_HOP_BAO_GIA'!G16>0, ('00_TONG_HOP_BAO_GIA'!K16 + '00_TONG_HOP_BAO_GIA'!M16) * (1 + '00_TONG_HOP_BAO_GIA'!P16) / '00_TONG_HOP_BAO_GIA'!G16, 0) | J31: =IF('00_TONG_HOP_BAO_GIA'!G16>0, '00_TONG_HOP_BAO_GIA'!L16 * (1 + '00_TONG_HOP_BAO_GIA'!P16) / '00_TONG_HOP_BAO_GIA'!G16, 0) | K31: ='00_TONG_HOP_BAO_GIA'!Q16 | L31: =('00_TONG_HOP_BAO_GIA'!K16 + '00_TONG_HOP_BAO_GIA'!M16) * (1 + '00_TONG_HOP_BAO_GIA'!P16) | M31: ='00_TONG_HOP_BAO_GIA'!L16 * (1 + '00_TONG_HOP_BAO_GIA'!P16) | N31: ='00_TONG_HOP_BAO_GIA'!R16 | O31: =IF(K31=0, "CẢNH BÁO: Đơn giá = 0. Tra cứu lại Sheet 06!", '00_TONG_HOP_BAO_GIA'!S16) | P31: =O31*N31 | Q31: Van tay gat
A32: H1 | B32: Van điều gió MD - Kích thước: 150x100 | C32: Van điều gió MD - Kích thước: 150x100, độ dày tôn 1.15 mm | D32: MD | E32: Swind | F32: 150 | G32: 100 | I32: =IF('00_TONG_HOP_BAO_GIA'!G17>0, ('00_TONG_HOP_BAO_GIA'!K17 + '00_TONG_HOP_BAO_GIA'!M17) * (1 + '00_TONG_HOP_BAO_GIA'!P17) / '00_TONG_HOP_BAO_GIA'!G17, 0) | J32: =IF('00_TONG_HOP_BAO_GIA'!G17>0, '00_TONG_HOP_BAO_GIA'!L17 * (1 + '00_TONG_HOP_BAO_GIA'!P17) / '00_TONG_HOP_BAO_GIA'!G17, 0) | K32: ='00_TONG_HOP_BAO_GIA'!Q17 | L32: =('00_TONG_HOP_BAO_GIA'!K17 + '00_TONG_HOP_BAO_GIA'!M17) * (1 + '00_TONG_HOP_BAO_GIA'!P17) | M32: ='00_TONG_HOP_BAO_GIA'!L17 * (1 + '00_TONG_HOP_BAO_GIA'!P17) | N32: ='00_TONG_HOP_BAO_GIA'!R17 | O32: =IF(K32=0, "CẢNH BÁO: Đơn giá = 0. Tra cứu lại Sheet 06!", '00_TONG_HOP_BAO_GIA'!S17) | P32: =O32*N32 | Q32: Van dùng động cơ ON/OFF 5N - 24V Belimo
A33: H1 | B33: Van điều gió MD - Kích thước: 150x150 | C33: Van điều gió MD - Kích thước: 150x150, độ dày tôn 1.15 mm | D33: MD | E33: Swind | F33: 150 | G33: 150 | I33: =IF('00_TONG_HOP_BAO_GIA'!G18>0, ('00_TONG_HOP_BAO_GIA'!K18 + '00_TONG_HOP_BAO_GIA'!M18) * (1 + '00_TONG_HOP_BAO_GIA'!P18) / '00_TONG_HOP_BAO_GIA'!G18, 0) | J33: =IF('00_TONG_HOP_BAO_GIA'!G18>0, '00_TONG_HOP_BAO_GIA'!L18 * (1 + '00_TONG_HOP_BAO_GIA'!P18) / '00_TONG_HOP_BAO_GIA'!G18, 0) | K33: ='00_TONG_HOP_BAO_GIA'!Q18 | L33: =('00_TONG_HOP_BAO_GIA'!K18 + '00_TONG_HOP_BAO_GIA'!M18) * (1 + '00_TONG_HOP_BAO_GIA'!P18) | M33: ='00_TONG_HOP_BAO_GIA'!L18 * (1 + '00_TONG_HOP_BAO_GIA'!P18) | N33: ='00_TONG_HOP_BAO_GIA'!R18 | O33: =IF(K33=0, "CẢNH BÁO: Đơn giá = 0. Tra cứu lại Sheet 06!", '00_TONG_HOP_BAO_GIA'!S18) | P33: =O33*N33 | Q33: Van dùng động cơ ON/OFF 5N - 24V Belimo
B34: Hệ thống ống gió, hút mùi vệ sinh | P34: =O34*N34
B35: Van gió, miệng gió | P35: =O35*N35
A36: H1 | B36: Van chặn lửa MFD - EI45 - Kích thước: 150x100 | C36: Van chặn lửa FD EI60 - Kích thước 150x100, độ dày tôn 1.15mm | D36: SWIND-2.01- E-FD-EI120 | E36: Swind | F36: 150 | G36: 100 | I36: =IF('00_TONG_HOP_BAO_GIA'!G19>0, ('00_TONG_HOP_BAO_GIA'!K19 + '00_TONG_HOP_BAO_GIA'!M19) * (1 + '00_TONG_HOP_BAO_GIA'!P19) / '00_TONG_HOP_BAO_GIA'!G19, 0) | J36: =IF('00_TONG_HOP_BAO_GIA'!G19>0, '00_TONG_HOP_BAO_GIA'!L19 * (1 + '00_TONG_HOP_BAO_GIA'!P19) / '00_TONG_HOP_BAO_GIA'!G19, 0) | K36: ='00_TONG_HOP_BAO_GIA'!Q19 | L36: =('00_TONG_HOP_BAO_GIA'!K19 + '00_TONG_HOP_BAO_GIA'!M19) * (1 + '00_TONG_HOP_BAO_GIA'!P19) | M36: ='00_TONG_HOP_BAO_GIA'!L19 * (1 + '00_TONG_HOP_BAO_GIA'!P19) | N36: ='00_TONG_HOP_BAO_GIA'!R19 | O36: =IF(K36=0, "CẢNH BÁO: Đơn giá = 0. Tra cứu lại Sheet 06!", '00_TONG_HOP_BAO_GIA'!S19) | P36: =O36*N36 | Q36: Van chặn lửa SWIND-E-FD - Tiêu chuẩn EI 120 2 đầu bích TDC - gắn cầu chì 72- 74 độ C Sản xuất theo BCTN số: 4761/VLXD-TBMT- kích thước tối thiểu van 150x150 làm thêm bích bù thu về 150x100
A37: H1 | B37: Van chặn lửa MFD - EI45 - Kích thước: 150x150 | C37: Van chặn lửa FD EI60 - Kích thước 150x150, độ dày tôn 1.15mm | D37: SWIND-2.01- E-FD-EI120 | E37: Swind | F37: 150 | G37: 150 | I37: =IF('00_TONG_HOP_BAO_GIA'!G20>0, ('00_TONG_HOP_BAO_GIA'!K20 + '00_TONG_HOP_BAO_GIA'!M20) * (1 + '00_TONG_HOP_BAO_GIA'!P20) / '00_TONG_HOP_BAO_GIA'!G20, 0) | J37: =IF('00_TONG_HOP_BAO_GIA'!G20>0, '00_TONG_HOP_BAO_GIA'!L20 * (1 + '00_TONG_HOP_BAO_GIA'!P20) / '00_TONG_HOP_BAO_GIA'!G20, 0) | K37: ='00_TONG_HOP_BAO_GIA'!Q20 | L37: =('00_TONG_HOP_BAO_GIA'!K20 + '00_TONG_HOP_BAO_GIA'!M20) * (1 + '00_TONG_HOP_BAO_GIA'!P20) | M37: ='00_TONG_HOP_BAO_GIA'!L20 * (1 + '00_TONG_HOP_BAO_GIA'!P20) | N37: ='00_TONG_HOP_BAO_GIA'!R20 | O37: =IF(K37=0, "CẢNH BÁO: Đơn giá = 0. Tra cứu lại Sheet 06!", '00_TONG_HOP_BAO_GIA'!S20) | P37: =O37*N37 | Q37: Van chặn lửa SWIND-E-FD - Tiêu chuẩn EI 120 2 đầu bích TDC - gắn cầu chì 72- 74 độ C Sản xuất theo BCTN số: 4761/VLXD-TBMT
A38: H1 | B38: Van điều chỉnh lưu lượng VCD - Kích thước: 150x100 | C38: Van điều chỉnh lưu lượng VCD - Kích thước: 150x100, độ dày tôn 0.75 mm | D38: VCD | E38: Swind | F38: 150 | G38: 100 | I38: =IF('00_TONG_HOP_BAO_GIA'!G21>0, ('00_TONG_HOP_BAO_GIA'!K21 + '00_TONG_HOP_BAO_GIA'!M21) * (1 + '00_TONG_HOP_BAO_GIA'!P21) / '00_TONG_HOP_BAO_GIA'!G21, 0) | J38: =IF('00_TONG_HOP_BAO_GIA'!G21>0, '00_TONG_HOP_BAO_GIA'!L21 * (1 + '00_TONG_HOP_BAO_GIA'!P21) / '00_TONG_HOP_BAO_GIA'!G21, 0) | K38: ='00_TONG_HOP_BAO_GIA'!Q21 | L38: =('00_TONG_HOP_BAO_GIA'!K21 + '00_TONG_HOP_BAO_GIA'!M21) * (1 + '00_TONG_HOP_BAO_GIA'!P21) | M38: ='00_TONG_HOP_BAO_GIA'!L21 * (1 + '00_TONG_HOP_BAO_GIA'!P21) | N38: ='00_TONG_HOP_BAO_GIA'!R21 | O38: =IF(K38=0, "CẢNH BÁO: Đơn giá = 0. Tra cứu lại Sheet 06!", '00_TONG_HOP_BAO_GIA'!S21) | P38: =O38*N38 | Q38: Van tay gat
A39: H1 | B39: Van điều chỉnh lưu lượng VCD - Kích thước: 150x150 | C39: Van điều chỉnh lưu lượng VCD - Kích thước: 150x150 | D39: VCD | E39: Swind | F39: 150 | G39: 150 | I39: =IF('00_TONG_HOP_BAO_GIA'!G22>0, ('00_TONG_HOP_BAO_GIA'!K22 + '00_TONG_HOP_BAO_GIA'!M22) * (1 + '00_TONG_HOP_BAO_GIA'!P22) / '00_TONG_HOP_BAO_GIA'!G22, 0) | J39: =IF('00_TONG_HOP_BAO_GIA'!G22>0, '00_TONG_HOP_BAO_GIA'!L22 * (1 + '00_TONG_HOP_BAO_GIA'!P22) / '00_TONG_HOP_BAO_GIA'!G22, 0) | K39: ='00_TONG_HOP_BAO_GIA'!Q22 | L39: =('00_TONG_HOP_BAO_GIA'!K22 + '00_TONG_HOP_BAO_GIA'!M22) * (1 + '00_TONG_HOP_BAO_GIA'!P22) | M39: ='00_TONG_HOP_BAO_GIA'!L22 * (1 + '00_TONG_HOP_BAO_GIA'!P22) | N39: ='00_TONG_HOP_BAO_GIA'!R22 | O39: =IF(K39=0, "CẢNH BÁO: Đơn giá = 0. Tra cứu lại Sheet 06!", '00_TONG_HOP_BAO_GIA'!S22) | P39: =O39*N39 | Q39: Van tay gat
A40: H1 | B40: Van điều gió MD - Kích thước: 150x100 | C40: Van điều gió MD - Kích thước: 150x100, độ dày tôn 1.15 mm | D40: MD | E40: Swind | F40: 150 | G40: 100 | I40: =IF('00_TONG_HOP_BAO_GIA'!G23>0, ('00_TONG_HOP_BAO_GIA'!K23 + '00_TONG_HOP_BAO_GIA'!M23) * (1 + '00_TONG_HOP_BAO_GIA'!P23) / '00_TONG_HOP_BAO_GIA'!G23, 0) | J40: =IF('00_TONG_HOP_BAO_GIA'!G23>0, '00_TONG_HOP_BAO_GIA'!L23 * (1 + '00_TONG_HOP_BAO_GIA'!P23) / '00_TONG_HOP_BAO_GIA'!G23, 0) | K40: ='00_TONG_HOP_BAO_GIA'!Q23 | L40: =('00_TONG_HOP_BAO_GIA'!K23 + '00_TONG_HOP_BAO_GIA'!M23) * (1 + '00_TONG_HOP_BAO_GIA'!P23) | M40: ='00_TONG_HOP_BAO_GIA'!L23 * (1 + '00_TONG_HOP_BAO_GIA'!P23) | N40: ='00_TONG_HOP_BAO_GIA'!R23 | O40: =IF(K40=0, "CẢNH BÁO: Đơn giá = 0. Tra cứu lại Sheet 06!", '00_TONG_HOP_BAO_GIA'!S23) | P40: =O40*N40 | Q40: Van dùng động cơ ON/OFF 5N - 24V Belimo
A41: H1 | B41: Van điều gió MD - Kích thước: 150x150 | C41: Van điều gió MD - Kích thước: 150x150, độ dày tôn 1.15 mm | D41: MD | E41: Swind | F41: 150 | G41: 150 | K41: 200 | L41: 1.15 | M41: Cái | N41: 0 | P41: =O41*N41 | Q41: Van dùng động cơ ON/OFF 5N - 24V Belimo
B42: Chi phí kiểm định | I42: =IF('00_TONG_HOP_BAO_GIA'!G24>0, ('00_TONG_HOP_BAO_GIA'!K24 + '00_TONG_HOP_BAO_GIA'!M24) * (1 + '00_TONG_HOP_BAO_GIA'!P24) / '00_TONG_HOP_BAO_GIA'!G24, 0) | J42: =IF('00_TONG_HOP_BAO_GIA'!G24>0, '00_TONG_HOP_BAO_GIA'!L24 * (1 + '00_TONG_HOP_BAO_GIA'!P24) / '00_TONG_HOP_BAO_GIA'!G24, 0) | K42: ='00_TONG_HOP_BAO_GIA'!Q24 | L42: =('00_TONG_HOP_BAO_GIA'!K24 + '00_TONG_HOP_BAO_GIA'!M24) * (1 + '00_TONG_HOP_BAO_GIA'!P24) | M42: ='00_TONG_HOP_BAO_GIA'!L24 * (1 + '00_TONG_HOP_BAO_GIA'!P24) | N42: ='00_TONG_HOP_BAO_GIA'!R24 | O42: =IF(K42=0, "CẢNH BÁO: Đơn giá = 0. Tra cứu lại Sheet 06!", '00_TONG_HOP_BAO_GIA'!S24) | P42: =O42*N42 | Q42: đã bao gồm cấp 1 lần cuối dự án
...

Sheet 00_TONG_HOP_BAO_GIA
A1: STT | B1: ITEM_ID | C1: PHÂN NHÓM | D1: TÊN SẢN PHẨM | E1: QUY CÁCH (WxH) | F1: ĐVT | G1: SỐ LƯỢNG | H1: CP VẬT TƯ ỐNG | I1: CP VẬT TƯ CỬA | J1: CP VẬT TƯ VAN | K1: TỔNG CP VẬT TƯ | L1: NHÂN CÔNG (25%) | M1: CP XƯỞNG (10%) | N1: TỔNG GIÁ VỐN | O1: GIÁ VỐN / ĐVT | P1: MARGIN (%) | Q1: ĐƠN GIÁ BÁN | R1: THÀNH TIỀN (VNĐ) | S1: GHI CHÚ
A2: 1 | B2: SW-DAMPER-001 | C2: VAN GIÓ | D2: VẬT TƯ THI CÔNG P1B: (số BNH-ĐXVT-P1B-29-M-Van ống hồi gió lạnh L12 - P1B) Van FD 1000x1200xL200 | E2: 1000x1200 | F2: cái | G2: 1 | H2: =SUMIF('01_BOC_TACH_ONG'!B:B, B2, '01_BOC_TACH_ONG'!K:K) | I2: =SUMIF('02_BOC_TACH_CUA'!B:B, B2, '02_BOC_TACH_CUA'!K:K) | J2: =SUMIF('03_BOC_TACH_VAN'!B:B, B2, '03_BOC_TACH_VAN'!K:K) | K2: =SUM(H2:J2) | L2: =(K2-SUMIFS('03_BOC_TACH_VAN'!K:K, '03_BOC_TACH_VAN'!B:B, B2, '03_BOC_TACH_VAN'!D:D, "ĐỘNG_CƠ_VÀ_CẢM_BIẾN"))*0.25 | M2: =(K2-SUMIFS('03_BOC_TACH_VAN'!K:K, '03_BOC_TACH_VAN'!B:B, B2, '03_BOC_TACH_VAN'!D:D, "ĐỘNG_CƠ_VÀ_CẢM_BIẾN"))*0.10 | N2: =K2+L2+M2 | O2: =IF(G2>0, N2/G2, 0) | P2: 0.18 | Q2: =IF(G2>0, ((N2-SUMIFS('03_BOC_TACH_VAN'!K:K, '03_BOC_TACH_VAN'!B:B, B2, '03_BOC_TACH_VAN'!D:D, "ĐỘNG_CƠ_VÀ_CẢM_BIẾN"))*(1+P2)+SUMIFS('03_BOC_TACH_VAN'!K:K, '03_BOC_TACH_VAN'!B:B, B2, '03_BOC_TACH_VAN'!D:D, "ĐỘNG_CƠ_VÀ_CẢM_BIẾN"))/G2, 0) | R2: =G2*Q2
A3: 2 | B3: SW-DAMPER-002 | C3: VAN GIÓ | D3: VẬT TƯ THI CÔNG P1B: (số BNH-ĐXVT-P1B-29-M-Van ống hồi gió lạnh L12 - P1B) Van FD 1200x700xL200 | E3: 1200x700 | F3: cái | G3: 1 | H3: =SUMIF('01_BOC_TACH_ONG'!B:B, B3, '01_BOC_TACH_ONG'!K:K) | I3: =SUMIF('02_BOC_TACH_CUA'!B:B, B3, '02_BOC_TACH_CUA'!K:K) | J3: =SUMIF('03_BOC_TACH_VAN'!B:B, B3, '03_BOC_TACH_VAN'!K:K) | K3: =SUM(H3:J3) | L3: =(K3-SUMIFS('03_BOC_TACH_VAN'!K:K, '03_BOC_TACH_VAN'!B:B, B3, '03_BOC_TACH_VAN'!D:D, "ĐỘNG_CƠ_VÀ_CẢM_BIẾN"))*0.25 | M3: =(K3-SUMIFS('03_BOC_TACH_VAN'!K:K, '03_BOC_TACH_VAN'!B:B, B3, '03_BOC_TACH_VAN'!D:D, "ĐỘNG_CƠ_VÀ_CẢM_BIẾN"))*0.10 | N3: =K3+L3+M3 | O3: =IF(G3>0, N3/G3, 0) | P3: 0.18 | Q3: =IF(G3>0, ((N3-SUMIFS('03_BOC_TACH_VAN'!K:K, '03_BOC_TACH_VAN'!B:B, B3, '03_BOC_TACH_VAN'!D:D, "ĐỘNG_CƠ_VÀ_CẢM_BIẾN"))*(1+P3)+SUMIFS('03_BOC_TACH_VAN'!K:K, '03_BOC_TACH_VAN'!B:B, B3, '03_BOC_TACH_VAN'!D:D, "ĐỘNG_CƠ_VÀ_CẢM_BIẾN"))/G3, 0) | R3: =G3*Q3
A4: 3 | B4: SW-DAMPER-003 | C4: VAN GIÓ | D4: VẬT TƯ THI CÔNG P1B: (số BNH-ĐXVT-P1B-29-M-Van ống hồi gió lạnh L12 - P1B) Van FD 1250x1000xL200 | E4: 1250x1000 | F4: cái | G4: 2 | H4: =SUMIF('01_BOC_TACH_ONG'!B:B, B4, '01_BOC_TACH_ONG'!K:K) | I4: =SUMIF('02_BOC_TACH_CUA'!B:B, B4, '02_BOC_TACH_CUA'!K:K) | J4: =SUMIF('03_BOC_TACH_VAN'!B:B, B4, '03_BOC_TACH_VAN'!K:K) | K4: =SUM(H4:J4) | L4: =(K4-SUMIFS('03_BOC_TACH_VAN'!K:K, '03_BOC_TACH_VAN'!B:B, B4, '03_BOC_TACH_VAN'!D:D, "ĐỘNG_CƠ_VÀ_CẢM_BIẾN"))*0.25 | M4: =(K4-SUMIFS('03_BOC_TACH_VAN'!K:K, '03_BOC_TACH_VAN'!B:B, B4, '03_BOC_TACH_VAN'!D:D, "ĐỘNG_CƠ_VÀ_CẢM_BIẾN"))*0.10 | N4: =K4+L4+M4 | O4: =IF(G4>0, N4/G4, 0) | P4: 0.18 | Q4: =IF(G4>0, ((N4-SUMIFS('03_BOC_TACH_VAN'!K:K, '03_BOC_TACH_VAN'!B:B, B4, '03_BOC_TACH_VAN'!D:D, "ĐỘNG_CƠ_VÀ_CẢM_BIẾN"))*(1+P4)+SUMIFS('03_BOC_TACH_VAN'!K:K, '03_BOC_TACH_VAN'!B:B, B4, '03_BOC_TACH_VAN'!D:D, "ĐỘNG_CƠ_VÀ_CẢM_BIẾN"))/G4, 0) | R4: =G4*Q4
A5: 4 | B5: SW-DAMPER-004 | C5: VAN GIÓ | D5: VẬT TƯ THI CÔNG P1B: (số BNH-ĐXVT-P1B-29-M-Van ống hồi gió lạnh L12 - P1B) Van FD 1350x900xL200 | E5: 1350x900 | F5: cái | G5: 1 | H5: =SUMIF('01_BOC_TACH_ONG'!B:B, B5, '01_BOC_TACH_ONG'!K:K) | I5: =SUMIF('02_BOC_TACH_CUA'!B:B, B5, '02_BOC_TACH_CUA'!K:K) | J5: =SUMIF('03_BOC_TACH_VAN'!B:B, B5, '03_BOC_TACH_VAN'!K:K) | K5: =SUM(H5:J5) | L5: =(K5-SUMIFS('03_BOC_TACH_VAN'!K:K, '03_BOC_TACH_VAN'!B:B, B5, '03_BOC_TACH_VAN'!D:D, "ĐỘNG_CƠ_VÀ_CẢM_BIẾN"))*0.25 | M5: =(K5-SUMIFS('03_BOC_TACH_VAN'!K:K, '03_BOC_TACH_VAN'!B:B, B5, '03_BOC_TACH_VAN'!D:D, "ĐỘNG_CƠ_VÀ_CẢM_BIẾN"))*0.10 | N5: =K5+L5+M5 | O5: =IF(G5>0, N5/G5, 0) | P5: 0.18 | Q5: =IF(G5>0, ((N5-SUMIFS('03_BOC_TACH_VAN'!K:K, '03_BOC_TACH_VAN'!B:B, B5, '03_BOC_TACH_VAN'!D:D, "ĐỘNG_CƠ_VÀ_CẢM_BIẾN"))*(1+P5)+SUMIFS('03_BOC_TACH_VAN'!K:K, '03_BOC_TACH_VAN'!B:B, B5, '03_BOC_TACH_VAN'!D:D, "ĐỘNG_CƠ_VÀ_CẢM_BIẾN"))/G5, 0) | R5: =G5*Q5
A6: 5 | B6: SW-DAMPER-005 | C6: VAN GIÓ | D6: VẬT TƯ THI CÔNG P1B: (số BNH-ĐXVT-P1B-29-M-Van ống hồi gió lạnh L12 - P1B) Van FD 1350x900xL300 | E6: 1350x900 | F6: cái | G6: 1 | H6: =SUMIF('01_BOC_TACH_ONG'!B:B, B6, '01_BOC_TACH_ONG'!K:K) | I6: =SUMIF('02_BOC_TACH_CUA'!B:B, B6, '02_BOC_TACH_CUA'!K:K) | J6: =SUMIF('03_BOC_TACH_VAN'!B:B, B6, '03_BOC_TACH_VAN'!K:K) | K6: =SUM(H6:J6) | L6: =(K6-SUMIFS('03_BOC_TACH_VAN'!K:K, '03_BOC_TACH_VAN'!B:B, B6, '03_BOC_TACH_VAN'!D:D, "ĐỘNG_CƠ_VÀ_CẢM_BIẾN"))*0.25 | M6: =(K6-SUMIFS('03_BOC_TACH_VAN'!K:K, '03_BOC_TACH_VAN'!B:B, B6, '03_BOC_TACH_VAN'!D:D, "ĐỘNG_CƠ_VÀ_CẢM_BIẾN"))*0.10 | N6: =K6+L6+M6 | O6: =IF(G6>0, N6/G6, 0) | P6: 0.18 | Q6: =IF(G6>0, ((N6-SUMIFS('03_BOC_TACH_VAN'!K:K, '03_BOC_TACH_VAN'!B:B, B6, '03_BOC_TACH_VAN'!D:D, "ĐỘNG_CƠ_VÀ_CẢM_BIẾN"))*(1+P6)+SUMIFS('03_BOC_TACH_VAN'!K:K, '03_BOC_TACH_VAN'!B:B, B6, '03_BOC_TACH_VAN'!D:D, "ĐỘNG_CƠ_VÀ_CẢM_BIẾN"))/G6, 0) | R6: =G6*Q6
A7: 6 | B7: SW-DAMPER-006 | C7: VAN GIÓ | D7: VẬT TƯ THI CÔNG P1B: (số BNH-ĐXVT-P1B-29-M-Van ống hồi gió lạnh L12 - P1B) Van FD 1400x1100xL200 | E7: 1400x1100 | F7: cái | G7: 1 | H7: =SUMIF('01_BOC_TACH_ONG'!B:B, B7, '01_BOC_TACH_ONG'!K:K) | I7: =SUMIF('02_BOC_TACH_CUA'!B:B, B7, '02_BOC_TACH_CUA'!K:K) | J7: =SUMIF('03_BOC_TACH_VAN'!B:B, B7, '03_BOC_TACH_VAN'!K:K) | K7: =SUM(H7:J7) | L7: =(K7-SUMIFS('03_BOC_TACH_VAN'!K:K, '03_BOC_TACH_VAN'!B:B, B7, '03_BOC_TACH_VAN'!D:D, "ĐỘNG_CƠ_VÀ_CẢM_BIẾN"))*0.25 | M7: =(K7-SUMIFS('03_BOC_TACH_VAN'!K:K, '03_BOC_TACH_VAN'!B:B, B7, '03_BOC_TACH_VAN'!D:D, "ĐỘNG_CƠ_VÀ_CẢM_BIẾN"))*0.10 | N7: =K7+L7+M7 | O7: =IF(G7>0, N7/G7, 0) | P7: 0.18 | Q7: =IF(G7>0, ((N7-SUMIFS('03_BOC_TACH_VAN'!K:K, '03_BOC_TACH_VAN'!B:B, B7, '03_BOC_TACH_VAN'!D:D, "ĐỘNG_CƠ_VÀ_CẢM_BIẾN"))*(1+P7)+SUMIFS('03_BOC_TACH_VAN'!K:K, '03_BOC_TACH_VAN'!B:B, B7, '03_BOC_TACH_VAN'!D:D, "ĐỘNG_CƠ_VÀ_CẢM_BIẾN"))/G7, 0) | R7: =G7*Q7
A8: 7 | B8: SW-DAMPER-007 | C8: VAN GIÓ | D8: VẬT TƯ THI CÔNG P1B: (số BNH-ĐXVT-P1B-29-M-Van ống hồi gió lạnh L12 - P1B) Van FD 1800x700xL200 | E8: 1800x700 | F8: cái | G8: 1 | H8: =SUMIF('01_BOC_TACH_ONG'!B:B, B8, '01_BOC_TACH_ONG'!K:K) | I8: =SUMIF('02_BOC_TACH_CUA'!B:B, B8, '02_BOC_TACH_CUA'!K:K) | J8: =SUMIF('03_BOC_TACH_VAN'!B:B, B8, '03_BOC_TACH_VAN'!K:K) | K8: =SUM(H8:J8) | L8: =(K8-SUMIFS('03_BOC_TACH_VAN'!K:K, '03_BOC_TACH_VAN'!B:B, B8, '03_BOC_TACH_VAN'!D:D, "ĐỘNG_CƠ_VÀ_CẢM_BIẾN"))*0.25 | M8: =(K8-SUMIFS('03_BOC_TACH_VAN'!K:K, '03_BOC_TACH_VAN'!B:B, B8, '03_BOC_TACH_VAN'!D:D, "ĐỘNG_CƠ_VÀ_CẢM_BIẾN"))*0.10 | N8: =K8+L8+M8 | O8: =IF(G8>0, N8/G8, 0) | P8: 0.18 | Q8: =IF(G8>0, ((N8-SUMIFS('03_BOC_TACH_VAN'!K:K, '03_BOC_TACH_VAN'!B:B, B8, '03_BOC_TACH_VAN'!D:D, "ĐỘNG_CƠ_VÀ_CẢM_BIẾN"))*(1+P8)+SUMIFS('03_BOC_TACH_VAN'!K:K, '03_BOC_TACH_VAN'!B:B, B8, '03_BOC_TACH_VAN'!D:D, "ĐỘNG_CƠ_VÀ_CẢM_BIẾN"))/G8, 0) | R8: =G8*Q8
A9: 8 | B9: SW-DAMPER-008 | C9: VAN GIÓ | D9: VẬT TƯ THI CÔNG P1B: (số BNH-ĐXVT-P1B-29-M-Van ống hồi gió lạnh L12 - P1B) Van FD 500x400xL200 | E9: 500x400 | F9: cái | G9: 2 | H9: =SUMIF('01_BOC_TACH_ONG'!B:B, B9, '01_BOC_TACH_ONG'!K:K) | I9: =SUMIF('02_BOC_TACH_CUA'!B:B, B9, '02_BOC_TACH_CUA'!K:K) | J9: =SUMIF('03_BOC_TACH_VAN'!B:B, B9, '03_BOC_TACH_VAN'!K:K) | K9: =SUM(H9:J9) | L9: =(K9-SUMIFS('03_BOC_TACH_VAN'!K:K, '03_BOC_TACH_VAN'!B:B, B9, '03_BOC_TACH_VAN'!D:D, "ĐỘNG_CƠ_VÀ_CẢM_BIẾN"))*0.25 | M9: =(K9-SUMIFS('03_BOC_TACH_VAN'!K:K, '03_BOC_TACH_VAN'!B:B, B9, '03_BOC_TACH_VAN'!D:D, "ĐỘNG_CƠ_VÀ_CẢM_BIẾN"))*0.10 | N9: =K9+L9+M9 | O9: =IF(G9>0, N9/G9, 0) | P9: 0.18 | Q9: =IF(G9>0, ((N9-SUMIFS('03_BOC_TACH_VAN'!K:K, '03_BOC_TACH_VAN'!B:B, B9, '03_BOC_TACH_VAN'!D:D, "ĐỘNG_CƠ_VÀ_CẢM_BIẾN"))*(1+P9)+SUMIFS('03_BOC_TACH_VAN'!K:K, '03_BOC_TACH_VAN'!B:B, B9, '03_BOC_TACH_VAN'!D:D, "ĐỘNG_CƠ_VÀ_CẢM_BIẾN"))/G9, 0) | R9: =G9*Q9
A10: 9 | B10: SW-DAMPER-009 | C10: VAN GIÓ | D10: VẬT TƯ THI CÔNG P1B: (số BNH-ĐXVT-P1B-29-M-Van ống hồi gió lạnh L12 - P1B) Van FD 700x500xL200 | E10: 700x500 | F10: cái | G10: 1 | H10: =SUMIF('01_BOC_TACH_ONG'!B:B, B10, '01_BOC_TACH_ONG'!K:K) | I10: =SUMIF('02_BOC_TACH_CUA'!B:B, B10, '02_BOC_TACH_CUA'!K:K) | J10: =SUMIF('03_BOC_TACH_VAN'!B:B, B10, '03_BOC_TACH_VAN'!K:K) | K10: =SUM(H10:J10) | L10: =(K10-SUMIFS('03_BOC_TACH_VAN'!K:K, '03_BOC_TACH_VAN'!B:B, B10, '03_BOC_TACH_VAN'!D:D, "ĐỘNG_CƠ_VÀ_CẢM_BIẾN"))*0.25 | M10: =(K10-SUMIFS('03_BOC_TACH_VAN'!K:K, '03_BOC_TACH_VAN'!B:B, B10, '03_BOC_TACH_VAN'!D:D, "ĐỘNG_CƠ_VÀ_CẢM_BIẾN"))*0.10 | N10: =K10+L10+M10 | O10: =IF(G10>0, N10/G10, 0) | P10: 0.18 | Q10: =IF(G10>0, ((N10-SUMIFS('03_BOC_TACH_VAN'!K:K, '03_BOC_TACH_VAN'!B:B, B10, '03_BOC_TACH_VAN'!D:D, "ĐỘNG_CƠ_VÀ_CẢM_BIẾN"))*(1+P10)+SUMIFS('03_BOC_TACH_VAN'!K:K, '03_BOC_TACH_VAN'!B:B, B10, '03_BOC_TACH_VAN'!D:D, "ĐỘNG_CƠ_VÀ_CẢM_BIẾN"))/G10, 0) | R10: =G10*Q10
A11: 10 | B11: SW-DAMPER-010 | C11: VAN GIÓ | D11: VẬT TƯ THI CÔNG P1B: (số BNH-ĐXVT-P1B-29-M-Van ống hồi gió lạnh L12 - P1B) Van FD 800x1550xL200 | E11: 800x1550 | F11: cái | G11: 1 | H11: =SUMIF('01_BOC_TACH_ONG'!B:B, B11, '01_BOC_TACH_ONG'!K:K) | I11: =SUMIF('02_BOC_TACH_CUA'!B:B, B11, '02_BOC_TACH_CUA'!K:K) | J11: =SUMIF('03_BOC_TACH_VAN'!B:B, B11, '03_BOC_TACH_VAN'!K:K) | K11: =SUM(H11:J11) | L11: =(K11-SUMIFS('03_BOC_TACH_VAN'!K:K, '03_BOC_TACH_VAN'!B:B, B11, '03_BOC_TACH_VAN'!D:D, "ĐỘNG_CƠ_VÀ_CẢM_BIẾN"))*0.25 | M11: =(K11-SUMIFS('03_BOC_TACH_VAN'!K:K, '03_BOC_TACH_VAN'!B:B, B11, '03_BOC_TACH_VAN'!D:D, "ĐỘNG_CƠ_VÀ_CẢM_BIẾN"))*0.10 | N11: =K11+L11+M11 | O11: =IF(G11>0, N11/G11, 0) | P11: 0.18 | Q11: =IF(G11>0, ((N11-SUMIFS('03_BOC_TACH_VAN'!K:K, '03_BOC_TACH_VAN'!B:B, B11, '03_BOC_TACH_VAN'!D:D, "ĐỘNG_CƠ_VÀ_CẢM_BIẾN"))*(1+P11)+SUMIFS('03_BOC_TACH_VAN'!K:K, '03_BOC_TACH_VAN'!B:B, B11, '03_BOC_TACH_VAN'!D:D, "ĐỘNG_CƠ_VÀ_CẢM_BIẾN"))/G11, 0) | R11: =G11*Q11
A12: 11 | B12: SW-DAMPER-011 | C12: VAN GIÓ | D12: VẬT TƯ THI CÔNG H1: (số BNH_DXVT_H1_29_M_Van MD, FD, VCD hệ HVAC trong phòng JS/DD, K1/DD, K1/AR, K1/K1 tầng 10-19 tòa H1) Van chặn lửa MFD - EI45 - Kích thước: 150x100 | E12: 150x100 | F12: Cái | G12: 39 | H12: =SUMIF('01_BOC_TACH_ONG'!B:B, B12, '01_BOC_TACH_ONG'!K:K) | I12: =SUMIF('02_BOC_TACH_CUA'!B:B, B12, '02_BOC_TACH_CUA'!K:K) | J12: =SUMIF('03_BOC_TACH_VAN'!B:B, B12, '03_BOC_TACH_VAN'!K:K) | K12: =SUM(H12:J12) | L12: =(K12-SUMIFS('03_BOC_TACH_VAN'!K:K, '03_BOC_TACH_VAN'!B:B, B12, '03_BOC_TACH_VAN'!D:D, "ĐỘNG_CƠ_VÀ_CẢM_BIẾN"))*0.25 | M12: =(K12-SUMIFS('03_BOC_TACH_VAN'!K:K, '03_BOC_TACH_VAN'!B:B, B12, '03_BOC_TACH_VAN'!D:D, "ĐỘNG_CƠ_VÀ_CẢM_BIẾN"))*0.10 | N12: =K12+L12+M12 | O12: =IF(G12>0, N12/G12, 0) | P12: 0.18 | Q12: =IF(G12>0, ((N12-SUMIFS('03_BOC_TACH_VAN'!K:K, '03_BOC_TACH_VAN'!B:B, B12, '03_BOC_TACH_VAN'!D:D, "ĐỘNG_CƠ_VÀ_CẢM_BIẾN"))*(1+P12)+SUMIFS('03_BOC_TACH_VAN'!K:K, '03_BOC_TACH_VAN'!B:B, B12, '03_BOC_TACH_VAN'!D:D, "ĐỘNG_CƠ_VÀ_CẢM_BIẾN"))/G12, 0) | R12: =G12*Q12
A13: 12 | B13: SW-DAMPER-012 | C13: VAN GIÓ | D13: VẬT TƯ THI CÔNG H1: (số BNH_DXVT_H1_29_M_Van MD, FD, VCD hệ HVAC trong phòng JS/DD, K1/DD, K1/AR, K1/K1 tầng 10-19 tòa H1) Van chặn lửa MFD - EI45 - Kích thước: 150x150 | E13: 150x150 | F13: Cái | G13: 19 | H13: =SUMIF('01_BOC_TACH_ONG'!B:B, B13, '01_BOC_TACH_ONG'!K:K) | I13: =SUMIF('02_BOC_TACH_CUA'!B:B, B13, '02_BOC_TACH_CUA'!K:K) | J13: =SUMIF('03_BOC_TACH_VAN'!B:B, B13, '03_BOC_TACH_VAN'!K:K) | K13: =SUM(H13:J13) | L13: =(K13-SUMIFS('03_BOC_TACH_VAN'!K:K, '03_BOC_TACH_VAN'!B:B, B13, '03_BOC_TACH_VAN'!D:D, "ĐỘNG_CƠ_VÀ_CẢM_BIẾN"))*0.25 | M13: =(K13-SUMIFS('03_BOC_TACH_VAN'!K:K, '03_BOC_TACH_VAN'!B:B, B13, '03_BOC_TACH_VAN'!D:D, "ĐỘNG_CƠ_VÀ_CẢM_BIẾN"))*0.10 | N13: =K13+L13+M13 | O13: =IF(G13>0, N13/G13, 0) | P13: 0.18 | Q13: =IF(G13>0, ((N13-SUMIFS('03_BOC_TACH_VAN'!K:K, '03_BOC_TACH_VAN'!B:B, B13, '03_BOC_TACH_VAN'!D:D, "ĐỘNG_CƠ_VÀ_CẢM_BIẾN"))*(1+P13)+SUMIFS('03_BOC_TACH_VAN'!K:K, '03_BOC_TACH_VAN'!B:B, B13, '03_BOC_TACH_VAN'!D:D, "ĐỘNG_CƠ_VÀ_CẢM_BIẾN"))/G13, 0) | R13: =G13*Q13
... A23: 22 | B23: SW-DAMPER-022 | C23: VAN GIÓ | D23: Van gió, miệng gió Van điều gió MD - Kích thước: 150x100 | E23: 150x100 | F23: Cái | G23: 55 | H23: =SUMIF('01_BOC_TACH_ONG'!B:B, B23, '01_BOC_TACH_ONG'!K:K) | I23: =SUMIF('02_BOC_TACH_CUA'!B:B, B23, '02_BOC_TACH_CUA'!K:K) | J23: =SUMIF('03_BOC_TACH_VAN'!B:B, B23, '03_BOC_TACH_VAN'!K:K) | K23: =SUM(H23:J23) | L23: =(K23-SUMIFS('03_BOC_TACH_VAN'!K:K, '03_BOC_TACH_VAN'!B:B, B23, '03_BOC_TACH_VAN'!D:D, "ĐỘNG_CƠ_VÀ_CẢM_BIẾN"))*0.25 | M23: =(K23-SUMIFS('03_BOC_TACH_VAN'!K:K, '03_BOC_TACH_VAN'!B:B, B23, '03_BOC_TACH_VAN'!D:D, "ĐỘNG_CƠ_VÀ_CẢM_BIẾN"))*0.10 | N23: =K23+L23+M23 | O23: =IF(G23>0, N23/G23, 0) | P23: 0.18 | Q23: =IF(G23>0, ((N23-SUMIFS('03_BOC_TACH_VAN'!K:K, '03_BOC_TACH_VAN'!B:B, B23, '03_BOC_TACH_VAN'!D:D, "ĐỘNG_CƠ_VÀ_CẢM_BIẾN"))*(1+P23)+SUMIFS('03_BOC_TACH_VAN'!K:K, '03_BOC_TACH_VAN'!B:B, B23, '03_BOC_TACH_VAN'!D:D, "ĐỘNG_CƠ_VÀ_CẢM_BIẾN"))/G23, 0) | R23: =G23*Q23
A24: 23 | B24: SW-UNKN-023 | C24: HẠNG MỤC KHÁC | D24: Van gió, miệng gió Chi phí kiểm định | E24: - | F24: lô | G24: 1 | H24: =SUMIF('01_BOC_TACH_ONG'!B:B, B24, '01_BOC_TACH_ONG'!K:K) | I24: =SUMIF('02_BOC_TACH_CUA'!B:B, B24, '02_BOC_TACH_CUA'!K:K) | J24: =SUMIF('03_BOC_TACH_VAN'!B:B, B24, '03_BOC_TACH_VAN'!K:K) | K24: =SUM(H24:J24) | L24: =(K24-SUMIFS('03_BOC_TACH_VAN'!K:K, '03_BOC_TACH_VAN'!B:B, B24, '03_BOC_TACH_VAN'!D:D, "ĐỘNG_CƠ_VÀ_CẢM_BIẾN"))*0.00 | M24: =(K24-SUMIFS('03_BOC_TACH_VAN'!K:K, '03_BOC_TACH_VAN'!B:B, B24, '03_BOC_TACH_VAN'!D:D, "ĐỘNG_CƠ_VÀ_CẢM_BIẾN"))*0.02 | N24: =K24+L24+M24 | O24: =IF(G24>0, N24/G24, 0) | P24: 0.1 | Q24: =IF(G24>0, ((N24-SUMIFS('03_BOC_TACH_VAN'!K:K, '03_BOC_TACH_VAN'!B:B, B24, '03_BOC_TACH_VAN'!D:D, "ĐỘNG_CƠ_VÀ_CẢM_BIẾN"))*(1+P24)+SUMIFS('03_BOC_TACH_VAN'!K:K, '03_BOC_TACH_VAN'!B:B, B24, '03_BOC_TACH_VAN'!D:D, "ĐỘNG_CƠ_VÀ_CẢM_BIẾN"))/G24, 0) | R24: =G24*Q24
A25: 24 | B25: SW-UNKN-024 | C25: HẠNG MỤC KHÁC | D25: Van gió, miệng gió Vận chuyển | E25: - | F25: lô | G25: 1 | H25: =SUMIF('01_BOC_TACH_ONG'!B:B, B25, '01_BOC_TACH_ONG'!K:K) | I25: =SUMIF('02_BOC_TACH_CUA'!B:B, B25, '02_BOC_TACH_CUA'!K:K) | J25: =SUMIF('03_BOC_TACH_VAN'!B:B, B25, '03_BOC_TACH_VAN'!K:K) | K25: =SUM(H25:J25) | L25: =(K25-SUMIFS('03_BOC_TACH_VAN'!K:K, '03_BOC_TACH_VAN'!B:B, B25, '03_BOC_TACH_VAN'!D:D, "ĐỘNG_CƠ_VÀ_CẢM_BIẾN"))*0.00 | M25: =(K25-SUMIFS('03_BOC_TACH_VAN'!K:K, '03_BOC_TACH_VAN'!B:B, B25, '03_BOC_TACH_VAN'!D:D, "ĐỘNG_CƠ_VÀ_CẢM_BIẾN"))*0.02 | N25: =K25+L25+M25 | O25: =IF(G25>0, N25/G25, 0) | P25: 0.1 | Q25: =IF(G25>0, ((N25-SUMIFS('03_BOC_TACH_VAN'!K:K, '03_BOC_TACH_VAN'!B:B, B25, '03_BOC_TACH_VAN'!D:D, "ĐỘNG_CƠ_VÀ_CẢM_BIẾN"))*(1+P25)+SUMIFS('03_BOC_TACH_VAN'!K:K, '03_BOC_TACH_VAN'!B:B, B25, '03_BOC_TACH_VAN'!D:D, "ĐỘNG_CƠ_VÀ_CẢM_BIẾN"))/G25, 0) | R25: =G25*Q25
A26: TỔNG CỘNG | H26: =SUM(H2:H25) | I26: =SUM(I2:I25) | J26: =SUM(J2:J25) | K26: =SUM(K2:K25) | L26: =SUM(L2:L25) | M26: =SUM(M2:M25) | N26: =SUM(N2:N25) | R26: =SUM(R2:R25)

Sheet 01_BOC_TACH_ONG
A1: SUB_KEY | B1: PARENT_ITEM_ID | C1: TÊN CẤU KIỆN | D1: PHÂN LOẠI | E1: MÃ VẬT TƯ (MAT_ID) | F1: ĐVT | G1: ĐỊNH MỨC / 1 SP | H1: SL DỰ ÁN | I1: TỔNG NHU CẦU | J1: ĐƠN GIÁ GỐC | K1: THÀNH TIỀN (VNĐ) | L1: GHI CHÚ KỸ THUẬT
A2: SW-UNKN-023-TM | B2: SW-UNKN-023 | C2: Van gió, miệng gió Chi phí kiểm định | D2: KHAC | E2: MAT-KHAC-CHI_PHI_KIEM_DINH | F2: lô | G2: 1 | H2: =IFERROR(INDEX('00_TONG_HOP_BAO_GIA'!$G$1:$G$5000, MATCH(B2, '00_TONG_HOP_BAO_GIA'!$B$1:$B$5000, 0)), 1) | I2: =G2*H2 | J2: =IFERROR(INDEX('06_BANG_GIA_VAT_TU_AP_DUNG'!$E$1:$E$5000, MATCH(E2, '06_BANG_GIA_VAT_TU_AP_DUNG'!$B$1:$B$5000, 0)), 0) | K2: =I2*J2 | L2: Hàng thương mại mua ngoài
